Workbook
Name _bdm.146e958bbea04416b86a4d5943392c04.edm: Model!$M$100
Name _bdm.bf5a9ed53fe44c598e3cfb84ac34b21f.edm: Integrity!$F$36
Name Case_Scenario: Cover!$F$22
Name Company_Cyclical_Multiples_Data: 'Multiples Data'!$C$14:$H$26
Name Company_Name: Cover!$F$19
Name Company_Rev_Methodology: 'Revenue Build'!$C$7
Name Cost_of_Debt: WACC!$G$17
Name Cost_of_Equity: WACC!$G$25
Name Cost_of_Preferred: WACC!$G$10
Name Current_Date: Cover!$F$27
Name Cycle_Period_Toggle: Valuation!$G$225
Name Cycle_Toggle: Valuation!$G$224
Name Cyclical_LTM_NTM_Toggle: Valuation!$G$226
Name Cyclical_Peer_Group_Toggle: Valuation!$G$227
Name Data: Model!$C$25:$AK$160
Name Diluted_Shares: Cover!$F$35
Name Discount_Rate: WACC!$O$13
Name Div_Yield: Cover!$F$34
Name ERP: WACC!$G$7
Name Fiscal_Periods: Model!$C$25:$AG$25
Name Hun: Cover!$F$41
Name IQRCIQIDLocaterI12: 'CIQ ID Locater'!$J$12:$N$12
Name IQRCIQIDLocaterI13: 'CIQ ID Locater'!$J$13:$N$13
Name IQRCIQIDLocaterI14: 'CIQ ID Locater'!$J$14:$N$14
Name IQRCIQIDLocaterI15: 'CIQ ID Locater'!$J$15:$N$15
Name IQRCIQIDLocaterI16: 'CIQ ID Locater'!$J$16:$N$16
Name IQRCIQIDLocaterI17: 'CIQ ID Locater'!$J$17:$N$17
Name IQRCIQIDLocaterI18: 'CIQ ID Locater'!$J$18:$N$18
Name IQRCIQIDLocaterI19: 'CIQ ID Locater'!$J$19:$N$19
Name IQRCIQIDLocaterI20: 'CIQ ID Locater'!$J$20:$N$20
Name IQRCIQIDLocaterI21: 'CIQ ID Locater'!$J$21:$L$21
Name IQRCIQIDLocaterI22: 'CIQ ID Locater'!$J$22:$N$22
Name IQRCIQIDLocaterI23: 'CIQ ID Locater'!$J$23:$N$23
Name IQRCIQIDLocaterI24: 'CIQ ID Locater'!$J$24:$N$24
Name IQRCIQIDLocaterI25: 'CIQ ID Locater'!$J$25:$N$25
Name IQRCIQIDLocaterI26: 'CIQ ID Locater'!$J$26:$N$26
Name IQRCIQIDLocaterI27: 'CIQ ID Locater'!$J$27:$N$27
Name IQRCIQIDLocaterI28: 'CIQ ID Locater'!$J$28:$K$28
Name IQRCIQIDLocaterI29: 'CIQ ID Locater'!$J$29
Name IQRCIQIDLocaterO12: 'CIQ ID Locater'!$P$12:$T$12
Name IQRCIQIDLocaterO13: 'CIQ ID Locater'!$P$13:$T$13
Name IQRCIQIDLocaterO14: 'CIQ ID Locater'!$P$14:$T$14
Name IQRCIQIDLocaterO15: 'CIQ ID Locater'!$P$15:$T$15
Name IQRCIQIDLocaterO16: 'CIQ ID Locater'!$P$16:$T$16
Name IQRCIQIDLocaterO17: 'CIQ ID Locater'!$P$17:$T$17
Name IQRCIQIDLocaterO18: 'CIQ ID Locater'!$P$18:$T$18
Name IQRCIQIDLocaterO19: 'CIQ ID Locater'!$P$19:$T$19
Name IQRCIQIDLocaterO20: 'CIQ ID Locater'!$P$20:$T$20
Name IQRCIQIDLocaterO21: 'CIQ ID Locater'!$P$21:$R$21
Name IQRCIQIDLocaterO22: 'CIQ ID Locater'!$P$22:$T$22
Name IQRCIQIDLocaterO23: 'CIQ ID Locater'!$P$23:$T$23
Name IQRCIQIDLocaterO24: 'CIQ ID Locater'!$P$24:$T$24
Name IQRCIQIDLocaterO25: 'CIQ ID Locater'!$P$25:$T$25
Name IQRCIQIDLocaterO26: 'CIQ ID Locater'!$P$26:$T$26
Name IQRCIQIDLocaterO27: 'CIQ ID Locater'!$P$27:$T$27
Name IQRCIQIDLocaterO28: 'CIQ ID Locater'!$P$28:$Q$28
Name IQRCIQIDLocaterO29: 'CIQ ID Locater'!$P$29
Name IQRCompaniesH13: 'CIQ ID Locater'!$J$12:$N$12
Name IQRCompaniesH14: 'CIQ ID Locater'!$J$13:$N$13
Name IQRCompaniesH15: 'CIQ ID Locater'!$J$14:$N$14

Sheet Cover
C1: =Company_Name&" - "&MID(CELL("filename",A1),FIND("]",CELL("filename",A1))+1,255)&": "&Case_Scenario&" Case" -> Jefferies Financial Group Inc. - Cover: Base Case | Q1: Font Toggle
C2: $ in Millions Except Per Share Data | Q2: Report
R3: x
A4: x | C4: Model Assumptions: | I4: Return Summary:
I6: Dividend Discount Model | N6: Multiple Analysis
I8: Exit Multiple Method | N8: EV/EBITDA Method
I9: Implied Enterprise Value: | L9: =Valuation!K69 -> 15177.212 | P9: Target Price: | Q9: % Return:
I10: Implied Equity Value: | L10: =Valuation!K76 -> 15177.212
N11: 1 Year LTM EV/EBITDA | P11: =Valuation!N141 -> 85.73526 | Q11: =Valuation!N142 -> 1.2544113
I12: Implied Share Price: | L12: =Valuation!K80 -> 68.136855
I13: % Return: | L13: =Valuation!K81 -> 0.79166065 | N13: 2009-2018 Late Cycle EV/EBITDA | P13: =Valuation!N219 -> 22.922881 | Q13: =Valuation!N220 -> -0.39724216
I15: Dividend Discount Model | N15: P/E Multiple Method
I16: Implied Enterprise Value: | L16: =Valuation!R69 -> 16987.417 | P16: Target Price: | Q16: % Return:
I17: Implied Equity Value: | L17: =Valuation!R76 -> 16987.417
N18: 1 Year LTM P/E | P18: =Valuation!F130 -> 122.96551 | Q18: =Valuation!F131 -> 2.2333818
C19: Company Name | F19: Jefferies Financial Group Inc. | I19: Implied Share Price: | L19: =Valuation!R80 -> 76.263622
C20: Ticker | F20: JEF | I20: % Return: | L20: =Valuation!R81 -> 1.0053543 | N20: 2009-2018 Late Cycle P/E | P20: =Valuation!F208 -> 131.11759 | Q20: =Valuation!F209 -> 2.447741
C22: Case Scenario | F22: Base | I22: Table of Contents
C24: Last Fiscal Year | F24: 45992 | I24: Cover
C25: Next Fiscal Year | F25: =Last_FYE+365 -> 46357 | I25: Summary
C26: Last Fiscal Quarter Reported | F26: 4Q | I26: Football Field
C27: Current Valuation Date | F27: 46091 | I27: Integrity
I28: Revenue Build
C29: Current Share Price | F29: 38.03 | I29: Model
C30: 52-Week High | F30: 17.04 | I30: Segment Analysis
C31: 52-Week Low | F31: 35.72 | I31: Drivers
I32: WACC
C33: Effective Tax Rate | F33: =IF(Last_FQR="1Q",Model!P71,IF(Last_FQR="2Q",Model!Q71,IF(Last_FQR="3Q",Model!R71,Model!S71))) -> 0.18721229 | I33: Valuation
C34: Dividend Yield | F34: =IF(Last_FQR="1Q",Model!U268,IF(Last_FQR="2Q",Model!V268,IF(Last_FQR="3Q",Model!W268,Model!X268))) -> 0.048216782 | I34: Comparables
C35: Diluted Shares Outstanding (MRQ) | F35: =IF(Last_FQR="1Q",Model!P287,IF(Last_FQR="2Q",Model!Q287,IF(Last_FQR="3Q",Model!R287,Model!S287))) -> 222.746 | I35: Charts
I36: Benchmark
C37: Model Type | F37: Top Down | I37: Multiples Data
I38: Pre-Earnings
I39: Post-Earnings
A42: x
C43: Model Color Legend | I43: Constants
C44: Blue = Hard-Coded Value (historical values & assumptions) | I44: Reference | J44: Type | K44: Name | L44: Value
C45: Black = Formulas | I45: Million | J45: (#) | K45: Mil | L45: 1000000
C46: Green = Linked Value (from separate worksheet) | I46: Thousand | J46: (#) | K46: Thou | L46: 1000
C47: Red = Unique Formula / Anomaly | I47: Hundred | J47: (#) | K47: Hun | L47: 100
...

Sheet Summary
C1: =Company_Name&" - "&MID(CELL("filename",A1),FIND("]",CELL("filename",A1))+1,255)&": "&Case_Scenario&" Case" -> Jefferies Financial Group Inc. - Summary: Base Case
C2: =Cover!C2 -> $ in Millions Except Per Share Data
C4: Year: | T4: =Model!J24 -> 2023 | U4: =Model!O24 -> 2024 | V4: =Model!T24 -> 2025 | W4: =Model!Y24 -> 2026 | X4: =Model!AD24 -> 2027 | Y4: =Model!AE24 -> 2028 | Z4: =Model!AF24 -> 2029 | AA4: =Model!AG24 -> 2030
G5: Quarterly | T5: Annuals | AC5: CAGR | AE5: CAGR
A6: x | C6: ="Consolidated "&Model!C25 -> Consolidated Income Statement | G6: =Model!P25 -> 1Q25 | H6: =Model!Q25 -> 2Q25 | I6: =Model!R25 -> 3Q25 | J6: =Model!S25 -> 4Q25 | K6: =Model!U25 -> 1Q26e | L6: =Model!V25 -> 2Q26e | M6: =Model!W25 -> 3Q26 | N6: =Model!X25 -> 4Q26e | O6: =Model!Z25 -> 1Q27e | P6: =Model!AA25 -> 2Q27e | Q6: =Model!AB25 -> 3Q27e | R6: =Model!AC25 -> 4Q27e | T6: =Model!J25 -> 2023 | U6: =Model!O25 -> 2024 | V6: =Model!T25 -> 2025 | W6: =Model!Y25 -> 2026e | X6: =Model!AD25 -> 2027e | Y6: =Model!AE25 -> 2028e | Z6: =Model!AF25 -> 2029e | AA6: =Model!AG25 -> 2030e | AC6: Historical | AE6: Projected
C8: =Model!C28 -> Revenue | G8: =Model!P28 -> 2472.864 | H8: =Model!Q28 -> 2494.315 | I8: =Model!R28 -> 2907.674 | J8: =Model!S28 -> 2948.824 | K8: =Model!U28 -> 2742.8525 | L8: =Model!V28 -> 2804.4553 | M8: =Model!W28 -> 3225.2028 | N8: =Model!X28 -> 3219.018 | O8: =Model!Z28 -> 2948.7114 | P8: =Model!AA28 -> 3086.9714 | Q8: =Model!AB28 -> 3511.4181 | R8: =Model!AC28 -> 3473.729 | T8: =Model!J28 -> 7441.38 | U8: =Model!O28 -> 10515.069 | V8: =Model!T28 -> 10823.677 | W8: =Model!Y28 -> 11991.529 | X8: =Model!AD28 -> 13020.83 | Y8: =Model!AE28 -> 13894.991 | Z8: =Model!AF28 -> 14550.917 | AA8: =Model!AG28 -> 14977.126 | AC8: =IFERROR((V8/T8)^(1/(V$4-T$4))-1,"N/A") -> 0.20603711 | AE8: =IFERROR((AA8/V8)^(1/(AA$4-V$4))-1,"N/A") -> 0.067113784
C9: YoY % Growth | K9: =K8/G8-1 -> 0.10918049 | L9: =L8/H8-1 -> 0.12433886 | M9: =M8/I8-1 -> 0.1092037 | N9: =N8/J8-1 -> 0.091627703 | O9: =O8/K8-1 -> 0.075052853 | P9: =P8/L8-1 -> 0.10073833 | Q9: =Q8/M8-1 -> 0.088743357 | R9: =R8/N8-1 -> 0.079126933 | U9: =IF(ISERROR(U8/T8-1),"NA",(U8/T8-1)) -> 0.41305363 | V9: =IF(ISERROR(V8/U8-1),"NA",(V8/U8-1)) -> 0.029349118 | W9: =IF(ISERROR(W8/V8-1),"NA",(W8/V8-1)) -> 0.10789785 | X9: =IF(ISERROR(X8/W8-1),"NA",(X8/W8-1)) -> 0.085835711 | Y9: =IF(ISERROR(Y8/X8-1),"NA",(Y8/X8-1)) -> 0.067135576 | Z9: =IF(ISERROR(Z8/Y8-1),"NA",(Z8/Y8-1)) -> 0.047205916 | AA9: =IF(ISERROR(AA8/Z8-1),"NA",(AA8/Z8-1)) -> 0.029290872
C11: =Model!C30 -> Net Revenue | G11: =Model!P30 -> 1593.019 | H11: =Model!Q30 -> 1634.447 | I11: =Model!R30 -> 2047.432 | J11: =Model!S30 -> 2068.853 | K11: =Model!U30 -> 1901.7557 | L11: =Model!V30 -> 1909.5563 | M11: =Model!W30 -> 2275.2515 | N11: =Model!X30 -> 2296.619 | O11: =Model!Z30 -> 2067.0293 | P11: =Model!AA30 -> 2192.3393 | Q11: =Model!AB30 -> 2603.8359 | R11: =Model!AC30 -> 2553.1968 | T11: =Model!J30 -> 4700.398 | U11: =Model!O30 -> 7034.803 | V11: =Model!T30 -> 7343.751 | W11: =Model!Y30 -> 8383.1825 | X11: =Model!AD30 -> 9416.4013 | Y11: =Model!AE30 -> 17136.804 | Z11: =Model!AF30 -> 17477.729 | AA11: =Model!AG30 -> 17588.938 | AC11: =IFERROR((V11/T11)^(1/(V$4-T$4))-1,"N/A") -> 0.24994716 | AE11: =IFERROR((AA11/V11)^(1/(AA$4-V$4))-1,"N/A") -> -0.0044007877
C12: % Margin | G12: =G11/G$8 -> 0.6442 | H12: =H11/H$8 -> 0.65526888 | I12: =I11/I$8 -> 0.70414771 | J12: =J11/J$8 -> 0.70158578 | K12: =K11/K$8 -> 0.69334962 | L12: =L11/L$8 -> 0.68090095 | M12: =M11/M$8 -> 0.70546 | N12: =N11/N$8 -> 0.71345329 | ... R12: =R11/R$8 -> 0.73500174 | T12: =T11/T$8 -> 0.63165676 | U12: =U11/U$8 -> 0.6690211 | V12: =V11/V$8 -> 0.67848948 | W12: =W11/W$8 -> 0.69909207 | X12: =X11/X$8 -> 0.72317981 | Y12: =Y11/Y$8 -> 0.81400555 | Z12: =Z11/Z$8 -> 0.8051149 | AA12: =AA11/AA$8 -> 0.79463636
C13: YoY % Growth | K13: =K11/G11-1 -> 0.19380606 | L13: =L11/H11-1 -> 0.16831948 | M13: =M11/I11-1 -> 0.11127086 | N13: =N11/J11-1 -> 0.11009287 | O13: =O11/K11-1 -> 0.086905762 | P13: =P11/L11-1 -> 0.14808832 | Q13: =Q11/M11-1 -> 0.14441674 | R13: =R11/N11-1 -> 0.11171983 | U13: =U11/T11-1 -> 0.49663986 | V13: =V11/U11-1 -> 0.043917079 | W13: =W11/V11-1 -> 0.14153959 | X13: =X11/W11-1 -> 0.12324899 | Y13: =Y11/X11-1 -> 0.033966301 | Z13: =Z11/Y11-1 -> 0.019894361 | AA13: =AA11/Z11-1 -> 0.0063628991
C15: =Model!C36 -> EBIT | G15: =Model!P36 -> 151.065 | H15: =Model!Q36 -> 134.901 | I15: =Model!R36 -> 331.815 | J15: =Model!S36 -> 200.505 | K15: =Model!U36 -> 292.56286 | L15: =Model!V36 -> 304.63348 | M15: =Model!W36 -> 359.57675 | N15: =Model!X36 -> 355.9426 | O15: =Model!Z36 -> 323.22138 | P15: =Model!AA36 -> 363.16369 | Q15: =Model!AB36 -> 486.00622 | R15: =Model!AC36 -> 512.82612 | T15: =Model!J36 -> 312.997 | U15: =Model!O36 -> 954.493 | V15: =Model!T36 -> 818.286 | W15: =Model!Y36 -> 1312.7157 | X15: =Model!AD36 -> 1685.2174 | Y15: =Model!AE36 -> 3110.8208 | Z15: =Model!AF36 -> 3232.3522 | AA15: =Model!AG36 -> 3112.2301 | AC15: =IFERROR((V15/T15)^(1/(V$4-T$4))-1,"N/A") -> 0.61689744 | AE15: =IFERROR((AA15/V15)^(1/(AA$4-V$4))-1,"N/A") -> -0.22943319
C16: Margin | G16: =G15/G$8 -> 0.061089085 | H16: =H15/H$8 -> 0.054083386 | I16: =I15/I$8 -> 0.11411699 | J16: =J15/J$8 -> 0.067994902 | K16: =K15/K$8 -> 0.10666372 | L16: =L15/L$8 -> 0.10862483 | M16: =M15/M$8 -> 0.11148966 | N16: =N15/N$8 -> 0.1105749 | ... R16: =R15/R$8 -> 0.14762986 | T16: =T15/T$8 -> 0.042061687 | U16: =U15/U$8 -> 0.090773822 | V16: =V15/V$8 -> 0.07560148 | W16: =W15/W$8 -> 0.10947026 | X16: =X15/X$8 -> 0.12942473 | Y16: =Y15/Y$8 -> 0.14776533 | Z16: =Z15/Z$8 -> 0.14889891 | AA16: =AA15/AA$8 -> 0.14060491
C17: YoY % Growth | K17: =K15/G15-1 -> 0.93666875 | L17: =L15/H15-1 -> 1.2582003 | M17: =M15/I15-1 -> 0.083666355 | N17: =N15/J15-1 -> 0.77523055 | O17: =O15/K15-1 -> 0.10479292 | P17: =P15/L15-1 -> 0.19213321 | Q17: =Q15/M15-1 -> 0.35160634 | R17: =R15/N15-1 -> 0.4407551 | U17: =U15/T15-1 -> 2.0495276 | V17: =V15/U15-1 -> -0.14270089 | W17: =W15/V15-1 -> 0.60422603 | X17: =X15/W15-1 -> 0.28376419 | Y17: =Y15/X15-1 -> -0.04733965 | Z17: =Z15/Y15-1 -> 0.039067308 | AA17: =AA15/Z15-1 -> -0.037162443
C19: =Model!C45 -> Net Income (Loss) | G19: =Model!P45 -> 136.849 | H19: =Model!Q45 -> 91.395 | I19: =Model!R45 -> 242.504 | J19: =Model!S45 -> 162.968 | K19: =Model!U45 -> 424.59742 | L19: =Model!V45 -> 459.46574 | M19: =Model!W45 -> 556.81753 | N19: =Model!X45 -> 600.76235 | O19: =Model!Z45 -> 429.86838 | P19: =Model!AA45 -> 513.32841 | Q19: =Model!AB45 -> 692.89705 | R19: =Model!AC45 -> 796.63206 | T19: =Model!J45 -> 221.117 | U19: =Model!O45 -> 661.299 | V19: =Model!T45 -> 633.716 | W19: =Model!Y45 -> 2041.643 | X19: =Model!AD45 -> 2432.7259 | Y19: =Model!AE45 -> 2333.1156 | Z19: =Model!AF45 -> 2424.2642 | AA19: =Model!AG45 -> 2334.1726 | AC19: =IFERROR((V19/T19)^(1/(V$4-T$4))-1,"N/A") -> 0.69291935 | AE19: =IFERROR((AA19/V19)^(1/(AA$4-V$4))-1,"N/A") -> -0.27015037
C20: Margin | G20: =G19/G$8 -> 0.055340286 | H20: =H19/H$8 -> 0.036641322 | I20: =I19/I$8 -> 0.083401372 | J20: =J19/J$8 -> 0.055265421 | K20: =K19/K$8 -> 0.10595883 | L20: =L19/L$8 -> 0.10514652 | M20: =M19/M$8 -> 0.10674655 | N20: =N19/N$8 -> 0.10813321 | ... R20: =R19/R$8 -> 0.13710279 | T20: =T19/T$8 -> 0.029714515 | U20: =U19/U$8 -> 0.0628906 | V20: =V19/V$8 -> 0.058549049 | W20: =W19/W$8 -> 0.1066189 | X20: =X19/X$8 -> 0.12056161 | Y20: =Y19/Y$8 -> 0.110824 | Z20: =Z19/Z$8 -> 0.11167419 | AA20: =AA19/AA$8 -> 0.10545369
C21: YoY % Growth | K21: =K19/G19-1 -> -0.81385748 | L21: =L19/H19-1 -> -0.81742411 | M21: =M19/I19-1 -> -0.82002154 | N21: =N19/J19-1 -> -0.82224299 | O21: =O19/K19-1 -> 0.012414007 | P21: =P19/L19-1 -> 0.11722893 | Q21: =Q19/M19-1 -> 0.244388 | R21: =R19/N19-1 -> 0.32603525 | U21: =U19/T19-1 -> 1.9907198 | V21: =V19/U19-1 -> -0.041710331 | W21: =W19/V19-1 -> -0.81886023 | X21: =X19/W19-1 -> 0.19155301 | Y21: =Y19/X19-1 -> -0.040945957 | Z21: =Z19/Y19-1 -> 0.039067308 | AA21: =AA19/Z19-1 -> -0.037162443
C23: =Model!C57 -> Adj. EPS (Diluted) | G23: =Model!P57 -> 0.57448482 | H23: =Model!Q57 -> 0.39665701 | I23: =Model!R57 -> 1.0057068 | J23: =Model!S57 -> 0.62085066 | K23: =Model!U57 -> 1.7209234 | L23: =Model!V57 -> 1.8891797 | M23: =Model!W57 -> 2.4111437 | N23: =Model!X57 -> 2.6493809 | O23: =Model!Z57 -> 2.0839822 | P23: =Model!AA57 -> 2.2818863 | Q23: =Model!AB57 -> 3.765282 | R23: =Model!AC57 -> 4.5622886 | T23: =Model!J57 -> 0.94143039 | U23: =Model!O57 -> 2.7800045 | V23: =Model!T57 -> 2.5987148 | W23: =Model!Y57 -> 8.6101474 | X23: =Model!AD57 -> 12.353374 | Y23: =Model!AE57 -> 13.270804 | Z23: =Model!AF57 -> 14.142717 | AA23: =Model!AG57 -> 13.927518 | AC23: =IFERROR((V23/T23)^(1/(V$4-T$4))-1,"N/A") -> 0.66144206 | AE23: =IFERROR((AA23/V23)^(1/(AA$4-V$4))-1,"N/A") -> -0.22685961
C24: YoY % Growth | K24: =K23/G23-1 -> -0.83150542 | L24: =L23/H23-1 -> -0.83319912 | M24: =M23/I23-1 -> -0.82538262 | N24: =N23/J23-1 -> -0.82410201 | O24: =O23/K23-1 -> 0.21096742 | P24: =P23/L23-1 -> 0.20787151 | Q24: =Q23/M23-1 -> 0.56161658 | R24: =R23/N23-1 -> 0.72202066 | U24: =IF(ISERROR(U23/T23-1),"NA",(U23/T23-1)) -> 1.9529581 | V24: =IF(ISERROR(V23/U23-1),"NA",(V23/U23-1)) -> -0.065212015 | W24: =IF(ISERROR(W23/V23-1),"NA",(W23/V23-1)) -> -0.82922327 | X24: =IF(ISERROR(X23/W23-1),"NA",(X23/W23-1)) -> 0.43474593 | Y24: =IF(ISERROR(Y23/X23-1),"NA",(Y23/X23-1)) -> 0.074265558 | Z24: =IF(ISERROR(Z23/Y23-1),"NA",(Z23/Y23-1)) -> 0.065701543 | AA24: =IF(ISERROR(AA23/Z23-1),"NA",(AA23/Z23-1)) -> -0.015216239
C27: =Model!C61 -> EBITDA | G27: =Model!P61 -> 172.997 | H27: =Model!Q61 -> 183.776 | I27: =Model!R61 -> 366.527 | J27: =Model!S61 -> 231.639 | K27: =Model!U61 -> 567.45455 | L27: =Model!V61 -> 643.65199 | M27: =Model!W61 -> 773.93172 | N27: =Model!X61 -> 812.72041 | O27: =Model!Z61 -> 598.26973 | P27: =Model!AA61 -> 710.05986 | Q27: =Model!AB61 -> 950.0348 | R27: =Model!AC61 -> 1087.7121 | T27: =Model!J61 -> 425.882 | U27: =Model!O61 -> 1105.407 | V27: =Model!T61 -> 954.939 | W27: =Model!Y61 -> 2797.7587 | X27: =Model!AD61 -> 3346.0765 | Y27: =Model!AE61 -> 3157.2841 | Z27: =Model!AF61 -> 3253.925 | AA27: =Model!AG61 -> 3102.5611 | AC27: =IFERROR((V27/T27)^(1/(V$4-T$4))-1,"N/A") -> 0.49741843 | AE27: =IFERROR((AA27/V27)^(1/(AA$4-V$4))-1,"N/A") -> -0.23173679
C28: Margin | G28: =G27/G$8 -> 0.069958154 | H28: =H27/H$8 -> 0.073677944 | I28: =I27/I$8 -> 0.12605505 | J28: =J27/J$8 -> 0.07855301 | K28: =K27/K$8 -> 0.14160901 | L28: =L27/L$8 -> 0.14729666 | M28: =M27/M$8 -> 0.14836915 | N28: =N27/N$8 -> 0.14628424 | ... R28: =R27/R$8 -> 0.18719856 | T28: =T27/T$8 -> 0.057231589 | U28: =U27/U$8 -> 0.10512599 | V28: =V27/V$8 -> 0.088226857 | W28: =W27/W$8 -> 0.14610485 | X28: =X27/X$8 -> 0.16582566 | Y28: =Y27/Y$8 -> 0.14997235 | Z28: =Z27/Z$8 -> 0.14989267 | AA28: =AA27/AA$8 -> 0.14016809
C29: YoY % Growth | K29: =K27/G27-1 -> -0.75511006 | L29: =L27/H27-1 -> -0.75329126 | M29: =M27/I27-1 -> -0.759486 | N29: =N27/J27-1 -> -0.76431642 | O29: =O27/K27-1 -> 0.054304226 | P29: =P27/L27-1 -> 0.10317356 | Q29: =Q27/M27-1 -> 0.22754344 | R29: =R27/N27-1 -> 0.33835958 | U29: =U27/T27-1 -> 1.5955711 | V29: =V27/U27-1 -> -0.13612 | W29: =W27/V27-1 -> -0.75865402 | X29: =X27/W27-1 -> 0.19598469 | Y29: =Y27/X27-1 -> -0.056422037 | Z29: =Z27/Y27-1 -> 0.030608859 | AA29: =AA27/Z27-1 -> -0.0465173
G31: =G$5 -> Quarterly | T31: =T$5 -> Annuals
A32: x | C32: ="Consolidated "&Model!C118 -> Consolidated Balance Sheet | G32: =G$6 -> 1Q25 | H32: =H$6 -> 2Q25 | I32: =I$6 -> 3Q25 | J32: =J$6 -> 4Q25 | K32: =K$6 -> 1Q26e | L32: =L$6 -> 2Q26e | M32: =M$6 -> 3Q26 | N32: =N$6 -> 4Q26e | ... R32: =R$6 -> 4Q27e | T32: =T$6 -> 2023 | U32: =U$6 -> 2024 | V32: =V$6 -> 2025 | W32: =W$6 -> 2026e | X32: =X$6 -> 2027e | Y32: =Y$6 -> 2028e | Z32: =Z$6 -> 2029e | AA32: =AA$6 -> 2030e
C34: =Model!C120 -> Cash & Cash Equivalents | G34: =Model!P120 -> 11176.343 | H34: =Model!Q120 -> 11260.403 | I34: =Model!R120 -> 11458.472 | J34: =Model!S120 -> 14043.889 | K34: =Model!U120 -> 10920.875 | L34: =Model!V120 -> 7054.6019 | M34: =Model!W120 -> 4564.8948 | N34: =Model!X120 -> 3427.7628 | O34: =Model!Z120 -> -89.421945 | P34: =Model!AA120 -> 6885.2868 | Q34: =Model!AB120 -> 5225.7751 | R34: =Model!AC120 -> 4200.5393 | T34: =Model!J120 -> 8526.363 | U34: =Model!O120 -> 12153.414 | V34: =Model!T120 -> 14043.889 | W34: =Model!Y120 -> 3427.7628 | X34: =Model!AD120 -> 4200.5393 | Y34: =Model!AE120 -> 837.3867 | Z34: =Model!AF120 -> 3766.0503 | AA34: =Model!AG120 -> 5400.0619
C35: =Model!C121 -> Accounts Receivable | G35: =Model!P121 -> 6703.258 | H35: =Model!Q121 -> 6225.189 | I35: =Model!R121 -> 6627.64 | J35: =Model!S121 -> 8556.388 | K35: =Model!U121 -> 6911.9883 | L35: =Model!V121 -> 6955.0491 | M35: =Model!W121 -> 7869.4947 | N35: =Model!X121 -> 7725.6431 | O35: =Model!Z121 -> 7430.7528 | P35: =Model!AA121 -> 7655.6891 | Q35: =Model!AB121 -> 8567.8601 | R35: =Model!AC121 -> 8336.9496 | T35: =Model!J121 -> 4716.299 | U35: =Model!O121 -> 5824.844 | V35: =Model!T121 -> 8556.388 | W35: =Model!Y121 -> 7725.6431 | X35: =Model!AD121 -> 8336.9496 | Y35: =Model!AE121 -> 9170.6939 | Z35: =Model!AF121 -> 9458.0958 | AA35: =Model!AG121 -> 9735.1316
C36: =Model!C122 -> Inventory | G36: =Model!P122 -> 0 | H36: =Model!Q122 -> 0 | I36: =Model!R122 -> 0 | J36: =Model!S122 -> 0 | K36: =Model!U122 -> 0 | L36: =Model!V122 -> 0 | M36: =Model!W122 -> 0 | N36: =Model!X122 -> 0 | O36: =Model!Z122 -> 0 | P36: =Model!AA122 -> 0 | Q36: =Model!AB122 -> 0 | R36: =Model!AC122 -> 0 | T36: =Model!J122 -> 0 | U36: =Model!O122 -> 0 | V36: =Model!T122 -> 0 | W36: =Model!Y122 -> 0 | X36: =Model!AD122 -> 0 | Y36: =Model!AE122 -> 0 | Z36: =Model!AF122 -> 0 | AA36: =Model!AG122 -> 0
C37: =Model!C123 -> Prepaid & Other Current Assets | G37: =Model!P123 -> 45950.985 | H37: =Model!Q123 -> 43438.891 | I37: =Model!R123 -> 44833.717 | J37: =Model!S123 -> 47081.324 | K37: =Model!U123 -> 50334.698 | L37: =Model!V123 -> 58997.556 | M37: =Model!W123 -> 63208.339 | N37: =Model!X123 -> 66708.665 | O37: =Model!Z123 -> 67969.214 | P37: =Model!AA123 -> 64201.312 | Q37: =Model!AB123 -> 67282.81 | R37: =Model!AC123 -> 70459.2 | T37: =Model!J123 -> 37552.851 | U37: =Model!O123 -> 40235.206 | V37: =Model!T123 -> 47081.324 | W37: =Model!Y123 -> 66708.665 | X37: =Model!AD123 -> 70459.2 | Y37: =Model!AE123 -> 77211.716 | Z37: =Model!AF123 -> 78168.048 | AA37: =Model!AG123 -> 80448.789
C38: =Model!C124 -> Total Current Assets | G38: =SUM(G34:G37) -> 63830.586 | H38: =SUM(H34:H37) -> 60924.483 | I38: =SUM(I34:I37) -> 62919.829 | J38: =SUM(J34:J37) -> 69681.601 | K38: =SUM(K34:K37) -> 71353.698 | L38: =SUM(L34:L37) -> 76889.178 | M38: =SUM(M34:M37) -> 80500.903 | N38: =SUM(N34:N37) -> 83470.257 | ... R38: =SUM(R34:R37) -> 88604.874 | T38: =SUM(T34:T37) -> 50795.513 | U38: =SUM(U34:U37) -> 58213.464 | V38: =SUM(V34:V37) -> 69681.601 | W38: =SUM(W34:W37) -> 83470.257 | X38: =SUM(X34:X37) -> 88604.874 | Y38: =SUM(Y34:Y37) -> 91943.713 | Z38: =SUM(Z34:Z37) -> 96044.537 | AA38: =SUM(AA34:AA37) -> 100236.33
C40: =Model!C125 -> PP&E, Net | G40: =Model!P126 -> 1217.202 | H40: =Model!Q126 -> 1235.343 | I40: =Model!R126 -> 1255 | J40: =Model!S126 -> 1246.47 | K40: =Model!U126 -> 1250.5117 | L40: =Model!V126 -> 1254.4012 | M40: =Model!W126 -> 1252.1224 | N40: =Model!X126 -> 1250.7918 | O40: =Model!Z126 -> 1251.9023 | P40: =Model!AA126 -> 1251.6051 | Q40: =Model!AB126 -> 1244.9303 | R40: =Model!AC126 -> 1238.5756 | T40: =Model!J126 -> 1065.68 | U40: =Model!O126 -> 1194.72 | V40: =Model!T126 -> 1246.47 | W40: =Model!Y126 -> 1250.7918 | X40: =Model!AD126 -> 1238.5756 | Y40: =Model!AE126 -> 1212.2213 | Z40: =Model!AF126 -> 1172.1541 | AA40: =Model!AG126 -> 1117.4596
C41: =Model!C127 -> Intangible Assets, Net | G41: =Model!P127 -> 0 | H41: =Model!Q127 -> 0 | I41: =Model!R127 -> 0 | J41: =Model!S127 -> 0 | K41: =Model!U127 -> 0 | L41: =Model!V127 -> 0 | M41: =Model!W127 -> 0 | N41: =Model!X127 -> 0 | O41: =Model!Z127 -> 0 | P41: =Model!AA127 -> 0 | Q41: =Model!AB127 -> 0 | R41: =Model!AC127 -> 0 | T41: =Model!J127 -> 0 | U41: =Model!O127 -> 0 | V41: =Model!T127 -> 0 | W41: =Model!Y127 -> 0 | X41: =Model!AD127 -> 0 | Y41: =Model!AE127 -> 0 | Z41: =Model!AF127 -> 0 | AA41: =Model!AG127 -> 0
C42: =Model!C128 -> Goodwill | G42: =Model!P128 -> 1824.647 | H42: =Model!Q128 -> 1842.114 | I42: =Model!R128 -> 1840.432 | J42: =Model!S128 -> 1837.57 | K42: =Model!U128 -> 1837.57 | L42: =Model!V128 -> 1837.57 | M42: =Model!W128 -> 1837.57 | N42: =Model!X128 -> 1837.57 | O42: =Model!Z128 -> 1837.57 | P42: =Model!AA128 -> 1837.57 | Q42: =Model!AB128 -> 1837.57 | R42: =Model!AC128 -> 1837.57 | T42: =Model!J128 -> 1847.856 | U42: =Model!O128 -> 1827.938 | V42: =Model!T128 -> 1837.57 | W42: =Model!Y128 -> 1837.57 | X42: =Model!AD128 -> 1837.57 | Y42: =Model!AE128 -> 1837.57 | Z42: =Model!AF128 -> 1837.57 | AA42: =Model!AG128 -> 1837.57
C43: =Model!C129 -> Other Non-Current Assets | G43: =Model!P129 -> 3346.456 | H43: =Model!Q129 -> 3283.404 | I43: =Model!R129 -> 3304.448 | J43: =Model!S129 -> 3246.706 | K43: =Model!U129 -> 3311.6401 | L43: =Model!V129 -> 3377.8729 | M43: =Model!W129 -> 3445.4304 | N43: =Model!X129 -> 3514.339 | O43: =Model!Z129 -> 3584.6258 | P43: =Model!AA129 -> 3656.3183 | Q43: =Model!AB129 -> 3729.4446 | R43: =Model!AC129 -> 3804.0335 | T43: =Model!J129 -> 4196.112 | U43: =Model!O129 -> 3124.187 | V43: =Model!T129 -> 3246.706 | W43: =Model!Y129 -> 3514.339 | X43: =Model!AD129 -> 3804.0335 | Y43: =Model!AE129 -> 4089.3361 | Z43: =Model!AF129 -> 4498.2697 | AA43: =Model!AG129 -> 4880.6226
C44: =Model!C130 -> Total Non-Current Assets | G44: =SUM(G40:G43) -> 6388.305 | H44: =SUM(H40:H43) -> 6360.861 | I44: =SUM(I40:I43) -> 6399.88 | J44: =SUM(J40:J43) -> 6330.746 | K44: =SUM(K40:K43) -> 6399.7219 | L44: =SUM(L40:L43) -> 6469.8441 | M44: =SUM(M40:M43) -> 6535.1228 | N44: =SUM(N40:N43) -> 6602.7007 | ... R44: =SUM(R40:R43) -> 6880.1791 | T44: =SUM(T40:T43) -> 7109.648 | U44: =SUM(U40:U43) -> 6146.845 | V44: =SUM(V40:V43) -> 6330.746 | W44: =SUM(W40:W43) -> 6602.7007 | X44: =SUM(X40:X43) -> 6880.1791 | Y44: =SUM(Y40:Y43) -> 7139.1274 | Z44: =SUM(Z40:Z43) -> 7507.9938 | AA44: =SUM(AA40:AA43) -> 7835.6522
C46: =Model!C132 -> Total Assets | G46: =SUM(G38,G44) -> 70218.891 | H46: =SUM(H38,H44) -> 67285.344 | I46: =SUM(I38,I44) -> 69319.709 | J46: =SUM(J38,J44) -> 76012.347 | K46: =SUM(K38,K44) -> 88243.888 | L46: =SUM(L38,L44) -> 94035.503 | M46: =SUM(M38,M44) -> 97895.447 | N46: =SUM(N38,N44) -> 101113.21 | ... R46: =SUM(R38,R44) -> 107314.86 | T46: =SUM(T38,T44) -> 57905.161 | U46: =SUM(U38,U44) -> 64360.309 | V46: =SUM(V38,V44) -> 76012.347 | W46: =SUM(W38,W44) -> 101113.21 | X46: =SUM(X38,X44) -> 107314.86 | Y46: =SUM(Y38,Y44) -> 111675.08 | Z46: =SUM(Z38,Z44) -> 117278.53 | AA46: =SUM(AA38,AA44) -> 122824.38
C48: =Model!C134 -> Short Term Borrowings | T48: =Model!J134 -> 989.715 | U48: =Model!O134 -> 443.16 | V48: =Model!T134 -> 1767.206 | W48: =Model!Y134 -> 1762.118 | X48: =Model!AD134 -> 1878.8771 | Y48: =Model!AE134 -> 1931.6675 | Z48: =Model!AF134 -> 2010.1515 | AA48: =Model!AG134 -> 2111.0136
C49: =Model!C135 -> Accounts Payable | G49: =Model!P135 -> 8344.09 | H49: =Model!Q135 -> 8076.672 | I49: =Model!R135 -> 8128.541 | J49: =Model!S135 -> 12171.814 | K49: =Model!U135 -> 7679.987 | L49: =Model!V135 -> 7712.252 | M49: =Model!W135 -> 8063.0069 | N49: =Model!X135 -> 8530.3976 | O49: =Model!Z135 -> 8256.392 | P49: =Model!AA135 -> 8489.1714 | Q49: =Model!AB135 -> 8778.5452 | R49: =Model!AC135 -> 9205.3818 | T49: =Model!J135 -> 7698.367 | U49: =Model!O135 -> 7760.342 | V49: =Model!T135 -> 12171.814 | W49: =Model!Y135 -> 8530.3976 | X49: =Model!AD135 -> 9205.3818 | Y49: =Model!AE135 -> 10143.343 | Z49: =Model!AF135 -> 10767.678 | AA49: =Model!AG135 -> 11157.959
C50: =Model!C136 -> Securities Loaned | G50: =Model!P136 -> 2501.643 | H50: =Model!Q136 -> 2041.795 | I50: =Model!R136 -> 2498.013 | J50: =Model!S136 -> 2540.759 | K50: =Model!U136 -> 2605.7099 | L50: =Model!V136 -> 2580.0989 | M50: =Model!W136 -> 2838.1784 | N50: =Model!X136 -> 2832.7358 | O50: =Model!Z136 -> 2801.2758 | P50: =Model!AA136 -> 2840.0137 | Q50: =Model!AB136 -> 3090.0479 | R50: =Model!AC136 -> 3056.8815 | T50: =Model!J136 -> 1840.518 | U50: =Model!O136 -> 2540.861 | V50: =Model!T136 -> 2540.759 | W50: =Model!Y136 -> 2832.7358 | X50: =Model!AD136 -> 3056.8815 | Y50: =Model!AE136 -> 3543.2227 | Z50: =Model!AF136 -> 3783.2383 | AA50: =Model!AG136 -> 3894.0527
C51: =Model!C137 -> Other Current Liabilities | G51: =Model!P137 -> 33145.954 | H51: =Model!Q137 -> 30117.227 | I51: =Model!R137 -> 30946.877 | J51: =Model!S137 -> 32994.068 | K51: =Model!U137 -> 30171.378 | L51: =Model!V137 -> 30849.008 | M51: =Model!W137 -> 30639.426 | N51: =Model!X137 -> 28971.162 | O51: =Model!Z137 -> 32435.826 | P51: =Model!AA137 -> 33956.685 | Q51: =Model!AB137 -> 33358.472 | R51: =Model!AC137 -> 31263.561 | T51: =Model!J137 -> 27875.268 | U51: =Model!O137 -> 29859.988 | V51: =Model!T137 -> 32994.068 | W51: =Model!Y137 -> 28971.162 | X51: =Model!AD137 -> 31263.561 | Y51: =Model!AE137 -> 35154.327 | Z51: =Model!AF137 -> 36668.31 | AA51: =Model!AG137 -> 38341.442
C52: =Model!C138 -> Total Current Liabilities (Excl. Debt) | G52: =SUM(G49:G51) -> 43991.687 | H52: =SUM(H49:H51) -> 40235.694 | I52: =SUM(I49:I51) -> 41573.431 | J52: =SUM(J49:J51) -> 47706.641 | K52: =SUM(K49:K51) -> 40457.075 | L52: =SUM(L49:L51) -> 41141.359 | M52: =SUM(M49:M51) -> 41540.611 | N52: =SUM(N49:N51) -> 40334.295 | ... R52: =SUM(R49:R51) -> 43525.824 | T52: =SUM(T48:T51) -> 38403.868 | U52: =SUM(U48:U51) -> 40604.351 | V52: =SUM(V48:V51) -> 49473.847 | W52: =SUM(W48:W51) -> 71375.816 | X52: =SUM(X48:X51) -> 74684.104 | Y52: =SUM(Y48:Y51) -> 75930.997 | Z52: =SUM(Z48:Z51) -> 78423.602 | AA52: =SUM(AA48:AA51) -> 81020.776
C54: =Model!C140 -> Revolver | G54: =Model!P140 -> 0 | H54: =Model!Q140 -> 0 | I54: =Model!R140 -> 0 | J54: =Model!S140 -> 0 | K54: =Model!U140 -> 0 | L54: =Model!V140 -> 0 | M54: =Model!W140 -> 0 | N54: =Model!X140 -> 0 | O54: =Model!Z140 -> 2269.8897 | P54: =Model!AA140 -> 0 | Q54: =Model!AB140 -> 0 | R54: =Model!AC140 -> 0 | T54: =Model!J140 -> 0 | U54: =Model!O140 -> 0 | V54: =Model!T140 -> 0 | W54: =Model!Y140 -> 0 | X54: =Model!AD140 -> 0 | Y54: =Model!AE140 -> 0 | Z54: =Model!AF140 -> 0 | AA54: =Model!AG140 -> 0
...

Sheet Model Output
B1: =Company_Name&" "&"("&Ticker&")"&" Valuation Overview" -> Jefferies Financial Group Inc. (JEF) Valuation Overview | K1: Price Target Scenario: | N1: =Case_Scenario&" Case" -> Base Case | R1: Base Case Check | S1: =IF(N1="Base Case","","Check!") | Y1: P/E
B2: =Cover!C2 -> $ in Millions Except Per Share Data | K2: Current Share Price: | O2: =Share_Price -> 38.03 | Y2: EV/EBITDA
K3: Valuation Date: | O3: =Current_Date -> 46091
B4: ="Multiples Analysis "&"("&S21&")" -> Multiples Analysis (P/E) | I4: Return Summary
I6: Exit Multiple Method
I7: =Cover!I9 -> Implied Enterprise Value: | N7: =Cover!L9 -> 15177.212
I8: =Cover!I10 -> Implied Equity Value: | N8: =Cover!L10 -> 15177.212
I9: =Cover!I12 -> Implied Share Price: | N9: =Cover!L12 -> 68.136855
I10: =Cover!I13 -> % Return: | N10: =Cover!L13 -> 0.79166065
I12: =Cover!I15 -> Dividend Discount Model
I13: =Cover!I16 -> Implied Enterprise Value: | N13: =Cover!L16 -> 16987.417
I14: =Cover!I17 -> Implied Equity Value: | N14: =Cover!L17 -> 16987.417
I15: =Cover!I19 -> Implied Share Price: | N15: =Cover!L19 -> 76.263622
I16: =Cover!I20 -> % Return: | N16: =Cover!L20 -> 1.0053543
E18: Annuals | M18: CAGR | O18: CAGR
B19: Consolidated Financials | E19: =Summary!U6 -> 2024 | F19: =Summary!V6 -> 2025 | G19: =Summary!W6 -> 2026e | H19: =Summary!X6 -> 2027e | I19: =Summary!Y6 -> 2028e | J19: =Summary!Z6 -> 2029e | K19: =Summary!AA6 -> 2030e | M19: Historical | O19: Projected
B21: =Summary!C8 -> Revenue | D21: =Summary!T8 -> 7441.38 | E21: =Summary!U8 -> 10515.069 | F21: =Summary!V8 -> 10823.677 | G21: =Summary!W8 -> 11991.529 | H21: =Summary!X8 -> 13020.83 | I21: =Summary!Y8 -> 13894.991 | J21: =Summary!Z8 -> 14550.917 | K21: =Summary!AA8 -> 14977.126 | M21: =Summary!AC8 -> 0.20603711 | O21: =Summary!AE8 -> 0.067113784 | R21: Multiple Toggle | S21: P/E
B22: =Summary!C9 -> YoY % Growth | E22: =Summary!U9 -> 0.41305363 | F22: =Summary!V9 -> 0.029349118 | G22: =Summary!W9 -> 0.10789785 | H22: =Summary!X9 -> 0.085835711 | I22: =Summary!Y9 -> 0.067135576 | J22: =Summary!Z9 -> 0.047205916 | K22: =Summary!AA9 -> 0.029290872
R23: Multiples Analysis | S23: EV/EBITDA | T23: P/E | U23: Chart
B24: =Summary!C11 -> Net Revenue | D24: =Summary!T11 -> 4700.398 | E24: =Summary!U11 -> 7034.803 | F24: =Summary!V11 -> 7343.751 | G24: =Summary!W11 -> 8383.1825 | H24: =Summary!X11 -> 9416.4013 | I24: =Summary!Y11 -> 17136.804 | J24: =Summary!Z11 -> 17477.729 | K24: =Summary!AA11 -> 17588.938 | M24: =Summary!AC11 -> 0.24994716 | O24: =Summary!AE11 -> -0.0044007877 | R24: Entry Multiple | S24: =Valuation!D12 -> 10.8796 | T24: =Valuation!D11 -> 8.3 | U24: =IF($S$21=$S$23,S24,T24) -> 8.3
B25: =Summary!C12 -> % Margin | E25: =Summary!U12 -> 0.6690211 | F25: =Summary!V12 -> 0.67848948 | G25: =Summary!W12 -> 0.69909207 | H25: =Summary!X12 -> 0.72317981 | I25: =Summary!Y12 -> 0.81400555 | J25: =Summary!Z12 -> 0.8051149 | K25: =Summary!AA12 -> 0.79463636 | R25: =Model!Y25 -> 2026e | S25: =('MM Banking Comparables'!$H$10*S30)/(Model!Y61) -> 6.0101681 | T25: =('MM Banking Comparables'!$G$10*S30)/Summary!W19 -> 5.6469253 | U25: =IF($S$21=$S$23,S25,T25) -> 5.6469253
B26: =Summary!C13 -> YoY % Growth | E26: =Summary!U13 -> 0.49663986 | F26: =Summary!V13 -> 0.043917079 | G26: =Summary!W13 -> 0.14153959 | H26: =Summary!X13 -> 0.12324899 | I26: =Summary!Y13 -> 0.033966301 | J26: =Summary!Z13 -> 0.019894361 | K26: =Summary!AA13 -> 0.0063628991 | R26: =Summary!AA6 -> 2030e | S26: =('MM Banking Comparables'!$H$10*S30)/(Model!AG61) -> 5.4197159 | T26: =('MM Banking Comparables'!$G$10*S30)/Summary!AA19 -> 4.9392259 | U26: =IF($S$21=$S$23,S26,T26) -> 4.9392259
R27: Exit Multiple | S27: =Valuation!K64 -> 8 | T27: =Valuation!K76/Summary!AA19 -> 6.5021807 | U27: =IF($S$21=$S$23,S27,T27) -> 6.5021807
B28: =Summary!C27 -> EBITDA | D28: =Summary!T27 -> 425.882 | E28: =Summary!U27 -> 1105.407 | F28: =Summary!V27 -> 954.939 | G28: =Summary!W27 -> 2797.7587 | H28: =Summary!X27 -> 3346.0765 | I28: =Summary!Y27 -> 3157.2841 | J28: =Summary!Z27 -> 3253.925 | K28: =Summary!AA27 -> 3102.5611 | M28: =Summary!AC15 -> 0.61689744 | O28: =Summary!AE15 -> -0.22943319 | R28: Implied PGM | S28: =Valuation!K83 -> 7.7503074 | T28: =Valuation!R76/Summary!AA19 -> 6.3350846 | U28: =IF($S$21=$S$23,S28,T28) -> 6.3350846
B29: =Summary!C28 -> Margin | E29: =Summary!U28 -> 0.10512599 | F29: =Summary!V28 -> 0.088226857 | G29: =Summary!W28 -> 0.14610485 | H29: =Summary!X28 -> 0.16582566 | I29: =Summary!Y28 -> 0.14997235 | J29: =Summary!Z28 -> 0.14989267 | K29: =Summary!AA28 -> 0.14016809
B30: =Summary!C29 -> YoY % Growth | E30: =Summary!U17 -> 2.0495276 | F30: =Summary!V17 -> -0.14270089 | G30: =Summary!W17 -> 0.60422603 | H30: =Summary!X17 -> 0.28376419 | I30: =Summary!Y17 -> -0.04733965 | J30: =Summary!Z17 -> 0.039067308 | K30: =Summary!AA17 -> -0.037162443 | R30: Financials Multiplier | S30: =IF($B$2="$ in Millions Except Per Share Data",1,IF($B$2="$ in Thousands Except Per Share Data",1000,IF($B$2="$ in Billions Except Per Share Data",0.001,0))) -> 1
B32: =Summary!C19 -> Net Income (Loss) | D32: =Summary!T19 -> 221.117 | E32: =Summary!U19 -> 661.299 | F32: =Summary!V19 -> 633.716 | G32: =Summary!W19 -> 2041.643 | H32: =Summary!X19 -> 2432.7259 | I32: =Summary!Y19 -> 2333.1156 | J32: =Summary!Z19 -> 2424.2642 | K32: =Summary!AA19 -> 2334.1726 | M32: =Summary!AC19 -> 0.69291935 | O32: =Summary!AE19 -> -0.27015037
B33: =Summary!C20 -> Margin | E33: =Summary!U20 -> 0.0628906 | F33: =Summary!V20 -> 0.058549049 | G33: =Summary!W20 -> 0.1066189 | H33: =Summary!X20 -> 0.12056161 | I33: =Summary!Y20 -> 0.110824 | J33: =Summary!Z20 -> 0.11167419 | K33: =Summary!AA20 -> 0.10545369
B34: =Summary!C21 -> YoY % Growth | E34: =Summary!U21 -> 1.9907198 | F34: =Summary!V21 -> -0.041710331 | G34: =Summary!W21 -> -0.81886023 | H34: =Summary!X21 -> 0.19155301 | I34: =Summary!Y21 -> -0.040945957 | J34: =Summary!Z21 -> 0.039067308 | K34: =Summary!AA21 -> -0.037162443
B36: =Summary!C23 -> Adj. EPS (Diluted) | D36: =Summary!T23 -> 0.94143039 | E36: =Summary!U23 -> 2.7800045 | F36: =Summary!V23 -> 2.5987148 | G36: =Summary!W23 -> 8.6101474 | H36: =Summary!X23 -> 12.353374 | I36: =Summary!Y23 -> 13.270804 | J36: =Summary!Z23 -> 14.142717 | K36: =Summary!AA23 -> 13.927518 | M36: =Summary!AC23 -> 0.66144206 | O36: =Summary!AE23 -> -0.22685961
B37: =Summary!C24 -> YoY % Growth | E37: =Summary!U24 -> 1.9529581 | F37: =Summary!V24 -> -0.065212015 | G37: =Summary!W24 -> -0.82922327 | H37: =Summary!X24 -> 0.43474593 | I37: =Summary!Y24 -> 0.074265558 | J37: =Summary!Z24 -> 0.065701543 | K37: =Summary!AA24 -> -0.015216239
B39: Free Cash Flow | D39: =Model!J112 -> -235.611 | E39: =Model!O112 -> -367.945 | F39: =Model!T112 -> 2332.925 | G39: =Model!Y112 -> -651.19216 | H39: =Model!AD112 -> 2033.0568 | I39: =Model!AE112 -> 1891.9183 | J39: =Model!AF112 -> 2457.1481 | K39: =Model!AG112 -> 2060.8546 | M39: =IFERROR((F39/D39)^(1/2)-1,"N/A") -> N/A | O39: =IFERROR((K39/G39)^(1/4)-1,"N/A") -> N/A
B40: YoY % Growth | E40: =E39/D39-1 -> 0.56166308 | F40: =F39/E39-1 -> -7.3404177 | G40: =G39/F39-1 -> -1.0502064 | H40: =H39/G39-1 -> -4.1220536 | I40: =I39/H39-1 -> -0.069421805 | J40: =J39/I39-1 -> 0.2987601 | K40: =K39/J39-1 -> -0.16128188
E42: Annuals | M42: Average | O42: Average
B43: Capitalization and Key Ratios | E43: =E19 -> 2024 | F43: =F19 -> 2025 | G43: =G19 -> 2026e | H43: =H19 -> 2027e | I43: =I19 -> 2028e | J43: =J19 -> 2029e | K43: =K19 -> 2030e | M43: Historical | O43: Projected
B44: =Summary!C92 -> Leverage
B45: =Summary!C93 -> Total Debt / EBITDA | D45: =Summary!T93 -> 22.773332 | E45: =Summary!U93 -> 12.240347 | F45: =Summary!V93 -> 16.645975 | G45: =Summary!W93 -> 6.0390809 | H45: =Summary!X93 -> 5.3483209 | I45: =Summary!Y93 -> 6.1432201 | J45: =Summary!Z93 -> 6.4217495 | K45: =Summary!AA93 -> 7.2185172 | M45: =AVERAGE(D45:F45) -> 17.219885 | O45: =AVERAGE(G45:K45) -> 6.2341777
B46: =Summary!C94 -> Total Debt / Equity | D46: =Summary!T94 -> 0.98945301 | E46: =Summary!U94 -> 1.3232843 | F46: =Summary!V94 -> 1.4936655 | G46: =Summary!W94 -> 1.3157668 | H46: =Summary!X94 -> 1.2145602 | I46: =Summary!Y94 -> 1.1864535 | J46: =Summary!Z94 -> 1.1635569 | K46: =Summary!AA94 -> 1.153993 | M46: =AVERAGE(D46:F46) -> 1.2688009 | O46: =AVERAGE(G46:K46) -> 1.2068661
B47: =Summary!C95 -> Total Debt / Total Assets | D47: =Summary!T95 -> 0.16749374 | E47: =Summary!U95 -> 0.21023151 | F47: =Summary!V95 -> 0.20912249 | G47: =Summary!W95 -> 0.16709875 | H47: =Summary!X95 -> 0.1667606 | I47: =Summary!Y95 -> 0.17368146 | J47: =Summary!Z95 -> 0.1781732 | K47: =Summary!AA95 -> 0.18234077 | M47: =AVERAGE(D47:F47) -> 0.19561591 | O47: =AVERAGE(G47:K47) -> 0.17361095
B49: =Summary!C104 -> Liquidity
...

Sheet Football Field
C1: =Company_Name&" - "&MID(CELL("filename",A1),FIND("]",CELL("filename",A1))+1,255)&": "&Case_Scenario&" Case" -> Jefferies Financial Group Inc. - Football Field: Base Case
C2: =Cover!C2 -> $ in Millions Except Per Share Data
A4: x | O4: Valuation Method: | T4: Downside | U4: Delta | V4: Upside | W4: x
O5: =TEXT(Valuation!E112,"0.0%")&" - "&TEXT(Valuation!E114,"0.0%")&" WACC"&" & "&TEXT(Valuation!G110,"0.0%")&" - "&TEXT(Valuation!I110,"0.0%")&" PGR" -> 6.0% - 7.0% WACC & 1.5% - 2.5% PGR | T5: =Valuation!G112 -> 41.244955 | U5: =V5-T5 -> 5.1222677 | V5: =Valuation!I114 -> 46.367223
O6: =TEXT(Valuation!E104,"0.0%")&" - "&TEXT(Valuation!E106,"0.0%")&" WACC"&" & "&TEXT(Valuation!G102,"0.0x")&" - "&TEXT(Valuation!I102,"0.0x")&" Exit Multiple" -> 6.0% - 7.0% WACC & 7.0x - 9.0x Exit Multiple | T6: =Valuation!G104 -> 146.60999 | U6: =V6-T6 -> 0 | V6: =Valuation!I106 -> 146.60999
O8: =Valuation!F188&": "&TEXT(Valuation!G189,"0.0x")&" - "&TEXT(Valuation!I189,"0.0x") -> NTM EV/EBITDA Spread to Comps: 7.7x - 9.7x | T8: =Valuation!G191 -> 208.74373 | U8: =V8-T8 -> 57.314398 | V8: =Valuation!I193 -> 266.05813
O9: =Valuation!F180&": "&TEXT(Valuation!G181,"0.0x")&" - "&TEXT(Valuation!I181,"0.0x") -> NTM EV/EBITDA: 10.7x - 12.7x | T9: =Valuation!G183 -> 163.01762 | U9: =V9-T9 -> 47.153041 | V9: =Valuation!I185 -> 210.17066
O10: =Valuation!F172&": "&TEXT(Valuation!G173,"0.0x")&" - "&TEXT(Valuation!I173,"0.0x") -> NTM P/E Spread to Comps: 10.9x - 12.9x | T10: =Valuation!G175 -> 97.321811 | U10: =V10-T10 -> 47.650009 | V10: =Valuation!I177 -> 144.97182
O11: =Valuation!F164&": "&TEXT(Valuation!G165,"0.0x")&" - "&TEXT(Valuation!I165,"0.0x") -> NTM P/E: 13.2x - 15.2x | T11: =Valuation!G167 -> 102.86539 | U11: =V11-T11 -> 41.934357 | V11: =Valuation!I169 -> 144.79975
O13: =Valuation!F264&": "&TEXT(Valuation!G265,"0.0x")&" - "&TEXT(Valuation!I265,"0.0x") -> 2009-2018 Mid Cycle EV/EBITDA Spread to Comps: 4.7x - 6.7x | T13: =Valuation!G267 -> 258.99843 | U13: =V13-T13 -> 26.688662 | V13: =Valuation!I267 -> 285.6871
O14: =Valuation!F256&": "&TEXT(Valuation!G257,"0.0x")&" - "&TEXT(Valuation!I257,"0.0x") -> 2009-2018 Mid Cycle EV/EBITDA: 5.7x - 7.7x | T14: =Valuation!G259 -> 202.25742 | U14: =V14-T14 -> 26.688662 | V14: =Valuation!I259 -> 228.94608
O15: =Valuation!F248&": "&TEXT(Valuation!G249,"0.0x")&" - "&TEXT(Valuation!I249,"0.0x") -> 2009-2018 Mid Cycle P/E Spread to Comps: 13.6x - 15.6x | T15: =Valuation!G251 -> 100.5704 | U15: =V15-T15 -> 21.291496 | V15: =Valuation!I251 -> 121.86189
O16: =Valuation!F240&": "&TEXT(Valuation!G241,"0.0x")&" - "&TEXT(Valuation!I241,"0.0x") -> 2009-2018 Mid Cycle P/E: 14.1x - 16.1x | T16: =Valuation!G243 -> 123.8191 | U16: =V16-T16 -> 21.291496 | V16: =Valuation!I243 -> 145.11059
O18: 52-Week Price Range: | T18: =Share_Price_Low -> 35.72 | U18: =V18-T18 -> -18.68 | V18: =Share_Price_High -> 17.04
O19: Median Value: | T19: =MEDIAN(T5:T18) -> 123.8191 | U19: =MEDIAN(U5:U18) -> 26.688662 | V19: =MEDIAN(V5:V18) -> 145.11059
A20: x | O20: Implied Return (%): | T20: =T19/Share_Price-1 -> 2.2558269 | V20: =V19/Share_Price-1 -> 2.8156875
T22: Reference Points for Price Axis
U24: Price
A25: x | T25: High | U25: =MAX(V5:V18)*1.1 -> 314.2558 | W25: x
T26: Low | U26: =MIN(T5:T18)*0.9 -> 32.148
A30: x

Sheet Integrity
C1: =Company_Name&" - "&MID(CELL("filename",A1),FIND("]",CELL("filename",A1))+1,255) -> Jefferies Financial Group Inc. - Integrity
C3: Integrity
C4: Metric
C6: Model:
C7: Balance Sheet Check: | D7: =SUM(Model!F159:AG159) -> 0
C8: Base Case: | D8: =IF(Case_Scenario="Base","OK!","Check!") -> OK!
C9: Interest Expense: | D9: =IF(Model!C8="On","OK!","CHECK - OFF") -> OK!
C10: Valuation Date:
C12: Formatting:
C13: Valuation Sensitivity Tables: | D13: =SUM(Valuation!F96,Valuation!K96,Valuation!P96,Valuation!F155:F159,Valuation!L155:L159,Valuation!F231:F235,Valuation!L231:L235) -> 0
C14: WACC Tables: | D14: =SUM(WACC!Q20,WACC!N33:N37) -> 0.0065630836
C16: Font Toggles:
C17: Cover: | D17: =Cover!$Q$2 -> Report
C18: Revenue Build: | D18: ='Revenue Build'!$C$22 -> Report
C19: Model: | D19: =Model!$C$5 -> Report
C20: Valuation: | D20: =Valuation!$R$2 -> Report
C22: Change Log
C23: Date | D23: Version | E23: Operator | F23: Revisions
C24: 44476 | D24: v01 | E24: Nate Latimer | F24: Top Down / Bottom Up toggle integration and Capital IQ comps sheet w/ ID Locator
C25: 44476 | D25: v02 | E25: Carson Shaner | F25: Formulas for EBIT/EBITDA margins on earnings sheets
C26: 44480 | D26: v03 | E26: Nate Latimer | F26: Historical driver adjustments to reflect Top Down / Bottom Up Toggle
C27: 44488 | D27: v04 | E27: Nate Latimer | F27: Bug fixes to model output, comps sheet and WACC Comps Relevered Beta
C28: 44489 | D28: v05 | E28: Lilianna Ruby | F28: Changed the year end driver in 2021 and 2022 to correctly pull operating margins
C29: 44491 | D29: v06 | E29: Lilianna Ruby | F29: Changed the first page to add 365 to your previous fiscal year
C30: 44496 | D30: v07 | E30: Carson Shaner | F30: Changed Model Output FCF formula, broke apart D&A for historical periods, added checks for EPS & EBITDA in Valuation sensitivity tables, added segment D&A breakdown, linked and fixed SOTP valuation
C31: 44503 | D31: v08 | E31: Lilianna Ruby | F31: Changed average of comps on valuation tab to average all peers not just the first one
C32: 44512 | D32: v09 | E32: Lilianna Ruby | F32: Rolled model forward to reflect 3Q'21. Also changed the multiples tab so the quarters roll forward and end on correct date.
C33: 44522 | D33: v10 | E33: Lilianna Ruby | F33: Fully fixed the multiples tab so it is automatic and fully functional. Also fixed definition of NTM_EPS and NTM_EBITDA
C34: 44582 | D34: v13 | E34: Carson Shaner | F34: Changed EPS, EBITDA, shares, tax rate, etc., to formulas so we do not have to hardcode them.
C35: 44584 | D35: v14 | E35: Lilianna Ruby | F35: Changed discount factor to mid year
... C42: 45130 | D42: v21 | E42: Jacob George | F42: Fixed formulas for NTM EPS and NTM EBITDA on Valuation tab; previously wasn't summing values if last reported quarter was 4Q

Sheet Revenue Build
C1: =Company_Name&" - "&MID(CELL("filename",A1),FIND("]",CELL("filename",A1))+1,255)&": "&Case_Scenario&" Case" -> Jefferies Financial Group Inc. - Revenue Build: Base Case
C2: =Cover!C2 -> $ in Millions Except Per Share Data
A4: x | C4: Segments
C6: =C30&" Methodology" -> Total Company Revenue Methodology
C7: Segment
C8: =C32&" Methodology" -> Investment Banking Revenue Methodology
C9: =IF(Company_Rev_Methodology="Segment","Segment",IF(Company_Rev_Methodology="Activity-Based","Activity-Based",IF(Company_Rev_Methodology="Backlog","Backlog",IF(Company_Rev_Methodology="Mixed",D9,"--")))) -> Segment | D9: Backlog
C10: =C35&" Methodology" -> Principal Transactions Revenue Methodology
C11: =IF(Company_Rev_Methodology="Segment","Segment",IF(Company_Rev_Methodology="Activity-Based","Activity-Based",IF(Company_Rev_Methodology="Backlog","Backlog",IF(Company_Rev_Methodology="Mixed",D11,"--")))) -> Segment | D11: Activity-Based
C12: =C38&" Methodology" -> Revenue Methodology
C13: =IF(Company_Rev_Methodology="Segment","Segment",IF(Company_Rev_Methodology="Activity-Based","Activity-Based",IF(Company_Rev_Methodology="Backlog","Backlog",IF(Company_Rev_Methodology="Mixed",D13,"--")))) -> Segment | D13: Segment
C14: =C41&" Methodology" -> Revenue Methodology
C15: =IF(Company_Rev_Methodology="Segment","Segment",IF(Company_Rev_Methodology="Activity-Based","Activity-Based",IF(Company_Rev_Methodology="Backlog","Backlog",IF(Company_Rev_Methodology="Mixed",D15,"--")))) -> Segment | D15: Segment
C16: =C44&" Methodology" -> Revenue Methodology
C17: =IF(Company_Rev_Methodology="Segment","Segment",IF(Company_Rev_Methodology="Activity-Based","Activity-Based",IF(Company_Rev_Methodology="Backlog","Backlog",IF(Company_Rev_Methodology="Mixed",D17,"--")))) -> Segment | D17: Segment
C18: =C47&" Methodology" -> Revenue Methodology
C19: =IF(Company_Rev_Methodology="Segment","Segment",IF(Company_Rev_Methodology="Activity-Based","Activity-Based",IF(Company_Rev_Methodology="Backlog","Backlog",IF(Company_Rev_Methodology="Mixed",D19,"--")))) -> Segment | D19: Segment
C21: Font Toggle
C22: Report
C24: Annual vs. Quarterly
C25: Annual
J26: 1 | O26: 2 | T26: 3 | Y26: 4 | AD26: 5 | AE26: 6 | AF26: 7 | AG26: 8
AI27: CAGR
A28: x | C28: Summary | F28: =Model!F$25 -> 1Q23 | G28: =Model!G$25 -> 2Q23 | H28: =Model!H$25 -> 3Q23 | I28: =Model!I$25 -> 4Q23 | J28: =Model!J$25 -> 2023 | K28: =Model!K$25 -> 1Q24 | L28: =Model!L$25 -> 2Q24 | M28: =Model!M$25 -> 3Q24 | ... AG28: =Model!AG$25 -> 2030e | AI28: Historical | AJ28: Projected
C30: Total Company Revenue | F30: ='Segment Analysis'!F7 -> 1780.56 | G30: ='Segment Analysis'!G7 -> 1651.242 | H30: ='Segment Analysis'!H7 -> 2040.888 | I30: ='Segment Analysis'!I7 -> 1968.69 | J30: ='Segment Analysis'!J7 -> 7441.38 | K30: ='Segment Analysis'!K7 -> 2551.9 | L30: ='Segment Analysis'!L7 -> 2516.23 | M30: ='Segment Analysis'!M7 -> 2595.48 | ... T30: ='Segment Analysis'!T7 -> 10823.677 | U30: =SUM(U32,U35,U38,U41,U44,U47,) -> 2742.8525 | V30: =SUM(V32,V35,V38,V41,V44,V47,) -> 2804.4553 | W30: =SUM(W32,W35,W38,W41,W44,W47,) -> 3225.2028 | X30: =SUM(X32,X35,X38,X41,X44,X47,) -> 3219.018 | Y30: =SUM(U30:X30) -> 11991.529 | Z30: =SUM(Z32,Z35,Z38,Z41,Z44,Z47,) -> 2948.7114 | AA30: =SUM(AA32,AA35,AA38,AA41,AA44,AA47,) -> 3086.9714 | AB30: =SUM(AB32,AB35,AB38,AB41,AB44,AB47,) -> 3511.4181 | AC30: =SUM(AC32,AC35,AC38,AC41,AC44,AC47,) -> 3473.729 | AD30: =SUM(Z30:AC30) -> 13020.83 | AE30: =SUM(AE32,AE35,AE38,AE41,AE44,AE47,) -> 13894.991 | AF30: =SUM(AF32,AF35,AF38,AF41,AF44,AF47,) -> 14550.917 | AG30: =SUM(AG32,AG35,AG38,AG41,AG44,AG47,) -> 14977.126 | AI30: =IFERROR((T30/J30)^(1/3)-1,"--") -> 0.13302749 | AJ30: =IFERROR((AG30/T30)^(1/5)-1,"--") -> 0.067113784
C31: =IF($C$25="Quarterly","% Growth QoQ","% Growth YoY") -> % Growth YoY | G31: =IF($C$25="Annual",'Segment Analysis'!G172,'Segment Analysis'!G192) -> 0 | H31: =IF($C$25="Annual",'Segment Analysis'!H172,'Segment Analysis'!H192) -> 0 | I31: =IF($C$25="Annual",'Segment Analysis'!I172,'Segment Analysis'!I192) -> 0 | K31: =IF($C$25="Annual",'Segment Analysis'!K172,'Segment Analysis'!K192) -> 0.43320079 | L31: =IF($C$25="Annual",'Segment Analysis'!L172,'Segment Analysis'!L192) -> 0.52384084 | M31: =IF($C$25="Annual",'Segment Analysis'!M172,'Segment Analysis'!M192) -> 0.27174054 | N31: =IF($C$25="Annual",'Segment Analysis'!N172,'Segment Analysis'!N192) -> 0.44840427 | O31: =IF($C$25="Annual",'Segment Analysis'!O172,'Segment Analysis'!O192) -> 0.41305363 | P31: =IF($C$25="Annual",'Segment Analysis'!P172,'Segment Analysis'!P192) -> -0.030971433 | Q31: =IF($C$25="Annual",'Segment Analysis'!Q172,'Segment Analysis'!Q192) -> -0.0087094582 | R31: =IF($C$25="Annual",'Segment Analysis'!R172,'Segment Analysis'!R192) -> 0.12028372 | ... T31: =IF($C$25="Annual",'Segment Analysis'!T172,'Segment Analysis'!T192) -> 0.029349118 | U31: =IFERROR(U30/S30-1,"--") -> -0.069848689 | V31: =IFERROR(V30/U30-1,"--") -> 0.022459381 | W31: =IFERROR(W30/V30-1,"--") -> 0.15002823 | X31: =IFERROR(X30/W30-1,"--") -> -0.0019176407 | Y31: =IFERROR(Y30/T30-1,"--") -> 0.10789785 | Z31: =IFERROR(Z30/X30-1,"--") -> -0.083971744 | AA31: =IFERROR(AA30/Z30-1,"--") -> 0.046888275 | AB31: =IFERROR(AB30/AA30-1,"--") -> 0.13749614 | AC31: =IFERROR(AC30/AB30-1,"--") -> -0.010733293 | AD31: =IFERROR(AD30/Y30-1,"--") -> 0.085835711 | AE31: =IFERROR(AE30/AD30-1,"--") -> 0.067135576 | AF31: =IFERROR(AF30/AE30-1,"--") -> 0.047205916 | AG31: =IFERROR(AG30/AF30-1,"--") -> 0.029290872
C32: ='Segment Analysis'!C8 -> Investment Banking Revenue | F32: ='Segment Analysis'!F8 -> 1744.68 | G32: ='Segment Analysis'!G8 -> 1681.412 | H32: ='Segment Analysis'!H8 -> 2075.3 | I32: ='Segment Analysis'!I8 -> 1855.578 | J32: ='Segment Analysis'!J8 -> 7356.97 | K32: ='Segment Analysis'!K8 -> 2384.8 | L32: ='Segment Analysis'!L8 -> 2306.27 | M32: ='Segment Analysis'!M8 -> 2459.03 | ... T32: ='Segment Analysis'!T8 -> 10135.32 | U32: =IF(Segment1_Rev_Methodology="Segment",U53,IF(Segment1_Rev_Methodology="Activity-Based",U91,IF(Segment1_Rev_Methodology="Backlog",U165,"--"))) -> 2519.9342 | V32: =IF(Segment1_Rev_Methodology="Segment",V53,IF(Segment1_Rev_Methodology="Activity-Based",V91,IF(Segment1_Rev_Methodology="Backlog",V165,"--"))) -> 2642.1181 | W32: =IF(Segment1_Rev_Methodology="Segment",W53,IF(Segment1_Rev_Methodology="Activity-Based",W91,IF(Segment1_Rev_Methodology="Backlog",W165,"--"))) -> 3063.0856 | X32: =IF(Segment1_Rev_Methodology="Segment",X53,IF(Segment1_Rev_Methodology="Activity-Based",X91,IF(Segment1_Rev_Methodology="Backlog",X165,"--"))) -> 3034.8043 | Y32: =SUM(U32:X32) -> 11259.942 | Z32: =IF(Segment1_Rev_Methodology="Segment",Z53,IF(Segment1_Rev_Methodology="Activity-Based",Z91,IF(Segment1_Rev_Methodology="Backlog",Z165,"--"))) -> 2797.127 | AA32: =IF(Segment1_Rev_Methodology="Segment",AA53,IF(Segment1_Rev_Methodology="Activity-Based",AA91,IF(Segment1_Rev_Methodology="Backlog",AA165,"--"))) -> 2932.7511 | AB32: =IF(Segment1_Rev_Methodology="Segment",AB53,IF(Segment1_Rev_Methodology="Activity-Based",AB91,IF(Segment1_Rev_Methodology="Backlog",AB165,"--"))) -> 3338.7633 | AC32: =IF(Segment1_Rev_Methodology="Segment",AC53,IF(Segment1_Rev_Methodology="Activity-Based",AC91,IF(Segment1_Rev_Methodology="Backlog",AC165,"--"))) -> 3307.9367 | AD32: =SUM(Z32:AC32) -> 12376.578 | AE32: =IF(Segment1_Rev_Methodology="Segment",AE53,IF(Segment1_Rev_Methodology="Activity-Based",AE91,IF(Segment1_Rev_Methodology="Backlog",AE165,"--"))) -> 13366.704 | AF32: =IF(Segment1_Rev_Methodology="Segment",AF53,IF(Segment1_Rev_Methodology="Activity-Based",AF91,IF(Segment1_Rev_Methodology="Backlog",AF165,"--"))) -> 14101.873 | AG32: =IF(Segment1_Rev_Methodology="Segment",AG53,IF(Segment1_Rev_Methodology="Activity-Based",AG91,IF(Segment1_Rev_Methodology="Backlog",AG165,"--"))) -> 14595.439 | AI32: =IFERROR((T32/J32)^(1/3)-1,"--") -> 0.1127036 | AJ32: =IFERROR((AG32/T32)^(1/5)-1,"--") -> 0.075662274
C33: =IF($C$25="Quarterly","% Growth QoQ","% Growth YoY") -> % Growth YoY | G33: =IF($C$25="Annual",'Segment Analysis'!G173,'Segment Analysis'!G193) -> 0 | H33: =IF($C$25="Annual",'Segment Analysis'!H173,'Segment Analysis'!H193) -> 0 | I33: =IF($C$25="Annual",'Segment Analysis'!I173,'Segment Analysis'!I193) -> 0 | K33: =IF($C$25="Annual",'Segment Analysis'!K173,'Segment Analysis'!K193) -> 0.36689823 | L33: =IF($C$25="Annual",'Segment Analysis'!L173,'Segment Analysis'!L193) -> 0.37162694 | M33: =IF($C$25="Annual",'Segment Analysis'!M173,'Segment Analysis'!M193) -> 0.18490339 | N33: =IF($C$25="Annual",'Segment Analysis'!N173,'Segment Analysis'!N193) -> 0.40375075 | O33: =IF($C$25="Annual",'Segment Analysis'!O173,'Segment Analysis'!O193) -> 0.32593568 | P33: =IF($C$25="Annual",'Segment Analysis'!P173,'Segment Analysis'!P193) -> -0.048049732 | Q33: =IF($C$25="Annual",'Segment Analysis'!Q173,'Segment Analysis'!Q193) -> 0.022878501 | R33: =IF($C$25="Annual",'Segment Analysis'!R173,'Segment Analysis'!R193) -> 0.11717303 | ... T33: =IF($C$25="Annual",'Segment Analysis'!T173,'Segment Analysis'!T193) -> 0.039001139 | U33: =IFERROR(U32/S32-1,"--") -> -0.086620633 | V33: =IFERROR(V32/U32-1,"--") -> 0.048486929 | W33: =IFERROR(W32/V32-1,"--") -> 0.15932957 | X33: =IFERROR(X32/W32-1,"--") -> -0.0092329544 | Y33: =IFERROR(Y32/T32-1,"--") -> 0.1109607 | Z33: =IFERROR(Z32/X32-1,"--") -> -0.078317184 | AA33: =IFERROR(AA32/Z32-1,"--") -> 0.048486929 | AB33: =IFERROR(AB32/AA32-1,"--") -> 0.13844075 | AC33: =IFERROR(AC32/AB32-1,"--") -> -0.0092329544 | AD33: =IFERROR(AD32/Y32-1,"--") -> 0.099168879 | AE33: =IFERROR(AE32/AD32-1,"--") -> 0.08 | AF33: =IFERROR(AF32/AE32-1,"--") -> 0.055 | AG33: =IFERROR(AG32/AF32-1,"--") -> 0.035
C34: % of Total Revenue | F34: ='Segment Analysis'!F16 -> 0.97984904 | G34: ='Segment Analysis'!G16 -> 1.0182711 | H34: ='Segment Analysis'!H16 -> 1.0168613 | I34: ='Segment Analysis'!I16 -> 0.94254453 | J34: ='Segment Analysis'!J16 -> 0.98865667 | K34: ='Segment Analysis'!K16 -> 0.93451938 | L34: ='Segment Analysis'!L16 -> 0.91655771 | M34: ='Segment Analysis'!M16 -> 0.94742784 | ... T34: ='Segment Analysis'!T16 -> 0.93640267 | U34: =U32/U$30 -> 0.91872757 | V34: =V32/V$30 -> 0.94211453 | W34: =W32/W$30 -> 0.94973429 | X34: =X32/X$30 -> 0.94277333 | Y34: =Y32/Y$30 -> 0.93899141 | Z34: =Z32/Z$30 -> 0.94859299 | AA34: =AA32/AA$30 -> 0.95004154 | AB34: =AB32/AB$30 -> 0.95083048 | ... AG34: =AG32/AG$30 -> 0.97451534
C35: ='Segment Analysis'!C9 -> Principal Transactions Revenue | F35: ='Segment Analysis'!F9 -> 35.88 | G35: ='Segment Analysis'!G9 -> -30.17 | H35: ='Segment Analysis'!H9 -> -34.412 | I35: ='Segment Analysis'!I9 -> 113.112 | J35: ='Segment Analysis'!J9 -> 84.41 | K35: ='Segment Analysis'!K9 -> 167.1 | L35: ='Segment Analysis'!L9 -> 209.96 | M35: ='Segment Analysis'!M9 -> 136.45 | ... T35: ='Segment Analysis'!T9 -> 688.357 | U35: =IF(Segment2_Rev_Methodology="Segment",U59,IF(Segment2_Rev_Methodology="Activity-Based",U103,IF(Segment2_Rev_Methodology="Backlog",U177,"--"))) -> 222.9183 | V35: =IF(Segment2_Rev_Methodology="Segment",V59,IF(Segment2_Rev_Methodology="Activity-Based",V103,IF(Segment2_Rev_Methodology="Backlog",V177,"--"))) -> 162.3372 | W35: =IF(Segment2_Rev_Methodology="Segment",W59,IF(Segment2_Rev_Methodology="Activity-Based",W103,IF(Segment2_Rev_Methodology="Backlog",W177,"--"))) -> 162.11712 | X35: =IF(Segment2_Rev_Methodology="Segment",X59,IF(Segment2_Rev_Methodology="Activity-Based",X103,IF(Segment2_Rev_Methodology="Backlog",X177,"--"))) -> 184.21367 | Y35: =SUM(U35:X35) -> 731.58629 | Z35: =IF(Segment2_Rev_Methodology="Segment",Z59,IF(Segment2_Rev_Methodology="Activity-Based",Z103,IF(Segment2_Rev_Methodology="Backlog",Z177,"--"))) -> 151.58444 | AA35: =IF(Segment2_Rev_Methodology="Segment",AA59,IF(Segment2_Rev_Methodology="Activity-Based",AA103,IF(Segment2_Rev_Methodology="Backlog",AA177,"--"))) -> 154.22034 | AB35: =IF(Segment2_Rev_Methodology="Segment",AB59,IF(Segment2_Rev_Methodology="Activity-Based",AB103,IF(Segment2_Rev_Methodology="Backlog",AB177,"--"))) -> 172.65473 | AC35: =IF(Segment2_Rev_Methodology="Segment",AC59,IF(Segment2_Rev_Methodology="Activity-Based",AC103,IF(Segment2_Rev_Methodology="Backlog",AC177,"--"))) -> 165.7923 | AD35: =SUM(Z35:AC35) -> 644.25182 | AE35: =IF(Segment2_Rev_Methodology="Segment",AE59,IF(Segment2_Rev_Methodology="Activity-Based",AE103,IF(Segment2_Rev_Methodology="Backlog",AE177,"--"))) -> 528.28649 | AF35: =IF(Segment2_Rev_Methodology="Segment",AF59,IF(Segment2_Rev_Methodology="Activity-Based",AF103,IF(Segment2_Rev_Methodology="Backlog",AF177,"--"))) -> 449.04352 | AG35: =IF(Segment2_Rev_Methodology="Segment",AG59,IF(Segment2_Rev_Methodology="Activity-Based",AG103,IF(Segment2_Rev_Methodology="Backlog",AG177,"--"))) -> 381.68699 | AI35: =IFERROR((T35/J35)^(1/3)-1,"--") -> 1.0128277 | AJ35: =IFERROR((AG35/T35)^(1/5)-1,"--") -> -0.11125182
C36: % Growth | G36: =IF($C$25="Annual",'Segment Analysis'!G174,'Segment Analysis'!G194) -> 0 | H36: =IF($C$25="Annual",'Segment Analysis'!H174,'Segment Analysis'!H194) -> 0 | I36: =IF($C$25="Annual",'Segment Analysis'!I174,'Segment Analysis'!I194) -> 0 | K36: =IF($C$25="Annual",'Segment Analysis'!K174,'Segment Analysis'!K194) -> 3.6571906 | L36: =IF($C$25="Annual",'Segment Analysis'!L174,'Segment Analysis'!L194) -> -7.959231 | M36: =IF($C$25="Annual",'Segment Analysis'!M174,'Segment Analysis'!M194) -> -4.9651866 | N36: =IF($C$25="Annual",'Segment Analysis'!N174,'Segment Analysis'!N194) -> 1.1809357 | O36: ='Segment Analysis'!O174 -> 8.0060419 | P36: =IF($C$25="Annual",'Segment Analysis'!P174,'Segment Analysis'!P194) -> 0.21276481 | Q36: =IF($C$25="Annual",'Segment Analysis'!Q174,'Segment Analysis'!Q194) -> -0.35568203 | R36: =IF($C$25="Annual",'Segment Analysis'!R174,'Segment Analysis'!R194) -> 0.17634298 | S36: =IF($C$25="Annual",'Segment Analysis'!S174,'Segment Analysis'!S194) -> -0.23016336 | T36: ='Segment Analysis'!T174 -> -0.094505393 | U36: =IFERROR(U35/S35-1,"--") -> 0.17380405 | V36: =IFERROR(V35/U35-1,"--") -> -0.27176369 | W36: =IFERROR(W35/V35-1,"--") -> -0.0013556967 | X36: =IFERROR(X35/W35-1,"--") -> 0.13629992 | Y36: =IFERROR(Y35/T35-1,"--") -> 0.062800683 | Z36: =IFERROR(Z35/X35-1,"--") -> -0.17712706 | AA36: =IFERROR(AA35/Z35-1,"--") -> 0.017388961 | AB36: =IFERROR(AB35/AA35-1,"--") -> 0.11953282 | AC36: =IFERROR(AC35/AB35-1,"--") -> -0.039746549 | AD36: =IFERROR(AD35/Y35-1,"--") -> -0.11937685 | AE36: =IFERROR(AE35/AD35-1,"--") -> -0.18 | AF36: =IFERROR(AF35/AE35-1,"--") -> -0.15 | AG36: =IFERROR(AG35/AF35-1,"--") -> -0.15
C37: % of Total Revenue | F37: ='Segment Analysis'!F17 -> 0.020150964 | G37: ='Segment Analysis'!G17 -> -0.018271095 | H37: ='Segment Analysis'!H17 -> -0.016861288 | I37: ='Segment Analysis'!I17 -> 0.057455465 | J37: ='Segment Analysis'!J17 -> 0.011343326 | K37: ='Segment Analysis'!K17 -> 0.065480622 | L37: ='Segment Analysis'!L17 -> 0.083442293 | M37: ='Segment Analysis'!M17 -> 0.052572164 | ... T37: ='Segment Analysis'!T17 -> 0.063597334 | U37: =U35/U$30 -> 0.081272434 | V37: =V35/V$30 -> 0.057885466 | W37: =W35/W$30 -> 0.050265714 | X37: =X35/X$30 -> 0.057226667 | Y37: =Y35/Y$30 -> 0.061008594 | Z37: =Z35/Z$30 -> 0.051407012 | AA37: =AA35/AA$30 -> 0.049958461 | AB37: =AB35/AB$30 -> 0.049169518 | ... AG37: =AG35/AG$30 -> 0.025484662
