Workbook
Name _bdm.146e958bbea04416b86a4d5943392c04.edm: Model!$M$100
Name _bdm.bf5a9ed53fe44c598e3cfb84ac34b21f.edm: Integrity!$F$37
Name Case_Scenario: Cover!$F$22
Name Company_Cyclical_Multiples_Data: 'Multiples Data'!$C$14:$H$26
Name Company_Name: Cover!$F$19
Name Company_Rev_Methodology: 'Revenue Build'!$C$7
Name Cost_of_Debt: WACC!$G$17
Name Cost_of_Equity: WACC!$G$25
Name Cost_of_Preferred: WACC!$G$10
Name Current_Date: Cover!$F$27
Name Cycle_Period_Toggle: Valuation!$G$221
Name Cycle_Toggle: Valuation!$G$220
Name Cyclical_LTM_NTM_Toggle: Valuation!$G$222
Name Cyclical_Peer_Group_Toggle: Valuation!$G$223
Name Data: Model!$C$25:$AK$159
Name Diluted_Shares: Cover!$F$35
Name Discount_Rate: WACC!$O$13
Name Div_Yield: Cover!$F$34
Name ERP: WACC!$G$7
Name Fiscal_Periods: Model!$C$25:$AG$25
Name Header_Row: $IV$11:$ROW$17
Name Hun: Cover!$F$41
Name IQRAF17: $AF$18:$AF$269
Name IQRC117: $C$118
Name IQRC12: $C$13
Name IQRC121: $C$122
Name IQRC123: $C$124
Name IQRC124: $C$125
Name IQRC125: $C$126
Name IQRC126: $C$127
Name IQRC5: $C$6:$C$13
Name IQRC94: $C$95
Name IQRCIQIDLocaterI13: 'CIQ ID Locater'!$K$14:$O$14
Name IQRCIQIDLocaterI14: 'CIQ ID Locater'!$K$15:$O$15
Name IQRCIQIDLocaterI15: 'CIQ ID Locater'!$K$16:$O$16
Name IQRCIQIDLocaterI16: 'CIQ ID Locater'!$K$17:$O$17
Name IQRCIQIDLocaterI17: 'CIQ ID Locater'!$K$18:$N$18
Name IQRCIQIDLocaterI18: 'CIQ ID Locater'!$K$19:$O$19
Name IQRCIQIDLocaterI19: 'CIQ ID Locater'!$K$20:$O$20
Name IQRCIQIDLocaterI20: 'CIQ ID Locater'!$K$21:$O$21
Name IQRCIQIDLocaterI21: 'CIQ ID Locater'!$K$22:$O$22
Name IQRCIQIDLocaterI22: 'CIQ ID Locater'!$K$23:$O$23
Name IQRCIQIDLocaterI23: 'CIQ ID Locater'!$K$24:$O$24
Name IQRCIQIDLocaterI24: 'CIQ ID Locater'!$K$25:$O$25
Name IQRCIQIDLocaterI25: 'CIQ ID Locater'!$K$26:$O$26
Name IQRCIQIDLocaterI26: 'CIQ ID Locater'!$K$27:$O$27
Name IQRCIQIDLocaterI27: 'CIQ ID Locater'!$K$28:$O$28
Name IQRCIQIDLocaterI28: 'CIQ ID Locater'!$K$29:$L$29
Name IQRCIQIDLocaterI29: 'CIQ ID Locater'!$K$30
Name IQRCIQIDLocaterO13: 'CIQ ID Locater'!$Q$14:$U$14
Name IQRCIQIDLocaterO14: 'CIQ ID Locater'!$Q$15:$U$15
Name IQRCIQIDLocaterO15: 'CIQ ID Locater'!$Q$16:$U$16
Name IQRCIQIDLocaterO16: 'CIQ ID Locater'!$Q$17:$U$17
Name IQRCIQIDLocaterO17: 'CIQ ID Locater'!$Q$18:$T$18
Name IQRCIQIDLocaterO18: 'CIQ ID Locater'!$Q$19:$U$19
Name IQRCIQIDLocaterO19: 'CIQ ID Locater'!$Q$20:$U$20
Name IQRCIQIDLocaterO20: 'CIQ ID Locater'!$Q$21:$U$21
Name IQRCIQIDLocaterO21: 'CIQ ID Locater'!$Q$22:$U$22
Name IQRCIQIDLocaterO22: 'CIQ ID Locater'!$Q$23:$U$23
Name IQRCIQIDLocaterO23: 'CIQ ID Locater'!$Q$24:$U$24

Sheet Intro
B1: William C. Dunkelberg Owl Fund - Valuation Workbook
A3: x | B3: INSTRUCTIONS - Please Read
B4: There are many tabs within the workbook, all of which are relevant and important to completing a proper valuation for your target company. Before beginning, ensure that your Excel options menu (under the 'Formulas' tab) is set up correctly, as shown in the picture to the right. Regardless of whether you set 'Workbook Calculation' to "Automatic" or "Automatic except for data tables," hit the F9 key when making changes to data tables to ensure all tables update. All values throughout the workbook are color-coded (blue, black or green) to allow for easier navigation & recognition. The 'Drivers' and 'Revenue Build' tabs are used to conduct a scenario analysis (Bull, Bear & Base cases). Input the assumptions in the appropriate cells and select your 'Active Case' in the Revenue Build tab (using the drop down menu in cell C9). READ ALL COMMENTS THROUGHOUT THE WORKBOOK (denoted by red triangles in the upper right corner of cells) as they will help you complete certain parts of the model! Make sure to change existing comments & input YOUR OWN to inform others of your assumptions. The 'Summary' tab combines everything into "report-ready" format. When submitting the final model with your Initiating Coverage Report, hide / remove this 'Intro' tab, but keep all other tabs visible. Be wary of copying or filling down the line with formulas. Formulas in quarterly periods will likely not be applicable or correct in an annual column. Additionally, not every quarterly formula will work for other quarterly columns (e.g. QoQ growth for 1Q would use 4Q as a base, which is 2 columns away vs other quarters using bases 1 column to the left). It is very important that you do not change the name of line items. Other items in the workbook are linked to values based on that nomenclature. You should have all the core items that you need and any extranneous items can be grouped in the "Other" row for that section. We can't contruct a schedule to project every little item every company reports, so we schedule the ones that every company has and group the rest together. For quick navigation, "X's" are placed in the left-hand columns of each worksheet. Use "CTRL + pg dn/pg up" to jump around the workbook. When attempting to locate a cell's precedents (i.e. to jump to the linked cells), use " CTRL + [ ". Hit the F5 key (or CTRL + G) and then "ENTER" to return to the original cell. Stay consistent with modeling best practices (i.e. consistent color-coding for input values, formulas, linked cells, etc.) if you make any changes to the model. You may delete this tab before finalizing.

Sheet Cover
C1: =Company_Name&" - "&MID(CELL("filename",A1),FIND("]",CELL("filename",A1))+1,255)&": "&Case_Scenario&" Case" -> Lowe's Companies, Inc. - Cover: Base Case | Q1: Font Toggle
C2: $ in Millions Except Per Share Data | Q2: Working
R3: x
A4: x | C4: Model Assumptions: | I4: Return Summary:
I6: Discounted Cash Flow Analysis | N6: Multiple Analysis
I8: Exit Multiple Method | N8: EV/EBITDA Method
I9: Implied Enterprise Value: | L9: =Valuation!K65 -> -85959.254 | P9: Target Price: | Q9: % Return:
I10: Implied Equity Value: | L10: =Valuation!K72 -> -103015.25
N11: 1 Year LTM EV/EBITDA | P11: =Valuation!N137 -> -24.12447 | Q11: =Valuation!N138 -> 1e-12
I12: Implied Share Price: | L12: =Valuation!K76 -> -145.70757
I13: % Return: | L13: =Valuation!K77 -> 1e-12 | N13: 2009-2018 Late Cycle EV/EBITDA | P13: =Valuation!N215 -> -24.12447 | Q13: =Valuation!N216 -> 1e-12
I15: Perpetuity Growth Method | N15: P/E Multiple Method
I16: Implied Enterprise Value: | L16: =Valuation!R65 -> -24426.903 | P16: Target Price: | Q16: % Return:
I17: Implied Equity Value: | L17: =Valuation!R72 -> -41482.903
N18: 1 Year LTM P/E | P18: =Valuation!F126 -> 1e-12 | Q18: =Valuation!F127 -> 1e-12
C19: Company Name | F19: COCA COLA CO | I19: Implied Share Price: | L19: =Valuation!R76 -> -58.674545
C20: Ticker | F20: KO | I20: % Return: | L20: =Valuation!R77 -> 1e-12 | N20: 2009-2018 Late Cycle P/E | P20: =Valuation!F204 -> 1e-12 | Q20: =Valuation!F205 -> 1e-12
C22: Case Scenario | F22: Base | I22: Table of Contents
C24: Last Fiscal Year | F24: 46022 | I24: Cover
C25: Next Fiscal Year | F25: =Last_FYE+365 -> 46387 | I25: Summary
C26: Last Fiscal Quarter Reported | F26: 2Q | I26: Football Field
C27: Current Valuation Date | F27: 45903 | I27: Integrity
I28: Revenue Build
C29: Current Share Price | F29: 82.62 | I29: Model
C30: 52-Week High | F30: 84.04 | I30: Segment Analysis
C31: 52-Week Low | F31: 65.35 | I31: Drivers
I32: WACC
C33: Effective Tax Rate | F33: =IF(Last_FQR="1Q",Model!U71,IF(Last_FQR="2Q",Model!V71,IF(Last_FQR="3Q",Model!W71,Model!X71))) -> 0.24436655 | I33: Valuation
C34: Dividend Yield | F34: =IF(Last_FQR="1Q",Model!U265,IF(Last_FQR="2Q",Model!V265,IF(Last_FQR="3Q",Model!W265,Model!X265))) -> 0.01277896 | I34: Comparables
C35: Diluted Shares Outstanding (MRQ) | F35: =IF(Last_FQR="1Q",Model!U284,IF(Last_FQR="2Q",Model!V284,IF(Last_FQR="3Q",Model!W284,Model!X284))) -> 707 | I35: Charts
I36: Benchmark
C37: Model Type | F37: Top Down | I37: Multiples Data
I38: Pre-Earnings
I39: Post-Earnings
A42: x
C43: Model Color Legend | I43: Constants
C44: Blue = Hard-Coded Value (historical values & assumptions) | I44: Reference | J44: Type | K44: Name | L44: Value
C45: Black = Formulas | I45: Million | J45: (#) | K45: Mil | L45: 1000000
C46: Green = Linked Value (from separate worksheet) | I46: Thousand | J46: (#) | K46: Thou | L46: 1000
C47: Red = Unique Formula / Anomaly | I47: Hundred | J47: (#) | K47: Hun | L47: 100
...

Sheet Summary
C1: =Company_Name&" - "&MID(CELL("filename",A1),FIND("]",CELL("filename",A1))+1,255)&": "&Case_Scenario&" Case" -> Lowe's Companies, Inc. - Summary: Base Case
C2: =Cover!C2 -> $ in Millions Except Per Share Data
C4: Year: | T4: =Model!J24 -> 2023 | U4: =Model!O24 -> 2024 | V4: =Model!T24 -> 2025 | W4: =Model!Y24 -> 2026 | X4: =Model!AD24 -> 2027 | Y4: =Model!AE24 -> 2028 | Z4: =Model!AF24 -> 2029 | AA4: =Model!AG24 -> 2030
G5: Quarterly | T5: Annuals | AC5: CAGR | AE5: CAGR
A6: x | C6: ="Consolidated "&Model!C25 -> Consolidated Income Statement | G6: =Model!P25 -> 1Q25 | H6: =Model!Q25 -> 2Q25 | I6: =Model!R25 -> 3Q25 | J6: =Model!S25 -> 4Q25 | K6: =Model!U25 -> 1Q26 | L6: =Model!V25 -> 2Q26 | M6: =Model!W25 -> 3Q26e | N6: =Model!X25 -> 4Q26e | O6: =Model!Z25 -> 1Q27e | P6: =Model!AA25 -> 2Q27e | Q6: =Model!AB25 -> 3Q27e | R6: =Model!AC25 -> 4Q27e | T6: =Model!J25 -> 2023 | U6: =Model!O25 -> 2024 | V6: =Model!T25 -> 2025 | W6: =Model!Y25 -> 2026e | X6: =Model!AD25 -> 2027e | Y6: =Model!AE25 -> 2028e | Z6: =Model!AF25 -> 2029e | AA6: =Model!AG25 -> 2030e | AC6: Historical | AE6: Projected
C8: =Model!C28 -> Revenue | G8: =Model!P28 -> 19675 | H8: =Model!Q28 -> 27302 | I8: =Model!R28 -> 22309 | J8: =Model!S28 -> 20311 | K8: =Model!U28 -> 24422 | L8: =Model!V28 -> 27570 | M8: =Model!W28 -> 22918 | N8: =Model!X28 -> 21772.1 | O8: =Model!Z28 -> 25691.078 | P8: =Model!AA28 -> 29287.829 | Q8: =Model!AB28 -> 25773.289 | R8: =Model!AC28 -> 24484.625 | T8: =Model!J28 -> 71309 | U8: =Model!O28 -> 72148 | V8: =Model!T28 -> 89597 | W8: =Model!Y28 -> 96682.1 | X8: =Model!AD28 -> 105236.82 | Y8: =Model!AE28 -> 107341.56 | Z8: =Model!AF28 -> 109488.39 | AA8: =Model!AG28 -> 111678.16 | AC8: =IFERROR((V8/T8)^(1/(V$4-T$4))-1,"N/A") -> 0.12091985 | AE8: =IFERROR((AA8/V8)^(1/(AA$4-V$4))-1,"N/A") -> 0.045044909
C9: YoY % Growth | K9: =K8/G8-1 -> 0.24127065 | L9: =L8/H8-1 -> 0.0098161307 | M9: =M8/I8-1 -> 0.0272984 | N9: =N8/J8-1 -> 0.071936389 | O9: =O8/K8-1 -> 0.05196454 | P9: =P8/L8-1 -> 0.062307904 | Q9: =Q8/M8-1 -> 0.1245872 | R9: =R8/N8-1 -> 0.1245872 | U9: =IF(ISERROR(U8/T8-1),"NA",(U8/T8-1)) -> 0.011765696 | V9: =IF(ISERROR(V8/U8-1),"NA",(V8/U8-1)) -> 0.24185009 | W9: =IF(ISERROR(W8/V8-1),"NA",(W8/V8-1)) -> 0.079077424 | X9: =IF(ISERROR(X8/W8-1),"NA",(X8/W8-1)) -> 0.088482991 | Y9: =IF(ISERROR(Y8/X8-1),"NA",(Y8/X8-1)) -> 0.02 | Z9: =IF(ISERROR(Z8/Y8-1),"NA",(Z8/Y8-1)) -> 0.02 | AA9: =IF(ISERROR(AA8/Z8-1),"NA",(AA8/Z8-1)) -> 0.02
C11: =Model!C30 -> Gross Profit | G11: =Model!P30 -> 6513 | H11: =Model!Q30 -> 9304 | I11: =Model!R30 -> 7300 | J11: =Model!S30 -> 6466 | K11: =Model!U30 -> 8130 | L11: =Model!V30 -> 9312 | M11: =Model!W30 -> 7587 | N11: =Model!X30 -> 2830.373 | O11: =Model!Z30 -> 3596.7509 | P11: =Model!AA30 -> 4246.7352 | Q11: =Model!AB30 -> 3092.7947 | R11: =Model!AC30 -> 3305.4244 | T11: =Model!J30 -> 22908 | U11: =Model!O30 -> 22943 | V11: =Model!T30 -> 29583 | W11: =Model!Y30 -> 27859.373 | X11: =Model!AD30 -> 14241.705 | Y11: =Model!AE30 -> 14920.477 | Z11: =Model!AF30 -> 15328.374 | AA11: =Model!AG30 -> 15858.298 | AC11: =IFERROR((V11/T11)^(1/(V$4-T$4))-1,"N/A") -> 0.1363903 | AE11: =IFERROR((AA11/V11)^(1/(AA$4-V$4))-1,"N/A") -> -0.11723954
C12: % Margin | G12: =G11/G$8 -> 0.33102922 | H12: =H11/H$8 -> 0.3407809 | I12: =I11/I$8 -> 0.3272222 | J12: =J11/J$8 -> 0.31834966 | K12: =K11/K$8 -> 0.33289657 | L12: =L11/L$8 -> 0.33775843 | M12: =M11/M$8 -> 0.33104983 | N12: =N11/N$8 -> 0.13 | ... R12: =R11/R$8 -> 0.135 | T12: =T11/T$8 -> 0.32124977 | U12: =U11/U$8 -> 0.31799911 | V12: =V11/V$8 -> 0.33017847 | W12: =W11/W$8 -> 0.28815441 | X12: =X11/X$8 -> 0.13533006 | Y12: =Y11/Y$8 -> 0.139 | Z12: =Z11/Z$8 -> 0.14 | AA12: =AA11/AA$8 -> 0.142
C13: YoY % Growth | K13: =K11/G11-1 -> 0.24827269 | L13: =L11/H11-1 -> 0.00085984523 | M13: =M11/I11-1 -> 0.039315068 | N13: =N11/J11-1 -> -0.56226833 | O13: =O11/K11-1 -> -0.55759521 | P13: =P11/L11-1 -> -0.54395026 | Q13: =Q11/M11-1 -> -0.59235604 | R13: =R11/N11-1 -> 0.16784055 | U13: =U11/T11-1 -> 0.0015278505 | V13: =V11/U11-1 -> 0.28941289 | W13: =W11/V11-1 -> -0.058264104 | X13: =X11/W11-1 -> -0.48880022 | Y13: =Y11/X11-1 -> 0.047660817 | Z13: =Z11/Y11-1 -> 0.027338129 | AA13: =AA11/Z11-1 -> 0.034571429
C15: =Model!C36 -> EBIT | G15: =Model!P36 -> 1991 | H15: =Model!Q36 -> 3957 | I15: =Model!R36 -> 2175 | J15: =Model!S36 -> 2769 | K15: =Model!U36 -> 3245 | L15: =Model!V36 -> 4210 | M15: =Model!W36 -> 2789 | N15: =Model!X36 -> -2290.6765 | O15: =Model!Z36 -> -2515.6105 | P15: =Model!AA36 -> -2679.8778 | Q15: =Model!AB36 -> -2919.5613 | R15: =Model!AC36 -> -2425.104 | T15: =Model!J36 -> 4018 | U15: =Model!O36 -> 6314 | V15: =Model!T36 -> 10892 | W15: =Model!Y36 -> 7953.3235 | X15: =Model!AD36 -> -10540.154 | Y15: =Model!AE36 -> -9578.1136 | Z15: =Model!AF36 -> -9246.1514 | AA15: =Model!AG36 -> -8671.5229 | AC15: =IFERROR((V15/T15)^(1/(V$4-T$4))-1,"N/A") -> 0.64645115 | AE15: =IFERROR((AA15/V15)^(1/(AA$4-V$4))-1,"N/A") -> -1.9554271
C16: Margin | G16: =G15/G$8 -> 0.10119441 | H16: =H15/H$8 -> 0.14493444 | I16: =I15/I$8 -> 0.097494285 | J16: =J15/J$8 -> 0.13633007 | K16: =K15/K$8 -> 0.132872 | L16: =L15/L$8 -> 0.15270221 | M16: =M15/M$8 -> 0.12169474 | N16: =N15/N$8 -> -0.10521156 | ... R16: =R15/R$8 -> -0.099045993 | T16: =T15/T$8 -> 0.056346324 | U16: =U15/U$8 -> 0.087514553 | V16: =V15/V$8 -> 0.12156657 | W16: =W15/W$8 -> 0.082262627 | X16: =X15/X$8 -> -0.10015652 | Y16: =Y15/Y$8 -> -0.089230245 | Z16: =Z15/Z$8 -> -0.084448694 | AA16: =AA15/AA$8 -> -0.077647439
C17: YoY % Growth | K17: =K15/G15-1 -> 0.62983425 | L17: =L15/H15-1 -> 0.063937326 | M17: =M15/I15-1 -> 0.28229885 | N17: =N15/J15-1 -> -1.8272577 | O17: =O15/K15-1 -> -1.7752267 | P17: =P15/L15-1 -> -1.6365505 | Q17: =Q15/M15-1 -> -2.046813 | R17: =R15/N15-1 -> 0.058684624 | U17: =U15/T15-1 -> 0.57142857 | V17: =V15/U15-1 -> 0.72505543 | W17: =W15/V15-1 -> -0.26980137 | X17: =X15/W15-1 -> -2.3252515 | Y17: =Y15/X15-1 -> -0.09127382 | Z17: =Z15/Y15-1 -> -0.034658402 | AA17: =AA15/Z15-1 -> -0.062147864
C19: =Model!C45 -> Net Income (Loss) | G19: =Model!P45 -> 1337 | H19: =Model!Q45 -> 2828 | I19: =Model!R45 -> 692 | J19: =Model!S45 -> 978 | K19: =Model!U45 -> 2321 | L19: =Model!V45 -> 3018 | M19: =Model!W45 -> 1896 | N19: =Model!X45 -> -1906.5764 | O19: =Model!Z45 -> -2096.8419 | P19: =Model!AA45 -> -2241.0006 | Q19: =Model!AB45 -> -2419.8446 | R19: =Model!AC45 -> -2072.2741 | T19: =Model!J45 -> 2314 | U19: =Model!O45 -> 4281 | V19: =Model!T45 -> 5835 | W19: =Model!Y45 -> 6994.4236 | X19: =Model!AD45 -> -8829.9613 | Y19: =Model!AE45 -> -8530.9817 | Z19: =Model!AF45 -> -8740.0017 | AA19: =Model!AG45 -> -8813.8051 | AC19: =IFERROR((V19/T19)^(1/(V$4-T$4))-1,"N/A") -> 0.58795705 | AE19: =IFERROR((AA19/V19)^(1/(AA$4-V$4))-1,"N/A") -> N/A
C20: Margin | G20: =G19/G$8 -> 0.067954257 | H20: =H19/H$8 -> 0.10358216 | I20: =I19/I$8 -> 0.031018871 | J20: =J19/J$8 -> 0.048151248 | K20: =K19/K$8 -> 0.095037261 | L20: =L19/L$8 -> 0.10946681 | M20: =M19/M$8 -> 0.082729732 | N20: =N19/N$8 -> -0.087569707 | ... R20: =R19/R$8 -> -0.08463573 | T20: =T19/T$8 -> 0.032450322 | U20: =U19/U$8 -> 0.059336364 | V20: =V19/V$8 -> 0.065124948 | W20: =W19/W$8 -> 0.082547507 | X20: =X19/X$8 -> -0.083905625 | Y20: =Y19/Y$8 -> -0.079475106 | Z20: =Z19/Z$8 -> -0.079825831 | AA20: =AA19/AA$8 -> -0.078921477
C21: YoY % Growth | K21: =K19/G19-1 -> 0.73597607 | L21: =L19/H19-1 -> 0.06718529 | M21: =M19/I19-1 -> 1.7398844 | N21: =N19/J19-1 -> -0.48303243 | O21: =O19/K19-1 -> -1.5259197 | P21: =P19/L19-1 -> -1.7425449 | Q21: =Q19/M19-1 -> -2.2762894 | R21: =R19/N19-1 -> 0.086908498 | U21: =U19/T19-1 -> 0.85004322 | V21: =V19/U19-1 -> 0.3629993 | W21: =W19/V19-1 -> -0.046431685 | X21: =X19/W19-1 -> -2.2624287 | Y21: =Y19/X19-1 -> -0.033859672 | Z21: =Z19/Y19-1 -> 0.02450128 | AA21: =AA19/Z19-1 -> 0.0084443292
C23: =Model!C57 -> Adj. EPS (Diluted) | G23: =Model!P57 -> 1.7785185 | H23: =Model!Q57 -> 3.7656441 | I23: =Model!R57 -> 1.9877719 | J23: =Model!S57 -> 1.304 | K23: =Model!U57 -> 3.2236111 | L23: =Model!V57 -> 4.2687412 | M23: =Model!W57 -> 2.7297688 | N23: =Model!X57 -> -2.825918 | O23: =Model!Z57 -> -3.1178378 | P23: =Model!AA57 -> -3.3428486 | Q23: =Model!AB57 -> -3.6212086 | R23: =Model!AC57 -> -3.1110649 | T23: =Model!J57 -> 5.1942447 | U23: =Model!O57 -> 5.5799001 | V23: =Model!T57 -> 8.8758267 | W23: =Model!Y57 -> 9.9444974 | X23: =Model!AD57 -> -13.192547 | Y23: =Model!AE57 -> -12.953343 | Z23: =Model!AF57 -> -13.535125 | AA23: =Model!AG57 -> -13.926902 | AC23: =IFERROR((V23/T23)^(1/(V$4-T$4))-1,"N/A") -> 0.30720351 | AE23: =IFERROR((AA23/V23)^(1/(AA$4-V$4))-1,"N/A") -> N/A
C24: YoY % Growth | K24: =K23/G23-1 -> 0.81252603 | L24: =L23/H23-1 -> 0.13360186 | M24: =M23/I23-1 -> 0.37328071 | N24: =N23/J23-1 -> -3.1671151 | O24: =O23/K23-1 -> -1.9671879 | P24: =P23/L23-1 -> -1.7830994 | Q24: =Q23/M23-1 -> -2.3265624 | R24: =R23/N23-1 -> 0.10090416 | U24: =IF(ISERROR(U23/T23-1),"NA",(U23/T23-1)) -> 0.074246681 | V24: =IF(ISERROR(V23/U23-1),"NA",(V23/U23-1)) -> 0.59067841 | W24: =IF(ISERROR(W23/V23-1),"NA",(W23/V23-1)) -> NA | X24: =IF(ISERROR(X23/W23-1),"NA",(X23/W23-1)) -> NA | Y24: =IF(ISERROR(Y23/X23-1),"NA",(Y23/X23-1)) -> NA | Z24: =IF(ISERROR(Z23/Y23-1),"NA",(Z23/Y23-1)) -> NA | AA24: =IF(ISERROR(AA23/Z23-1),"NA",(AA23/Z23-1)) -> NA
C27: =Model!C61 -> EBITDA | G27: =Model!P61 -> 2324.56 | H27: =Model!Q61 -> 4291.53 | I27: =Model!R61 -> 3336.78 | J27: =Model!S61 -> 3159 | K27: =Model!U61 -> 3636 | L27: =Model!V61 -> 4619 | M27: =Model!W61 -> 3207 | N27: =Model!X61 -> -1959.489 | O27: =Model!Z61 -> -2183.7416 | P27: =Model!AA61 -> -2343.0263 | Q27: =Model!AB61 -> -2577.3289 | R27: =Model!AC61 -> -2081.1931 | T27: =Model!J61 -> 7341.59 | U27: =Model!O61 -> 7764.5 | V27: =Model!T61 -> 13111.87 | W27: =Model!Y61 -> 10588.511 | X27: =Model!AD61 -> -9185.29 | Y27: =Model!AE61 -> -8157.9584 | Z27: =Model!AF61 -> -7773.6756 | AA27: =Model!AG61 -> -7147.402 | AC27: =IFERROR((V27/T27)^(1/(V$4-T$4))-1,"N/A") -> 0.33640242 | AE27: =IFERROR((AA27/V27)^(1/(AA$4-V$4))-1,"N/A") -> N/A
C28: Margin | G28: =G27/G$8 -> 0.1181479 | H28: =H27/H$8 -> 0.15718739 | I28: =I27/I$8 -> 0.14957103 | J28: =J27/J$8 -> 0.15553149 | K28: =K27/K$8 -> 0.14888216 | L28: =L27/L$8 -> 0.16753718 | M28: =M27/M$8 -> 0.13993368 | N28: =N27/N$8 -> -0.09 | ... R28: =R27/R$8 -> -0.085 | T28: =T27/T$8 -> 0.10295461 | U28: =U27/U$8 -> 0.10761906 | V28: =V27/V$8 -> 0.14634273 | W28: =W27/W$8 -> 0.12496458 | X28: =X27/X$8 -> -0.087282093 | Y28: =Y27/Y$8 -> -0.076 | Z28: =Z27/Z$8 -> -0.071 | AA28: =AA27/AA$8 -> -0.064
C29: YoY % Growth | K29: =K27/G27-1 -> 0.56416698 | L29: =L27/H27-1 -> 0.076306119 | M29: =M27/I27-1 -> -0.038893784 | N29: =N27/J27-1 -> 0.19190328 | O29: =O27/K27-1 -> -1.4624612 | P29: =P27/L27-1 -> -1.5072583 | Q29: =Q27/M27-1 -> -1.8036573 | R29: =R27/N27-1 -> 0.062110133 | U29: =U27/T27-1 -> 0.057604688 | V29: =V27/U27-1 -> 0.6886947 | W29: =W27/V27-1 -> -0.12128539 | X29: =X27/W27-1 -> -1.867477 | Y29: =Y27/X27-1 -> -0.11184531 | Z29: =Z27/Y27-1 -> -0.047105263 | AA29: =AA27/Z27-1 -> -0.08056338
G31: =G$5 -> Quarterly | T31: =T$5 -> Annuals
A32: x | C32: ="Consolidated "&Model!C118 -> Consolidated Balance Sheet | G32: =G$6 -> 1Q25 | H32: =H$6 -> 2Q25 | I32: =I$6 -> 3Q25 | J32: =J$6 -> 4Q25 | K32: =K$6 -> 1Q26 | L32: =L$6 -> 2Q26 | M32: =M$6 -> 3Q26e | N32: =N$6 -> 4Q26e | ... R32: =R$6 -> 4Q27e | T32: =T$6 -> 2023 | U32: =U$6 -> 2024 | V32: =V$6 -> 2025 | W32: =W$6 -> 2026e | X32: =X$6 -> 2027e | Y32: =Y$6 -> 2028e | Z32: =Z$6 -> 2029e | AA32: =AA$6 -> 2030e
C34: =Model!C120 -> Cash & Cash Equivalents | G34: =Model!P120 -> 6156 | H34: =Model!Q120 -> 12726 | I34: =Model!R120 -> 10101 | J34: =Model!S120 -> 5196 | K34: =Model!U120 -> 7146 | L34: =Model!V120 -> 6255 | M34: =Model!W120 -> 6673 | N34: =Model!X120 -> 2432.4999 | O34: =Model!Z120 -> 16.041032 | P34: =Model!AA120 -> 1645.8512 | Q34: =Model!AB120 -> 1217.7828 | R34: =Model!AC120 -> 15.287746 | T34: =Model!J120 -> 729 | U34: =Model!O120 -> 876 | V34: =Model!T120 -> 5196 | W34: =Model!Y120 -> 2432.4999 | X34: =Model!AD120 -> 15.287746 | Y34: =Model!AE120 -> 67.022077 | Z34: =Model!AF120 -> 68.362519 | AA34: =Model!AG120 -> 69.729769
C35: =Model!C121 -> Accounts Receivable | G35: =Model!P121 -> 4091 | H35: =Model!Q121 -> 4168 | I35: =Model!R121 -> 3946 | J35: =Model!S121 -> 3038 | K35: =Model!U121 -> 3675 | L35: =Model!V121 -> 1e-12 | M35: =Model!W121 -> 1e-12 | N35: =Model!X121 -> 1e-12 | O35: =Model!Z121 -> 1e-12 | P35: =Model!AA121 -> 1e-12 | Q35: =Model!AB121 -> 1e-12 | R35: =Model!AC121 -> 1e-12 | T35: =Model!J121 -> 3410 | U35: =Model!O121 -> 3569 | V35: =Model!T121 -> 3038 | W35: =Model!Y121 -> 1e-12 | X35: =Model!AD121 -> 1e-12 | Y35: =Model!AE121 -> 1e-12 | Z35: =Model!AF121 -> 1e-12 | AA35: =Model!AG121 -> 1e-12
C36: =Model!C122 -> Inventory | G36: =Model!P122 -> 14283 | H36: =Model!Q122 -> 13831 | I36: =Model!R122 -> 15712 | J36: =Model!S122 -> 16193 | K36: =Model!U122 -> 18382 | L36: =Model!V122 -> 17322 | M36: =Model!W122 -> 16685 | N36: =Model!X122 -> 18529.95 | O36: =Model!Z122 -> 23065.506 | P36: =Model!AA122 -> 22014.148 | Q36: =Model!AB122 -> 20954.805 | R36: =Model!AC122 -> 20718.783 | T36: =Model!J122 -> 12561 | U36: =Model!O122 -> 13179 | V36: =Model!T122 -> 16193 | W36: =Model!Y122 -> 18529.95 | X36: =Model!AD122 -> 20718.783 | Y36: =Model!AE122 -> 21269.509 | Z36: =Model!AF122 -> 21669.702 | AA36: =Model!AG122 -> 22051.693
C37: =Model!C123 -> Prepaid & Other Current Assets | G37: =Model!P123 -> 1487 | H37: =Model!Q123 -> 1160 | I37: =Model!R123 -> 1103 | J37: =Model!S123 -> 937 | K37: =Model!U123 -> 1288 | L37: =Model!V123 -> 1506 | M37: =Model!W123 -> 1491 | N37: =Model!X123 -> 1e-12 | O37: =Model!Z123 -> 1849.7576 | P37: =Model!AA123 -> 2108.7237 | Q37: =Model!AB123 -> 1855.6768 | R37: =Model!AC123 -> 1762.893 | T37: =Model!J123 -> 938 | U37: =Model!O123 -> 1263 | V37: =Model!T123 -> 937 | W37: =Model!Y123 -> 1e-12 | X37: =Model!AD123 -> 1762.893 | Y37: =Model!AE123 -> 1932.148 | Z37: =Model!AF123 -> 1970.791 | AA37: =Model!AG123 -> 2010.2068
C38: =Model!C124 -> Total Current Assets | G38: =SUM(G34:G37) -> 21926 | H38: =SUM(H34:H37) -> 27717 | I38: =SUM(I34:I37) -> 26916 | J38: =SUM(J34:J37) -> 22326 | K38: =SUM(K34:K37) -> 26816 | L38: =SUM(L34:L37) -> 25083 | M38: =SUM(M34:M37) -> 24849 | N38: =SUM(N34:N37) -> 20962.45 | ... R38: =SUM(R34:R37) -> 22496.964 | T38: =SUM(T34:T37) -> 14228 | U38: =SUM(U34:U37) -> 15318 | V38: =SUM(V34:V37) -> 22326 | W38: =SUM(W34:W37) -> 20962.45 | X38: =SUM(X34:X37) -> 22496.964 | Y38: =SUM(Y34:Y37) -> 23268.679 | Z38: =SUM(Z34:Z37) -> 23708.855 | AA38: =SUM(AA34:AA37) -> 24131.63
C40: =Model!C126 -> PP&E, Net | G40: =Model!P126 -> 18501 | H40: =Model!Q126 -> 18612 | I40: =Model!R126 -> 18683 | J40: =Model!S126 -> 22987 | K40: =Model!U126 -> 19059 | L40: =Model!V126 -> 19031 | M40: =Model!W126 -> 18925 | N40: =Model!X126 -> 18963.938 | O40: =Model!Z126 -> 19248.655 | P40: =Model!AA126 -> 19556.136 | Q40: =Model!AB126 -> 19652.049 | R40: =Model!AC126 -> 19724.377 | T40: =Model!J126 -> 18432 | U40: =Model!O126 -> 18669 | V40: =Model!T126 -> 22987 | W40: =Model!Y126 -> 18963.938 | X40: =Model!AD126 -> 19724.377 | Y40: =Model!AE126 -> 20451.053 | Z40: =Model!AF126 -> 21168.345 | AA40: =Model!AG126 -> 21989.466
C41: =Model!C127 -> Intangible Assets, Net | G41: =Model!P127 -> 1e-12 | H41: =Model!Q127 -> 1e-12 | I41: =Model!R127 -> 1e-12 | J41: =Model!S127 -> 1e-12 | K41: =Model!U127 -> 1e-12 | L41: =Model!V127 -> 1e-12 | M41: =Model!W127 -> 1e-12 | N41: =Model!X127 -> 1e-12 | O41: =Model!Z127 -> 1e-12 | P41: =Model!AA127 -> 1e-12 | Q41: =Model!AB127 -> 1e-12 | R41: =Model!AC127 -> 1e-12 | T41: =Model!J127 -> 355 | U41: =Model!O127 -> 1e-12 | V41: =Model!T127 -> 1e-12 | W41: =Model!Y127 -> 1e-12 | X41: =Model!AD127 -> 1e-12 | Y41: =Model!AE127 -> 1e-12 | Z41: =Model!AF127 -> 1e-12 | AA41: =Model!AG127 -> 1e-12
C42: =Model!C128 -> Goodwill | G42: =Model!P128 -> 18333 | H42: =Model!Q128 -> 18663 | I42: =Model!R128 -> 18662 | J42: =Model!S128 -> 311 | K42: =Model!U128 -> 15411 | L42: =Model!V128 -> 1e-12 | M42: =Model!W128 -> 1e-12 | N42: =Model!X128 -> 1e-12 | O42: =Model!Z128 -> 1e-12 | P42: =Model!AA128 -> 1e-12 | Q42: =Model!AB128 -> 1e-12 | R42: =Model!AC128 -> 1e-12 | T42: =Model!J128 -> 303 | U42: =Model!O128 -> 303 | V42: =Model!T128 -> 311 | W42: =Model!Y128 -> 1e-12 | X42: =Model!AD128 -> 1e-12 | Y42: =Model!AE128 -> 1e-12 | Z42: =Model!AF128 -> 1e-12 | AA42: =Model!AG128 -> 1e-12
C43: =Model!C129 -> Other Non-Current Assets | G43: =Model!P129 -> 5405 | H43: =Model!Q129 -> 5434 | I43: =Model!R129 -> 5281 | J43: =Model!S129 -> 1111 | K43: =Model!U129 -> 5325 | L43: =Model!V129 -> 5290 | M43: =Model!W129 -> 5626 | N43: =Model!X129 -> 5738.52 | O43: =Model!Z129 -> 5853.2904 | P43: =Model!AA129 -> 5970.3562 | Q43: =Model!AB129 -> 6089.7633 | R43: =Model!AC129 -> 6211.5586 | T43: =Model!J129 -> 1545 | U43: =Model!O129 -> 5181 | V43: =Model!T129 -> 1111 | W43: =Model!Y129 -> 5738.52 | X43: =Model!AD129 -> 6211.5586 | Y43: =Model!AE129 -> 6335.7898 | Z43: =Model!AF129 -> 6462.5056 | AA43: =Model!AG129 -> 6591.7557
C44: =Model!C130 -> Total Non-Current Assets | G44: =SUM(G40:G43) -> 23906 | H44: =SUM(H40:H43) -> 24046 | I44: =SUM(I40:I43) -> 23964 | J44: =SUM(J40:J43) -> 24409 | K44: =SUM(K40:K43) -> 24384 | L44: =SUM(L40:L43) -> 24321 | M44: =SUM(M40:M43) -> 24551 | N44: =SUM(N40:N43) -> 24702.458 | ... R44: =SUM(R40:R43) -> 25935.936 | T44: =SUM(T40:T43) -> 20280 | U44: =SUM(U40:U43) -> 24153 | V44: =SUM(V40:V43) -> 24409 | W44: =SUM(W40:W43) -> 24702.458 | X44: =SUM(X40:X43) -> 25935.936 | Y44: =SUM(Y40:Y43) -> 26786.843 | Z44: =SUM(Z40:Z43) -> 27630.851 | AA44: =SUM(AA40:AA43) -> 28581.221
C46: =Model!C132 -> Total Assets | G46: =SUM(G38,G44) -> 45832 | H46: =SUM(H38,H44) -> 51763 | I46: =SUM(I38,I44) -> 50880 | J46: =SUM(J38,J44) -> 46735 | K46: =SUM(K38,K44) -> 51200 | L46: =SUM(L38,L44) -> 49404 | M46: =SUM(M38,M44) -> 49400 | N46: =SUM(N38,N44) -> 45664.908 | ... R46: =SUM(R38,R44) -> 48432.9 | T46: =SUM(T38,T44) -> 34508 | U46: =SUM(U38,U44) -> 39471 | V46: =SUM(V38,V44) -> 46735 | W46: =SUM(W38,W44) -> 45664.908 | X46: =SUM(X38,X44) -> 48432.9 | Y46: =SUM(Y38,Y44) -> 50055.522 | Z46: =SUM(Z38,Z44) -> 51339.706 | AA46: =SUM(AA38,AA44) -> 52712.851
C48: =Model!C134 -> Accounts Payable | G48: =Model!P134 -> 10841 | H48: =Model!Q134 -> 12916 | I48: =Model!R134 -> 12759 | J48: =Model!S134 -> 10884 | K48: =Model!U134 -> 13964 | L48: =Model!V134 -> 12011 | M48: =Model!W134 -> 11334 | N48: =Model!X134 -> 11323.859 | O48: =Model!Z134 -> 14082.099 | P48: =Model!AA134 -> 13208.489 | Q48: =Model!AB134 -> 13065.937 | R48: =Model!AC134 -> 12661.479 | T48: =Model!J134 -> 8279 | U48: =Model!O134 -> 7659 | V48: =Model!T134 -> 10884 | W48: =Model!Y134 -> 11323.859 | X48: =Model!AD134 -> 12661.479 | Y48: =Model!AE134 -> 13673.256 | Z48: =Model!AF134 -> 13930.523 | AA48: =Model!AG134 -> 14176.089
C49: =Model!C135 -> Accrued Liabilities | G49: =Model!P135 -> 982 | H49: =Model!Q135 -> 1139 | I49: =Model!R135 -> 1117 | J49: =Model!S135 -> 2411 | K49: =Model!U135 -> 1312 | L49: =Model!V135 -> 1331 | M49: =Model!W135 -> 1353 | N49: =Model!X135 -> 947.08635 | O49: =Model!Z135 -> 1104.7164 | P49: =Model!AA135 -> 1252.0547 | Q49: =Model!AB135 -> 1134.0247 | R49: =Model!AC135 -> 1058.96 | T49: =Model!J135 -> 662 | U49: =Model!O135 -> 684 | V49: =Model!T135 -> 2411 | W49: =Model!Y135 -> 947.08635 | X49: =Model!AD135 -> 1058.96 | Y49: =Model!AE135 -> 1201.4741 | Z49: =Model!AF135 -> 1224.0802 | AA49: =Model!AG135 -> 1245.6582
C50: =Model!C136 -> Other Current Liabilities | G50: =Model!P136 -> 5898 | H50: =Model!Q136 -> 6706 | I50: =Model!R136 -> 5079 | J50: =Model!S136 -> 3614 | K50: =Model!U136 -> 6278 | L50: =Model!V136 -> 6978 | M50: =Model!W136 -> 6795 | N50: =Model!X136 -> 9470.8635 | O50: =Model!Z136 -> 9721.5039 | P50: =Model!AA136 -> 11018.081 | Q50: =Model!AB136 -> 11340.247 | R50: =Model!AC136 -> 10589.6 | T50: =Model!J136 -> 4446 | U50: =Model!O136 -> 6242 | V50: =Model!T136 -> 3614 | W50: =Model!Y136 -> 9470.8635 | X50: =Model!AD136 -> 10589.6 | Y50: =Model!AE136 -> 11090.53 | Z50: =Model!AF136 -> 11299.202 | AA50: =Model!AG136 -> 11498.383
C51: =Model!C137 -> Total Current Liabilities (Excl. Debt) | G51: =SUM(G48:G50) -> 17721 | H51: =SUM(H48:H50) -> 20761 | I51: =SUM(I48:I50) -> 18955 | J51: =SUM(J48:J50) -> 16909 | K51: =SUM(K48:K50) -> 21554 | L51: =SUM(L48:L50) -> 20320 | M51: =SUM(M48:M50) -> 19482 | N51: =SUM(N48:N50) -> 21741.808 | ... R51: =SUM(R48:R50) -> 24310.039 | T51: =SUM(T48:T50) -> 13387 | U51: =SUM(U48:U50) -> 14585 | V51: =SUM(V48:V50) -> 16909 | W51: =SUM(W48:W50) -> 21741.808 | X51: =SUM(X48:X50) -> 24310.039 | Y51: =SUM(Y48:Y50) -> 25965.26 | Z51: =SUM(Z48:Z50) -> 26453.805 | AA51: =SUM(AA48:AA50) -> 26920.13
C53: =Model!C139 -> Revolver | G53: =Model!P139 -> 5045 | H53: =Model!Q139 -> 4040 | I53: =Model!R139 -> 1992 | J53: =Model!S139 -> 56 | K53: =Model!U139 -> 250 | L53: =Model!V139 -> 1e-12 | M53: =Model!W139 -> 1e-12 | N53: =Model!X139 -> 1e-12 | O53: =Model!Z139 -> 4764.4476 | P53: =Model!AA139 -> 4764.4476 | Q53: =Model!AB139 -> 4764.4476 | R53: =Model!AC139 -> 11402.879 | T53: =Model!J139 -> 348 | U53: =Model!O139 -> 360 | V53: =Model!T139 -> 56 | W53: =Model!Y139 -> 1e-12 | X53: =Model!AD139 -> 11402.879 | Y53: =Model!AE139 -> 23713.548 | Z53: =Model!AF139 -> 37567.014 | AA53: =Model!AG139 -> 52328.082
C54: =Model!C140 -> LT Debt (Incl. Current Portion) | G54: =Model!P140 -> 20804 | H54: =Model!Q140 -> 20806 | I54: =Model!R140 -> 21794 | J54: =Model!S140 -> 26211 | K54: =Model!U140 -> 23244 | L54: =Model!V140 -> 23311 | M54: =Model!W140 -> 25233 | N54: =Model!X140 -> 24733 | O54: =Model!Z140 -> 24233 | P54: =Model!AA140 -> 23733 | Q54: =Model!AB140 -> 23233 | R54: =Model!AC140 -> 22733 | T54: =Model!J140 -> 15501 | U54: =Model!O140 -> 17365 | V54: =Model!T140 -> 26211 | W54: =Model!Y140 -> 24733 | X54: =Model!AD140 -> 22733 | Y54: =Model!AE140 -> 21333 | Z54: =Model!AF140 -> 20033 | AA54: =Model!AG140 -> 18833
...

Sheet Model Output
B1: =Company_Name&" "&"("&Ticker&")"&" Valuation Overview" -> Lowe's Companies, Inc. (LOW) Valuation Overview | K1: Price Target Scenario: | N1: =Case_Scenario&" Case" -> Base Case | R1: Base Case Check | S1: =IF(N1="Base Case","","Check!") | Y1: P/E
B2: =Cover!C2 -> $ in Millions Except Per Share Data | K2: Current Share Price: | O2: =Share_Price -> 233.18 | Y2: EV/EBITDA
K3: Valuation Date: | O3: =Current_Date -> 45903
B4: ="Multiples Analysis "&"("&S21&")" -> Multiples Analysis (P/E) | I4: Return Summary
I6: Exit Multiple Method
I7: =Cover!I9 -> Implied Enterprise Value: | N7: =Cover!L9 -> -85959.254
I8: =Cover!I10 -> Implied Equity Value: | N8: =Cover!L10 -> -103015.25
I9: =Cover!I12 -> Implied Share Price: | N9: =Cover!L12 -> -145.70757
I10: =Cover!I13 -> % Return: | N10: =Cover!L13 -> 1e-12
I12: =Cover!I15 -> Perpetuity Growth Method
I13: =Cover!I16 -> Implied Enterprise Value: | N13: =Cover!L16 -> -24426.903
I14: =Cover!I17 -> Implied Equity Value: | N14: =Cover!L17 -> -41482.903
I15: =Cover!I19 -> Implied Share Price: | N15: =Cover!L19 -> -58.674545
I16: =Cover!I20 -> % Return: | N16: =Cover!L20 -> 1e-12
E18: Annuals | M18: CAGR | O18: CAGR
B19: Consolidated Financials | E19: =Summary!U6 -> 2024 | F19: =Summary!V6 -> 2025 | G19: =Summary!W6 -> 2026e | H19: =Summary!X6 -> 2027e | I19: =Summary!Y6 -> 2028e | J19: =Summary!Z6 -> 2029e | K19: =Summary!AA6 -> 2030e | M19: Historical | O19: Projected
B21: =Summary!C8 -> Revenue | D21: =Summary!T8 -> 71309 | E21: =Summary!U8 -> 72148 | F21: =Summary!V8 -> 89597 | G21: =Summary!W8 -> 96682.1 | H21: =Summary!X8 -> 105236.82 | I21: =Summary!Y8 -> 107341.56 | J21: =Summary!Z8 -> 109488.39 | K21: =Summary!AA8 -> 111678.16 | M21: =Summary!AC8 -> 0.12091985 | O21: =Summary!AE8 -> 0.045044909 | R21: Multiple Toggle | S21: P/E
B22: =Summary!C9 -> YoY % Growth | E22: =Summary!U9 -> 0.011765696 | F22: =Summary!V9 -> 0.24185009 | G22: =Summary!W9 -> 0.079077424 | H22: =Summary!X9 -> 0.088482991 | I22: =Summary!Y9 -> 0.02 | J22: =Summary!Z9 -> 0.02 | K22: =Summary!AA9 -> 0.02
R23: Multiples Analysis | S23: EV/EBITDA | T23: P/E | U23: Chart
B24: =Summary!C11 -> Gross Profit | D24: =Summary!T11 -> 22908 | E24: =Summary!U11 -> 22943 | F24: =Summary!V11 -> 29583 | G24: =Summary!W11 -> 27859.373 | H24: =Summary!X11 -> 14241.705 | I24: =Summary!Y11 -> 14920.477 | J24: =Summary!Z11 -> 15328.374 | K24: =Summary!AA11 -> 15858.298 | M24: =Summary!AC11 -> 0.1363903 | O24: =Summary!AE11 -> -0.11723954 | R24: Entry Multiple | S24: =Valuation!D12 -> 12.4849 | T24: =Valuation!D11 -> 18.6398 | U24: =IF($S$21=$S$23,S24,T24) -> 18.6398
B25: =Summary!C12 -> % Margin | E25: =Summary!U12 -> 0.31799911 | F25: =Summary!V12 -> 0.33017847 | G25: =Summary!W12 -> 0.28815441 | H25: =Summary!X12 -> 0.13533006 | I25: =Summary!Y12 -> 0.139 | J25: =Summary!Z12 -> 0.14 | K25: =Summary!AA12 -> 0.142 | R25: =Model!Y25 -> 2026e | S25: =(Comparables!H10*S30)/(Model!Y61) -> 15.585656 | T25: =(Comparables!$G$10*S30)/Summary!W19 -> 20.383651 | U25: =IF($S$21=$S$23,S25,T25)
B26: =Summary!C13 -> YoY % Growth | E26: =Summary!U13 -> 0.0015278505 | F26: =Summary!V13 -> 0.28941289 | G26: =Summary!W13 -> -0.058264104 | H26: =Summary!X13 -> -0.48880022 | I26: =Summary!Y13 -> 0.047660817 | J26: =Summary!Z13 -> 0.027338129 | K26: =Summary!AA13 -> 0.034571429 | R26: =Summary!AA6 -> 2030e | S26: =(Comparables!H10*S30)/(Model!AG61) -> -23.089353 | T26: =(Comparables!$G$10*S30)/Summary!AA19 -> -14.670223 | U26: =IF($S$21=$S$23,S26,T26)
R27: Exit Multiple | S27: =Valuation!K60 -> 13 | T27: =Valuation!K72/Summary!AA19 -> 10.599963 | U27: =IF($S$21=$S$23,S27,T27)
B28: =Summary!C27 -> EBITDA | D28: =Summary!T27 -> 7341.59 | E28: =Summary!U27 -> 7764.5 | F28: =Summary!V27 -> 13111.87 | G28: =Summary!W27 -> 10588.511 | H28: =Summary!X27 -> -9185.29 | I28: =Summary!Y27 -> -8157.9584 | J28: =Summary!Z27 -> -7773.6756 | K28: =Summary!AA27 -> -7147.402 | M28: =Summary!AC27 -> 0.33640242 | O28: =Summary!AE27 -> N/A | R28: Implied PGM | S28: =Valuation!K79 -> 1e-12 | T28: =Valuation!R72/Summary!AA19 -> 4.2684673 | U28: =IF($S$21=$S$23,S28,T28)
B29: =Summary!C28 -> Margin | E29: =Summary!U28 -> 0.10761906 | F29: =Summary!V28 -> 0.14634273 | G29: =Summary!W28 -> 0.12496458 | H29: =Summary!X28 -> -0.087282093 | I29: =Summary!Y28 -> -0.076 | J29: =Summary!Z28 -> -0.071 | K29: =Summary!AA28 -> -0.064
B30: =Summary!C29 -> YoY % Growth | E30: =Summary!U17 -> 0.57142857 | F30: =Summary!V17 -> 0.72505543 | G30: =Summary!W29 -> -0.12128539 | H30: =Summary!X29 -> -1.867477 | I30: =Summary!Y29 -> -0.11184531 | J30: =Summary!Z29 -> -0.047105263 | K30: =Summary!AA29 -> -0.08056338 | R30: Financials Multiplier | S30: =IF($B$2="$ in Millions Except Per Share Data",1,IF($B$2="$ in Thousands Except Per Share Data",1000,IF($B$2="$ in Billions Except Per Share Data",0.001,0))) -> 1
B32: =Summary!C19 -> Net Income (Loss) | D32: =Summary!T19 -> 2314 | E32: =Summary!U19 -> 4281 | F32: =Summary!V19 -> 5835 | G32: =Summary!W19 -> 6994.4236 | H32: =Summary!X19 -> -8789.6274 | I32: =Summary!Y19 -> -8724.2869 | J32: =Summary!Z19 -> -9308.4366 | K32: =Summary!AA19 -> -9718.454 | M32: =Summary!AC19 -> 0.58795705 | O32: =Summary!AE19 -> N/A
B33: =Summary!C20 -> Margin | E33: =Summary!U20 -> 0.059336364 | F33: =Summary!V20 -> 0.065124948 | G33: =Summary!W20 -> 0.082547507 | H33: =Summary!X20 -> -0.083522358 | I33: =Summary!Y20 -> -0.081275949 | J33: =Summary!Z20 -> -0.085017569 | K33: =Summary!AA20 -> -0.087021977
B34: =Summary!C21 -> YoY % Growth | E34: =Summary!U21 -> 0.85004322 | F34: =Summary!V21 -> 0.3629993 | G34: =Summary!W21 -> -0.046431685 | H34: =Summary!X21 -> -2.2566622 | I34: =Summary!Y21 -> -0.0074338189 | J34: =Summary!Z21 -> 0.066956727 | K34: =Summary!AA21 -> 0.044047932
B36: =Summary!C23 -> Adj. EPS (Diluted) | D36: =Summary!T23 -> 5.1942447 | E36: =Summary!U23 -> 5.5799001 | F36: =Summary!V23 -> 8.8758267 | G36: =Summary!W23 -> 9.9444974 | H36: =Summary!X23 -> -13.132285 | I36: =Summary!Y23 -> -13.246855 | J36: =Summary!Z23 -> -14.415426 | K36: =Summary!AA23 -> -15.356359 | M36: =Summary!AC23 -> 0.30720351 | O36: =Summary!AE23 -> N/A
B37: =Summary!C24 -> YoY % Growth | E37: =Summary!U24 -> 0.074246681 | F37: =Summary!V24 -> 0.59067841 | G37: =Summary!W24 -> NA | H37: =Summary!X24 -> NA | I37: =Summary!Y24 -> NA | J37: =Summary!Z24 -> NA | K37: =Summary!AA24 -> NA
B39: Free Cash Flow | D39: =Model!J112 -> 3799 | E39: =Model!O112 -> 2821 | F39: =Model!T112 -> 5715 | G39: =Model!Y112 -> 1141.3936 | H39: =Model!AD112 -> -10401.279 | I39: =Model!AE112 -> -8989.9116 | J39: =Model!AF112 -> -10168.655 | K39: =Model!AG112 -> -10676 | M39: =IFERROR((F39/D39)^(1/2)-1,"N/A") -> 0.22651671 | O39: =IFERROR((K39/G39)^(1/4)-1,"N/A") -> N/A
B40: YoY % Growth | E40: =E39/D39-1 -> -0.25743617 | F40: =F39/E39-1 -> 1.0258773 | G40: =G39/F39-1 -> -0.86330616 | H40: =H39/G39-1 -> -10.112789 | I40: =I39/H39-1 -> -0.13569174 | J40: =J39/I39-1 -> 0.13111842 | K40: =K39/J39-1 -> 0.049893069
E42: Annuals | M42: Average | O42: Average
B43: Capitalization and Key Ratios | E43: =E19 -> 2024 | F43: =F19 -> 2025 | G43: =G19 -> 2026e | H43: =H19 -> 2027e | I43: =I19 -> 2028e | J43: =J19 -> 2029e | K43: =K19 -> 2030e | M43: Historical | O43: Projected
B44: =Summary!C91 -> Leverage
B45: =Summary!C92 -> Total Debt / EBITDA | D45: =Summary!T92 -> 2.1113955 | E45: =Summary!U92 -> 2.2364608 | F45: =Summary!V92 -> 1.9990284 | G45: =Summary!W92 -> NA | H45: =Summary!X92 -> NA | I45: =Summary!Y92 -> NA | J45: =Summary!Z92 -> NA | K45: =Summary!AA92 -> NA | M45: =AVERAGE(D45:F45) -> 2.1156282 | O45: =AVERAGE(G45:K45)
B46: =Summary!C93 -> Total Debt / Equity | D46: =Summary!T93 -> 4.2538419 | E46: =Summary!U93 -> 8.8057809 | F46: =Summary!V93 -> 18.240084 | G46: =Summary!W93 -> NA | H46: =Summary!X93 -> NA | I46: =Summary!Y93 -> NA | J46: =Summary!Z93 -> NA | K46: =Summary!AA93 -> NA | M46: =AVERAGE(D46:F46) -> 10.433235 | O46: =AVERAGE(G46:K46)
B47: =Summary!C94 -> Total Debt / Total Assets | D47: =Summary!T94 -> 0.44920019 | E47: =Summary!U94 -> 0.43994325 | F47: =Summary!V94 -> 0.56084305 | G47: =Summary!W94 -> NA | H47: =Summary!X94 -> NA | I47: =Summary!Y94 -> NA | J47: =Summary!Z94 -> NA | K47: =Summary!AA94 -> NA | M47: =AVERAGE(D47:F47) -> 0.48332883 | O47: =AVERAGE(G47:K47)
B49: =Summary!C103 -> Liquidity
...

Sheet Football Field
C1: =Company_Name&" - "&MID(CELL("filename",A1),FIND("]",CELL("filename",A1))+1,255)&": "&Case_Scenario&" Case" -> Lowe's Companies, Inc. - Football Field: Base Case
C2: =Cover!C2 -> $ in Millions Except Per Share Data
A4: x | O4: Valuation Method: | T4: Downside | U4: Delta | V4: Upside | W4: x
O5: =TEXT(Valuation!E108,"0.0%")&" - "&TEXT(Valuation!E110,"0.0%")&" WACC"&" & "&TEXT(Valuation!G106,"0.0%")&" - "&TEXT(Valuation!I106,"0.0%")&" PGR" -> 8.4% - 9.4% WACC & 1.5% - 2.5% PGR | T5: =Valuation!G108 -> 195.04955 | U5: =V5-T5 -> 20.385916 | V5: =Valuation!I110 -> 215.43546
O6: =TEXT(Valuation!E100,"0.0%")&" - "&TEXT(Valuation!E102,"0.0%")&" WACC"&" & "&TEXT(Valuation!G98,"0.0x")&" - "&TEXT(Valuation!I98,"0.0x")&" Exit Multiple" -> 8.4% - 9.4% WACC & 12.0x - 14.0x Exit Multiple | T6: =Valuation!G100 -> 250.78262 | U6: =V6-T6 -> 27.264041 | V6: =Valuation!I102 -> 278.04666
O8: =Valuation!F184&": "&TEXT(Valuation!G185,"0.0x")&" - "&TEXT(Valuation!I185,"0.0x") -> NTM EV/EBITDA Spread to Comps: 12.0x - 14.0x | T8: =Valuation!G187 -> 209.23348 | U8: =V8-T8 -> 100.49025 | V8: =Valuation!I189 -> 309.72373
O9: =Valuation!F176&": "&TEXT(Valuation!G177,"0.0x")&" - "&TEXT(Valuation!I177,"0.0x") -> NTM EV/EBITDA: 11.4x - 13.4x | T9: =Valuation!G179 -> 197.97414 | U9: =V9-T9 -> 97.988172 | V9: =Valuation!I181 -> 295.96231
O10: =Valuation!F168&": "&TEXT(Valuation!G169,"0.0x")&" - "&TEXT(Valuation!I169,"0.0x") -> NTM P/E Spread to Comps: 18.3x - 20.3x | T10: =Valuation!G171 -> 241.4239 | U10: =V10-T10 -> 85.926567 | V10: =Valuation!I173 -> 327.35047
O11: =Valuation!F160&": "&TEXT(Valuation!G161,"0.0x")&" - "&TEXT(Valuation!I161,"0.0x") -> NTM P/E: 17.8x - 19.8x | T11: =Valuation!G163 -> 234.48845 | U11: =V11-T11 -> 84.385357 | V11: =Valuation!I165 -> 318.87381
O13: =Valuation!F260&": "&TEXT(Valuation!G261,"0.0x")&" - "&TEXT(Valuation!I261,"0.0x") -> 2009-2018 Early Cycle EV/EBITDA Spread to Comps: 11.7x - 13.7x | T13: =Valuation!G263 -> 202.21364 | U13: =V13-T13 -> 39.300331 | V13: =Valuation!I263 -> 241.51397
O14: =Valuation!F252&": "&TEXT(Valuation!G253,"0.0x")&" - "&TEXT(Valuation!I253,"0.0x") -> 2009-2018 Early Cycle EV/EBITDA: 6.4x - 8.4x | T14: =Valuation!G255 -> 99.103102 | U14: =V14-T14 -> 39.300331 | V14: =Valuation!I255 -> 138.40343
O15: =Valuation!F244&": "&TEXT(Valuation!G245,"0.0x")&" - "&TEXT(Valuation!I245,"0.0x") -> 2009-2018 Early Cycle P/E Spread to Comps: 20.2x - 22.2x | T15: =Valuation!G247 -> 267.04261 | U15: =V15-T15 -> 26.408301 | V15: =Valuation!I247 -> 293.45091
O16: =Valuation!F236&": "&TEXT(Valuation!G237,"0.0x")&" - "&TEXT(Valuation!I237,"0.0x") -> 2009-2018 Early Cycle P/E: 15.5x - 17.5x | T16: =Valuation!G239 -> 205.30919 | U16: =V16-T16 -> 26.408301 | V16: =Valuation!I239 -> 231.71749
O18: 52-Week Price Range: | T18: =Share_Price_Low -> 146.72 | U18: =V18-T18 -> 68.5 | V18: =Share_Price_High -> 215.22
O19: Median Value: | T19: =MEDIAN(T5:T18) -> 205.30919 | U19: =MEDIAN(U5:U18) -> 39.300331 | V19: =MEDIAN(V5:V18) -> 278.04666
A20: x | O20: Implied Return (%): | T20: =T19/Share_Price-1 -> -0.11952488 | V20: =V19/Share_Price-1 -> 0.19241212
T22: Reference Points for Price Axis
U24: Price
A25: x | T25: High | U25: =MAX(V5:V18)*1.1 -> 360.08551 | W25: x
T26: Low | U26: =MIN(T5:T18)*0.9 -> 89.192792
A30: x

Sheet Integrity
C1: =Company_Name&" - "&MID(CELL("filename",A1),FIND("]",CELL("filename",A1))+1,255) -> Lowe's Companies, Inc. - Integrity
C3: Integrity
C4: Metric
C6: Model:
C7: Balance Sheet Check: | D7: =SUM(Model!F158:AG158) -> -329924
C8: Base Case: | D8: =IF(Case_Scenario="Base","OK!","Check!") -> OK!
C9: Interest Expense: | D9: =IF(Model!C8="On","OK!","CHECK - OFF") -> OK!
C10: Valuation Date:
C12: Formatting:
C13: Valuation Sensitivity Tables: | D13: =SUM(Valuation!F92,Valuation!K92,Valuation!P92,Valuation!F151:F155,Valuation!L151:L155,Valuation!F227:F231,Valuation!L227:L231) -> 0.00024017932
C14: WACC Tables: | D14: =SUM(WACC!Q20,WACC!N33:N37) -> -0.00258654
C16: Font Toggles:
C17: Cover: | D17: =Cover!$Q$2 -> Working
C18: Revenue Build: | D18: ='Revenue Build'!$C$22 -> Working
C19: Model: | D19: =Model!$C$5 -> Working
C20: WACC | D20: =WACC!R5 -> Working
C21: Valuation: | D21: =Valuation!$R$2 -> Working
C23: Change Log
C24: Date | D24: Version | E24: Operator | F24: Revisions
C25: 44476 | D25: v01 | E25: Nate Latimer | F25: Top Down / Bottom Up toggle integration and Capital IQ comps sheet w/ ID Locator
C26: 44476 | D26: v02 | E26: Carson Shaner | F26: Formulas for EBIT/EBITDA margins on earnings sheets
C27: 44480 | D27: v03 | E27: Nate Latimer | F27: Historical driver adjustments to reflect Top Down / Bottom Up Toggle
C28: 44488 | D28: v04 | E28: Nate Latimer | F28: Bug fixes to model output, comps sheet and WACC Comps Relevered Beta
C29: 44489 | D29: v05 | E29: Lilianna Ruby | F29: Changed the year end driver in 2021 and 2022 to correctly pull operating margins
C30: 44491 | D30: v06 | E30: Lilianna Ruby | F30: Changed the first page to add 365 to your previous fiscal year
C31: 44496 | D31: v07 | E31: Carson Shaner | F31: Changed Model Output FCF formula, broke apart D&A for historical periods, added checks for EPS & EBITDA in Valuation sensitivity tables, added segment D&A breakdown, linked and fixed SOTP valuation
C32: 44503 | D32: v08 | E32: Lilianna Ruby | F32: Changed average of comps on valuation tab to average all peers not just the first one
C33: 44512 | D33: v09 | E33: Lilianna Ruby | F33: Rolled model forward to reflect 3Q'21. Also changed the multiples tab so the quarters roll forward and end on correct date.
C34: 44522 | D34: v10 | E34: Lilianna Ruby | F34: Fully fixed the multiples tab so it is automatic and fully functional. Also fixed definition of NTM_EPS and NTM_EBITDA
C35: 44582 | D35: v13 | E35: Carson Shaner | F35: Changed EPS, EBITDA, shares, tax rate, etc., to formulas so we do not have to hardcode them.
C36: 44584 | D36: v14 | E36: Lilianna Ruby | F36: Changed discount factor to mid year
... C47: 45581 | D47: v25 | E47: Conor McCabe | F47: Added font toggle to integrity tab for WACC tab. Formatted Comparables Tab.

Sheet Revenue Build
C1: =Company_Name&" - "&MID(CELL("filename",A1),FIND("]",CELL("filename",A1))+1,255)&": "&Case_Scenario&" Case" -> Lowe's Companies, Inc. - Revenue Build: Base Case
C2: =Cover!C2 -> $ in Millions Except Per Share Data
A4: x | C4: Segments
C6: =C30&" Methodology" -> Total Company Revenue Methodology
C7: Segment
C8: =C32&" Methodology" -> Home Improvement Retail Revenue Methodology
C9: =IF(Company_Rev_Methodology="Segment","Segment",IF(Company_Rev_Methodology="Activity-Based","Activity-Based",IF(Company_Rev_Methodology="Backlog","Backlog",IF(Company_Rev_Methodology="Mixed",D9,"--")))) -> Segment | D9: Backlog
C10: =C35&" Methodology" -> Segment 2 Revenue Methodology
C11: =IF(Company_Rev_Methodology="Segment","Segment",IF(Company_Rev_Methodology="Activity-Based","Activity-Based",IF(Company_Rev_Methodology="Backlog","Backlog",IF(Company_Rev_Methodology="Mixed",D11,"--")))) -> Segment | D11: Activity-Based
C12: =C38&" Methodology" -> Segment 3 Revenue Methodology
C13: =IF(Company_Rev_Methodology="Segment","Segment",IF(Company_Rev_Methodology="Activity-Based","Activity-Based",IF(Company_Rev_Methodology="Backlog","Backlog",IF(Company_Rev_Methodology="Mixed",D13,"--")))) -> Segment | D13: Segment
C14: =C41&" Methodology" -> Segment 4 Revenue Methodology
C15: =IF(Company_Rev_Methodology="Segment","Segment",IF(Company_Rev_Methodology="Activity-Based","Activity-Based",IF(Company_Rev_Methodology="Backlog","Backlog",IF(Company_Rev_Methodology="Mixed",D15,"--")))) -> Segment | D15: Segment
C16: =C44&" Methodology" -> Segment 5 Revenue Methodology
C17: =IF(Company_Rev_Methodology="Segment","Segment",IF(Company_Rev_Methodology="Activity-Based","Activity-Based",IF(Company_Rev_Methodology="Backlog","Backlog",IF(Company_Rev_Methodology="Mixed",D17,"--")))) -> Segment | D17: Segment
C18: =C47&" Methodology" -> Segment 6 Revenue Methodology
C19: =IF(Company_Rev_Methodology="Segment","Segment",IF(Company_Rev_Methodology="Activity-Based","Activity-Based",IF(Company_Rev_Methodology="Backlog","Backlog",IF(Company_Rev_Methodology="Mixed",D19,"--")))) -> Segment | D19: Segment
C21: Font Toggle
C22: Working
C24: Annual vs. Quarterly
C25: Quarterly
J26: 1 | O26: 2 | T26: 3 | Y26: 4 | AD26: 5 | AE26: 6 | AF26: 7 | AG26: 8
AI27: CAGR
A28: x | C28: Summary | F28: =Model!F$25 -> 1Q23 | G28: =Model!G$25 -> 2Q23 | H28: =Model!H$25 -> 3Q23 | I28: =Model!I$25 -> 4Q23 | J28: =Model!J$25 -> 2023 | K28: =Model!K$25 -> 1Q24 | L28: =Model!L$25 -> 2Q24 | M28: =Model!M$25 -> 3Q24 | ... AG28: =Model!AG$25 -> 2030e | AI28: Historical | AJ28: Projected
C30: Total Company Revenue | F30: ='Segment Analysis'!F7 -> 17360 | G30: ='Segment Analysis'!G7 -> 20888 | H30: ='Segment Analysis'!H7 -> 17415 | I30: ='Segment Analysis'!I7 -> 15646 | J30: ='Segment Analysis'!J7 -> 71309 | K30: ='Segment Analysis'!K7 -> 17741 | L30: ='Segment Analysis'!L7 -> 20992 | M30: ='Segment Analysis'!M7 -> 17388 | ... W30: ='Segment Analysis'!W7 -> 22918 | X30: =SUM(X32,X35,X38,X41,X44,X47,) -> 21772.1 | Y30: =SUM(U30:X30) -> 96682.1 | Z30: =SUM(Z32,Z35,Z38,Z41,Z44,Z47,) -> 25691.078 | AA30: =SUM(AA32,AA35,AA38,AA41,AA44,AA47,) -> 29287.829 | AB30: =SUM(AB32,AB35,AB38,AB41,AB44,AB47,) -> 25773.289 | AC30: =SUM(AC32,AC35,AC38,AC41,AC44,AC47,) -> 24484.625 | AD30: =SUM(Z30:AC30) -> 105236.82 | AE30: =SUM(AE32,AE35,AE38,AE41,AE44,AE47,) -> 107341.56 | AF30: =SUM(AF32,AF35,AF38,AF41,AF44,AF47,) -> 109488.39 | AG30: =SUM(AG32,AG35,AG38,AG41,AG44,AG47,) -> 111678.16 | AI30: =IFERROR((T30/J30)^(1/3)-1,"--") -> 0.079070221 | AJ30: =IFERROR((AG30/T30)^(1/5)-1,"--") -> 0.045044909
C31: =IF($C$25="Quarterly","% Growth QoQ","% Growth YoY") -> % Growth QoQ | G31: =IF($C$25="Annual",'Segment Analysis'!G172,'Segment Analysis'!G192) -> 0.20322581 | H31: =IF($C$25="Annual",'Segment Analysis'!H172,'Segment Analysis'!H192) -> -0.16626771 | I31: =IF($C$25="Annual",'Segment Analysis'!I172,'Segment Analysis'!I192) -> -0.1015791 | K31: =IF($C$25="Annual",'Segment Analysis'!K172,'Segment Analysis'!K192) -> 0.13390004 | L31: =IF($C$25="Annual",'Segment Analysis'!L172,'Segment Analysis'!L192) -> 0.18324784 | M31: =IF($C$25="Annual",'Segment Analysis'!M172,'Segment Analysis'!M192) -> -0.17168445 | N31: =IF($C$25="Annual",'Segment Analysis'!N172,'Segment Analysis'!N192) -> -0.078272372 | O31: =IF($C$25="Annual",'Segment Analysis'!O172,'Segment Analysis'!O192) -> 1e-12 | P31: =IF($C$25="Annual",'Segment Analysis'!P172,'Segment Analysis'!P192) -> 0.2276159 | Q31: =IF($C$25="Annual",'Segment Analysis'!Q172,'Segment Analysis'!Q192) -> 0.3876493 | R31: =IF($C$25="Annual",'Segment Analysis'!R172,'Segment Analysis'!R192) -> -0.18288038 | ... W31: =IF($C$25="Annual",'Segment Analysis'!W172,'Segment Analysis'!W192) -> -0.16873413 | X31: =IFERROR(X30/W30-1,"--") -> -0.05 | Y31: =IFERROR(Y30/T30-1,"--") -> 0.079077424 | Z31: =IFERROR(Z30/X30-1,"--") -> 0.18 | AA31: =IFERROR(AA30/Z30-1,"--") -> 0.14 | AB31: =IFERROR(AB30/AA30-1,"--") -> -0.12 | AC31: =IFERROR(AC30/AB30-1,"--") -> -0.05 | AD31: =IFERROR(AD30/Y30-1,"--") -> 0.088482991 | AE31: =IFERROR(AE30/AD30-1,"--") -> 0.02 | AF31: =IFERROR(AF30/AE30-1,"--") -> 0.02 | AG31: =IFERROR(AG30/AF30-1,"--") -> 0.02
C32: ='Segment Analysis'!C8 -> Home Improvement Retail Revenue | F32: ='Segment Analysis'!F8 -> 17360 | G32: ='Segment Analysis'!G8 -> 20888 | H32: ='Segment Analysis'!H8 -> 17415 | I32: ='Segment Analysis'!I8 -> 15646 | J32: ='Segment Analysis'!J8 -> 71309 | K32: ='Segment Analysis'!K8 -> 17741 | L32: ='Segment Analysis'!L8 -> 20992 | M32: ='Segment Analysis'!M8 -> 17388 | ... W32: ='Segment Analysis'!W8 -> 22918 | X32: =IF(Segment1_Rev_Methodology="Segment",X53,IF(Segment1_Rev_Methodology="Activity-Based",X91,IF(Segment1_Rev_Methodology="Backlog",X165,"--"))) -> 21772.1 | Y32: =SUM(U32:X32) -> 96682.1 | Z32: =IF(Segment1_Rev_Methodology="Segment",Z53,IF(Segment1_Rev_Methodology="Activity-Based",Z91,IF(Segment1_Rev_Methodology="Backlog",Z165,"--"))) -> 25691.078 | AA32: =IF(Segment1_Rev_Methodology="Segment",AA53,IF(Segment1_Rev_Methodology="Activity-Based",AA91,IF(Segment1_Rev_Methodology="Backlog",AA165,"--"))) -> 29287.829 | AB32: =IF(Segment1_Rev_Methodology="Segment",AB53,IF(Segment1_Rev_Methodology="Activity-Based",AB91,IF(Segment1_Rev_Methodology="Backlog",AB165,"--"))) -> 25773.289 | AC32: =IF(Segment1_Rev_Methodology="Segment",AC53,IF(Segment1_Rev_Methodology="Activity-Based",AC91,IF(Segment1_Rev_Methodology="Backlog",AC165,"--"))) -> 24484.625 | AD32: =SUM(Z32:AC32) -> 105236.82 | AE32: =IF(Segment1_Rev_Methodology="Segment",AE53,IF(Segment1_Rev_Methodology="Activity-Based",AE91,IF(Segment1_Rev_Methodology="Backlog",AE165,"--"))) -> 107341.56 | AF32: =IF(Segment1_Rev_Methodology="Segment",AF53,IF(Segment1_Rev_Methodology="Activity-Based",AF91,IF(Segment1_Rev_Methodology="Backlog",AF165,"--"))) -> 109488.39 | AG32: =IF(Segment1_Rev_Methodology="Segment",AG53,IF(Segment1_Rev_Methodology="Activity-Based",AG91,IF(Segment1_Rev_Methodology="Backlog",AG165,"--"))) -> 111678.16 | AI32: =IFERROR((T32/J32)^(1/3)-1,"--") -> 0.079070221 | AJ32: =IFERROR((AG32/T32)^(1/5)-1,"--") -> 0.045044909
C33: =IF($C$25="Quarterly","% Growth QoQ","% Growth YoY") -> % Growth QoQ | G33: =IF($C$25="Annual",'Segment Analysis'!G173,'Segment Analysis'!G193) -> 0.20322581 | H33: =IF($C$25="Annual",'Segment Analysis'!H173,'Segment Analysis'!H193) -> -0.16626771 | I33: =IF($C$25="Annual",'Segment Analysis'!I173,'Segment Analysis'!I193) -> -0.1015791 | K33: =IF($C$25="Annual",'Segment Analysis'!K173,'Segment Analysis'!K193) -> 0.13390004 | L33: =IF($C$25="Annual",'Segment Analysis'!L173,'Segment Analysis'!L193) -> 0.18324784 | M33: =IF($C$25="Annual",'Segment Analysis'!M173,'Segment Analysis'!M193) -> -0.17168445 | N33: =IF($C$25="Annual",'Segment Analysis'!N173,'Segment Analysis'!N193) -> -0.078272372 | O33: =IF($C$25="Annual",'Segment Analysis'!O173,'Segment Analysis'!O193) -> 1e-12 | P33: =IF($C$25="Annual",'Segment Analysis'!P173,'Segment Analysis'!P193) -> 0.2276159 | Q33: =IF($C$25="Annual",'Segment Analysis'!Q173,'Segment Analysis'!Q193) -> 0.3876493 | R33: =IF($C$25="Annual",'Segment Analysis'!R173,'Segment Analysis'!R193) -> -0.18288038 | ... W33: =IF($C$25="Annual",'Segment Analysis'!W173,'Segment Analysis'!W193) -> -0.16873413 | X33: =IFERROR(X32/W32-1,"--") -> -0.05 | Y33: =IFERROR(Y32/T32-1,"--") -> 0.079077424 | Z33: =IFERROR(Z32/X32-1,"--") -> 0.18 | AA33: =IFERROR(AA32/Z32-1,"--") -> 0.14 | AB33: =IFERROR(AB32/AA32-1,"--") -> -0.12 | AC33: =IFERROR(AC32/AB32-1,"--") -> -0.05 | AD33: =IFERROR(AD32/Y32-1,"--") -> 0.088482991 | AE33: =IFERROR(AE32/AD32-1,"--") -> 0.02 | AF33: =IFERROR(AF32/AE32-1,"--") -> 0.02 | AG33: =IFERROR(AG32/AF32-1,"--") -> 0.02
C34: % of Total Revenue | F34: ='Segment Analysis'!F16 -> 1 | G34: ='Segment Analysis'!G16 -> 1 | H34: ='Segment Analysis'!H16 -> 1 | I34: ='Segment Analysis'!I16 -> 1 | J34: ='Segment Analysis'!J16 -> 1 | K34: ='Segment Analysis'!K16 -> 1 | L34: ='Segment Analysis'!L16 -> 1 | M34: ='Segment Analysis'!M16 -> 1 | ... W34: ='Segment Analysis'!W16 -> 1 | X34: =X32/X$30 -> 1 | Y34: =Y32/Y$30 -> 1 | Z34: =Z32/Z$30 -> 1 | AA34: =AA32/AA$30 -> 1 | AB34: =AB32/AB$30 -> 1 | AC34: =AC32/AC$30 -> 1 | AD34: =AD32/AD$30 -> 1 | AE34: =AE32/AE$30 -> 1 | ... AG34: =AG32/AG$30 -> 1
C35: ='Segment Analysis'!C9 -> Segment 2 Revenue | F35: ='Segment Analysis'!F9 -> 1e-12 | G35: ='Segment Analysis'!G9 -> 1e-12 | H35: ='Segment Analysis'!H9 -> 1e-12 | I35: ='Segment Analysis'!I9 -> 1e-12 | J35: ='Segment Analysis'!J9 -> 1e-12 | K35: ='Segment Analysis'!K9 -> 1e-12 | L35: ='Segment Analysis'!L9 -> 1e-12 | M35: ='Segment Analysis'!M9 -> 1e-12 | ... W35: ='Segment Analysis'!W9 -> 1e-12 | X35: =IF(Segment2_Rev_Methodology="Segment",X59,IF(Segment2_Rev_Methodology="Activity-Based",X103,IF(Segment2_Rev_Methodology="Backlog",X177,"--"))) -> 0 | Y35: =SUM(U35:X35) -> 1e-12 | Z35: =IF(Segment2_Rev_Methodology="Segment",Z59,IF(Segment2_Rev_Methodology="Activity-Based",Z103,IF(Segment2_Rev_Methodology="Backlog",Z177,"--"))) -> 0 | AA35: =IF(Segment2_Rev_Methodology="Segment",AA59,IF(Segment2_Rev_Methodology="Activity-Based",AA103,IF(Segment2_Rev_Methodology="Backlog",AA177,"--"))) -> 0 | AB35: =IF(Segment2_Rev_Methodology="Segment",AB59,IF(Segment2_Rev_Methodology="Activity-Based",AB103,IF(Segment2_Rev_Methodology="Backlog",AB177,"--"))) -> 0 | AC35: =IF(Segment2_Rev_Methodology="Segment",AC59,IF(Segment2_Rev_Methodology="Activity-Based",AC103,IF(Segment2_Rev_Methodology="Backlog",AC177,"--"))) -> 0 | AD35: =SUM(Z35:AC35) -> 1e-12 | AE35: =IF(Segment2_Rev_Methodology="Segment",AE59,IF(Segment2_Rev_Methodology="Activity-Based",AE103,IF(Segment2_Rev_Methodology="Backlog",AE177,"--"))) -> 0 | AF35: =IF(Segment2_Rev_Methodology="Segment",AF59,IF(Segment2_Rev_Methodology="Activity-Based",AF103,IF(Segment2_Rev_Methodology="Backlog",AF177,"--"))) -> 0 | AG35: =IF(Segment2_Rev_Methodology="Segment",AG59,IF(Segment2_Rev_Methodology="Activity-Based",AG103,IF(Segment2_Rev_Methodology="Backlog",AG177,"--"))) -> 0 | AI35: =IFERROR((T35/J35)^(1/3)-1,"--") -> -- | AJ35: =IFERROR((AG35/T35)^(1/5)-1,"--") -> --
C36: % Growth | G36: =IF($C$25="Annual",'Segment Analysis'!G174,'Segment Analysis'!G194) -> N/A | H36: =IF($C$25="Annual",'Segment Analysis'!H174,'Segment Analysis'!H194) -> N/A | I36: =IF($C$25="Annual",'Segment Analysis'!I174,'Segment Analysis'!I194) -> N/A | K36: =IF($C$25="Annual",'Segment Analysis'!K174,'Segment Analysis'!K194) -> N/A | L36: =IF($C$25="Annual",'Segment Analysis'!L174,'Segment Analysis'!L194) -> N/A | M36: =IF($C$25="Annual",'Segment Analysis'!M174,'Segment Analysis'!M194) -> N/A | N36: =IF($C$25="Annual",'Segment Analysis'!N174,'Segment Analysis'!N194) -> N/A | O36: ='Segment Analysis'!O174 -> N/A | P36: =IF($C$25="Annual",'Segment Analysis'!P174,'Segment Analysis'!P194) -> N/A | Q36: =IF($C$25="Annual",'Segment Analysis'!Q174,'Segment Analysis'!Q194) -> N/A | R36: =IF($C$25="Annual",'Segment Analysis'!R174,'Segment Analysis'!R194) -> N/A | S36: =IF($C$25="Annual",'Segment Analysis'!S174,'Segment Analysis'!S194) -> N/A | T36: ='Segment Analysis'!T174 -> N/A | U36: =IF($C$25="Annual",'Segment Analysis'!U174,'Segment Analysis'!U194) -> N/A | V36: =IF($C$25="Annual",'Segment Analysis'!V174,'Segment Analysis'!V194) -> N/A | W36: =IF($C$25="Annual",'Segment Analysis'!W174,'Segment Analysis'!W194) -> N/A | X36: =IFERROR(X35/W35-1,"--") -> -- | Y36: =IFERROR(Y35/T35-1,"--") -> -- | Z36: =IFERROR(Z35/X35-1,"--") -> -- | AA36: =IFERROR(AA35/Z35-1,"--") -> -- | AB36: =IFERROR(AB35/AA35-1,"--") -> -- | AC36: =IFERROR(AC35/AB35-1,"--") -> -- | AD36: =IFERROR(AD35/Y35-1,"--") -> -- | AE36: =IFERROR(AE35/AD35-1,"--") -> -- | AF36: =IFERROR(AF35/AE35-1,"--") -> -- | AG36: =IFERROR(AG35/AF35-1,"--") -> --
C37: % of Total Revenue | F37: ='Segment Analysis'!F17 -> 1e-12 | G37: ='Segment Analysis'!G17 -> 1e-12 | H37: ='Segment Analysis'!H17 -> 1e-12 | I37: ='Segment Analysis'!I17 -> 1e-12 | J37: ='Segment Analysis'!J17 -> 1e-12 | K37: ='Segment Analysis'!K17 -> 1e-12 | L37: ='Segment Analysis'!L17 -> 1e-12 | M37: ='Segment Analysis'!M17 -> 1e-12 | ... W37: ='Segment Analysis'!W17 -> 1e-12 | X37: =X35/X$30 -> 1e-12 | Y37: =Y35/Y$30 -> 1e-12 | Z37: =Z35/Z$30 -> 1e-12 | AA37: =AA35/AA$30 -> 1e-12 | AB37: =AB35/AB$30 -> 1e-12 | AC37: =AC35/AC$30 -> 1e-12 | AD37: =AD35/AD$30 -> 1e-12 | AE37: =AE35/AE$30 -> 1e-12 | ... AG37: =AG35/AG$30 -> 1e-12
C38: ='Segment Analysis'!C10 -> Segment 3 Revenue | F38: ='Segment Analysis'!F10 -> 1e-12 | G38: ='Segment Analysis'!G10 -> 1e-12 | H38: ='Segment Analysis'!H10 -> 1e-12 | I38: ='Segment Analysis'!I10 -> 1e-12 | J38: ='Segment Analysis'!J10 -> 1e-12 | K38: ='Segment Analysis'!K10 -> 1e-12 | L38: ='Segment Analysis'!L10 -> 1e-12 | M38: ='Segment Analysis'!M10 -> 1e-12 | ... W38: ='Segment Analysis'!W10 -> 1e-12 | X38: =IF(Segment3_Rev_Methodology="Segment",X65,IF(Segment3_Rev_Methodology="Activity-Based",X115,IF(Segment3_Rev_Methodology="Backlog",X189,"--"))) -> 0 | Y38: =SUM(U38:X38) -> 1e-12 | Z38: =IF(Segment3_Rev_Methodology="Segment",Z65,IF(Segment3_Rev_Methodology="Activity-Based",Z115,IF(Segment3_Rev_Methodology="Backlog",Z189,"--"))) -> 0 | AA38: =IF(Segment3_Rev_Methodology="Segment",AA65,IF(Segment3_Rev_Methodology="Activity-Based",AA115,IF(Segment3_Rev_Methodology="Backlog",AA189,"--"))) -> 0 | AB38: =IF(Segment3_Rev_Methodology="Segment",AB65,IF(Segment3_Rev_Methodology="Activity-Based",AB115,IF(Segment3_Rev_Methodology="Backlog",AB189,"--"))) -> 0 | AC38: =IF(Segment3_Rev_Methodology="Segment",AC65,IF(Segment3_Rev_Methodology="Activity-Based",AC115,IF(Segment3_Rev_Methodology="Backlog",AC189,"--"))) -> 0 | AD38: =SUM(Z38:AC38) -> 1e-12 | AE38: =IF(Segment3_Rev_Methodology="Segment",AE65,IF(Segment3_Rev_Methodology="Activity-Based",AE115,IF(Segment3_Rev_Methodology="Backlog",AE189,"--"))) -> 0 | AF38: =IF(Segment3_Rev_Methodology="Segment",AF65,IF(Segment3_Rev_Methodology="Activity-Based",AF115,IF(Segment3_Rev_Methodology="Backlog",AF189,"--"))) -> 0 | AG38: =IF(Segment3_Rev_Methodology="Segment",AG65,IF(Segment3_Rev_Methodology="Activity-Based",AG115,IF(Segment3_Rev_Methodology="Backlog",AG189,"--"))) -> 0 | AI38: =IFERROR((T38/J38)^(1/3)-1,"--") -> -- | AJ38: =IFERROR((AG38/T38)^(1/5)-1,"--") -> --
