Workbook
Name _bdm.146e958bbea04416b86a4d5943392c04.edm: Model!$M$102
Name _bdm.bf5a9ed53fe44c598e3cfb84ac34b21f.edm: Integrity!$F$37
Name al: '[3]2010 Labor Rates 091130'!$A$161
Name al09salary: '[3]Salaries'!$G$13
Name al10salary: '[3]Salaries'!$K$13
Name alid: '[3]2010 Labor Rates 091130'!$E$168
Name alname: '[3]Salaries'!$A$13
Name aprpto: '[3]Vacation'!$I$56
Name augpto: '[3]Vacation'!$M$56
Name avg_Health_and_Welfare: '[4]PBCFringe'!$Q$22
Name bf: '[3]2010 Labor Rates 091130'!$A$239
Name bf09salary: '[3]Salaries'!$G$18
Name bf10salary: '[3]Salaries'!$K$18
Name bfid: '[3]2010 Labor Rates 091130'!$E$246
Name bfname: '[3]Salaries'!$A$18
Name Bonus_estimate_2011: '[4]PBCFringe'!$B$100
Name Case_Scenario: Cover!$F$22
Name cc: '[3]2010 Labor Rates 091130'!$A$135
Name cc09salary: '[3]Salaries'!$G$11
Name cc10salary: '[3]Salaries'!$K$11
Name ccid: '[3]2010 Labor Rates 091130'!$E$142
Name ccname: '[3]Salaries'!$A$11
Name Ccy: '[5]data'!$A$5
Name cf: '[3]2010 Labor Rates 091130'!$A$148
Name cf09salary: '[3]Salaries'!$G$12
Name cf10salary: '[3]Salaries'!$K$12
Name cfid: '[3]2010 Labor Rates 091130'!$E$155
Name cfname: '[3]Salaries'!$A$12
Name ck: '[3]2010 Labor Rates 091130'!$A$213
Name ck09salary: '[3]Salaries'!$G$17
Name ck10salary: '[3]Salaries'!$K$17
Name ckid: '[3]2010 Labor Rates 091130'!$E$220
Name ckname: '[3]Salaries'!$A$17
Name Company_Cyclical_Multiples_Data: 'Multiples Data'!$C$14:$H$26
Name Company_Name: Cover!$F$19
Name Company_Rev_Methodology: 'Revenue Build'!$C$7
Name Cost_of_Debt: WACC!$G$17
Name Cost_of_Equity: WACC!$G$25
Name Cost_of_Preferred: WACC!$G$10
Name cs: '[3]2010 Labor Rates 091130'!$A$252
Name cs09salary: '[3]Salaries'!$G$19
Name cs10salary: '[3]Salaries'!$K$19
Name csid: '[3]2010 Labor Rates 091130'!$E$259
Name csname: '[3]Salaries'!$A$19
Name Current_Date: Cover!$F$27
Name CV: '[3]2010 Labor Rates 091130'!$A$5
Name cv09salary: '[3]Salaries'!$G$2
Name cv10salary: '[3]Salaries'!$K$2
Name cvid: '[3]2010 Labor Rates 091130'!$E$12
Name cvname: '[3]Salaries'!$A$2
Name Cycle_Period_Toggle: Valuation!$G$221
Name Cycle_Toggle: Valuation!$G$220
Name Cyclical_LTM_NTM_Toggle: Valuation!$G$222
Name Cyclical_Peer_Group_Toggle: Valuation!$G$223
Name Data: Model!$C$25:$AK$162
Name decpto: '[3]Vacation'!$Q$56
Name Denominator: '[5]data'!$A$6
Name df09salary: '[3]Salaries'!$G$26
Name df10salary: '[3]Salaries'!$K$26
Name dff: '[9]Salaries'!$A$26

Sheet Cover
C1: =Company_Name&" - "&MID(CELL("filename",A1),FIND("]",CELL("filename",A1))+1,255)&": "&Case_Scenario&" Case" -> Republic Services, Inc. - Cover: Base Case | Q1: Font Toggle
C2: $ in Millions Except Per Share Data | Q2: Report
R3: x
A4: x | C4: Model Assumptions: | I4: Return Summary:
I6: Discounted Cash Flow Analysis | N6: Multiple Analysis
I8: Exit Multiple Method | N8: EV/EBITDA Method
I9: Implied Enterprise Value: | L9: =Valuation!K65 -> 89474.779 | P9: Target Price: | Q9: % Return:
I10: Implied Equity Value: | L10: =Valuation!K72 -> 76784.353
N11: 1 Year LTM EV/EBITDA | P11: =Valuation!O137 -> 230.35445 | Q11: =Valuation!O138 -> 0.11524791
I12: Implied Share Price: | L12: =Valuation!K76 -> 245.86728
I13: % Return: | L13: =Valuation!K77 -> 0.19035238 | N13: 2013-2022 Late Cycle EV/EBITDA | P13: =Valuation!O215 -> 212.86147 | Q13: =Valuation!O216 -> 0.030556621
I15: Perpetuity Growth Method | N15: P/E Multiple Method
I16: Implied Enterprise Value: | L16: =Valuation!S65 -> 95925.297 | P16: Target Price: | Q16: % Return:
I17: Implied Equity Value: | L17: =Valuation!S72 -> 83234.871
N18: 1 Year LTM P/E | P18: =Valuation!F126 -> #DIV/0! | Q18: =Valuation!F127 -> #DIV/0!
C19: Company Name | F19: Republic Services, Inc. | I19: Implied Share Price: | L19: =Valuation!S76 -> 266.52216
C20: Ticker | F20: RSG | I20: % Return: | L20: =Valuation!S77 -> 0.29035179 | N20: 2013-2022 Late Cycle P/E | P20: =Valuation!F204 -> #DIV/0! | Q20: =Valuation!F205 -> #DIV/0!
C22: Case Scenario | F22: Base | I22: Table of Contents
C24: Last Fiscal Year | F24: 45705 | I24: Cover
C25: Next Fiscal Year | F25: =Last_FYE+366 -> 46071 | I25: Summary
C26: Last Fiscal Quarter Reported | F26: 4Q | I26: Football Field
C27: Current Valuation Date | F27: 46145 | I27: Integrity
I28: Revenue Build
C29: Current Share Price | F29: 206.55 | I29: Model
C30: 52-Week High | F30: 258.75 | I30: Segment Analysis
C31: 52-Week Low | F31: 201.42 | I31: Drivers
I32: WACC
C33: Effective Tax Rate | F33: 0.1776 | I33: Valuation
C34: Dividend Yield | F34: 0.0116 | I34: Comparables
C35: Diluted Shares Outstanding (MRQ) | F35: =IF(Last_FQR="1Q",Model!U287,IF(Last_FQR="2Q",Model!V287,IF(Last_FQR="3Q",Model!W287,Model!X287))) -> 0 | I35: Charts
I36: Benchmark
C37: Model Type | F37: Top Down | I37: Multiples Data
I38: Pre-Earnings
I39: Post-Earnings
A42: x
C43: Model Color Legend | I43: Constants
C44: Blue = Hard-Coded Value (historical values & assumptions) | I44: Reference | J44: Type | K44: Name | L44: Value
C45: Black = Formulas | I45: Million | J45: (#) | K45: Mil | L45: 1000000
C46: Green = Linked Value (from separate worksheet) | I46: Thousand | J46: (#) | K46: Thou | L46: 1000
C47: Red = Unique Formula / Anomaly | I47: Hundred | J47: (#) | K47: Hun | L47: 100
...

Sheet Summary
C1: =Company_Name&" - "&MID(CELL("filename",A1),FIND("]",CELL("filename",A1))+1,255)&": "&Case_Scenario&" Case" -> Republic Services, Inc. - Summary: Base Case
C2: =Cover!C2 -> $ in Millions Except Per Share Data
C4: Year: | T4: =Model!J24 -> 2023 | U4: =Model!O24 -> 2024 | V4: =Model!T24 -> 2025 | W4: =Model!Y24 -> 2026 | X4: =Model!AD24 -> 2027 | Y4: =Model!AE24 -> 2028 | Z4: =Model!AF24 -> 2029 | AA4: =Model!AG24 -> 2030
G5: Quarterly | T5: Annuals | AC5: CAGR | AE5: CAGR
A6: x | C6: ="Consolidated "&Model!C25 -> Consolidated Income Statement | G6: =Model!P25 -> 1Q25 | H6: =Model!Q25 -> 2Q25 | I6: =Model!R25 -> 3Q25 | J6: =Model!S25 -> 4Q25 | K6: =Model!U25 -> 1Q26e | L6: =Model!V25 -> 2Q26e | M6: =Model!W25 -> 3Q26 | N6: =Model!X25 -> 4Q26e | O6: =Model!Z25 -> 1Q27e | P6: =Model!AA25 -> 2Q27e | Q6: =Model!AB25 -> 3Q27e | R6: =Model!AC25 -> 4Q27e | T6: =Model!J25 -> 2023 | U6: =Model!O25 -> 2024 | V6: =Model!T25 -> 2025 | W6: =Model!Y25 -> 2026e | X6: =Model!AD25 -> 2027e | Y6: =Model!AE25 -> 2028e | Z6: =Model!AF25 -> 2029e | AA6: =Model!AG25 -> 2030e | AC6: Historical | AE6: Projected
C8: =Model!C28 -> Revenue | G8: =Model!P28 -> 4009 | H8: =Model!Q28 -> 4235 | I8: =Model!R28 -> 4212 | J8: =Model!S28 -> 4136 | K8: =Model!U28 -> 4152.631 | L8: =Model!V28 -> 4379.486 | M8: =Model!W28 -> 4358.186 | N8: =Model!X28 -> 4435.8154 | O8: =Model!Z28 -> 4358.6652 | P8: =Model!AA28 -> 4593.3476 | Q8: =Model!AB28 -> 4573.9711 | R8: =Model!AC28 -> 4522.6788 | T8: =Model!J28 -> 14964.5 | U8: =Model!O28 -> 16031.9 | V8: =Model!T28 -> 16592 | W8: =Model!Y28 -> 17326.118 | X8: =Model!AD28 -> 18048.663 | Y8: =Model!AE28 -> 18921.749 | Z8: =Model!AF28 -> 19882.733 | AA8: =Model!AG28 -> 20839.079 | AC8: =IFERROR((V8/T8)^(1/(V$4-T$4))-1,"N/A") -> 0.052975495 | AE8: =IFERROR((AA8/V8)^(1/(AA$4-V$4))-1,"N/A") -> 0.046636692
C9: YoY % Growth | K9: =K8/G8-1 -> 0.035827139 | L9: =L8/H8-1 -> 0.034117119 | M9: =M8/I8-1 -> 0.034707028 | N9: =N8/J8-1 -> 0.072489227 | O9: =O8/K8-1 -> 0.049615333 | P9: =P8/L8-1 -> 0.048832572 | Q9: =Q8/M8-1 -> 0.049512595 | R9: =R8/N8-1 -> 0.019582282 | U9: =IF(ISERROR(U8/T8-1),"NA",(U8/T8-1)) -> 0.071328812 | V9: =IF(ISERROR(V8/U8-1),"NA",(V8/U8-1)) -> 0.034936595 | W9: =IF(ISERROR(W8/V8-1),"NA",(W8/V8-1)) -> 0.044245326 | X9: =IF(ISERROR(X8/W8-1),"NA",(X8/W8-1)) -> 0.041702602 | Y9: =IF(ISERROR(Y8/X8-1),"NA",(Y8/X8-1)) -> 0.048374028 | Z9: =IF(ISERROR(Z8/Y8-1),"NA",(Z8/Y8-1)) -> 0.050787257 | AA9: =IF(ISERROR(AA8/Z8-1),"NA",(AA8/Z8-1)) -> 0.048099317
C11: =Model!C30 -> Gross Profit | G11: =Model!P30 -> 4009 | H11: =Model!Q30 -> 4235 | I11: =Model!R30 -> 4212 | J11: =Model!S30 -> 4136 | K11: =Model!U30 -> 4152.631 | L11: =Model!V30 -> 4379.486 | M11: =Model!W30 -> 4358.186 | N11: =Model!X30 -> 1880.7857 | O11: =Model!Z30 -> 1865.5087 | P11: =Model!AA30 -> 1952.1727 | Q11: =Model!AB30 -> 1957.6596 | R11: =Model!AC30 -> 1935.7065 | T11: =Model!J30 -> 14964.5 | U11: =Model!O30 -> 16031.9 | V11: =Model!T30 -> 16592 | W11: =Model!Y30 -> 14771.089 | X11: =Model!AD30 -> 7711.0476 | Y11: =Model!AE30 -> 8155.2739 | Z11: =Model!AF30 -> 8509.8097 | AA11: =Model!AG30 -> 8919.1257 | AC11: =IFERROR((V11/T11)^(1/(V$4-T$4))-1,"N/A") -> 0.052975495 | AE11: =IFERROR((AA11/V11)^(1/(AA$4-V$4))-1,"N/A") -> -0.11674784
C12: % Margin | G12: =G11/G$8 -> 1 | H12: =H11/H$8 -> 1 | I12: =I11/I$8 -> 1 | J12: =J11/J$8 -> 1 | K12: =K11/K$8 -> 1 | L12: =L11/L$8 -> 1 | M12: =M11/M$8 -> 1 | N12: =N11/N$8 -> 0.424 | ... R12: =R11/R$8 -> 0.428 | T12: =T11/T$8 -> 1 | U12: =U11/U$8 -> 1 | V12: =V11/V$8 -> 1 | W12: =W11/W$8 -> 0.85253306 | X12: =X11/X$8 -> 0.42723651 | Y12: =Y11/Y$8 -> 0.431 | Z12: =Z11/Z$8 -> 0.428 | AA12: =AA11/AA$8 -> 0.428
C13: YoY % Growth | K13: =K11/G11-1 -> 0.035827139 | L13: =L11/H11-1 -> 0.034117119 | M13: =M11/I11-1 -> 0.034707028 | N13: =N11/J11-1 -> -0.54526457 | O13: =O11/K11-1 -> -0.55076464 | P13: =P11/L11-1 -> -0.55424616 | Q13: =Q11/M11-1 -> -0.55080861 | R13: =R11/N11-1 -> 0.029200983 | U13: =U11/T11-1 -> 0.071328812 | V13: =V11/U11-1 -> 0.034936595 | W13: =W11/V11-1 -> -0.10974634 | X13: =X11/W11-1 -> -0.47796349 | Y13: =Y11/X11-1 -> 0.057609075 | Z13: =Z11/Y11-1 -> 0.043473193 | AA13: =AA11/Z11-1 -> 0.048099317
C15: =Model!C36 -> EBIT | G15: =Model!P36 -> 4009 | H15: =Model!Q36 -> 4235 | I15: =Model!R36 -> 4212 | J15: =Model!S36 -> 4136 | K15: =Model!U36 -> 4152.631 | L15: =Model!V36 -> 4379.486 | M15: =Model!W36 -> 4358.186 | N15: =Model!X36 -> 893.95769 | O15: =Model!Z36 -> 887.68351 | P15: =Model!AA36 -> 974.754 | Q15: =Model!AB36 -> 981.59418 | R15: =Model!AC36 -> 950.48416 | T15: =Model!J36 -> 14964.5 | U15: =Model!O36 -> 16031.9 | V15: =Model!T36 -> 16592 | W15: =Model!Y36 -> 3829.2607 | X15: =Model!AD36 -> 3794.5159 | Y15: =Model!AE36 -> 4153.3135 | Z15: =Model!AF36 -> 4316.9821 | AA15: =Model!AG36 -> 4540.3607 | AC15: =IFERROR((V15/T15)^(1/(V$4-T$4))-1,"N/A") -> 0.052975495 | AE15: =IFERROR((AA15/V15)^(1/(AA$4-V$4))-1,"N/A") -> 0.043903065
C16: Margin | G16: =G15/G$8 -> 1 | H16: =H15/H$8 -> 1 | I16: =I15/I$8 -> 1 | J16: =J15/J$8 -> 1 | K16: =K15/K$8 -> 1 | L16: =L15/L$8 -> 1 | M16: =M15/M$8 -> 1 | N16: =N15/N$8 -> 0.20153176 | ... R16: =R15/R$8 -> 0.21015955 | T16: =T15/T$8 -> 1 | U16: =U15/U$8 -> 1 | V16: =V15/V$8 -> 1 | W16: =W15/W$8 -> 0.22101088 | X16: =X15/X$8 -> 0.21023806 | Y16: =Y15/Y$8 -> 0.21949945 | Z16: =Z15/Z$8 -> 0.21712217 | AA16: =AA15/AA$8 -> 0.21787723
C17: YoY % Growth | K17: =K15/G15-1 -> 0.035827139 | L17: =L15/H15-1 -> 0.034117119 | M17: =M15/I15-1 -> 0.034707028 | N17: =N15/J15-1 -> 0.11744711 | O17: =O15/K15-1 -> -0.063260368 | P17: =P15/L15-1 -> -0.030564327 | Q17: =Q15/M15-1 -> -0.00060254999 | R17: =R15/N15-1 -> 0.063231701 | U17: =U15/T15-1 -> 0.071328812 | V17: =V15/U15-1 -> 0.034936595 | W17: =W15/V15-1 -> 0.045503383 | X17: =X15/W15-1 -> -0.0090735113 | Y17: =Y15/X15-1 -> 0.094556896 | Z17: =Z15/Y15-1 -> 0.03940675 | AA17: =AA15/Z15-1 -> 0.051744161
C19: =Model!C45 -> Net Income (Loss) | G19: =Model!P45 -> 4009 | H19: =Model!Q45 -> 4235 | I19: =Model!R45 -> 4212 | J19: =Model!S45 -> 4136 | K19: =Model!U45 -> 4152.631 | L19: =Model!V45 -> 4379.486 | M19: =Model!W45 -> 4358.186 | N19: =Model!X45 -> 566.85193 | O19: =Model!Z45 -> 568.11173 | P19: =Model!AA45 -> 637.59271 | Q19: =Model!AB45 -> 647.98055 | R19: =Model!AC45 -> 628.44699 | T19: =Model!J45 -> 14964.5 | U19: =Model!O45 -> 16031.9 | V19: =Model!T45 -> 16592 | W19: =Model!Y45 -> 2596.1549 | X19: =Model!AD45 -> 2482.132 | Y19: =Model!AE45 -> 2803.4173 | Z19: =Model!AF45 -> 2919.2989 | AA19: =Model!AG45 -> 3107.5491 | AC19: =IFERROR((V19/T19)^(1/(V$4-T$4))-1,"N/A") -> 0.052975495 | AE19: =IFERROR((AA19/V19)^(1/(AA$4-V$4))-1,"N/A") -> 0.040618282
C20: Margin | G20: =G19/G$8 -> 1 | H20: =H19/H$8 -> 1 | I20: =I19/I$8 -> 1 | J20: =J19/J$8 -> 1 | K20: =K19/K$8 -> 1 | L20: =L19/L$8 -> 1 | M20: =M19/M$8 -> 1 | N20: =N19/N$8 -> 0.12778979 | ... R20: =R19/R$8 -> 0.13895459 | T20: =T19/T$8 -> 1 | U20: =U19/U$8 -> 1 | V20: =V19/V$8 -> 1 | W20: =W19/W$8 -> 0.14984054 | X20: =X19/X$8 -> 0.13752443 | Y20: =Y19/Y$8 -> 0.14815846 | Z20: =Z19/Z$8 -> 0.14682584 | AA20: =AA19/AA$8 -> 0.14912123
C21: YoY % Growth | K21: =K19/G19-1 -> 0.035827139 | L21: =L19/H19-1 -> 0.034117119 | M21: =M19/I19-1 -> 0.034707028 | N21: =N19/J19-1 -> 0.040095278 | O21: =O19/K19-1 -> -0.11042257 | P21: =P19/L19-1 -> -0.081921435 | Q21: =Q19/M19-1 -> -0.069242201 | R21: =R19/N19-1 -> 0.10866165 | U21: =U19/T19-1 -> 0.071328812 | V21: =V19/U19-1 -> 0.034936595 | W21: =W19/V19-1 -> 0.01945925 | X21: =X19/W19-1 -> -0.043919933 | Y21: =Y19/X19-1 -> 0.12943926 | Z21: =Z19/Y19-1 -> 0.041335835 | AA21: =AA19/Z19-1 -> 0.064484719
C23: =Model!C57 -> Adj. EPS (Diluted) | G23: =Model!P57 -> #DIV/0! | H23: =Model!Q57 -> #DIV/0! | I23: =Model!R57 -> #DIV/0! | J23: =Model!S57 -> #DIV/0! | K23: =Model!U57 -> #DIV/0! | L23: =Model!V57 -> #DIV/0! | M23: =Model!W57 -> #DIV/0! | N23: =Model!X57 -> 1.8150878 | O23: =Model!Z57 -> 1.8278218 | P23: =Model!AA57 -> 2.0612254 | Q23: =Model!AB57 -> 2.0948074 | R23: =Model!AC57 -> 2.0316588 | T23: =Model!J57 -> #DIV/0! | U23: =Model!O57 -> #DIV/0! | V23: =Model!T57 -> #DIV/0! | W23: =Model!Y57 -> 8.3010549 | X23: =Model!AD57 -> 8.0146684 | Y23: =Model!AE57 -> 9.1030862 | Z23: =Model!AF57 -> 9.5676296 | AA23: =Model!AG57 -> 10.283124 | AC23: =IFERROR((V23/T23)^(1/(V$4-T$4))-1,"N/A") -> N/A | AE23: =IFERROR((AA23/V23)^(1/(AA$4-V$4))-1,"N/A") -> 0.04917992
C24: YoY % Growth | K24: =K23/G23-1 -> #DIV/0! | L24: =L23/H23-1 -> #DIV/0! | M24: =M23/I23-1 -> #DIV/0! | N24: =N23/J23-1 -> 0.045090932 | O24: =O23/K23-1 -> -0.10330601 | P24: =P23/L23-1 -> -0.069832904 | Q24: =Q23/M23-1 -> -0.061199287 | R24: =R23/N23-1 -> 0.11931711 | U24: =IF(ISERROR(U23/T23-1),"NA",(U23/T23-1)) -> NA | V24: =IF(ISERROR(V23/U23-1),"NA",(V23/U23-1)) -> NA | W24: =IF(ISERROR(W23/V23-1),"NA",(W23/V23-1)) -> 0.026261562 | X24: =IF(ISERROR(X23/W23-1),"NA",(X23/W23-1)) -> -0.034500014 | Y24: =IF(ISERROR(Y23/X23-1),"NA",(Y23/X23-1)) -> 0.13580322 | Z24: =IF(ISERROR(Z23/Y23-1),"NA",(Z23/Y23-1)) -> 0.051031418 | AA24: =IF(ISERROR(AA23/Z23-1),"NA",(AA23/Z23-1)) -> 0.07478283
C27: =Model!C61 -> EBITDA | G27: =Model!P61 -> 4009 | H27: =Model!Q61 -> 4235 | I27: =Model!R61 -> 4212 | J27: =Model!S61 -> 4136 | K27: =Model!U61 -> 4152.631 | L27: =Model!V61 -> 4379.486 | M27: =Model!W61 -> 4358.186 | N27: =Model!X61 -> 1388.4102 | O27: =Model!Z61 -> 1372.9795 | P27: =Model!AA61 -> 1460.6845 | Q27: =Model!AB61 -> 1468.2447 | R27: =Model!AC61 -> 1438.2119 | T27: =Model!J61 -> 14964.5 | U27: =Model!O61 -> 16031.9 | V27: =Model!T61 -> 16592 | W27: =Model!Y61 -> 5679.7132 | X27: =Model!AD61 -> 5740.1206 | Y27: =Model!AE61 -> 6130.6467 | Z27: =Model!AF61 -> 6402.24 | AA27: =Model!AG61 -> 6731.0225 | AC27: =IFERROR((V27/T27)^(1/(V$4-T$4))-1,"N/A") -> 0.052975495 | AE27: =IFERROR((AA27/V27)^(1/(AA$4-V$4))-1,"N/A") -> 0.046809263
C28: Margin | G28: =G27/G$8 -> 1 | H28: =H27/H$8 -> 1 | I28: =I27/I$8 -> 1 | J28: =J27/J$8 -> 1 | K28: =K27/K$8 -> 1 | L28: =L27/L$8 -> 1 | M28: =M27/M$8 -> 1 | N28: =N27/N$8 -> 0.313 | ... R28: =R27/R$8 -> 0.318 | T28: =T27/T$8 -> 1 | U28: =U27/U$8 -> 1 | V28: =V27/V$8 -> 1 | W28: =W27/W$8 -> 0.32781221 | X28: =X27/X$8 -> 0.31803579 | Y28: =Y27/Y$8 -> 0.324 | Z28: =Z27/Z$8 -> 0.322 | AA28: =AA27/AA$8 -> 0.323
C29: YoY % Growth | K29: =K27/G27-1 -> 0.035827139 | L29: =L27/H27-1 -> 0.034117119 | M29: =M27/I27-1 -> 0.034707028 | N29: =N27/J27-1 -> 0.10366473 | O29: =O27/K27-1 -> -0.0062617817 | P29: =P27/L27-1 -> -0.0053125968 | Q29: =Q27/M27-1 -> 0.018775316 | R29: =R27/N27-1 -> 0.035869539 | U29: =U27/T27-1 -> 0.071328812 | V29: =V27/U27-1 -> 0.034936595 | W29: =W27/V27-1 -> 0.060677006 | X29: =X27/W27-1 -> 0.010635645 | Y29: =Y27/X27-1 -> 0.068034474 | Z29: =Z27/Y27-1 -> 0.044300916 | AA29: =AA27/Z27-1 -> 0.051354284
G31: =G$5 -> Quarterly | T31: =T$5 -> Annuals
A32: x | C32: ="Consolidated "&Model!C121 -> Consolidated Balance Sheet | G32: =G$6 -> 1Q25 | H32: =H$6 -> 2Q25 | I32: =I$6 -> 3Q25 | J32: =J$6 -> 4Q25 | K32: =K$6 -> 1Q26e | L32: =L$6 -> 2Q26e | M32: =M$6 -> 3Q26 | N32: =N$6 -> 4Q26e | ... R32: =R$6 -> 4Q27e | T32: =T$6 -> 2023 | U32: =U$6 -> 2024 | V32: =V$6 -> 2025 | W32: =W$6 -> 2026e | X32: =X$6 -> 2027e | Y32: =Y$6 -> 2028e | Z32: =Z$6 -> 2029e | AA32: =AA$6 -> 2030e
C34: =Model!C123 -> Cash & Cash Equivalents | G34: =Model!P123 -> 0 | H34: =Model!Q123 -> 0 | I34: =Model!R123 -> 0 | J34: =Model!S123 -> 0 | K34: =Model!U123 -> 0 | L34: =Model!V123 -> 0 | M34: =Model!W123 -> 0 | N34: =Model!X123 -> 58.332248 | O34: =Model!Z123 -> 57.317699 | P34: =Model!AA123 -> 60.40384 | Q34: =Model!AB123 -> 60.149034 | R34: =Model!AC123 -> 59.474526 | T34: =Model!J123 -> 0 | U34: =Model!O123 -> 0 | V34: =Model!T123 -> 0 | W34: =Model!Y123 -> 58.332248 | X34: =Model!AD123 -> 59.474526 | Y34: =Model!AE123 -> 248.82644 | Z34: =Model!AF123 -> 261.46365 | AA34: =Model!AG123 -> 274.03987
C35: =Model!C124 -> Accounts Receivable | G35: =Model!P124 -> 0 | H35: =Model!Q124 -> 0 | I35: =Model!R124 -> 0 | J35: =Model!S124 -> 0 | K35: =Model!U124 -> 0 | L35: =Model!V124 -> 0 | M35: =Model!W124 -> 0 | N35: =Model!X124 -> 2015.4031 | O35: =Model!Z124 -> 1973.3737 | P35: =Model!AA124 -> 2029.1491 | Q35: =Model!AB124 -> 2028.4567 | R35: =Model!AC124 -> 2030.2895 | T35: =Model!J124 -> 0 | U35: =Model!O124 -> 0 | V35: =Model!T124 -> 0 | W35: =Model!Y124 -> 2015.4031 | X35: =Model!AD124 -> 2030.2895 | Y35: =Model!AE124 -> 2156.561 | Z35: =Model!AF124 -> 2233.4029 | AA35: =Model!AG124 -> 2340.828
C36: =Model!C125 -> Inventory | G36: =Model!P125 -> 0 | H36: =Model!Q125 -> 0 | I36: =Model!R125 -> 0 | J36: =Model!S125 -> 0 | K36: =Model!U125 -> 0 | L36: =Model!V125 -> 0 | M36: =Model!W125 -> 0 | N36: =Model!X125 -> 0 | O36: =Model!Z125 -> 0 | P36: =Model!AA125 -> 0 | Q36: =Model!AB125 -> 0 | R36: =Model!AC125 -> 0 | T36: =Model!J125 -> 0 | U36: =Model!O125 -> 0 | V36: =Model!T125 -> 0 | W36: =Model!Y125 -> 0 | X36: =Model!AD125 -> 0 | Y36: =Model!AE125 -> 0 | Z36: =Model!AF125 -> 0 | AA36: =Model!AG125 -> 0
C37: =Model!C126 -> Prepaid & Other Current Assets | G37: =Model!P126 -> 0 | H37: =Model!Q126 -> 0 | I37: =Model!R126 -> 0 | J37: =Model!S126 -> 0 | K37: =Model!U126 -> 0 | L37: =Model!V126 -> 0 | M37: =Model!W126 -> 0 | N37: =Model!X126 -> 461.32481 | O37: =Model!Z126 -> 383.56253 | P37: =Model!AA126 -> 404.21459 | Q37: =Model!AB126 -> 402.50946 | R37: =Model!AC126 -> 397.99574 | T37: =Model!J126 -> 0 | U37: =Model!O126 -> 0 | V37: =Model!T126 -> 0 | W37: =Model!Y126 -> 461.32481 | X37: =Model!AD126 -> 397.99574 | Y37: =Model!AE126 -> 416.27848 | Z37: =Model!AF126 -> 437.42012 | AA37: =Model!AG126 -> 458.45973
C38: =Model!C127 -> Total Current Assets | G38: =SUM(G34:G37) -> 0 | H38: =SUM(H34:H37) -> 0 | I38: =SUM(I34:I37) -> 0 | J38: =SUM(J34:J37) -> 0 | K38: =SUM(K34:K37) -> 0 | L38: =SUM(L34:L37) -> 0 | M38: =SUM(M34:M37) -> 0 | N38: =SUM(N34:N37) -> 2535.0602 | ... R38: =SUM(R34:R37) -> 2487.7598 | T38: =SUM(T34:T37) -> 0 | U38: =SUM(U34:U37) -> 0 | V38: =SUM(V34:V37) -> 0 | W38: =SUM(W34:W37) -> 2535.0602 | X38: =SUM(X34:X37) -> 2487.7598 | Y38: =SUM(Y34:Y37) -> 2821.6659 | Z38: =SUM(Z34:Z37) -> 2932.2867 | AA38: =SUM(AA34:AA37) -> 3073.3276
C40: =Model!C129 -> PP&E, Net | G40: =Model!P129 -> 0 | H40: =Model!Q129 -> 0 | I40: =Model!R129 -> 0 | J40: =Model!S129 -> 0 | K40: =Model!U129 -> 0 | L40: =Model!V129 -> 0 | M40: =Model!W129 -> 0 | N40: =Model!X129 -> 12225.409 | O40: =Model!Z129 -> 12223.925 | P40: =Model!AA129 -> 12261.636 | Q40: =Model!AB129 -> 12278.123 | R40: =Model!AC129 -> 12319.548 | T40: =Model!J129 -> 0 | U40: =Model!O129 -> 0 | V40: =Model!T129 -> 0 | W40: =Model!Y129 -> 12225.409 | X40: =Model!AD129 -> 12319.548 | Y40: =Model!AE129 -> 12397.117 | Z40: =Model!AF129 -> 12427.382 | AA40: =Model!AG129 -> 12466.502
C41: =Model!C130 -> Intangible Assets, Net | G41: =Model!P130 -> 0 | H41: =Model!Q130 -> 0 | I41: =Model!R130 -> 0 | J41: =Model!S130 -> 0 | K41: =Model!U130 -> 0 | L41: =Model!V130 -> 0 | M41: =Model!W130 -> 0 | N41: =Model!X130 -> 0 | O41: =Model!Z130 -> 0 | P41: =Model!AA130 -> 0 | Q41: =Model!AB130 -> 0 | R41: =Model!AC130 -> 0 | T41: =Model!J130 -> 0 | U41: =Model!O130 -> 0 | V41: =Model!T130 -> 0 | W41: =Model!Y130 -> 0 | X41: =Model!AD130 -> 0 | Y41: =Model!AE130 -> 0 | Z41: =Model!AF130 -> 0 | AA41: =Model!AG130 -> 0
C42: =Model!C131 -> Goodwill | G42: =Model!P131 -> 0 | H42: =Model!Q131 -> 0 | I42: =Model!R131 -> 0 | J42: =Model!S131 -> 0 | K42: =Model!U131 -> 0 | L42: =Model!V131 -> 0 | M42: =Model!W131 -> 0 | N42: =Model!X131 -> 0 | O42: =Model!Z131 -> 0 | P42: =Model!AA131 -> 0 | Q42: =Model!AB131 -> 0 | R42: =Model!AC131 -> 0 | T42: =Model!J131 -> 0 | U42: =Model!O131 -> 0 | V42: =Model!T131 -> 0 | W42: =Model!Y131 -> 0 | X42: =Model!AD131 -> 0 | Y42: =Model!AE131 -> 0 | Z42: =Model!AF131 -> 0 | AA42: =Model!AG131 -> 0
C43: =Model!C132 -> Other Non-Current Assets | G43: =Model!P132 -> 0 | H43: =Model!Q132 -> 0 | I43: =Model!R132 -> 0 | J43: =Model!S132 -> 0 | K43: =Model!U132 -> 0 | L43: =Model!V132 -> 0 | M43: =Model!W132 -> 0 | N43: =Model!X132 -> 0 | O43: =Model!Z132 -> 0 | P43: =Model!AA132 -> 0 | Q43: =Model!AB132 -> 0 | R43: =Model!AC132 -> 0 | T43: =Model!J132 -> 0 | U43: =Model!O132 -> 0 | V43: =Model!T132 -> 0 | W43: =Model!Y132 -> 0 | X43: =Model!AD132 -> 0 | Y43: =Model!AE132 -> 0 | Z43: =Model!AF132 -> 0 | AA43: =Model!AG132 -> 0
C44: =Model!C133 -> Total Non-Current Assets | G44: =SUM(G40:G43) -> 0 | H44: =SUM(H40:H43) -> 0 | I44: =SUM(I40:I43) -> 0 | J44: =SUM(J40:J43) -> 0 | K44: =SUM(K40:K43) -> 0 | L44: =SUM(L40:L43) -> 0 | M44: =SUM(M40:M43) -> 0 | N44: =SUM(N40:N43) -> 31362.659 | ... R44: =SUM(R40:R43) -> 31821.827 | T44: =SUM(T40:T43) -> 0 | U44: =SUM(U40:U43) -> 0 | V44: =SUM(V40:V43) -> 0 | W44: =SUM(W40:W43) -> 31362.659 | X44: =SUM(X40:X43) -> 31821.827 | Y44: =SUM(Y40:Y43) -> 32056.277 | Z44: =SUM(Z40:Z43) -> 32251.627 | AA44: =SUM(AA40:AA43) -> 32474.78
C46: =Model!C135 -> Total Assets | G46: =SUM(G38,G44) -> 0 | H46: =SUM(H38,H44) -> 0 | I46: =SUM(I38,I44) -> 0 | J46: =SUM(J38,J44) -> 0 | K46: =SUM(K38,K44) -> 0 | L46: =SUM(L38,L44) -> 0 | M46: =SUM(M38,M44) -> 0 | N46: =SUM(N38,N44) -> 33897.72 | ... R46: =SUM(R38,R44) -> 34309.587 | T46: =SUM(T38,T44) -> 0 | U46: =SUM(U38,U44) -> 0 | V46: =SUM(V38,V44) -> 0 | W46: =SUM(W38,W44) -> 33897.72 | X46: =SUM(X38,X44) -> 34309.587 | Y46: =SUM(Y38,Y44) -> 34877.943 | Z46: =SUM(Z38,Z44) -> 35183.914 | AA46: =SUM(AA38,AA44) -> 35548.108
C48: =Model!C137 -> Accounts Payable | G48: =Model!P137 -> 0 | H48: =Model!Q137 -> 0 | I48: =Model!R137 -> 0 | J48: =Model!S137 -> 0 | K48: =Model!U137 -> 0 | L48: =Model!V137 -> 0 | M48: =Model!W137 -> 0 | N48: =Model!X137 -> 1305.2869 | O48: =Model!Z137 -> 1342.4689 | P48: =Model!AA137 -> 1407.6591 | Q48: =Model!AB137 -> 1379.2512 | R48: =Model!AC137 -> 1349.7247 | T48: =Model!J137 -> 0 | U48: =Model!O137 -> 0 | V48: =Model!T137 -> 0 | W48: =Model!Y137 -> 1305.2869 | X48: =Model!AD137 -> 1349.7247 | Y48: =Model!AE137 -> 1401.1166 | Z48: =Model!AF137 -> 1464.4586 | AA48: =Model!AG137 -> 1534.8981
C49: =Model!C138 -> Accrued Liabilities | G49: =Model!P138 -> 0 | H49: =Model!Q138 -> 0 | I49: =Model!R138 -> 0 | J49: =Model!S138 -> 0 | K49: =Model!U138 -> 0 | L49: =Model!V138 -> 0 | M49: =Model!W138 -> 0 | N49: =Model!X138 -> 153.30178 | O49: =Model!Z138 -> 139.61676 | P49: =Model!AA138 -> 147.90579 | Q49: =Model!AB138 -> 146.51344 | R49: =Model!AC138 -> 144.87045 | T49: =Model!J138 -> 0 | U49: =Model!O138 -> 0 | V49: =Model!T138 -> 0 | W49: =Model!Y138 -> 153.30178 | X49: =Model!AD138 -> 144.87045 | Y49: =Model!AE138 -> 150.73065 | Z49: =Model!AF138 -> 159.22093 | AA49: =Model!AG138 -> 166.87934
C50: =Model!C139 -> Other Current Liabilities | G50: =Model!P139 -> 0 | H50: =Model!Q139 -> 0 | I50: =Model!R139 -> 0 | J50: =Model!S139 -> 0 | K50: =Model!U139 -> 0 | L50: =Model!V139 -> 0 | M50: =Model!W139 -> 0 | N50: =Model!X139 -> 2810.5327 | O50: =Model!Z139 -> 2792.3353 | P50: =Model!AA139 -> 2958.1158 | Q50: =Model!AB139 -> 2930.2688 | R50: =Model!AC139 -> 2897.409 | T50: =Model!J139 -> 0 | U50: =Model!O139 -> 0 | V50: =Model!T139 -> 0 | W50: =Model!Y139 -> 2810.5327 | X50: =Model!AD139 -> 2897.409 | Y50: =Model!AE139 -> 3014.6131 | Z50: =Model!AF139 -> 3184.4185 | AA50: =Model!AG139 -> 3337.5869
C51: =Model!C140 -> Total Current Liabilities (Excl. Debt) | G51: =SUM(G48:G50) -> 0 | H51: =SUM(H48:H50) -> 0 | I51: =SUM(I48:I50) -> 0 | J51: =SUM(J48:J50) -> 0 | K51: =SUM(K48:K50) -> 0 | L51: =SUM(L48:L50) -> 0 | M51: =SUM(M48:M50) -> 0 | N51: =SUM(N48:N50) -> 4269.1214 | ... R51: =SUM(R48:R50) -> 4392.0041 | T51: =SUM(T48:T50) -> 0 | U51: =SUM(U48:U50) -> 0 | V51: =SUM(V48:V50) -> 0 | W51: =SUM(W48:W50) -> 4269.1214 | X51: =SUM(X48:X50) -> 4392.0041 | Y51: =SUM(Y48:Y50) -> 4566.4604 | Z51: =SUM(Z48:Z50) -> 4808.098 | AA51: =SUM(AA48:AA50) -> 5039.3643
C53: =Model!C142 -> Revolver | G53: =Model!P142 -> 0 | H53: =Model!Q142 -> 0 | I53: =Model!R142 -> 0 | J53: =Model!S142 -> 0 | K53: =Model!U142 -> 0 | L53: =Model!V142 -> 0 | M53: =Model!W142 -> 0 | N53: =Model!X142 -> 144.75856 | O53: =Model!Z142 -> 3375.1146 | P53: =Model!AA142 -> 293.00155 | Q53: =Model!AB142 -> 973.40359 | R53: =Model!AC142 -> 892.34028 | T53: =Model!J142 -> 0 | U53: =Model!O142 -> 0 | V53: =Model!T142 -> 0 | W53: =Model!Y142 -> 144.75856 | X53: =Model!AD142 -> 892.34028 | Y53: =Model!AE142 -> 1086.0882 | Z53: =Model!AF142 -> 1691.7654 | AA53: =Model!AG142 -> 2456.6647
C54: =Model!C143 -> LT Debt (Incl. Current Portion) | G54: =Model!P143 -> 0 | H54: =Model!Q143 -> 0 | I54: =Model!R143 -> 0 | J54: =Model!S143 -> 0 | K54: =Model!U143 -> 0 | L54: =Model!V143 -> 0 | M54: =Model!W143 -> 0 | N54: =Model!X143 -> 250 | O54: =Model!Z143 -> 250 | P54: =Model!AA143 -> -350 | Q54: =Model!AB143 -> -950 | R54: =Model!AC143 -> -1550 | T54: =Model!J143 -> 0 | U54: =Model!O143 -> 0 | V54: =Model!T143 -> 0 | W54: =Model!Y143 -> 250 | X54: =Model!AD143 -> -1550 | Y54: =Model!AE143 -> -1550 | Z54: =Model!AF143 -> -2150 | AA54: =Model!AG143 -> -2750
...

Sheet Model Output
B1: =Company_Name&" "&"("&Ticker&")"&" Valuation Overview" -> Republic Services, Inc. (RSG) Valuation Overview | K1: Price Target Scenario: | N1: =Case_Scenario&" Case" -> Base Case | R1: Base Case Check | S1: =IF(N1="Base Case","","Check!") | Y1: P/E
B2: =Cover!C2 -> $ in Millions Except Per Share Data | K2: Current Share Price: | O2: =Share_Price -> 206.55 | Y2: EV/EBITDA
K3: Valuation Date: | O3: =Current_Date -> 46145
B4: ="Multiples Analysis "&"("&S21&")" -> Multiples Analysis (P/E) | I4: Return Summary
I6: Exit Multiple Method
I7: =Cover!I9 -> Implied Enterprise Value: | N7: =Cover!L9 -> 89474.779
I8: =Cover!I10 -> Implied Equity Value: | N8: =Cover!L10 -> 76784.353
I9: =Cover!I12 -> Implied Share Price: | N9: =Cover!L12 -> 245.86728
I10: =Cover!I13 -> % Return: | N10: =Cover!L13 -> 0.19035238
I12: =Cover!I15 -> Perpetuity Growth Method
I13: =Cover!I16 -> Implied Enterprise Value: | N13: =Cover!L16 -> 95925.297
I14: =Cover!I17 -> Implied Equity Value: | N14: =Cover!L17 -> 83234.871
I15: =Cover!I19 -> Implied Share Price: | N15: =Cover!L19 -> 266.52216
I16: =Cover!I20 -> % Return: | N16: =Cover!L20 -> 0.29035179
E18: Annuals | M18: CAGR | O18: CAGR
B19: Consolidated Financials | E19: =Summary!U6 -> 2024 | F19: =Summary!V6 -> 2025 | G19: =Summary!W6 -> 2026e | H19: =Summary!X6 -> 2027e | I19: =Summary!Y6 -> 2028e | J19: =Summary!Z6 -> 2029e | K19: =Summary!AA6 -> 2030e | M19: Historical | O19: Projected
B21: =Summary!C8 -> Revenue | D21: =Summary!T8 -> 14964.5 | E21: =Summary!U8 -> 16031.9 | F21: =Summary!V8 -> 16592 | G21: =Summary!W8 -> 17326.118 | H21: =Summary!X8 -> 18048.663 | I21: =Summary!Y8 -> 18921.749 | J21: =Summary!Z8 -> 19882.733 | K21: =Summary!AA8 -> 20839.079 | M21: =Summary!AC8 -> 0.052975495 | O21: =Summary!AE8 -> 0.046636692 | R21: Multiple Toggle | S21: P/E
B22: =Summary!C9 -> YoY % Growth | E22: =Summary!U9 -> 0.071328812 | F22: =Summary!V9 -> 0.034936595 | G22: =Summary!W9 -> 0.044245326 | H22: =Summary!X9 -> 0.041702602 | I22: =Summary!Y9 -> 0.048374028 | J22: =Summary!Z9 -> 0.050787257 | K22: =Summary!AA9 -> 0.048099317
R23: Multiples Analysis | S23: EV/EBITDA | T23: P/E | U23: Chart
B24: =Summary!C11 -> Gross Profit | D24: =Summary!T11 -> 14964.5 | E24: =Summary!U11 -> 16031.9 | F24: =Summary!V11 -> 16592 | G24: =Summary!W11 -> 14771.089 | H24: =Summary!X11 -> 7711.0476 | I24: =Summary!Y11 -> 8155.2739 | J24: =Summary!Z11 -> 8509.8097 | K24: =Summary!AA11 -> 8919.1257 | M24: =Summary!AC11 -> 0.052975495 | O24: =Summary!AE11 -> -0.11674784 | R24: Entry Multiple | S24: =Valuation!D12 -> 14.516056 | T24: =Valuation!D11 -> 29.928045 | U24: =IF($S$21=$S$23,S24,T24) -> 29.928045
B25: =Summary!C12 -> % Margin | E25: =Summary!U12 -> 1 | F25: =Summary!V12 -> 1 | G25: =Summary!W12 -> 0.85253306 | H25: =Summary!X12 -> 0.42723651 | I25: =Summary!Y12 -> 0.431 | J25: =Summary!Z12 -> 0.428 | K25: =Summary!AA12 -> 0.428 | R25: =Model!Y25 -> 2026e | S25: =(Comparables!H10*S30)/(Model!Y61) -> 14.255962 | T25: =(Comparables!$G$10*S30)/Summary!W19 -> 26.018007 | U25: =IF($S$21=$S$23,S25,T25) -> 26.018007
B26: =Summary!C13 -> YoY % Growth | E26: =Summary!U13 -> 0.071328812 | F26: =Summary!V13 -> 0.034936595 | G26: =Summary!W13 -> -0.10974634 | H26: =Summary!X13 -> -0.47796349 | I26: =Summary!Y13 -> 0.057609075 | J26: =Summary!Z13 -> 0.043473193 | K26: =Summary!AA13 -> 0.048099317 | R26: =Summary!AA6 -> 2030e | S26: =(Comparables!H10*S30)/(Model!AG61) -> 12.029343 | T26: =(Comparables!$G$10*S30)/Summary!AA19 -> 21.736351 | U26: =IF($S$21=$S$23,S26,T26) -> 21.736351
R27: Exit Multiple | S27: =Valuation!K60 -> 14 | T27: =Valuation!K72/Summary!AA19 -> 24.708975 | U27: =IF($S$21=$S$23,S27,T27) -> 24.708975
B28: =Summary!C27 -> EBITDA | D28: =Summary!T27 -> 14964.5 | E28: =Summary!U27 -> 16031.9 | F28: =Summary!V27 -> 16592 | G28: =Summary!W27 -> 5679.7132 | H28: =Summary!X27 -> 5740.1206 | I28: =Summary!Y27 -> 6130.6467 | J28: =Summary!Z27 -> 6402.24 | K28: =Summary!AA27 -> 6731.0225 | M28: =Summary!AC27 -> 0.052975495 | O28: =Summary!AE27 -> 0.046809263 | R28: Implied PGM | S28: =Valuation!K79 -> 15.185435 | T28: =Valuation!S72/Summary!AA19 -> 26.784733 | U28: =IF($S$21=$S$23,S28,T28) -> 26.784733
B29: =Summary!C28 -> Margin | E29: =Summary!U28 -> 1 | F29: =Summary!V28 -> 1 | G29: =Summary!W28 -> 0.32781221 | H29: =Summary!X28 -> 0.31803579 | I29: =Summary!Y28 -> 0.324 | J29: =Summary!Z28 -> 0.322 | K29: =Summary!AA28 -> 0.323
B30: =Summary!C29 -> YoY % Growth | E30: =Summary!U17 -> 0.071328812 | F30: =Summary!V17 -> 0.034936595 | G30: =Summary!W29 -> 0.060677006 | H30: =Summary!X29 -> 0.010635645 | I30: =Summary!Y29 -> 0.068034474 | J30: =Summary!Z29 -> 0.044300916 | K30: =Summary!AA29 -> 0.051354284 | R30: Financials Multiplier | S30: =IF($B$2="$ in Millions Except Per Share Data",1,IF($B$2="$ in Thousands Except Per Share Data",1000,IF($B$2="$ in Billions Except Per Share Data",0.001,0))) -> 1
B32: =Summary!C19 -> Net Income (Loss) | D32: =Summary!T19 -> 14964.5 | E32: =Summary!U19 -> 16031.9 | F32: =Summary!V19 -> 16592 | G32: =Summary!W19 -> 2596.1549 | H32: =Summary!X19 -> 2482.132 | I32: =Summary!Y19 -> 2803.4173 | J32: =Summary!Z19 -> 2919.2989 | K32: =Summary!AA19 -> 3107.5491 | M32: =Summary!AC19 -> 0.052975495 | O32: =Summary!AE19 -> 0.040618282
B33: =Summary!C20 -> Margin | E33: =Summary!U20 -> 1 | F33: =Summary!V20 -> 1 | G33: =Summary!W20 -> 0.14984054 | H33: =Summary!X20 -> 0.13752443 | I33: =Summary!Y20 -> 0.14815846 | J33: =Summary!Z20 -> 0.14682584 | K33: =Summary!AA20 -> 0.14912123
B34: =Summary!C21 -> YoY % Growth | E34: =Summary!U21 -> 0.071328812 | F34: =Summary!V21 -> 0.034936595 | G34: =Summary!W21 -> 0.01945925 | H34: =Summary!X21 -> -0.043919933 | I34: =Summary!Y21 -> 0.12943926 | J34: =Summary!Z21 -> 0.041335835 | K34: =Summary!AA21 -> 0.064484719
B36: =Summary!C23 -> Adj. EPS (Diluted) | D36: =Summary!T23 -> #DIV/0! | E36: =Summary!U23 -> #DIV/0! | F36: =Summary!V23 -> #DIV/0! | G36: =Summary!W23 -> 8.3010549 | H36: =Summary!X23 -> 8.0146684 | I36: =Summary!Y23 -> 9.1030862 | J36: =Summary!Z23 -> 9.5676296 | K36: =Summary!AA23 -> 10.283124 | M36: =Summary!AC23 -> N/A | O36: =Summary!AE23 -> 0.04917992
B37: =Summary!C24 -> YoY % Growth | E37: =Summary!U24 -> NA | F37: =Summary!V24 -> NA | G37: =Summary!W24 -> 0.026261562 | H37: =Summary!X24 -> -0.034500014 | I37: =Summary!Y24 -> 0.13580322 | J37: =Summary!Z24 -> 0.051031418 | K37: =Summary!AA24 -> 0.07478283
B39: Free Cash Flow | D39: =Model!J115 -> 20273 | E39: =Model!O115 -> 16031.9 | F39: =Model!T115 -> 16592 | G39: =Model!Y115 -> 7446.2411 | H39: =Model!AD115 -> 6633.6955 | I39: =Model!AE115 -> 6904.0477 | J39: =Model!AF115 -> 7257.1309 | K39: =Model!AG115 -> 7648.7992 | M39: =IFERROR((F39/D39)^(1/2)-1,"N/A") -> -0.095329645 | O39: =IFERROR((K39/G39)^(1/4)-1,"N/A") -> 0.0067323883
B40: YoY % Growth | E40: =E39/D39-1 -> -0.20919943 | F40: =F39/E39-1 -> 0.034936595 | G40: =G39/F39-1 -> -0.14651371 | H40: =H39/G39-1 -> -0.10912158 | I40: =I39/H39-1 -> 0.040754379 | J40: =J39/I39-1 -> 0.051141482 | K40: =K39/J39-1 -> 0.053970128
E42: Annuals | M42: Average | O42: Average
B43: Capitalization and Key Ratios | E43: =E19 -> 2024 | F43: =F19 -> 2025 | G43: =G19 -> 2026e | H43: =H19 -> 2027e | I43: =I19 -> 2028e | J43: =J19 -> 2029e | K43: =K19 -> 2030e | M43: Historical | O43: Projected
B44: =Summary!C91 -> Leverage
B45: =Summary!C92 -> Total Debt / EBITDA | D45: =Summary!T92 -> 0 | E45: =Summary!U92 -> 0 | F45: =Summary!V92 -> 0 | G45: =Summary!W92 -> 2.244437 | H45: =Summary!X92 -> 2.0374729 | I45: =Summary!Y92 -> 1.9392878 | J45: =Summary!Z92 -> 1.8579068 | K45: =Summary!AA92 -> 1.7916542 | M45: =AVERAGE(D45:F45) -> 0 | O45: =AVERAGE(G45:K45) -> 1.9741517
B46: =Summary!C93 -> Total Debt / Equity | D46: =Summary!T93 -> NA | E46: =Summary!U93 -> NA | F46: =Summary!V93 -> NA | G46: =Summary!W93 -> 1.0816532 | H46: =Summary!X93 -> 0.98256759 | I46: =Summary!Y93 -> 0.98232675 | J46: =Summary!Z93 -> 0.97805575 | K46: =Summary!AA93 -> 0.99422844 | M46: =AVERAGE(D46:F46) -> #DIV/0! | O46: =AVERAGE(G46:K46) -> 1.0037663
B47: =Summary!C94 -> Total Debt / Total Assets | D47: =Summary!T94 -> NA | E47: =Summary!U94 -> NA | F47: =Summary!V94 -> NA | G47: =Summary!W94 -> 0.37606537 | H47: =Summary!X94 -> 0.34087674 | I47: =Summary!Y94 -> 0.34087699 | J47: =Summary!Z94 -> 0.33807397 | K47: =Summary!AA94 -> 0.33924913 | M47: =AVERAGE(D47:F47) -> #DIV/0! | O47: =AVERAGE(G47:K47) -> 0.34702844
B49: =Summary!C103 -> Liquidity
...

Sheet Football Field
C1: =Company_Name&" - "&MID(CELL("filename",A1),FIND("]",CELL("filename",A1))+1,255)&": "&Case_Scenario&" Case" -> Republic Services, Inc. - Football Field: Base Case
C2: =Cover!C2 -> $ in Millions Except Per Share Data
A4: x | O4: Valuation Method: | T4: Downside | U4: Delta | V4: Upside | W4: x
O5: =TEXT(Valuation!E108,"0.0%")&" - "&TEXT(Valuation!E110,"0.0%")&" WACC"&" & "&TEXT(Valuation!G106,"0.0%")&" - "&TEXT(Valuation!I106,"0.0%")&" PGR" -> #DIV/0! | T5: =Valuation!G108 -> 269.88986 | U5: =V5-T5 -> -6.6777133 | V5: =Valuation!I110 -> 263.21214
O6: =TEXT(Valuation!E100,"0.0%")&" - "&TEXT(Valuation!E102,"0.0%")&" WACC"&" & "&TEXT(Valuation!G98,"0.0x")&" - "&TEXT(Valuation!I98,"0.0x")&" Exit Multiple" -> #DIV/0! | T6: =Valuation!G100 -> 232.45368 | U6: =V6-T6 -> 26.311981 | V6: =Valuation!I102 -> 258.76566
O8: =Valuation!F184&": "&TEXT(Valuation!G185,"0.0x")&" - "&TEXT(Valuation!I185,"0.0x") -> NTM EV/EBITDA Spread to Comps: 13.5x - 15.5x | T8: =Valuation!G187 -> 184.16511 | U8: =V8-T8 -> 90.688419 | V8: =Valuation!I189 -> 274.85353
O9: =Valuation!F176&": "&TEXT(Valuation!G177,"0.0x")&" - "&TEXT(Valuation!I177,"0.0x") -> NTM EV/EBITDA: 13.6x - 15.6x | T9: =Valuation!G179 -> 186.59498 | U9: =V9-T9 -> 91.228391 | V9: =Valuation!I181 -> 277.82337
O10: =Valuation!F168&": "&TEXT(Valuation!G169,"0.0x")&" - "&TEXT(Valuation!I169,"0.0x") -> NTM P/E Spread to Comps: 27.2x - 31.2x | T10: =Valuation!G171 -> #DIV/0! | U10: =V10-T10 -> #DIV/0! | V10: =Valuation!I173 -> #DIV/0!
O11: =Valuation!F160&": "&TEXT(Valuation!G161,"0.0x")&" - "&TEXT(Valuation!I161,"0.0x") -> NTM P/E: 29.2x - 31.2x | T11: =Valuation!G163 -> #DIV/0! | U11: =V11-T11 -> #DIV/0! | V11: =Valuation!I165 -> #DIV/0!
T13: =Valuation!G263 -> 151.01425 | U13: =V13-T13 -> 33.327384 | V13: =Valuation!I263 -> 184.34163
O14: =Valuation!F252&": "&TEXT(Valuation!G253,"0.0x")&" - "&TEXT(Valuation!I253,"0.0x") -> 2006-2010 Late Cycle EV/EBITDA: 12.7x - 14.7x | T14: =Valuation!G255 -> 170.8513 | U14: =V14-T14 -> 33.327384 | V14: =Valuation!I255 -> 204.17868
O15: =Valuation!F244&": "&TEXT(Valuation!G245,"0.0x")&" - "&TEXT(Valuation!I245,"0.0x") -> 2006-2010 Late Cycle P/E Spread to Comps: 27.3x - 29.3x | T15: =Valuation!G247 -> #DIV/0! | U15: =V15-T15 -> #DIV/0! | V15: =Valuation!I247 -> #DIV/0!
O16: =Valuation!F236&": "&TEXT(Valuation!G237,"0.0x")&" - "&TEXT(Valuation!I237,"0.0x") -> 2006-2010 Late Cycle P/E: 27.6x - 29.6x | T16: =Valuation!G239 -> #DIV/0! | U16: =V16-T16 -> #DIV/0! | V16: =Valuation!I239 -> #DIV/0!
O18: 52-Week Price Range: | T18: =Share_Price_Low -> 201.42 | U18: =V18-T18 -> 57.33 | V18: =Share_Price_High -> 258.75
O19: Median Value: | T19: =MEDIAN(T5:T18) -> 203.08467 | U19: =MEDIAN(U5:U18) -> 33.327384 | V19: =MEDIAN(V5:V18) -> 258.76566
A20: x | O20: Implied Return (%): | T20: =T19/Share_Price-1 -> -0.016777216 | V20: =V19/Share_Price-1 -> 0.25279911
T22: Reference Points for Price Axis
U24: Price
A25: x | T25: High | U25: =MAX(V5:V18)*1.1 -> 313.24833 | W25: x
T26: Low | U26: =MIN(T5:T18)*0.9 -> 135.91282
A30: x

Sheet Integrity
C1: =Company_Name&" - "&MID(CELL("filename",A1),FIND("]",CELL("filename",A1))+1,255) -> Republic Services, Inc. - Integrity
C3: Integrity
C4: Metric
C6: Model:
C7: Balance Sheet Check: | D7: =IF(Case_Scenario="Base","OK!","Check!") -> OK!
C8: Base Case: | D8: =IF(Case_Scenario="Base","OK!","Check!") -> OK!
C9: Interest Expense: | D9: =IF(Model!C8="On","OK!","CHECK - OFF") -> OK!
C10: Valuation Date:
C12: Formatting:
C13: Valuation Sensitivity Tables: | D13: =SUM(Valuation!F92,Valuation!K92,Valuation!Q92,Valuation!F151:F155,Valuation!M151:M155,Valuation!F227:F231,Valuation!M227:M231) -> #DIV/0!
C14: WACC Tables: | D14: =SUM(WACC!Q20,WACC!N33:N37) -> #DIV/0!
C16: Font Toggles:
C17: Cover: | D17: =Cover!$Q$2 -> Report
C18: Revenue Build: | D18: ='Revenue Build'!$C$22 -> Report
C19: Model: | D19: =Model!$C$5 -> Report
C20: WACC | D20: =WACC!R5 -> Report
C21: Valuation: | D21: =Valuation!$S$2 -> Report
C23: Change Log
C24: Date | D24: Version | E24: Operator | F24: Revisions
C25: 44476 | D25: v01 | E25: Nate Latimer | F25: Top Down / Bottom Up toggle integration and Capital IQ comps sheet w/ ID Locator
C26: 44476 | D26: v02 | E26: Carson Shaner | F26: Formulas for EBIT/EBITDA margins on earnings sheets
C27: 44480 | D27: v03 | E27: Nate Latimer | F27: Historical driver adjustments to reflect Top Down / Bottom Up Toggle
C28: 44488 | D28: v04 | E28: Nate Latimer | F28: Bug fixes to model output, comps sheet and WACC Comps Relevered Beta
C29: 44489 | D29: v05 | E29: Lilianna Ruby | F29: Changed the year end driver in 2021 and 2022 to correctly pull operating margins
C30: 44491 | D30: v06 | E30: Lilianna Ruby | F30: Changed the first page to add 365 to your previous fiscal year
C31: 44496 | D31: v07 | E31: Carson Shaner | F31: Changed Model Output FCF formula, broke apart D&A for historical periods, added checks for EPS & EBITDA in Valuation sensitivity tables, added segment D&A breakdown, linked and fixed SOTP valuation
C32: 44503 | D32: v08 | E32: Lilianna Ruby | F32: Changed average of comps on valuation tab to average all peers not just the first one
C33: 44512 | D33: v09 | E33: Lilianna Ruby | F33: Rolled model forward to reflect 3Q'21. Also changed the multiples tab so the quarters roll forward and end on correct date.
C34: 44522 | D34: v10 | E34: Lilianna Ruby | F34: Fully fixed the multiples tab so it is automatic and fully functional. Also fixed definition of NTM_EPS and NTM_EBITDA
C35: 44582 | D35: v13 | E35: Carson Shaner | F35: Changed EPS, EBITDA, shares, tax rate, etc., to formulas so we do not have to hardcode them.
C36: 44584 | D36: v14 | E36: Lilianna Ruby | F36: Changed discount factor to mid year
... C47: 45581 | D47: v25 | E47: Conor McCabe | F47: Added font toggle to integrity tab for WACC tab. Formatted Comparables Tab.

Sheet Revenue Build
C1: =Company_Name&" - "&MID(CELL("filename",A1),FIND("]",CELL("filename",A1))+1,255)&": "&Case_Scenario&" Case" -> Republic Services, Inc. - Revenue Build: Base Case
C2: =Cover!C2 -> $ in Millions Except Per Share Data
A4: x | C4: Segments
C6: =C30&" Methodology" -> Total Company Revenue Methodology
C7: Segment
C8: =C32&" Methodology" -> Collection Revenue Methodology
C9: =IF(Company_Rev_Methodology="Segment","Segment",IF(Company_Rev_Methodology="Activity-Based","Activity-Based",IF(Company_Rev_Methodology="Backlog","Backlog",IF(Company_Rev_Methodology="Mixed",D9,"--")))) -> Segment | D9: Backlog
C10: =C35&" Methodology" -> Landfill Revenue Methodology
C11: =IF(Company_Rev_Methodology="Segment","Segment",IF(Company_Rev_Methodology="Activity-Based","Activity-Based",IF(Company_Rev_Methodology="Backlog","Backlog",IF(Company_Rev_Methodology="Mixed",D11,"--")))) -> Segment | D11: Activity-Based
C12: =C38&" Methodology" -> Environmental solutions Revenue Methodology
C13: =IF(Company_Rev_Methodology="Segment","Segment",IF(Company_Rev_Methodology="Activity-Based","Activity-Based",IF(Company_Rev_Methodology="Backlog","Backlog",IF(Company_Rev_Methodology="Mixed",D13,"--")))) -> Segment | D13: Segment
C14: =C41&" Methodology" -> Transfer Revenue Methodology
C15: =IF(Company_Rev_Methodology="Segment","Segment",IF(Company_Rev_Methodology="Activity-Based","Activity-Based",IF(Company_Rev_Methodology="Backlog","Backlog",IF(Company_Rev_Methodology="Mixed",D15,"--")))) -> Segment | D15: Segment
C16: =C44&" Methodology" -> Other Revenue Methodology
C17: =IF(Company_Rev_Methodology="Segment","Segment",IF(Company_Rev_Methodology="Activity-Based","Activity-Based",IF(Company_Rev_Methodology="Backlog","Backlog",IF(Company_Rev_Methodology="Mixed",D17,"--")))) -> Segment | D17: Segment
C18: =C47&" Methodology" -> Professional Services and Other Revenue Methodology
C19: =IF(Company_Rev_Methodology="Segment","Segment",IF(Company_Rev_Methodology="Activity-Based","Activity-Based",IF(Company_Rev_Methodology="Backlog","Backlog",IF(Company_Rev_Methodology="Mixed",D19,"--")))) -> Segment | D19: Segment
C21: Font Toggle
C22: Report
C24: Annual vs. Quarterly
C25: Annual
J26: 1 | O26: 2 | T26: 3 | Y26: 4 | AD26: 5 | AE26: 6 | AF26: 7 | AG26: 8
AI27: CAGR
A28: x | C28: Summary | F28: =Model!F$25 -> 1Q23 | G28: =Model!G$25 -> 2Q23 | H28: =Model!H$25 -> 3Q23 | I28: =Model!I$25 -> 4Q23 | J28: =Model!J$25 -> 2023 | K28: =Model!K$25 -> 1Q24 | L28: =Model!L$25 -> 2Q24 | M28: =Model!M$25 -> 3Q24 | ... AG28: =Model!AG$25 -> 2030e | AI28: Historical | AJ28: Projected
C30: Total Company Revenue | F30: ='Segment Analysis'!F8 -> 3581.1 | G30: ='Segment Analysis'!G8 -> 3725.9 | H30: ='Segment Analysis'!H8 -> 3825.9 | I30: ='Segment Analysis'!I8 -> 3831.6 | J30: ='Segment Analysis'!J8 -> 14964.5 | K30: ='Segment Analysis'!K8 -> 3861.7 | L30: ='Segment Analysis'!L8 -> 4048 | M30: ='Segment Analysis'!M8 -> 4076.2 | ... T30: ='Segment Analysis'!T8 -> 16592 | U30: =SUM(U32,U35,U38,U41,U44,U47,) -> 4152.631 | V30: =SUM(V32,V35,V38,V41,V44,V47,) -> 4379.486 | W30: =SUM(W32,W35,W38,W41,W44,W47,) -> 4358.186 | X30: =SUM(X32,X35,X38,X41,X44,X47,) -> 4310.51 | Y30: =SUM(U30:X30) -> 17200.813 | Z30: =SUM(Z32,Z35,Z38,Z41,Z44,Z47,) -> 4358.6652 | AA30: =SUM(AA32,AA35,AA38,AA41,AA44,AA47,) -> 4593.3476 | AB30: =SUM(AB32,AB35,AB38,AB41,AB44,AB47,) -> 4573.9711 | AC30: =SUM(AC32,AC35,AC38,AC41,AC44,AC47,) -> 4522.6788 | AD30: =SUM(Z30:AC30) -> 18048.663 | AE30: =SUM(AE32,AE35,AE38,AE41,AE44,AE47,) -> 18921.749 | AF30: =SUM(AF32,AF35,AF38,AF41,AF44,AF47,) -> 19882.733 | AG30: =SUM(AG32,AG35,AG38,AG41,AG44,AG47,) -> 20839.079 | AI30: =IFERROR((T30/J30)^(1/2)-1,"--") -> 0.052975495 | AJ30: =IFERROR((AG30/T30)^(1/5)-1,"--") -> 0.046636692
C31: =IF($C$25="Quarterly","% Growth QoQ","% Growth YoY") -> % Growth YoY | G31: =IF($C$25="Annual",'Segment Analysis'!G173,'Segment Analysis'!G193) -> N/A | H31: =IF($C$25="Annual",'Segment Analysis'!H173,'Segment Analysis'!H193) -> N/A | I31: =IF($C$25="Annual",'Segment Analysis'!I173,'Segment Analysis'!I193) -> N/A | K31: =IF($C$25="Annual",'Segment Analysis'!K173,'Segment Analysis'!K193) -> 0.078355812 | L31: =IF($C$25="Annual",'Segment Analysis'!L173,'Segment Analysis'!L193) -> 0.086448912 | M31: =IF($C$25="Annual",'Segment Analysis'!M173,'Segment Analysis'!M193) -> 0.065422515 | N31: =IF($C$25="Annual",'Segment Analysis'!N173,'Segment Analysis'!N193) -> 0.055955737 | O31: =IF($C$25="Annual",'Segment Analysis'!O173,'Segment Analysis'!O193) -> 0.071328812 | P31: =IF($C$25="Annual",'Segment Analysis'!P173,'Segment Analysis'!P193) -> 0.038143823 | Q31: =IF($C$25="Annual",'Segment Analysis'!Q173,'Segment Analysis'!Q193) -> 0.046195652 | R31: =IF($C$25="Annual",'Segment Analysis'!R173,'Segment Analysis'!R193) -> 0.033315343 | ... T31: =IF($C$25="Annual",'Segment Analysis'!T173,'Segment Analysis'!T193) -> 0.034936595 | U31: =IFERROR(U30/S30-1,"--") -> 0.0040210348 | V31: =IFERROR(V30/U30-1,"--") -> 0.054629222 | W31: =IFERROR(W30/V30-1,"--") -> -0.0048635844 | X31: =IFERROR(X30/W30-1,"--") -> -0.010939414 | Y31: =IFERROR(Y30/T30-1,"--") -> 0.036693165 | Z31: =IFERROR(Z30/X30-1,"--") -> 0.011171571 | AA31: =IFERROR(AA30/Z30-1,"--") -> 0.053842722 | AB31: =IFERROR(AB30/AA30-1,"--") -> -0.0042183758 | AC31: =IFERROR(AC30/AB30-1,"--") -> -0.011213947 | AD31: =IFERROR(AD30/Y30-1,"--") -> 0.049291255 | AE31: =IFERROR(AE30/AD30-1,"--") -> 0.048374028 | AF31: =IFERROR(AF30/AE30-1,"--") -> 0.050787257 | AG31: =IFERROR(AG30/AF30-1,"--") -> 0.048099317
C32: ='Segment Analysis'!C9 -> Collection Revenue | F32: ='Segment Analysis'!F9 -> 2458.4 | G32: ='Segment Analysis'!G9 -> 2543 | H32: ='Segment Analysis'!H9 -> 2616.5 | I32: ='Segment Analysis'!I9 -> 2635 | J32: ='Segment Analysis'!J9 -> 10252.9 | K32: ='Segment Analysis'!K9 -> 2662.8 | L32: ='Segment Analysis'!L9 -> 2722.8 | M32: ='Segment Analysis'!M9 -> 2741.8 | ... T32: ='Segment Analysis'!T9 -> 11233 | U32: =IF(Segment1_Rev_Methodology="Segment",U53,IF(Segment1_Rev_Methodology="Activity-Based",U91,IF(Segment1_Rev_Methodology="Backlog",U165,"--"))) -> 2841.748 | V32: =IF(Segment1_Rev_Methodology="Segment",V53,IF(Segment1_Rev_Methodology="Activity-Based",V91,IF(Segment1_Rev_Methodology="Backlog",V165,"--"))) -> 2932.058 | W32: =IF(Segment1_Rev_Methodology="Segment",W53,IF(Segment1_Rev_Methodology="Activity-Based",W91,IF(Segment1_Rev_Methodology="Backlog",W165,"--"))) -> 2945.565 | X32: =IF(Segment1_Rev_Methodology="Segment",X53,IF(Segment1_Rev_Methodology="Activity-Based",X91,IF(Segment1_Rev_Methodology="Backlog",X165,"--"))) -> 2954.819 | Y32: =SUM(U32:X32) -> 11674.19 | Z32: =IF(Segment1_Rev_Methodology="Segment",Z53,IF(Segment1_Rev_Methodology="Activity-Based",Z91,IF(Segment1_Rev_Methodology="Backlog",Z165,"--"))) -> 2983.8354 | AA32: =IF(Segment1_Rev_Methodology="Segment",AA53,IF(Segment1_Rev_Methodology="Activity-Based",AA91,IF(Segment1_Rev_Methodology="Backlog",AA165,"--"))) -> 3075.7288 | AB32: =IF(Segment1_Rev_Methodology="Segment",AB53,IF(Segment1_Rev_Methodology="Activity-Based",AB91,IF(Segment1_Rev_Methodology="Backlog",AB165,"--"))) -> 3095.7888 | AC32: =IF(Segment1_Rev_Methodology="Segment",AC53,IF(Segment1_Rev_Methodology="Activity-Based",AC91,IF(Segment1_Rev_Methodology="Backlog",AC165,"--"))) -> 3105.5148 | AD32: =SUM(Z32:AC32) -> 12260.868 | AE32: =IF(Segment1_Rev_Methodology="Segment",AE53,IF(Segment1_Rev_Methodology="Activity-Based",AE91,IF(Segment1_Rev_Methodology="Backlog",AE165,"--"))) -> 12849.389 | AF32: =IF(Segment1_Rev_Methodology="Segment",AF53,IF(Segment1_Rev_Methodology="Activity-Based",AF91,IF(Segment1_Rev_Methodology="Backlog",AF165,"--"))) -> 13504.708 | AG32: =IF(Segment1_Rev_Methodology="Segment",AG53,IF(Segment1_Rev_Methodology="Activity-Based",AG91,IF(Segment1_Rev_Methodology="Backlog",AG165,"--"))) -> 14098.916 | AI32: =IFERROR((T32/J32)^(1/2)-1,"--") -> 0.04670553 | AJ32: =IFERROR((AG32/T32)^(1/5)-1,"--") -> 0.046497005
C33: =IF($C$25="Quarterly","% Growth QoQ","% Growth YoY") -> % Growth YoY | G33: =IF($C$25="Annual",'Segment Analysis'!G174,'Segment Analysis'!G194) -> N/A | H33: =IF($C$25="Annual",'Segment Analysis'!H174,'Segment Analysis'!H194) -> N/A | I33: =IF($C$25="Annual",'Segment Analysis'!I174,'Segment Analysis'!I194) -> N/A | K33: =IF($C$25="Annual",'Segment Analysis'!K174,'Segment Analysis'!K194) -> 0.083143508 | L33: =IF($C$25="Annual",'Segment Analysis'!L174,'Segment Analysis'!L194) -> 0.070703893 | M33: =IF($C$25="Annual",'Segment Analysis'!M174,'Segment Analysis'!M194) -> 0.047888401 | N33: =IF($C$25="Annual",'Segment Analysis'!N174,'Segment Analysis'!N194) -> 0.035294118 | O33: =IF($C$25="Annual",'Segment Analysis'!O174,'Segment Analysis'!O194) -> 0.058763862 | P33: =IF($C$25="Annual",'Segment Analysis'!P174,'Segment Analysis'!P194) -> 0.030118672 | Q33: =IF($C$25="Annual",'Segment Analysis'!Q174,'Segment Analysis'!Q194) -> 0.036433084 | R33: =IF($C$25="Annual",'Segment Analysis'!R174,'Segment Analysis'!R194) -> 0.033992268 | ... T33: =IF($C$25="Annual",'Segment Analysis'!T174,'Segment Analysis'!T194) -> 0.034784531 | U33: =IFERROR(U32/S32-1,"--") -> 0.0030878927 | V33: =IFERROR(V32/U32-1,"--") -> 0.031779736 | W33: =IFERROR(W32/V32-1,"--") -> 0.0046066619 | X33: =IFERROR(X32/W32-1,"--") -> 0.0031416723 | Y33: =IFERROR(Y32/T32-1,"--") -> 0.03927624 | Z33: =IFERROR(Z32/X32-1,"--") -> 0.0098200262 | AA33: =IFERROR(AA32/Z32-1,"--") -> 0.030797088 | AB33: =IFERROR(AB32/AA32-1,"--") -> 0.0065220226 | AC33: =IFERROR(AC32/AB32-1,"--") -> 0.0031416723 | AD33: =IFERROR(AD32/Y32-1,"--") -> 0.050254264 | AE33: =IFERROR(AE32/AD32-1,"--") -> 0.048 | AF33: =IFERROR(AF32/AE32-1,"--") -> 0.051 | AG33: =IFERROR(AG32/AF32-1,"--") -> 0.044
C34: % of Total Revenue | F34: ='Segment Analysis'!F17 -> 0.68649298 | G34: ='Segment Analysis'!G17 -> 0.68251966 | H34: ='Segment Analysis'!H17 -> 0.68389137 | I34: ='Segment Analysis'!I17 -> 0.68770227 | J34: ='Segment Analysis'!J17 -> 0.68514818 | K34: ='Segment Analysis'!K17 -> 0.68954088 | L34: ='Segment Analysis'!L17 -> 0.67262846 | M34: ='Segment Analysis'!M17 -> 0.67263628 | ... T34: ='Segment Analysis'!T17 -> 0.67701302 | U34: =U32/U$30 -> 0.68432471 | V34: =V32/V$30 -> 0.6694982 | W34: =W32/W$30 -> 0.6758695 | X34: =X32/X$30 -> 0.68549174 | Y34: =Y32/Y$30 -> 0.6786999 | Z34: =Z32/Z$30 -> 0.6845755 | AA34: =AA32/AA$30 -> 0.66960508 | AB34: =AB32/AB$30 -> 0.67682737 | ... AG34: =AG32/AG$30 -> 0.67656136
C35: ='Segment Analysis'!C10 -> Landfill Revenue | F35: ='Segment Analysis'!F10 -> 392.6 | G35: ='Segment Analysis'!G10 -> 431 | H35: ='Segment Analysis'!H10 -> 436.3 | I35: ='Segment Analysis'!I10 -> 419.6 | J35: ='Segment Analysis'!J10 -> 1679.5 | K35: ='Segment Analysis'!K10 -> 404.4 | L35: ='Segment Analysis'!L10 -> 440.2 | M35: ='Segment Analysis'!M10 -> 452.8 | ... T35: ='Segment Analysis'!T10 -> 1920 | U35: =IF(Segment2_Rev_Methodology="Segment",U59,IF(Segment2_Rev_Methodology="Activity-Based",U103,IF(Segment2_Rev_Methodology="Backlog",U177,"--"))) -> 439.103 | V35: =IF(Segment2_Rev_Methodology="Segment",V59,IF(Segment2_Rev_Methodology="Activity-Based",V103,IF(Segment2_Rev_Methodology="Backlog",V177,"--"))) -> 519.612 | W35: =IF(Segment2_Rev_Methodology="Segment",W59,IF(Segment2_Rev_Methodology="Activity-Based",W103,IF(Segment2_Rev_Methodology="Backlog",W177,"--"))) -> 520.644 | X35: =IF(Segment2_Rev_Methodology="Segment",X59,IF(Segment2_Rev_Methodology="Activity-Based",X103,IF(Segment2_Rev_Methodology="Backlog",X177,"--"))) -> 488.949 | Y35: =SUM(U35:X35) -> 1968.308 | Z35: =IF(Segment2_Rev_Methodology="Segment",Z59,IF(Segment2_Rev_Methodology="Activity-Based",Z103,IF(Segment2_Rev_Methodology="Backlog",Z177,"--"))) -> 459.74084 | AA35: =IF(Segment2_Rev_Methodology="Segment",AA59,IF(Segment2_Rev_Methodology="Activity-Based",AA103,IF(Segment2_Rev_Methodology="Backlog",AA177,"--"))) -> 546.63182 | AB35: =IF(Segment2_Rev_Methodology="Segment",AB59,IF(Segment2_Rev_Methodology="Activity-Based",AB103,IF(Segment2_Rev_Methodology="Backlog",AB177,"--"))) -> 545.63491 | AC35: =IF(Segment2_Rev_Methodology="Segment",AC59,IF(Segment2_Rev_Methodology="Activity-Based",AC103,IF(Segment2_Rev_Methodology="Backlog",AC177,"--"))) -> 510.9517 | AD35: =SUM(Z35:AC35) -> 2062.9593 | AE35: =IF(Segment2_Rev_Methodology="Segment",AE59,IF(Segment2_Rev_Methodology="Activity-Based",AE103,IF(Segment2_Rev_Methodology="Backlog",AE177,"--"))) -> 2180.548 | AF35: =IF(Segment2_Rev_Methodology="Segment",AF59,IF(Segment2_Rev_Methodology="Activity-Based",AF103,IF(Segment2_Rev_Methodology="Backlog",AF177,"--"))) -> 2302.6586 | AG35: =IF(Segment2_Rev_Methodology="Segment",AG59,IF(Segment2_Rev_Methodology="Activity-Based",AG103,IF(Segment2_Rev_Methodology="Backlog",AG177,"--"))) -> 2427.0022 | AI35: =IFERROR((T35/J35)^(1/3)-1,"--") -> 0.04561966 | AJ35: =IFERROR((AG35/T35)^(1/5)-1,"--") -> 0.047981917
C36: % Growth | G36: =IF($C$25="Annual",'Segment Analysis'!G175,'Segment Analysis'!G195) -> N/A | H36: =IF($C$25="Annual",'Segment Analysis'!H175,'Segment Analysis'!H195) -> N/A | I36: =IF($C$25="Annual",'Segment Analysis'!I175,'Segment Analysis'!I195) -> N/A | K36: =IF($C$25="Annual",'Segment Analysis'!K175,'Segment Analysis'!K195) -> 0.030056037 | L36: =IF($C$25="Annual",'Segment Analysis'!L175,'Segment Analysis'!L195) -> 0.021345708 | M36: =IF($C$25="Annual",'Segment Analysis'!M175,'Segment Analysis'!M195) -> 0.037818015 | N36: =IF($C$25="Annual",'Segment Analysis'!N175,'Segment Analysis'!N195) -> 0.055767398 | O36: ='Segment Analysis'!O175 -> 0.036260792 | P36: =IF($C$25="Annual",'Segment Analysis'!P175,'Segment Analysis'!P195) -> 0.041048467 | Q36: =IF($C$25="Annual",'Segment Analysis'!Q175,'Segment Analysis'!Q195) -> 0.17219446 | R36: =IF($C$25="Annual",'Segment Analysis'!R175,'Segment Analysis'!R195) -> 0.13957597 | S36: =IF($C$25="Annual",'Segment Analysis'!S175,'Segment Analysis'!S195) -> 0.054176072 | T36: ='Segment Analysis'!T175 -> 0.10319467 | U36: =IFERROR(U35/S35-1,"--") -> -0.059736617 | V36: =IFERROR(V35/U35-1,"--") -> 0.18334878 | W36: =IFERROR(W35/V35-1,"--") -> 0.0019860973 | X36: =IFERROR(X35/W35-1,"--") -> -0.06087653 | Y36: =IFERROR(Y35/T35-1,"--") -> 0.025160417 | Z36: =IFERROR(Z35/X35-1,"--") -> -0.059736617 | AA36: =IFERROR(AA35/Z35-1,"--") -> 0.18899992 | AB36: =IFERROR(AB35/AA35-1,"--") -> -0.0018237358 | AC36: =IFERROR(AC35/AB35-1,"--") -> -0.06356486 | AD36: =IFERROR(AD35/Y35-1,"--") -> 0.048087638 | AE36: =IFERROR(AE35/AD35-1,"--") -> 0.057 | AF36: =IFERROR(AF35/AE35-1,"--") -> 0.056 | AG36: =IFERROR(AG35/AF35-1,"--") -> 0.054
C37: % of Total Revenue | F37: ='Segment Analysis'!F18 -> 0.10963112 | G37: ='Segment Analysis'!G18 -> 0.11567675 | H37: ='Segment Analysis'!H18 -> 0.11403853 | I37: ='Segment Analysis'!I18 -> 0.10951039 | J37: ='Segment Analysis'!J18 -> 0.11223228 | K37: ='Segment Analysis'!K18 -> 0.10472072 | L37: ='Segment Analysis'!L18 -> 0.10874506 | M37: ='Segment Analysis'!M18 -> 0.11108385 | ... T37: ='Segment Analysis'!T18 -> 0.11571842 | U37: =U35/U$30 -> 0.10574091 | V37: =V35/V$30 -> 0.1186468 | W37: =W35/W$30 -> 0.11946346 | X37: =X35/X$30 -> 0.11343182 | Y37: =Y35/Y$30 -> 0.1144311 | Z37: =Z35/Z$30 -> 0.10547744 | AA37: =AA35/AA$30 -> 0.11900511 | AB37: =AB35/AB$30 -> 0.11929129 | ... AG37: =AG35/AG$30 -> 0.11646399
C38: ='Segment Analysis'!C11 -> Environmental solutions Revenue | F38: ='Segment Analysis'!F11 -> 408.3 | G38: ='Segment Analysis'!G11 -> 398.3 | H38: ='Segment Analysis'!H11 -> 404.8 | I38: ='Segment Analysis'!I11 -> 413.4 | J38: ='Segment Analysis'!J11 -> 1624.8 | K38: ='Segment Analysis'!K11 -> 423.3 | L38: ='Segment Analysis'!L11 -> 472.6 | M38: ='Segment Analysis'!M11 -> 464.7 | ... T38: ='Segment Analysis'!T11 -> 1766 | U38: =IF(Segment3_Rev_Methodology="Segment",U65,IF(Segment3_Rev_Methodology="Activity-Based",U115,IF(Segment3_Rev_Methodology="Backlog",U189,"--"))) -> 463.368 | V38: =IF(Segment3_Rev_Methodology="Segment",V65,IF(Segment3_Rev_Methodology="Activity-Based",V115,IF(Segment3_Rev_Methodology="Backlog",V189,"--"))) -> 478.17 | W38: =IF(Segment3_Rev_Methodology="Segment",W65,IF(Segment3_Rev_Methodology="Activity-Based",W115,IF(Segment3_Rev_Methodology="Backlog",W189,"--"))) -> 449.021 | X38: =IF(Segment3_Rev_Methodology="Segment",X65,IF(Segment3_Rev_Methodology="Activity-Based",X115,IF(Segment3_Rev_Methodology="Backlog",X189,"--"))) -> 442.256 | Y38: =SUM(U38:X38) -> 1832.815 | Z38: =IF(Segment3_Rev_Methodology="Segment",Z65,IF(Segment3_Rev_Methodology="Activity-Based",Z115,IF(Segment3_Rev_Methodology="Backlog",Z189,"--"))) -> 489.31661 | AA38: =IF(Segment3_Rev_Methodology="Segment",AA65,IF(Segment3_Rev_Methodology="Activity-Based",AA115,IF(Segment3_Rev_Methodology="Backlog",AA189,"--"))) -> 502.55667 | AB38: =IF(Segment3_Rev_Methodology="Segment",AB65,IF(Segment3_Rev_Methodology="Activity-Based",AB115,IF(Segment3_Rev_Methodology="Backlog",AB189,"--"))) -> 471.02303 | AC38: =IF(Segment3_Rev_Methodology="Segment",AC65,IF(Segment3_Rev_Methodology="Activity-Based",AC115,IF(Segment3_Rev_Methodology="Backlog",AC189,"--"))) -> 463.92654 | AD38: =SUM(Z38:AC38) -> 1926.8229 | AE38: =IF(Segment3_Rev_Methodology="Segment",AE65,IF(Segment3_Rev_Methodology="Activity-Based",AE115,IF(Segment3_Rev_Methodology="Backlog",AE189,"--"))) -> 2025.0908 | AF38: =IF(Segment3_Rev_Methodology="Segment",AF65,IF(Segment3_Rev_Methodology="Activity-Based",AF115,IF(Segment3_Rev_Methodology="Backlog",AF189,"--"))) -> 2138.4959 | AG38: =IF(Segment3_Rev_Methodology="Segment",AG65,IF(Segment3_Rev_Methodology="Activity-Based",AG115,IF(Segment3_Rev_Methodology="Backlog",AG189,"--"))) -> 2288.1906 | AI38: =IFERROR((T38/J38)^(1/3)-1,"--") -> 0.028166848 | AJ38: =IFERROR((AG38/T38)^(1/5)-1,"--") -> 0.053174415
C39: % Growth | G39: =IF($C$25="Annual",'Segment Analysis'!G176,'Segment Analysis'!G196) -> N/A | H39: =IF($C$25="Annual",'Segment Analysis'!H176,'Segment Analysis'!H196) -> N/A | I39: =IF($C$25="Annual",'Segment Analysis'!I176,'Segment Analysis'!I196) -> N/A | K39: =IF($C$25="Annual",'Segment Analysis'!K176,'Segment Analysis'!K196) -> 0.036737693 | L39: =IF($C$25="Annual",'Segment Analysis'!L176,'Segment Analysis'!L196) -> 0.18654281 | M39: =IF($C$25="Annual",'Segment Analysis'!M176,'Segment Analysis'!M196) -> 0.14797431 | N39: =IF($C$25="Annual",'Segment Analysis'!N176,'Segment Analysis'!N196) -> 0.16594098 | O39: =IF($C$25="Annual",'Segment Analysis'!O176,'Segment Analysis'!O196) -> 0.13404727 | P39: =IF($C$25="Annual",'Segment Analysis'!P176,'Segment Analysis'!P196) -> 0.060713442 | Q39: =IF($C$25="Annual",'Segment Analysis'!Q176,'Segment Analysis'!Q196) -> -0.022429116 | R39: =IF($C$25="Annual",'Segment Analysis'!R176,'Segment Analysis'!R196) -> -0.068216053 | ... T39: =IF($C$25="Annual",'Segment Analysis'!T176,'Segment Analysis'!T196) -> -0.041571692 | U39: =IFERROR(U38/S38-1,"--") -> 0.098028436 | V39: =IFERROR(V38/U38-1,"--") -> 0.031944373 | W39: =IFERROR(W38/V38-1,"--") -> -0.060959491 | X39: =IFERROR(X38/W38-1,"--") -> -0.01506611 | Y39: =IFERROR(Y38/T38-1,"--") -> 0.037834088 | Z39: =IFERROR(Z38/X38-1,"--") -> 0.10641033 | AA39: =IFERROR(AA38/Z38-1,"--") -> 0.027058272 | AB39: =IFERROR(AB38/AA38-1,"--") -> -0.062746438 | AC39: =IFERROR(AC38/AB38-1,"--") -> -0.01506611 | AD39: =IFERROR(AD38/Y38-1,"--") -> 0.051291511 | AE39: =IFERROR(AE38/AD38-1,"--") -> 0.051 | AF39: =IFERROR(AF38/AE38-1,"--") -> 0.056 | AG39: =IFERROR(AG38/AF38-1,"--") -> 0.07
