Workbook
Name __1_0_Table2_: [1]MERGER!#REF!
Name __FDS_HYPERLINK_TOGGLE_STATE__: "ON"
Name _1_0_Table2_: [1]MERGER!#REF!
Name _2_0_Table2_: [1]MERGER!#REF!
Name _3_0_Table2_: [1]MERGER!#REF!
Name _4_0_Table2_: [1]MERGER!#REF!
Name _5_0_Table2_: [1]MERGER!#REF!
Name _9_0_Table2_: [1]MERGER!#REF!
Name _AtRisk_SimSetting_AutomaticallyGenerateReports: FALSE
Name _AtRisk_SimSetting_AutomaticResultsDisplayMode: 0
Name _AtRisk_SimSetting_ConvergenceConfidenceLevel: 0.95
Name _AtRisk_SimSetting_ConvergencePercentileToTest: 0.9
Name _AtRisk_SimSetting_ConvergencePerformMeanTest: TRUE
Name _AtRisk_SimSetting_ConvergencePerformPercentileTest: FALSE
Name _AtRisk_SimSetting_ConvergencePerformStdDeviationTest: FALSE
Name _AtRisk_SimSetting_ConvergenceTestAllOutputs: TRUE
Name _AtRisk_SimSetting_ConvergenceTestingPeriod: 100
Name _AtRisk_SimSetting_ConvergenceTolerance: 0.03
Name _AtRisk_SimSetting_LiveUpdate: TRUE
Name _AtRisk_SimSetting_LiveUpdatePeriod: -1
Name _AtRisk_SimSetting_RandomNumberGenerator: 0
Name _AtRisk_SimSetting_ReportsList: 0
Name _AtRisk_SimSetting_SimNameCount: 0
Name _AtRisk_SimSetting_SmartSensitivityAnalysisEnabled: TRUE
Name _AtRisk_SimSetting_StatisticFunctionUpdating: 1
Name _AtRisk_SimSetting_StdRecalcBehavior: 0
Name _AtRisk_SimSetting_StdRecalcWithoutRiskStatic: 0
Name _AtRisk_SimSetting_StdRecalcWithoutRiskStaticPercentile: 0.5
Name _bdm.001de5d049b6489bbc2025ad50c87030.edm: Model!$1:$1048576
Name _bdm.146e958bbea04416b86a4d5943392c04.edm: Model!$M$100
Name _bdm.1ff456f35144482ea0525e6d75d0206f.edm: Integrity!$1:$1048576
Name _bdm.a65ed6e2cd6142fea39714a1a8762f97.edm: Integrity!$1:$1048576
Name _bdm.bf5a9ed53fe44c598e3cfb84ac34b21f.edm: Integrity!$F$37
Name _bdm.dca432f6461240c98baf2847c1b05465.edm: Integrity!$1:$1048576
Name _Fill: #REF!
Name _Key1: #REF!
Name _Order1: 255
Name _Order2: 255
Name _Sort: #REF!
Name _Table1_In1: [2]merger!#REF!
Name _Table1_Out: [2]merger!#REF!
Name _Table2_In1: [2]merger!#REF!
Name _Table2_Out: [2]merger!#REF!
Name _Toc209821136: Cover!$F$33
Name a: {"summary1",#N/A,TRUE,"Comps";"summary2",#N/A,TRUE,"Comps";"summary3",#N/A,TRUE,"Comps"}
Name aaaaaaaa: {"summary1",#N/A,TRUE,"Comps";"summary2",#N/A,TRUE,"Comps";"summary3",#N/A,TRUE,"Comps"}
Name adsfsadfas: {"multiple",#N/A,FALSE,"client (2)";"margins",#N/A,FALSE,"client (2)";"data",#N/A,FALSE,"client (2)";"multiple",#N/A,FALSE,"client";"margins",#N/A,FALSE,"client";"data",#N/A,FALSE,"client"}
Name adsfsdfe: {"Page1",#N/A,FALSE,"CompCo";"Page2",#N/A,FALSE,"CompCo"}
Name aefae: {"inputs raw data",#N/A,TRUE,"INPUT"}
Name aefe: {"cap_structure",#N/A,FALSE,"Graph-Mkt Cap";"price",#N/A,FALSE,"Graph-Price";"ebit",#N/A,FALSE,"Graph-EBITDA";"ebitda",#N/A,FALSE,"Graph-EBITDA"}
Name al: '[3]2010 Labor Rates 091130'!$A$161
Name al09salary: [3]Salaries!$G$13
Name al10salary: [3]Salaries!$K$13
Name alid: '[3]2010 Labor Rates 091130'!$E$168
Name alname: [3]Salaries!$A$13
Name aprpto: [3]Vacation!$I$56
Name asdfasdfas: {"cap_structure",#N/A,FALSE,"Graph-Mkt Cap";"price",#N/A,FALSE,"Graph-Price";"ebit",#N/A,FALSE,"Graph-EBITDA";"ebitda",#N/A,FALSE,"Graph-EBITDA"}
Name asdfsdfasdf: {"Page1",#N/A,FALSE,"CompCo";"Page2",#N/A,FALSE,"CompCo"}
Name augpto: [3]Vacation!$M$56
Name avg_Health_and_Welfare: [4]PBCFringe!$Q$22

Sheet Cover
C1: =Company_Name&" - "&MID(CELL("filename",A1),FIND("]",CELL("filename",A1))+1,255)&": "&Case_Scenario&" Case" -> American Express Company - Cover: Base Case | Q1: Font Toggle
C2: $ in Millions Except Per Share Data | Q2: Report
R3: x
A4: x | C4: Model Assumptions: | I4: Return Summary:
I6: Discounted Cash Flow Analysis | N6: Multiple Analysis
I8: Exit Multiple Method | N8: EV/EBITDA Method
I9: Implied Enterprise Value: | L9: =Valuation!K57 -> 296624.47 | P9: Target Price: | Q9: % Return:
I10: Implied Equity Value: | L10: =Valuation!K64 -> 0
N11: 1 Year LTM EV/EBITDA | P11: =Valuation!N129 -> 335.71784 | Q11: =Valuation!N130 -> 0.070733679
I12: Implied Share Price: | L12: =Valuation!K68 -> 0
I13: % Return: | L13: =Valuation!K69 -> 0 | N13: 2009-2018 Late Cycle EV/EBITDA | P13: =Valuation!N207 -> 423.10361 | Q13: =Valuation!N208 -> 0.34944063
I15: Perpetuity Growth Method | N15: P/E Multiple Method
I16: Implied Enterprise Value: | L16: =Valuation!R57 -> 10375.823 | P16: Target Price: | Q16: % Return:
I17: Implied Equity Value: | L17: =Valuation!R64 -> 0
N18: 1 Year LTM P/E | P18: =Valuation!F118 -> 362.36736 | Q18: =Valuation!F119 -> 0.15077441
C19: Company Name | F19: American Express Company | I19: Implied Share Price: | L19: =Valuation!R68 -> 0
C20: Ticker | F20: AXP | I20: % Return: | L20: =Valuation!R69 -> 0 | N20: 2009-2018 Late Cycle P/E | P20: =Valuation!F196 -> 260.24205 | Q20: =Valuation!F197 -> -0.17354615
C22: Case Scenario | F22: Base | I22: Table of Contents
C24: Last Fiscal Year | F24: 46022 | I24: Cover
C25: Next Fiscal Year | F25: =Last_FYE+365 -> 46387 | I25: Summary
C26: Last Fiscal Quarter Reported | F26: 1Q | I26: Football Field
C27: Current Valuation Date | F27: 46147 | I27: Integrity
I28: Revenue Build
C29: Current Share Price | F29: 314.89 | I29: Model
C30: 52-Week High | F30: 387.49 | I30: Segment Analysis
C31: 52-Week Low | F31: 273.61 | I31: Drivers
I32: WACC
C33: Effective Tax Rate | F33: =IF(Last_FQR="1Q",Model!U71,IF(Last_FQR="2Q",Model!V71,IF(Last_FQR="3Q",Model!W71,Model!X71))) -> 0.21360508 | I33: Valuation
C34: Dividend Yield | F34: =IF(Last_FQR="1Q",Model!U265,IF(Last_FQR="2Q",Model!V265,IF(Last_FQR="3Q",Model!W265,Model!X265))) -> 0.012503379 | I34: Comparables
C35: Diluted Shares Outstanding (MRQ) | F35: =IF(Last_FQR="1Q",Model!U284,IF(Last_FQR="2Q",Model!V284,IF(Last_FQR="3Q",Model!W284,Model!X284))) -> 686 | I35: Charts
I36: Benchmark
C37: Model Type | F37: Top Down | I37: Multiples Data
I38: Pre-Earnings
I39: Post-Earnings
A42: x
C43: Model Color Legend | I43: Constants
C44: Blue = Hard-Coded Value (historical values & assumptions) | I44: Reference | J44: Type | K44: Name | L44: Value
C45: Black = Formulas | I45: Million | J45: (#) | K45: Mil | L45: 1000000
C46: Green = Linked Value (from separate worksheet) | I46: Thousand | J46: (#) | K46: Thou | L46: 1000
C47: Red = Unique Formula / Anomaly | I47: Hundred | J47: (#) | K47: Hun | L47: 100
...

Sheet Summary
C1: =Company_Name&" - "&MID(CELL("filename",A1),FIND("]",CELL("filename",A1))+1,255)&": "&Case_Scenario&" Case" -> American Express Company - Summary: Base Case
C2: =Cover!C2 -> $ in Millions Except Per Share Data
C4: Year: | T4: =Model!J24 -> 2023 | U4: =Model!O24 -> 2024 | V4: =Model!T24 -> 2025 | W4: =Model!Y24 -> 2026 | X4: =Model!AD24 -> 2027 | Y4: =Model!AE24 -> 2028 | Z4: =Model!AF24 -> 2029 | AA4: =Model!AG24 -> 2030
G5: Quarterly | T5: Annuals | AC5: CAGR | AE5: CAGR
A6: x | C6: ="Consolidated "&Model!C25 -> Consolidated Income Statement | G6: =Model!P25 -> 1Q25 | H6: =Model!Q25 -> 2Q25 | I6: =Model!R25 -> 3Q25 | J6: =Model!S25 -> 4Q25 | K6: =Model!U25 -> 1Q26 | L6: =Model!V25 -> 2Q26e | M6: =Model!W25 -> 3Q26e | N6: =Model!X25 -> 4Q26e | O6: =Model!Z25 -> 1Q27e | P6: =Model!AA25 -> 2Q27e | Q6: =Model!AB25 -> 3Q27e | R6: =Model!AC25 -> 4Q27e | T6: =Model!J25 -> 2023 | U6: =Model!O25 -> 2024 | V6: =Model!T25 -> 2025 | W6: =Model!Y25 -> 2026e | X6: =Model!AD25 -> 2027e | Y6: =Model!AE25 -> 2028e | Z6: =Model!AF25 -> 2029e | AA6: =Model!AG25 -> 2030e | AC6: Historical | AE6: Projected
C8: =Model!C28 -> Revenue | G8: =Model!P28 -> 18933 | H8: =Model!Q28 -> 19933 | I8: =Model!R28 -> 20557 | J8: =Model!S28 -> 21040 | K8: =Model!U28 -> 20880 | L8: =Model!V28 -> 21729.203 | M8: =Model!W28 -> 22323.439 | N8: =Model!X28 -> 23124.4 | O8: =Model!Z28 -> 23062.491 | P8: =Model!AA28 -> 24123.963 | Q8: =Model!AB28 -> 24704.225 | R8: =Model!AC28 -> 25658.825 | T8: =Model!J28 -> 67364 | U8: =Model!O28 -> 74201 | V8: =Model!T28 -> 80463 | W8: =Model!Y28 -> 88057.042 | X8: =Model!AD28 -> 97549.504 | Y8: =Model!AE28 -> 104638.91 | Z8: =Model!AF28 -> 111964.78 | AA8: =Model!AG28 -> 118840.28 | AC8: =IFERROR((V8/T8)^(1/(V$4-T$4))-1,"N/A") -> 0.092909439 | AE8: =IFERROR((AA8/V8)^(1/(AA$4-V$4))-1,"N/A") -> 0.081118978
C9: YoY % Growth | K9: =K8/G8-1 -> 0.10283632 | L9: =L8/H8-1 -> 0.090112025 | M9: =M8/I8-1 -> 0.08592883 | N9: =N8/J8-1 -> 0.099068459 | O9: =O8/K8-1 -> 0.10452544 | P9: =P8/L8-1 -> 0.11020928 | Q9: =Q8/M8-1 -> 0.10664959 | R9: =R8/N8-1 -> 0.1095996 | U9: =IF(ISERROR(U8/T8-1),"NA",(U8/T8-1)) -> 0.10149338 | V9: =IF(ISERROR(V8/U8-1),"NA",(V8/U8-1)) -> 0.084392394 | W9: =IF(ISERROR(W8/V8-1),"NA",(W8/V8-1)) -> 0.094379309 | X9: =IF(ISERROR(X8/W8-1),"NA",(X8/W8-1)) -> 0.107799 | Y9: =IF(ISERROR(Y8/X8-1),"NA",(Y8/X8-1)) -> 0.072674931 | Z9: =IF(ISERROR(Z8/Y8-1),"NA",(Z8/Y8-1)) -> 0.070011007 | AA9: =IF(ISERROR(AA8/Z8-1),"NA",(AA8/Z8-1)) -> 0.061407704
C11: =Model!C32 -> Gross Profit | G11: =Model!P32 -> 15817 | H11: =Model!Q32 -> 16451 | I11: =Model!R32 -> 17139 | J11: =Model!S32 -> 17566 | K11: =Model!U32 -> 17656 | L11: =Model!V32 -> 18250.819 | M11: =Model!W32 -> 19007.869 | N11: =Model!X32 -> 19678.936 | O11: =Model!Z32 -> 19900.084 | P11: =Model!AA32 -> 20827.046 | Q11: =Model!AB32 -> 21340.718 | R11: =Model!AC32 -> 22288.523 | T11: =Model!J32 -> 55592 | U11: =Model!O32 -> 60764 | V11: =Model!T32 -> 66973 | W11: =Model!Y32 -> 74593.624 | X11: =Model!AD32 -> 84356.371 | Y11: =Model!AE32 -> 91504.218 | Z11: =Model!AF32 -> 98291.244 | AA11: =Model!AG32 -> 104639.02 | AC11: =IFERROR((V11/T11)^(1/(V$4-T$4))-1,"N/A") -> 0.097599062 | AE11: =IFERROR((AA11/V11)^(1/(AA$4-V$4))-1,"N/A") -> 0.093348923
C12: % Margin | G12: =G11/G$8 -> 0.83541964 | H12: =H11/H$8 -> 0.8253148 | I12: =I11/I$8 -> 0.8337306 | J12: =J11/J$8 -> 0.83488593 | K12: =K11/K$8 -> 0.84559387 | L12: =L11/L$8 -> 0.83992124 | M12: =M11/M$8 -> 0.85147583 | N12: =N11/N$8 -> 0.85100307 | ... R12: =R11/R$8 -> 0.86864939 | T12: =T11/T$8 -> 0.82524791 | U12: =U11/U$8 -> 0.8189108 | V12: =V11/V$8 -> 0.8323453 | W12: =W11/W$8 -> 0.84710571 | X12: =X11/X$8 -> 0.86475448 | Y12: =Y11/Y$8 -> 0.87447605 | Z12: =Z11/Z$8 -> 0.87787643 | AA12: =AA11/AA$8 -> 0.88050127
C13: YoY % Growth | K13: =K11/G11-1 -> 0.11626731 | L13: =L11/H11-1 -> 0.10940485 | M13: =M11/I11-1 -> 0.10904188 | N13: =N11/J11-1 -> 0.12028553 | O13: =O11/K11-1 -> 0.12710038 | P13: =P11/L11-1 -> 0.14115676 | Q13: =Q11/M11-1 -> 0.12273071 | R13: =R11/N11-1 -> 0.13260815 | U13: =U11/T11-1 -> 0.093034969 | V13: =V11/U11-1 -> 0.10218221 | W13: =W11/V11-1 -> 0.1137865 | X13: =X11/W11-1 -> 0.13087911 | Y13: =Y11/X11-1 -> 0.084733939 | Z13: =Z11/Y11-1 -> 0.074171722 | AA13: =AA11/Z11-1 -> 0.064581294
C15: =Model!C39 -> Operating Income | G15: =Model!P39 -> 3330 | H15: =Model!Q39 -> 3550 | I15: =Model!R39 -> 3825 | J15: =Model!S39 -> 3090 | K15: =Model!U39 -> 3778 | L15: =Model!V39 -> 3757.4408 | M15: =Model!W39 -> 4140.4584 | N15: =Model!X39 -> 4416.8314 | O15: =Model!Z39 -> 4494.3402 | P15: =Model!AA39 -> 4808.7344 | Q15: =Model!AB39 -> 5159.4508 | R15: =Model!AC39 -> 5430.6746 | T15: =Model!J39 -> 10513 | U15: =Model!O39 -> 12895 | V15: =Model!T39 -> 13795 | W15: =Model!Y39 -> 16092.731 | X15: =Model!AD39 -> 19893.2 | Y15: =Model!AE39 -> 22756.456 | Z15: =Model!AF39 -> 24898.329 | AA15: =Model!AG39 -> 26798.634 | AC15: =IFERROR((V15/T15)^(1/(V$4-T$4))-1,"N/A") -> 0.1455064 | AE15: =IFERROR((AA15/V15)^(1/(AA$4-V$4))-1,"N/A") -> 0.14203178
C16: Margin | G16: =G15/G$8 -> 0.17588338 | H16: =H15/H$8 -> 0.17809662 | I16: =I15/I$8 -> 0.18606801 | J16: =J15/J$8 -> 0.14686312 | K16: =K15/K$8 -> 0.1809387 | L16: =L15/L$8 -> 0.17292124 | M16: =M15/M$8 -> 0.18547583 | N16: =N15/N$8 -> 0.19100307 | ... R16: =R15/R$8 -> 0.21164939 | T16: =T15/T$8 -> 0.15606259 | U16: =U15/U$8 -> 0.17378472 | V16: =V15/V$8 -> 0.17144526 | W16: =W15/W$8 -> 0.18275348 | X16: =X15/X$8 -> 0.20392928 | Y16: =Y15/Y$8 -> 0.21747605 | Z16: =Z15/Z$8 -> 0.22237643 | AA16: =AA15/AA$8 -> 0.22550127
C17: YoY % Growth | K17: =K15/G15-1 -> 0.13453453 | L17: =L15/H15-1 -> 0.058434028 | M17: =M15/I15-1 -> 0.082472783 | N17: =N15/J15-1 -> 0.42939528 | O17: =O15/K15-1 -> 0.18960831 | P17: =P15/L15-1 -> 0.27978981 | Q17: =Q15/M15-1 -> 0.24610617 | R17: =R15/N15-1 -> 0.22954085 | U17: =U15/T15-1 -> 0.22657662 | V17: =V15/U15-1 -> 0.069794494 | W17: =W15/V15-1 -> 0.16656257 | X17: =X15/W15-1 -> 0.23616063 | Y17: =Y15/X15-1 -> 0.1439314 | Z17: =Z15/Y15-1 -> 0.094121533 | AA17: =AA15/Z15-1 -> 0.076322612
AM18: 1
C19: =Model!C45 -> Net Income (Loss) | G19: =Model!P45 -> 2584 | H19: =Model!Q45 -> 2885 | I19: =Model!R45 -> 2902 | J19: =Model!S45 -> 2462 | K19: =Model!U45 -> 2971 | L19: =Model!V45 -> 2953.3485 | M19: =Model!W45 -> 3254.4003 | N19: =Model!X45 -> 3471.6295 | O19: =Model!Z45 -> 3528.057 | P19: =Model!AA45 -> 3774.8565 | Q19: =Model!AB45 -> 4050.1689 | R19: =Model!AC45 -> 4263.0796 | T19: =Model!J45 -> 8374 | U19: =Model!O45 -> 10129 | V19: =Model!T45 -> 10833 | W19: =Model!Y45 -> 12650.378 | X19: =Model!AD45 -> 15616.162 | Y19: =Model!AE45 -> 17841.062 | Z19: =Model!AF45 -> 19545.188 | AA19: =Model!AG45 -> 21063.727 | AC19: =IFERROR((V19/T19)^(1/(V$4-T$4))-1,"N/A") -> 0.13738604 | AE19: =IFERROR((AA19/V19)^(1/(AA$4-V$4))-1,"N/A") -> 0.14223981
C20: Margin | G20: =G19/G$8 -> 0.13648128 | H20: =H19/H$8 -> 0.14473486 | I20: =I19/I$8 -> 0.14116846 | J20: =J19/J$8 -> 0.11701521 | K20: =K19/K$8 -> 0.14228927 | L20: =L19/L$8 -> 0.1359161 | M20: =M19/M$8 -> 0.145784 | N20: =N19/N$8 -> 0.15012841 | ... R20: =R19/R$8 -> 0.16614477 | T20: =T19/T$8 -> 0.12430972 | U20: =U19/U$8 -> 0.13650759 | V20: =V19/V$8 -> 0.13463331 | W20: =W19/W$8 -> 0.14366118 | X20: =X19/X$8 -> 0.16008448 | Y20: =Y19/Y$8 -> 0.17050122 | Z20: =Z19/Z$8 -> 0.1745655 | AA20: =AA19/AA$8 -> 0.177244
C21: YoY % Growth | K21: =K19/G19-1 -> 0.1497678 | L21: =L19/H19-1 -> 0.023690977 | M21: =M19/I19-1 -> 0.1214336 | N21: =N19/J19-1 -> 0.41008509 | O21: =O19/K19-1 -> 0.18749816 | P21: =P19/L19-1 -> 0.27816157 | Q21: =Q19/M19-1 -> 0.2445208 | R21: =R19/N19-1 -> 0.22797655 | U21: =U19/T19-1 -> 0.20957726 | V21: =V19/U19-1 -> 0.069503406 | W21: =W19/V19-1 -> 0.16776315 | X21: =X19/W19-1 -> 0.2344423 | Y21: =Y19/X19-1 -> 0.14247417 | Z21: =Z19/Y19-1 -> 0.095517096 | AA21: =AA19/Z19-1 -> 0.077693724
C23: =Model!C57 -> Adj. EPS (Diluted) | G23: =Model!P57 -> 3.7222222 | H23: =Model!Q57 -> 4.2961373 | I23: =Model!R57 -> 4.1861472 | J23: =Model!S57 -> 3.4971264 | K23: =Model!U57 -> 4.2813411 | L23: =Model!V57 -> 4.3066281 | M23: =Model!W57 -> 4.7488381 | N23: =Model!X57 -> 5.0692497 | O23: =Model!Z57 -> 5.1551064 | P23: =Model!AA57 -> 5.5194014 | Q23: =Model!AB57 -> 5.9259003 | R23: =Model!AC57 -> 6.2415799 | T23: =Model!J57 -> 11.565217 | U23: =Model!O57 -> 13.753156 | V23: =Model!T57 -> 15.734195 | W23: =Model!Y57 -> 18.405216 | X23: =Model!AD57 -> 22.840765 | Y23: =Model!AE57 -> 26.164702 | Z23: =Model!AF57 -> 28.740459 | AA23: =Model!AG57 -> 31.056162 | AC23: =IFERROR((V23/T23)^(1/(V$4-T$4))-1,"N/A") -> 0.16639425 | AE23: =IFERROR((AA23/V23)^(1/(AA$4-V$4))-1,"N/A") -> 0.14567293
C24: YoY % Growth | K24: =K23/G23-1 -> 0.15021104 | L24: =L23/H23-1 -> 0.0024418948 | M24: =M23/I23-1 -> 0.13441739 | N24: =N23/J23-1 -> 0.44954717 | O24: =O23/K23-1 -> 0.20408681 | P24: =P23/L23-1 -> 0.28160623 | Q24: =Q23/M23-1 -> 0.2478632 | R24: =R23/N23-1 -> 0.23126305 | U24: =IF(ISERROR(U23/T23-1),"NA",(U23/T23-1)) -> 0.18918263 | V24: =IF(ISERROR(V23/U23-1),"NA",(V23/U23-1)) -> 0.14404256 | W24: =IF(ISERROR(W23/V23-1),"NA",(W23/V23-1)) -> 0.16975898 | X24: =IF(ISERROR(X23/W23-1),"NA",(X23/W23-1)) -> 0.24099412 | Y24: =IF(ISERROR(Y23/X23-1),"NA",(Y23/X23-1)) -> 0.1455265 | Z24: =IF(ISERROR(Z23/Y23-1),"NA",(Z23/Y23-1)) -> 0.098443959 | AA24: =IF(ISERROR(AA23/Z23-1),"NA",(AA23/Z23-1)) -> 0.080572957
C27: =Model!C61 -> EBITDA | G27: =Model!P61 -> 3774.25 | H27: =Model!Q61 -> 3994.25 | I27: =Model!R61 -> 4269.25 | J27: =Model!S61 -> 3534.25 | K27: =Model!U61 -> 4246 | L27: =Model!V61 -> 4326.4002 | M27: =Model!W61 -> 4714.2262 | N27: =Model!X61 -> 4991.1211 | O27: =Model!Z61 -> 5068.9301 | P27: =Model!AA61 -> 5387.1041 | Q27: =Model!AB61 -> 5739.7638 | R27: =Model!AC61 -> 6011.977 | T27: =Model!J61 -> 12164 | U27: =Model!O61 -> 14571 | V27: =Model!T61 -> 15572 | W27: =Model!Y61 -> 18277.747 | X27: =Model!AD61 -> 22207.775 | Y27: =Model!AE61 -> 25108.645 | Z27: =Model!AF61 -> 27242.601 | AA27: =Model!AG61 -> 29356.275 | AC27: =IFERROR((V27/T27)^(1/(V$4-T$4))-1,"N/A") -> 0.13144642 | AE27: =IFERROR((AA27/V27)^(1/(AA$4-V$4))-1,"N/A") -> 0.1351972
C28: Margin | G28: =G27/G$8 -> 0.1993477 | H28: =H27/H$8 -> 0.20038379 | I28: =I27/I$8 -> 0.20767865 | J28: =J27/J$8 -> 0.16797766 | K28: =K27/K$8 -> 0.20335249 | L28: =L27/L$8 -> 0.19910533 | M28: =M27/M$8 -> 0.21117831 | N28: =N27/N$8 -> 0.21583786 | ... R28: =R27/R$8 -> 0.23430445 | T28: =T27/T$8 -> 0.18057122 | U28: =U27/U$8 -> 0.19637202 | V28: =V27/V$8 -> 0.19352995 | W28: =W27/W$8 -> 0.20756713 | X28: =X27/X$8 -> 0.22765646 | Y28: =Y27/Y$8 -> 0.23995515 | Z28: =Z27/Z$8 -> 0.24331402 | AA28: =AA27/AA$8 -> 0.24702293
C29: YoY % Growth | K29: =K27/G27-1 -> 0.12499172 | L29: =L27/H27-1 -> 0.083157076 | M29: =M27/I27-1 -> 0.10422819 | N29: =N27/J27-1 -> 0.41221508 | O29: =O27/K27-1 -> 0.19381303 | P29: =P27/L27-1 -> 0.24517011 | Q29: =Q27/M27-1 -> 0.21754104 | R29: =R27/N27-1 -> 0.20453437 | U29: =U27/T27-1 -> 0.19787899 | V29: =V27/U27-1 -> 0.068698099 | W29: =W27/V27-1 -> 0.17375722 | X29: =X27/W27-1 -> 0.21501706 | Y29: =Y27/X27-1 -> 0.13062405 | Z29: =Z27/Y27-1 -> 0.08498893 | AA29: =AA27/Z27-1 -> 0.077587067
G31: =G$5 -> Quarterly | T31: =T$5 -> Annuals
A32: x | C32: ="Consolidated "&Model!C118 -> Consolidated Balance Sheet | G32: =G$6 -> 1Q25 | H32: =H$6 -> 2Q25 | I32: =I$6 -> 3Q25 | J32: =J$6 -> 4Q25 | K32: =K$6 -> 1Q26 | L32: =L$6 -> 2Q26e | M32: =M$6 -> 3Q26e | N32: =N$6 -> 4Q26e | ... R32: =R$6 -> 4Q27e | T32: =T$6 -> 2023 | U32: =U$6 -> 2024 | V32: =V$6 -> 2025 | W32: =W$6 -> 2026e | X32: =X$6 -> 2027e | Y32: =Y$6 -> 2028e | Z32: =Z$6 -> 2029e | AA32: =AA$6 -> 2030e
C34: =Model!C120 -> Cash & Cash Equivalents | G34: =Model!P120 -> 52508 | H34: =Model!Q120 -> 57937 | I34: =Model!R120 -> 54706 | J34: =Model!S120 -> 47792 | K34: =Model!U120 -> 53757 | L34: =Model!V120 -> 62511.832 | M34: =Model!W120 -> 68333.224 | N34: =Model!X120 -> 71873.755 | O34: =Model!Z120 -> 75720.922 | P34: =Model!AA120 -> 86701.19 | Q34: =Model!AB120 -> 90740.151 | R34: =Model!AC120 -> 93787.34 | T34: =Model!J120 -> 46596 | U34: =Model!O120 -> 40640 | V34: =Model!T120 -> 47792 | W34: =Model!Y120 -> 71873.755 | X34: =Model!AD120 -> 93787.34 | Y34: =Model!AE120 -> 109956.47 | Z34: =Model!AF120 -> 133376.01 | AA34: =Model!AG120 -> 156792.61
C35: =Model!C121 -> Card Member Recievables | G35: =Model!P121 -> 58355 | H35: =Model!Q121 -> 59405 | I35: =Model!R121 -> 60823 | J35: =Model!S121 -> 61851 | K35: =Model!U121 -> 0 | L35: =Model!V121 -> 65187.609 | M35: =Model!W121 -> 65999.733 | N35: =Model!X121 -> 68367.792 | O35: =Model!Z121 -> 68934.04 | P35: =Model!AA121 -> 71974.24 | Q35: =Model!AB121 -> 72904.315 | R35: =Model!AC121 -> 75581.975 | T35: =Model!J121 -> 60237 | U35: =Model!O121 -> 59240 | V35: =Model!T121 -> 61851 | W35: =Model!Y121 -> 68367.792 | X35: =Model!AD121 -> 75581.975 | Y35: =Model!AE121 -> 77690.805 | Z35: =Model!AF121 -> 83130.017 | AA35: =Model!AG121 -> 87909.25
C36: =Model!C122 -> Inventory | G36: =Model!P122 -> 0 | H36: =Model!Q122 -> 0 | I36: =Model!R122 -> 0 | J36: =Model!S122 -> 0 | K36: =Model!U122 -> 0 | L36: =Model!V122 -> 0 | M36: =Model!W122 -> 0 | N36: =Model!X122 -> 0 | O36: =Model!Z122 -> 0 | P36: =Model!AA122 -> 0 | Q36: =Model!AB122 -> 0 | R36: =Model!AC122 -> 0 | T36: =Model!J122 -> 0 | U36: =Model!O122 -> 0 | V36: =Model!T122 -> 0 | W36: =Model!Y122 -> 0 | X36: =Model!AD122 -> 0 | Y36: =Model!AE122 -> 0 | Z36: =Model!AF122 -> 0 | AA36: =Model!AG122 -> 0
C37: =Model!C123 -> Prepaid & Other Current Assets | G37: =Model!P123 -> 0 | H37: =Model!Q123 -> 0 | I37: =Model!R123 -> 0 | J37: =Model!S123 -> 0 | K37: =Model!U123 -> 0 | L37: =Model!V123 -> 0 | M37: =Model!W123 -> 0 | N37: =Model!X123 -> 0 | O37: =Model!Z123 -> 0 | P37: =Model!AA123 -> 0 | Q37: =Model!AB123 -> 0 | R37: =Model!AC123 -> 0 | T37: =Model!J123 -> 0 | U37: =Model!O123 -> 0 | V37: =Model!T123 -> 0 | W37: =Model!Y123 -> 0 | X37: =Model!AD123 -> 0 | Y37: =Model!AE123 -> 0 | Z37: =Model!AF123 -> 0 | AA37: =Model!AG123 -> 0
C38: =Model!C124 -> Total Current Assets | G38: =SUM(G34:G37) -> 110863 | H38: =SUM(H34:H37) -> 117342 | I38: =SUM(I34:I37) -> 115529 | J38: =SUM(J34:J37) -> 109643 | K38: =SUM(K34:K37) -> 53757 | L38: =SUM(L34:L37) -> 130021.56 | M38: =SUM(M34:M37) -> 136376.52 | N38: =SUM(N34:N37) -> 142683.43 | ... R38: =SUM(R34:R37) -> 172103.87 | T38: =SUM(T34:T37) -> 106833 | U38: =SUM(U34:U37) -> 99880 | V38: =SUM(V34:V37) -> 109643 | W38: =SUM(W34:W37) -> 142683.43 | X38: =SUM(X34:X37) -> 172103.87 | Y38: =SUM(Y34:Y37) -> 190432.66 | Z38: =SUM(Z34:Z37) -> 219470.06 | AA38: =SUM(AA34:AA37) -> 247832.14
C40: =Model!C126 -> PP&E, Net | G40: =Model!P126 -> 5383 | H40: =Model!Q126 -> 5662 | I40: =Model!R126 -> 5861 | J40: =Model!S126 -> 6118 | K40: =Model!U126 -> 7240 | L40: =Model!V126 -> 7301.1875 | M40: =Model!W126 -> 7307.8291 | N40: =Model!X126 -> 7311.6494 | O40: =Model!Z126 -> 7359.7467 | P40: =Model!AA126 -> 7384.4761 | Q40: =Model!AB126 -> 7397.0644 | R40: =Model!AC126 -> 7482.8915 | T40: =Model!J126 -> 5138 | U40: =Model!O126 -> 5371 | V40: =Model!T126 -> 6118 | W40: =Model!Y126 -> 7311.6494 | X40: =Model!AD126 -> 7482.8915 | Y40: =Model!AE126 -> 7457.7097 | Z40: =Model!AF126 -> 8136.4861 | AA40: =Model!AG126 -> 8458.2493
C41: =Model!C127 -> Card Member Loans | G41: =Model!P127 -> 134387 | H41: =Model!Q127 -> 138913 | I41: =Model!R127 -> 141370 | J41: =Model!S127 -> 148380 | K41: =Model!U127 -> 209724 | L41: =Model!V127 -> 209724 | M41: =Model!W127 -> 209724 | N41: =Model!X127 -> 209724 | O41: =Model!Z127 -> 209724 | P41: =Model!AA127 -> 209724 | Q41: =Model!AB127 -> 209724 | R41: =Model!AC127 -> 209724 | T41: =Model!J127 -> 120877 | U41: =Model!O127 -> 134753 | V41: =Model!T127 -> 148380 | W41: =Model!Y127 -> 209724 | X41: =Model!AD127 -> 209724 | Y41: =Model!AE127 -> 209724 | Z41: =Model!AF127 -> 209724 | AA41: =Model!AG127 -> 209724
C42: =Model!C128 -> Investment Securities | G42: =Model!P128 -> 1110 | H42: =Model!Q128 -> 1258 | I42: =Model!R128 -> 1374 | J42: =Model!S128 -> 1043 | K42: =Model!U128 -> 2625 | L42: =Model!V128 -> 2625 | M42: =Model!W128 -> 2625 | N42: =Model!X128 -> 2625 | O42: =Model!Z128 -> 2625 | P42: =Model!AA128 -> 2625 | Q42: =Model!AB128 -> 2625 | R42: =Model!AC128 -> 2625 | T42: =Model!J128 -> 2186 | U42: =Model!O128 -> 1240 | V42: =Model!T128 -> 1043 | W42: =Model!Y128 -> 2625 | X42: =Model!AD128 -> 2625 | Y42: =Model!AE128 -> 2625 | Z42: =Model!AF128 -> 2625 | AA42: =Model!AG128 -> 2625
C43: =Model!C129 -> Other Assets and Loans | G43: =Model!P129 -> 30501 | H43: =Model!Q129 -> 32381 | I43: =Model!R129 -> 33416 | J43: =Model!S129 -> 34868 | K43: =Model!U129 -> 35548 | L43: =Model!V129 -> 37041.016 | M43: =Model!W129 -> 38226.329 | N43: =Model!X129 -> 39564.25 | O43: =Model!Z129 -> 41265.513 | P43: =Model!AA129 -> 42668.54 | Q43: =Model!AB129 -> 43991.265 | R43: =Model!AC129 -> 45574.95 | T43: =Model!J129 -> 26074 | U43: =Model!O129 -> 30217 | V43: =Model!T129 -> 34868 | W43: =Model!Y129 -> 39564.25 | X43: =Model!AD129 -> 45574.95 | Y43: =Model!AE129 -> 52183.318 | Z43: =Model!AF129 -> 59488.983 | AA43: =Model!AG129 -> 67519.996
C44: =Model!C130 -> Total Non-Current Assets | G44: =SUM(G40:G43) -> 171381 | H44: =SUM(H40:H43) -> 178214 | I44: =SUM(I40:I43) -> 182021 | J44: =SUM(J40:J43) -> 190409 | K44: =SUM(K40:K43) -> 255137 | L44: =SUM(L40:L43) -> 256691.2 | M44: =SUM(M40:M43) -> 257883.16 | N44: =SUM(N40:N43) -> 259224.9 | ... R44: =SUM(R40:R43) -> 265406.84 | T44: =SUM(T40:T43) -> 154275 | U44: =SUM(U40:U43) -> 171581 | V44: =SUM(V40:V43) -> 190409 | W44: =SUM(W40:W43) -> 259224.9 | X44: =SUM(X40:X43) -> 265406.84 | Y44: =SUM(Y40:Y43) -> 271990.03 | Z44: =SUM(Z40:Z43) -> 279974.47 | AA44: =SUM(AA40:AA43) -> 288327.24
C46: =Model!C132 -> Total Assets | G46: =SUM(G38,G44) -> 282244 | H46: =SUM(H38,H44) -> 295556 | I46: =SUM(I38,I44) -> 297550 | J46: =SUM(J38,J44) -> 300052 | K46: =SUM(K38,K44) -> 308894 | L46: =SUM(L38,L44) -> 324124.25 | M46: =SUM(M38,M44) -> 331797.2 | N46: =SUM(N38,N44) -> 339572.74 | ... R46: =SUM(R38,R44) -> 375650.22 | T46: =SUM(T38,T44) -> 261108 | U46: =SUM(U38,U44) -> 271461 | V46: =SUM(V38,V44) -> 300052 | W46: =SUM(W38,W44) -> 339572.74 | X46: =SUM(X38,X44) -> 375650.22 | Y46: =SUM(Y38,Y44) -> 400998.54 | Z46: =SUM(Z38,Z44) -> 438435.08 | AA46: =SUM(AA38,AA44) -> 475528.32
C48: =Model!C134 -> Accounts Payable | G48: =Model!P134 -> 13564 | H48: =Model!Q134 -> 14121 | I48: =Model!R134 -> 14708 | J48: =Model!S134 -> 14700 | K48: =Model!U134 -> 14635 | L48: =Model!V134 -> 14428.191 | M48: =Model!W134 -> 14712.117 | N48: =Model!X134 -> 15109.282 | O48: =Model!Z134 -> 15534.362 | P48: =Model!AA134 -> 16109.505 | Q48: =Model!AB134 -> 16204.36 | R48: =Model!AC134 -> 16771.668 | T48: =Model!J134 -> 13109 | U48: =Model!O134 -> 13884 | V48: =Model!T134 -> 14700 | W48: =Model!Y134 -> 15109.282 | X48: =Model!AD134 -> 16771.668 | Y48: =Model!AE134 -> 16778.777 | Z48: =Model!AF134 -> 17906.313 | AA48: =Model!AG134 -> 18989.212
C49: =Model!C135 -> Customer Deposits | G49: =Model!P135 -> 146396 | H49: =Model!Q135 -> 149386 | I49: =Model!R135 -> 149883 | J49: =Model!S135 -> 152488 | K49: =Model!U135 -> 157948 | L49: =Model!V135 -> 162969.02 | M49: =Model!W135 -> 165395.33 | N49: =Model!X135 -> 171261.32 | O49: =Model!Z135 -> 173024.44 | P49: =Model!AA135 -> 181087.19 | Q49: =Model!AB135 -> 183864.68 | R49: =Model!AC135 -> 190466.58 | T49: =Model!J135 -> 129144 | U49: =Model!O135 -> 139413 | V49: =Model!T135 -> 152488 | W49: =Model!Y135 -> 171261.32 | X49: =Model!AD135 -> 190466.58 | Y49: =Model!AE135 -> 196557.74 | Z49: =Model!AF135 -> 211150.24 | AA49: =Model!AG135 -> 224168.59
C50: =Model!C136 -> Other Current Liabilities | G50: =Model!P136 -> 0 | H50: =Model!Q136 -> 0 | I50: =Model!R136 -> 0 | J50: =Model!S136 -> 0 | K50: =Model!U136 -> 0 | L50: =Model!V136 -> 0 | M50: =Model!W136 -> 0 | N50: =Model!X136 -> 0 | O50: =Model!Z136 -> 0 | P50: =Model!AA136 -> 0 | Q50: =Model!AB136 -> 0 | R50: =Model!AC136 -> 0 | T50: =Model!J136 -> 0 | U50: =Model!O136 -> 0 | V50: =Model!T136 -> 0 | W50: =Model!Y136 -> 0 | X50: =Model!AD136 -> 0 | Y50: =Model!AE136 -> 0 | Z50: =Model!AF136 -> 0 | AA50: =Model!AG136 -> 0
C51: =Model!C137 -> Total Current Liabilities (Excl. Debt) | G51: =SUM(G48:G50) -> 159960 | H51: =SUM(H48:H50) -> 163507 | I51: =SUM(I48:I50) -> 164591 | J51: =SUM(J48:J50) -> 167188 | K51: =SUM(K48:K50) -> 172583 | L51: =SUM(L48:L50) -> 177397.21 | M51: =SUM(M48:M50) -> 180107.45 | N51: =SUM(N48:N50) -> 186370.6 | ... R51: =SUM(R48:R50) -> 207238.24 | T51: =SUM(T48:T50) -> 142253 | U51: =SUM(U48:U50) -> 153297 | V51: =SUM(V48:V50) -> 167188 | W51: =SUM(W48:W50) -> 186370.6 | X51: =SUM(X48:X50) -> 207238.24 | Y51: =SUM(Y48:Y50) -> 213336.51 | Z51: =SUM(Z48:Z50) -> 229056.56 | AA51: =SUM(AA48:AA50) -> 243157.8
C53: =Model!C139 -> Short-term Borrowings | G53: =Model!P139 -> 1559 | H53: =Model!Q139 -> 1493 | I53: =Model!R139 -> 1446 | J53: =Model!S139 -> 1371 | K53: =Model!U139 -> 1692 | L53: =Model!V139 -> 0 | M53: =Model!W139 -> 0 | N53: =Model!X139 -> 0 | O53: =Model!Z139 -> 0 | P53: =Model!AA139 -> 0 | Q53: =Model!AB139 -> 0 | R53: =Model!AC139 -> 0 | T53: =Model!J139 -> 1293 | U53: =Model!O139 -> 1374 | V53: =Model!T139 -> 1371 | W53: =Model!Y139 -> 0 | X53: =Model!AD139 -> 0 | Y53: =Model!AE139 -> 0 | Z53: =Model!AF139 -> 0 | AA53: =Model!AG139 -> 0
...

Sheet Model Output
B1: =Company_Name&" "&"("&Ticker&")"&" Valuation Overview" -> American Express Company (AXP) Valuation Overview | K1: Price Target Scenario: | N1: =Case_Scenario&" Case" -> Base Case | R1: Base Case Check | S1: =IF(N1="Base Case","","Check!") | Y1: P/E
B2: =Cover!C2 -> $ in Millions Except Per Share Data | K2: Current Share Price: | O2: =Share_Price -> 314.89 | Y2: EV/EBITDA
K3: Valuation Date: | O3: =Current_Date -> 46147
B4: ="Multiples Analysis "&"("&S21&")" -> Multiples Analysis (P/E) | I4: Return Summary
I6: Exit Multiple Method
I7: =Cover!I9 -> Implied Enterprise Value: | N7: =Cover!L9 -> 296624.47
I8: =Cover!I10 -> Implied Equity Value: | N8: =Cover!L10 -> 0
I9: =Cover!I12 -> Implied Share Price: | N9: =Cover!L12 -> 0
I10: =Cover!I13 -> % Return: | N10: =Cover!L13 -> 0
I12: =Cover!I15 -> Perpetuity Growth Method
I13: =Cover!I16 -> Implied Enterprise Value: | N13: =Cover!L16 -> 10375.823
I14: =Cover!I17 -> Implied Equity Value: | N14: =Cover!L17 -> 0
I15: =Cover!I19 -> Implied Share Price: | N15: =Cover!L19 -> 0
I16: =Cover!I20 -> % Return: | N16: =Cover!L20 -> 0
E18: Annuals | M18: CAGR | O18: CAGR
B19: Consolidated Financials | E19: =Summary!U6 -> 2024 | F19: =Summary!V6 -> 2025 | G19: =Summary!W6 -> 2026e | H19: =Summary!X6 -> 2027e | I19: =Summary!Y6 -> 2028e | J19: =Summary!Z6 -> 2029e | K19: =Summary!AA6 -> 2030e | M19: Historical | O19: Projected
B21: =Summary!C8 -> Revenue | D21: =Summary!T8 -> 67364 | E21: =Summary!U8 -> 74201 | F21: =Summary!V8 -> 80463 | G21: =Summary!W8 -> 88057.042 | H21: =Summary!X8 -> 97549.504 | I21: =Summary!Y8 -> 104638.91 | J21: =Summary!Z8 -> 111964.78 | K21: =Summary!AA8 -> 118840.28 | M21: =Summary!AC8 -> 0.092909439 | O21: =Summary!AE8 -> 0.081118978 | R21: Multiple Toggle | S21: P/E
B22: =Summary!C9 -> YoY % Growth | E22: =Summary!U9 -> 0.10149338 | F22: =Summary!V9 -> 0.084392394 | G22: =Summary!W9 -> 0.094379309 | H22: =Summary!X9 -> 0.107799 | I22: =Summary!Y9 -> 0.072674931 | J22: =Summary!Z9 -> 0.070011007 | K22: =Summary!AA9 -> 0.061407704
R23: Multiples Analysis | S23: EV/EBITDA | T23: P/E | U23: Chart
B24: =Summary!C11 -> Gross Profit | D24: =Summary!T11 -> 55592 | E24: =Summary!U11 -> 60764 | F24: =Summary!V11 -> 66973 | G24: =Summary!W11 -> 74593.624 | H24: =Summary!X11 -> 84356.371 | I24: =Summary!Y11 -> 91504.218 | J24: =Summary!Z11 -> 98291.244 | K24: =Summary!AA11 -> 104639.02 | M24: =Summary!AC11 -> 0.097599062 | O24: =Summary!AE11 -> 0.093348923 | R24: Entry Multiple | S24: =Valuation!D12 -> 16.606971 | T24: =Valuation!D11 -> 16.643764 | U24: =IF($S$21=$S$23,S24,T24) -> 16.643764
B25: =Summary!C12 -> % Margin | E25: =Summary!U12 -> 0.8189108 | F25: =Summary!V12 -> 0.8323453 | G25: =Summary!W12 -> 0.84710571 | H25: =Summary!X12 -> 0.86475448 | I25: =Summary!Y12 -> 0.87447605 | J25: =Summary!Z12 -> 0.87787643 | K25: =Summary!AA12 -> 0.88050127 | R25: =Model!Y25 -> 2026e | S25: =(Comparables!H10*S30)/(Model!Y61) -> 11.966599 | T25: =(Comparables!$G$10*S30)/Summary!W19 -> 16.273031 | U25: =IF($S$21=$S$23,S25,T25) -> 16.273031
B26: =Summary!C13 -> YoY % Growth | E26: =Summary!U13 -> 0.093034969 | F26: =Summary!V13 -> 0.10218221 | G26: =Summary!W13 -> 0.1137865 | H26: =Summary!X13 -> 0.13087911 | I26: =Summary!Y13 -> 0.084733939 | J26: =Summary!Z13 -> 0.074171722 | K26: =Summary!AA13 -> 0.064581294 | R26: =Summary!AA6 -> 2030e | S26: =(Comparables!H10*S30)/(Model!AG61) -> 7.450621 | T26: =(Comparables!$G$10*S30)/Summary!AA19 -> 9.7731994 | U26: =IF($S$21=$S$23,S26,T26) -> 9.7731994
R27: Exit Multiple | S27: =Valuation!K52 -> 18 | T27: =Valuation!K64/Summary!AA19 -> 0 | U27: =IF($S$21=$S$23,S27,T27) -> 0
B28: =Summary!C27 -> EBITDA | D28: =Summary!T27 -> 12164 | E28: =Summary!U27 -> 14571 | F28: =Summary!V27 -> 15572 | G28: =Summary!W27 -> 18277.747 | H28: =Summary!X27 -> 22207.775 | I28: =Summary!Y27 -> 25108.645 | J28: =Summary!Z27 -> 27242.601 | K28: =Summary!AA27 -> 29356.275 | M28: =Summary!AC27 -> 0.13144642 | O28: =Summary!AE27 -> 0.1351972 | R28: Implied PGM | S28: =Valuation!K71 -> 0 | T28: =Valuation!R64/Summary!AA19 -> 0 | U28: =IF($S$21=$S$23,S28,T28) -> 0
B29: =Summary!C28 -> Margin | E29: =Summary!U28 -> 0.19637202 | F29: =Summary!V28 -> 0.19352995 | G29: =Summary!W28 -> 0.20756713 | H29: =Summary!X28 -> 0.22765646 | I29: =Summary!Y28 -> 0.23995515 | J29: =Summary!Z28 -> 0.24331402 | K29: =Summary!AA28 -> 0.24702293
B30: =Summary!C29 -> YoY % Growth | E30: =Summary!U17 -> 0.22657662 | F30: =Summary!V17 -> 0.069794494 | G30: =Summary!W29 -> 0.17375722 | H30: =Summary!X29 -> 0.21501706 | I30: =Summary!Y29 -> 0.13062405 | J30: =Summary!Z29 -> 0.08498893 | K30: =Summary!AA29 -> 0.077587067 | R30: Financials Multiplier | S30: =IF($B$2="$ in Millions Except Per Share Data",1,IF($B$2="$ in Thousands Except Per Share Data",1000,IF($B$2="$ in Billions Except Per Share Data",0.001,0))) -> 1
B32: =Summary!C19 -> Net Income (Loss) | D32: =Summary!T19 -> 8374 | E32: =Summary!U19 -> 10129 | F32: =Summary!V19 -> 10833 | G32: =Summary!W19 -> 12650.378 | H32: =Summary!X19 -> 15616.162 | I32: =Summary!Y19 -> 17841.062 | J32: =Summary!Z19 -> 19545.188 | K32: =Summary!AA19 -> 21063.727 | M32: =Summary!AC19 -> 0.13738604 | O32: =Summary!AE19 -> 0.14223981
B33: =Summary!C20 -> Margin | E33: =Summary!U20 -> 0.13650759 | F33: =Summary!V20 -> 0.13463331 | G33: =Summary!W20 -> 0.14366118 | H33: =Summary!X20 -> 0.16008448 | I33: =Summary!Y20 -> 0.17050122 | J33: =Summary!Z20 -> 0.1745655 | K33: =Summary!AA20 -> 0.177244
B34: =Summary!C21 -> YoY % Growth | E34: =Summary!U21 -> 0.20957726 | F34: =Summary!V21 -> 0.069503406 | G34: =Summary!W21 -> 0.16776315 | H34: =Summary!X21 -> 0.2344423 | I34: =Summary!Y21 -> 0.14247417 | J34: =Summary!Z21 -> 0.095517096 | K34: =Summary!AA21 -> 0.077693724
B36: =Summary!C23 -> Adj. EPS (Diluted) | D36: =Summary!T23 -> 11.565217 | E36: =Summary!U23 -> 13.753156 | F36: =Summary!V23 -> 15.734195 | G36: =Summary!W23 -> 18.405216 | H36: =Summary!X23 -> 22.840765 | I36: =Summary!Y23 -> 26.164702 | J36: =Summary!Z23 -> 28.740459 | K36: =Summary!AA23 -> 31.056162 | M36: =Summary!AC23 -> 0.16639425 | O36: =Summary!AE23 -> 0.14567293
B37: =Summary!C24 -> YoY % Growth | E37: =Summary!U24 -> 0.18918263 | F37: =Summary!V24 -> 0.14404256 | G37: =Summary!W24 -> 0.16975898 | H37: =Summary!X24 -> 0.24099412 | I37: =Summary!Y24 -> 0.1455265 | J37: =Summary!Z24 -> 0.098443959 | K37: =Summary!AA24 -> 0.080572957
B39: Free Cash Flow | D39: =Model!J112 -> 10845 | E39: =Model!O112 -> 11666 | F39: =Model!T112 -> 8390 | G39: =Model!Y112 -> 5790.2185 | H39: =Model!AD112 -> 9893.1237 | I39: =Model!AE112 -> 15764.522 | J39: =Model!AF112 -> 14554.736 | K39: =Model!AG112 -> 17045.629 | M39: =IFERROR((F39/D39)^(1/2)-1,"N/A") -> -0.12043852 | O39: =IFERROR((K39/G39)^(1/4)-1,"N/A") -> 0.30987399
B40: YoY % Growth | E40: =E39/D39-1 -> 0.075703089 | F40: =F39/E39-1 -> -0.28081605 | G40: =G39/F39-1 -> -0.30986668 | H40: =H39/G39-1 -> 0.70859245 | I40: =I39/H39-1 -> 0.59348276 | J40: =J39/I39-1 -> -0.076741054 | K40: =K39/J39-1 -> 0.17113967
E42: Annuals | M42: Average | O42: Average
B43: Capitalization and Key Ratios | E43: =E19 -> 2024 | F43: =F19 -> 2025 | G43: =G19 -> 2026e | H43: =H19 -> 2027e | I43: =I19 -> 2028e | J43: =J19 -> 2029e | K43: =K19 -> 2030e | M43: Historical | O43: Projected
B44: =Summary!C91 -> Leverage
B45: =Summary!C92 -> Total Debt / EBITDA | D45: =Summary!T92 -> 4.0413515 | E45: =Summary!U92 -> 3.506211 | F45: =Summary!V92 -> 3.7090932 | G45: =Summary!W92 -> 3.2971494 | H45: =Summary!X92 -> 2.7187806 | I45: =Summary!Y92 -> 2.5549035 | J45: =Summary!Z92 -> 2.4978164 | K45: =Summary!AA92 -> 2.4457359 | M45: =AVERAGE(D45:F45) -> 3.7522186 | O45: =AVERAGE(G45:K45) -> 2.7028772
B46: =Summary!C93 -> Total Debt / Equity | D46: =Summary!T93 -> 1.7521118 | E46: =Summary!U93 -> 1.6881113 | F46: =Summary!V93 -> 1.7254586 | G46: =Summary!W93 -> 1.404809 | H46: =Summary!X93 -> 1.1002183 | I46: =Summary!Y93 -> 0.92478632 | J46: =Summary!Z93 -> 0.79519722 | K46: =Summary!AA93 -> 0.69545426 | M46: =AVERAGE(D46:F46) -> 1.7218939 | O46: =AVERAGE(G46:K46) -> 0.98409303
B47: =Summary!C94 -> Total Debt / Total Assets | D47: =Summary!T94 -> 0.18827075 | E47: =Summary!U94 -> 0.18820015 | F47: =Summary!V94 -> 0.1924933 | G47: =Summary!W94 -> 0.18048269 | H47: =Summary!X94 -> 0.16634357 | I47: =Summary!Y94 -> 0.1658036 | J47: =Summary!Z94 -> 0.16122569 | K47: =Summary!AA94 -> 0.1570611 | M47: =AVERAGE(D47:F47) -> 0.18965473 | O47: =AVERAGE(G47:K47) -> 0.16618333
B49: =Summary!C103 -> Liquidity
...

Sheet Football Field
C1: =Company_Name&" - "&MID(CELL("filename",A1),FIND("]",CELL("filename",A1))+1,255)&": "&Case_Scenario&" Case" -> American Express Company - Football Field: Base Case
C2: =Cover!C2 -> $ in Millions Except Per Share Data
A4: x | O4: Valuation Method: | T4: Downside | U4: Delta | V4: Upside | W4: x
O5: =TEXT(Valuation!E100,"0.0%")&" - "&TEXT(Valuation!E102,"0.0%")&" WACC"&" & "&TEXT(Valuation!G98,"0.0%")&" - "&TEXT(Valuation!I98,"0.0%")&" PGR" -> 7.7% - 8.7% WACC & 1.5% - 2.5% PGR | T5: =Valuation!G100 -> 195.04955 | U5: =V5-T5 -> 20.385916 | V5: =Valuation!I102 -> 215.43546
O6: =TEXT(Valuation!E92,"0.0%")&" - "&TEXT(Valuation!E94,"0.0%")&" WACC"&" & "&TEXT(Valuation!G90,"0.0x")&" - "&TEXT(Valuation!I90,"0.0x")&" Exit Multiple" -> 7.7% - 8.7% WACC & 17.0x - 19.0x Exit Multiple | T6: =Valuation!G92 -> 250.78262 | U6: =V6-T6 -> 27.264041 | V6: =Valuation!I94 -> 278.04666
O8: =Valuation!F176&": "&TEXT(Valuation!G177,"0.0x")&" - "&TEXT(Valuation!I177,"0.0x") -> NTM EV/EBITDA Spread to Comps: 9.9x - 11.9x | T8: =Valuation!G179 -> 209.23348 | U8: =V8-T8 -> 100.49025 | V8: =Valuation!I181 -> 309.72373
O9: =Valuation!F168&": "&TEXT(Valuation!G169,"0.0x")&" - "&TEXT(Valuation!I169,"0.0x") -> NTM EV/EBITDA: 11.5x - 13.5x | T9: =Valuation!G171 -> 197.97414 | U9: =V9-T9 -> 97.988172 | V9: =Valuation!I173 -> 295.96231
O10: =Valuation!F160&": "&TEXT(Valuation!G161,"0.0x")&" - "&TEXT(Valuation!I161,"0.0x") -> NTM P/E Spread to Comps: 16.3x - 18.3x | T10: =Valuation!G163 -> 271.58666 | U10: =V10-T10 -> 101.0125 | V10: =Valuation!I165 -> 372.59916
O11: =Valuation!F152&": "&TEXT(Valuation!G153,"0.0x")&" - "&TEXT(Valuation!I153,"0.0x") -> NTM P/E: 18.6x - 20.6x | T11: =Valuation!G155 -> 309.49702 | U11: =V11-T11 -> 109.43703 | V11: =Valuation!I157 -> 418.93405
O13: =Valuation!F252&": "&TEXT(Valuation!G253,"0.0x")&" - "&TEXT(Valuation!I253,"0.0x") -> 2009-2018 Early Cycle EV/EBITDA Spread to Comps: 12.5x - 14.5x | T13: =Valuation!G255 -> 202.21364 | U13: =V13-T13 -> 39.300331 | V13: =Valuation!I255 -> 241.51397
O14: =Valuation!F244&": "&TEXT(Valuation!G245,"0.0x")&" - "&TEXT(Valuation!I245,"0.0x") -> 2009-2018 Early Cycle EV/EBITDA: 14.8x - 16.8x | T14: =Valuation!G247 -> 99.103102 | U14: =V14-T14 -> 39.300331 | V14: =Valuation!I247 -> 138.40343
O15: =Valuation!F236&": "&TEXT(Valuation!G237,"0.0x")&" - "&TEXT(Valuation!I237,"0.0x") -> 2009-2018 Early Cycle P/E Spread to Comps: 16.1x - 18.1x | T15: =Valuation!G239 -> 267.04261 | U15: =V15-T15 -> 26.408301 | V15: =Valuation!I239 -> 293.45091
O16: =Valuation!F228&": "&TEXT(Valuation!G229,"0.0x")&" - "&TEXT(Valuation!I229,"0.0x") -> 2009-2018 Early Cycle P/E: 13.1x - 15.1x | T16: =Valuation!G231 -> 205.30919 | U16: =V16-T16 -> 26.408301 | V16: =Valuation!I231 -> 231.71749
O18: 52-Week Price Range: | T18: =Share_Price_Low -> 273.61 | U18: =V18-T18 -> 113.88 | V18: =Share_Price_High -> 387.49
O19: Median Value: | T19: =MEDIAN(T5:T18) -> 209.23348 | U19: =MEDIAN(U5:U18) -> 39.300331 | V19: =MEDIAN(V5:V18) -> 293.45091
A20: x | O20: Implied Return (%): | T20: =T19/Share_Price-1 -> -0.33553469 | V20: =V19/Share_Price-1 -> -0.068084383
T22: Reference Points for Price Axis
U24: Price
A25: x | T25: High | U25: =MAX(V5:V18)*1.1 -> 460.82745 | W25: x
T26: Low | U26: =MIN(T5:T18)*0.9 -> 89.192792
A30: x

Sheet Integrity
C1: =Company_Name&" - "&MID(CELL("filename",A1),FIND("]",CELL("filename",A1))+1,255) -> American Express Company - Integrity
C3: Integrity
C4: Metric
C6: Model:
C7: Balance Sheet Check: | D7: =SUM(Model!F158:AG158) -> 0
C8: Base Case: | D8: =IF(Case_Scenario="Base","OK!","Check!") -> OK!
C9: Interest Expense: | D9: =IF(Model!C8="On","OK!","CHECK - OFF") -> OK!
C10: Valuation Date:
C12: Formatting:
C13: Valuation Sensitivity Tables: | D13: =SUM(Valuation!F84,Valuation!K84,Valuation!P84,Valuation!F143:F147,Valuation!L143:L147,Valuation!F219:F223,Valuation!L219:L223) -> 0
C14: WACC Tables: | D14: =SUM(WACC!Q20,WACC!N33:N37) -> 0
C16: Font Toggles:
C17: Cover: | D17: =Cover!$Q$2 -> Report
C18: Revenue Build: | D18: ='Revenue Build'!$C$22 -> Report
C19: Model: | D19: =Model!$C$5 -> Report
C20: WACC | D20: =WACC!R5 -> Report
C21: Valuation: | D21: =Valuation!$R$2 -> Report
C23: Change Log
C24: Date | D24: Version | E24: Operator | F24: Revisions
C25: 44476 | D25: v01 | E25: Nate Latimer | F25: Top Down / Bottom Up toggle integration and Capital IQ comps sheet w/ ID Locator
C26: 44476 | D26: v02 | E26: Carson Shaner | F26: Formulas for EBIT/EBITDA margins on earnings sheets
C27: 44480 | D27: v03 | E27: Nate Latimer | F27: Historical driver adjustments to reflect Top Down / Bottom Up Toggle
C28: 44488 | D28: v04 | E28: Nate Latimer | F28: Bug fixes to model output, comps sheet and WACC Comps Relevered Beta
C29: 44489 | D29: v05 | E29: Lilianna Ruby | F29: Changed the year end driver in 2021 and 2022 to correctly pull operating margins
C30: 44491 | D30: v06 | E30: Lilianna Ruby | F30: Changed the first page to add 365 to your previous fiscal year
C31: 44496 | D31: v07 | E31: Carson Shaner | F31: Changed Model Output FCF formula, broke apart D&A for historical periods, added checks for EPS & EBITDA in Valuation sensitivity tables, added segment D&A breakdown, linked and fixed SOTP valuation
C32: 44503 | D32: v08 | E32: Lilianna Ruby | F32: Changed average of comps on valuation tab to average all peers not just the first one
C33: 44512 | D33: v09 | E33: Lilianna Ruby | F33: Rolled model forward to reflect 3Q'21. Also changed the multiples tab so the quarters roll forward and end on correct date.
C34: 44522 | D34: v10 | E34: Lilianna Ruby | F34: Fully fixed the multiples tab so it is automatic and fully functional. Also fixed definition of NTM_EPS and NTM_EBITDA
C35: 44582 | D35: v13 | E35: Carson Shaner | F35: Changed EPS, EBITDA, shares, tax rate, etc., to formulas so we do not have to hardcode them.
C36: 44584 | D36: v14 | E36: Lilianna Ruby | F36: Changed discount factor to mid year
... C47: 45581 | D47: v25 | E47: Conor McCabe | F47: Added font toggle to integrity tab for WACC tab. Formatted Comparables Tab.

Sheet Revenue Build
C1: =Company_Name&" - "&MID(CELL("filename",A1),FIND("]",CELL("filename",A1))+1,255)&": "&Case_Scenario&" Case" -> American Express Company - Revenue Build: Base Case
C2: =Cover!C2 -> $ in Millions Except Per Share Data
A4: x | C4: Segments
C6: =C30&" Methodology" -> Total Company Revenue Methodology
C7: Segment
C8: =C33&" Methodology" -> Discount Revenue Methodology
C9: =IF(Company_Rev_Methodology="Segment","Segment",IF(Company_Rev_Methodology="Activity-Based","Activity-Based",IF(Company_Rev_Methodology="Backlog","Backlog",IF(Company_Rev_Methodology="Mixed",D9,"--")))) -> Segment | D9: Backlog
C10: =C41&" Methodology" -> Net Card Fees Revenue Methodology
C11: =IF(Company_Rev_Methodology="Segment","Segment",IF(Company_Rev_Methodology="Activity-Based","Activity-Based",IF(Company_Rev_Methodology="Backlog","Backlog",IF(Company_Rev_Methodology="Mixed",D11,"--")))) -> Segment | D11: Activity-Based
C12: =C45&" Methodology" -> Service Fees and Other Revenue Methodology
C13: =IF(Company_Rev_Methodology="Segment","Segment",IF(Company_Rev_Methodology="Activity-Based","Activity-Based",IF(Company_Rev_Methodology="Backlog","Backlog",IF(Company_Rev_Methodology="Mixed",D13,"--")))) -> Segment | D13: Segment
C14: =#REF!&" Methodology" -> #REF!
C15: =IF(Company_Rev_Methodology="Segment","Segment",IF(Company_Rev_Methodology="Activity-Based","Activity-Based",IF(Company_Rev_Methodology="Backlog","Backlog",IF(Company_Rev_Methodology="Mixed",D15,"--")))) -> Segment | D15: Segment
C16: =#REF!&" Methodology" -> #REF!
C17: =IF(Company_Rev_Methodology="Segment","Segment",IF(Company_Rev_Methodology="Activity-Based","Activity-Based",IF(Company_Rev_Methodology="Backlog","Backlog",IF(Company_Rev_Methodology="Mixed",D17,"--")))) -> Segment | D17: Segment
C18: =#REF!&" Methodology" -> #REF!
C19: =IF(Company_Rev_Methodology="Segment","Segment",IF(Company_Rev_Methodology="Activity-Based","Activity-Based",IF(Company_Rev_Methodology="Backlog","Backlog",IF(Company_Rev_Methodology="Mixed",D19,"--")))) -> Segment | D19: Segment
C21: Font Toggle
C22: Report
C24: Annual vs. Quarterly
C25: Quarterly
J26: 1 | O26: 2 | T26: 3 | Y26: 4 | AD26: 5 | AE26: 6 | AF26: 7 | AG26: 8
AI27: CAGR
A28: x | C28: Summary | F28: =Model!F$25 -> 1Q23 | G28: =Model!G$25 -> 2Q23 | H28: =Model!H$25 -> 3Q23 | I28: =Model!I$25 -> 4Q23 | J28: =Model!J$25 -> 2023 | K28: =Model!K$25 -> 1Q24 | L28: =Model!L$25 -> 2Q24 | M28: =Model!M$25 -> 3Q24 | ... AG28: =Model!AG$25 -> 2030e | AI28: Historical | AJ28: Projected
C30: Total Company Revenue | F30: ='Segment Analysis'!F7 -> 15714 | G30: ='Segment Analysis'!G7 -> 16724 | H30: ='Segment Analysis'!H7 -> 17179 | I30: ='Segment Analysis'!I7 -> 17747 | J30: ='Segment Analysis'!J7 -> 67364 | K30: ='Segment Analysis'!K7 -> 17807 | L30: ='Segment Analysis'!L7 -> 18397 | M30: ='Segment Analysis'!M7 -> 18779 | ... U30: ='Segment Analysis'!U7 -> 20880 | V30: =SUM(V33,V37,V41,V45) -> 21729.203 | W30: =SUM(W33,W37,W41,W45) -> 22323.439 | X30: =SUM(X33,X37,X41,X45) -> 23124.4 | Y30: =SUM(U30:X30) -> 88057.042 | Z30: =SUM(Z33,Z37,Z41,Z45) -> 23062.491 | AA30: =SUM(AA33,AA37,AA41,AA45) -> 24123.963 | AB30: =SUM(AB33,AB37,AB41,AB45) -> 24704.225 | AC30: =SUM(AC33,AC37,AC41,AC45) -> 25658.825 | AD30: =SUM(Z30:AC30) -> 97549.504 | AE30: =SUM(AE33,AE37,AE41,AE45) -> 104638.91 | AF30: =SUM(AF33,AF37,AF41,AF45) -> 111964.78 | AG30: =SUM(AG33,AG37,AG41,AG45) -> 118840.28 | AI30: =IFERROR((T30/J30)^(1/3)-1,"--") -> 0.06101808 | AJ30: =IFERROR((AG30/T30)^(1/5)-1,"--") -> 0.081118978
C31: =IF($C$25="Quarterly","% Growth QoQ","% Growth YoY") -> % Growth QoQ | G31: =IF($C$25="Annual",'Segment Analysis'!G145,'Segment Analysis'!G163) -> 0.064273896 | H31: =IF($C$25="Annual",'Segment Analysis'!H145,'Segment Analysis'!H163) -> 0.02720641 | I31: =IF($C$25="Annual",'Segment Analysis'!I145,'Segment Analysis'!I163) -> 0.033063624 | J31: =IF($C$25="Annual",'Segment Analysis'!J145,'Segment Analysis'!J145) -> 0 | K31: =IF($C$25="Annual",'Segment Analysis'!K145,'Segment Analysis'!K145) -> 0.13319333 | L31: =IF($C$25="Annual",'Segment Analysis'!L145,'Segment Analysis'!L145) -> 0.10003588 | M31: =IF($C$25="Annual",'Segment Analysis'!M145,'Segment Analysis'!M145) -> 0.09313697 | N31: =IF($C$25="Annual",'Segment Analysis'!N145,'Segment Analysis'!N145) -> 0.082887249 | O31: =IF($C$25="Annual",'Segment Analysis'!O145,'Segment Analysis'!O145) -> 0.10149338 | P31: =IF($C$25="Annual",'Segment Analysis'!P145,'Segment Analysis'!P145) -> 0.06323356 | Q31: =IF($C$25="Annual",'Segment Analysis'!Q145,'Segment Analysis'!Q145) -> 0.083491874 | ... U31: =IF($C$25="Annual",'Segment Analysis'!U145,'Segment Analysis'!U145) -> 0.10283632 | V31: =IFERROR(V30/U30-1,"--") -> 0.040670642 | W31: =IFERROR(W30/V30-1,"--") -> 0.027347342 | X31: =IFERROR(X30/W30-1,"--") -> 0.035879841 | Y31: =IFERROR(Y30/T30-1,"--") -> 0.094379309 | Z31: =IFERROR(Z30/X30-1,"--") -> -0.0026772245 | AA31: =IFERROR(AA30/Z30-1,"--") -> 0.046025884 | AB31: =IFERROR(AB30/AA30-1,"--") -> 0.02405334 | AC31: =IFERROR(AC30/AB30-1,"--") -> 0.038641194 | AD31: =IFERROR(AD30/Y30-1,"--") -> 0.107799 | AE31: =IFERROR(AE30/AD30-1,"--") -> 0.072674931 | AF31: =IFERROR(AF30/AE30-1,"--") -> 0.070011007 | AG31: =IFERROR(AG30/AF30-1,"--") -> 0.061407704
C33: ='Segment Analysis'!C8 -> Discount Revenue | F33: ='Segment Analysis'!F8 -> 7947 | G33: ='Segment Analysis'!G8 -> 8481 | H33: ='Segment Analysis'!H8 -> 8408 | I33: ='Segment Analysis'!I8 -> 8580 | J33: ='Segment Analysis'!J8 -> 33416 | K33: ='Segment Analysis'!K8 -> 8380 | L33: ='Segment Analysis'!L8 -> 8855 | M33: ='Segment Analysis'!M8 -> 8780 | ... U33: ='Segment Analysis'!U8 -> 9512 | V33: =IF(Segment1_Rev_Methodology="Segment",V51,IF(Segment1_Rev_Methodology="Activity-Based",#REF!,IF(Segment1_Rev_Methodology="Backlog",V147,"--"))) -> 10082.72 | W33: =IF(Segment1_Rev_Methodology="Segment",W51,IF(Segment1_Rev_Methodology="Activity-Based",#REF!,IF(Segment1_Rev_Methodology="Backlog",W147,"--"))) -> 10233.961 | X33: =IF(Segment1_Rev_Methodology="Segment",X51,IF(Segment1_Rev_Methodology="Activity-Based",#REF!,IF(Segment1_Rev_Methodology="Backlog",X147,"--"))) -> 10796.829 | Y33: =SUM(U33:X33) -> 40625.509 | Z33: =IF(Segment1_Rev_Methodology="Segment",Z51,IF(Segment1_Rev_Methodology="Activity-Based",#REF!,IF(Segment1_Rev_Methodology="Backlog",Z147,"--"))) -> 10688.86 | AA33: =IF(Segment1_Rev_Methodology="Segment",AA51,IF(Segment1_Rev_Methodology="Activity-Based",#REF!,IF(Segment1_Rev_Methodology="Backlog",AA147,"--"))) -> 11437.081 | AB33: =IF(Segment1_Rev_Methodology="Segment",AB51,IF(Segment1_Rev_Methodology="Activity-Based",#REF!,IF(Segment1_Rev_Methodology="Backlog",AB147,"--"))) -> 11665.822 | AC33: =IF(Segment1_Rev_Methodology="Segment",AC51,IF(Segment1_Rev_Methodology="Activity-Based",#REF!,IF(Segment1_Rev_Methodology="Backlog",AC147,"--"))) -> 12307.442 | AD33: =SUM(Z33:AC33) -> 46099.206 | AE33: =IF(Segment1_Rev_Methodology="Segment",AE51,IF(Segment1_Rev_Methodology="Activity-Based",#REF!,IF(Segment1_Rev_Methodology="Backlog",AE147,"--"))) -> 49326.15 | AF33: =IF(Segment1_Rev_Methodology="Segment",AF51,IF(Segment1_Rev_Methodology="Activity-Based",#REF!,IF(Segment1_Rev_Methodology="Backlog",AF147,"--"))) -> 52285.719 | AG33: =IF(Segment1_Rev_Methodology="Segment",AG51,IF(Segment1_Rev_Methodology="Activity-Based",#REF!,IF(Segment1_Rev_Methodology="Backlog",AG147,"--"))) -> 55422.862 | AI33: =IFERROR((T33/J33)^(1/3)-1,"--") -> 0.038268275 | AJ33: =IFERROR((AG33/T33)^(1/5)-1,"--") -> 0.081835297
C34: =IF($C$25="Quarterly","% Growth QoQ","% Growth YoY") -> % Growth QoQ | G34: =IF($C$25="Annual",'Segment Analysis'!G146,'Segment Analysis'!G164) -> 0.067195168 | H34: =IF($C$25="Annual",'Segment Analysis'!H146,'Segment Analysis'!H164) -> -0.0086074755 | I34: =IF($C$25="Annual",'Segment Analysis'!I146,'Segment Analysis'!I164) -> 0.020456708 | J34: =IF($C$25="Annual",'Segment Analysis'!J148,'Segment Analysis'!J148) -> 0 | K34: =IF($C$25="Annual",'Segment Analysis'!K146,'Segment Analysis'!K146) -> 0.05448597 | L34: =IF($C$25="Annual",'Segment Analysis'!L146,'Segment Analysis'!L146) -> 0.044098573 | M34: =IF($C$25="Annual",'Segment Analysis'!M146,'Segment Analysis'!M146) -> 0.044243578 | N34: =IF($C$25="Annual",'Segment Analysis'!N146,'Segment Analysis'!N146) -> 0.06958042 | O34: =IF($C$25="Annual",'Segment Analysis'!O146,'Segment Analysis'!O146) -> 0.053148192 | P34: =IF($C$25="Annual",'Segment Analysis'!P146,'Segment Analysis'!P146) -> 0.043317422 | Q34: =IF($C$25="Annual",'Segment Analysis'!Q146,'Segment Analysis'!Q146) -> 0.057142857 | R34: =IF($C$25="Annual",'Segment Analysis'!R146,'Segment Analysis'!R146) -> 0.072095672 | ... U34: =IF($C$25="Annual",'Segment Analysis'!U146,'Segment Analysis'!U146) -> 0.087956079 | V34: =IFERROR(V33/U33-1,"--") -> 0.06 | W34: =IFERROR(W33/V33-1,"--") -> 0.015 | X34: =IFERROR(X33/W33-1,"--") -> 0.055 | Y34: =IFERROR(Y33/T33-1,"--") -> 0.086214525 | Z34: =IFERROR(Z33/X33-1,"--") -> -0.01 | AA34: =IFERROR(AA33/Z33-1,"--") -> 0.07 | AB34: =IFERROR(AB33/AA33-1,"--") -> 0.02 | AC34: =IFERROR(AC33/AB33-1,"--") -> 0.055 | AD34: =IFERROR(AD33/Y33-1,"--") -> 0.13473545 | AE34: =IFERROR(AE33/AD33-1,"--") -> 0.07 | AF34: =IFERROR(AF33/AE33-1,"--") -> 0.06 | AG34: =IFERROR(AG33/AF33-1,"--") -> 0.06
C35: % of Total Revenue | F35: ='Segment Analysis'!F14 -> 0.50572738 | G35: ='Segment Analysis'!G14 -> 0.50711552 | H35: ='Segment Analysis'!H14 -> 0.48943478 | I35: ='Segment Analysis'!I14 -> 0.48346199 | J35: ='Segment Analysis'!J14 -> 0.4960513 | K35: ='Segment Analysis'!K14 -> 0.47060145 | L35: ='Segment Analysis'!L14 -> 0.48132848 | M35: ='Segment Analysis'!M14 -> 0.46754353 | ... U35: ='Segment Analysis'!U14 -> 0.45555556 | V35: =V33/V$30 -> 0.46401702 | W35: =W33/W$30 -> 0.45844015 | X35: =X33/X$30 -> 0.46690199 | Y35: =Y33/Y$30 -> 0.46135446 | Z35: =Z33/Z$30 -> 0.4634738 | AA35: =AA33/AA$30 -> 0.47409626 | AB35: =AB33/AB$30 -> 0.47221973 | AC35: =AC33/AC$30 -> 0.47965728 | ... AG35: =AG33/AG$30 -> 0.46636427
C37: ='Segment Analysis'!C11 -> Interest Income | F37: ='Segment Analysis'!F11 -> 4416 | G37: ='Segment Analysis'!G11 -> 4775 | H37: ='Segment Analysis'!H11 -> 5240 | I37: ='Segment Analysis'!I11 -> 5552 | J37: ='Segment Analysis'!J11 -> 19983 | K37: ='Segment Analysis'!K11 -> 5775 | L37: ='Segment Analysis'!L11 -> 5794 | M37: ='Segment Analysis'!M11 -> 6149 | ... U37: ='Segment Analysis'!U11 -> 6665 | V37: =V57 -> 6702.48 | W37: =W57 -> 6898.275 | X37: =X57 -> 6937.0668 | Y37: =SUM(U37:X37) -> 27202.822 | Z37: =Z57 -> 6930.1297 | AA37: =AA57 -> 6999.431 | AB37: =AB57 -> 7174.4168 | AC37: =AC57 -> 7353.7772 | AD37: =SUM(Z37:AC37) -> 28457.755 | AE37: =IF(Segment1_Rev_Methodology="Segment",AE57,IF(Segment1_Rev_Methodology="Activity-Based",#REF!,IF(Segment1_Rev_Methodology="Backlog",AE150,"--"))) -> 29738.354 | AF37: =IF(Segment1_Rev_Methodology="Segment",AF57,IF(Segment1_Rev_Methodology="Activity-Based",#REF!,IF(Segment1_Rev_Methodology="Backlog",AF150,"--"))) -> 31522.655 | AG37: =IF(Segment1_Rev_Methodology="Segment",AG57,IF(Segment1_Rev_Methodology="Activity-Based",#REF!,IF(Segment1_Rev_Methodology="Backlog",AG150,"--"))) -> 33571.628 | AI37: =IFERROR((T37/J37)^(1/3)-1,"--") -> 0.086046571 | AJ37: =IFERROR((AG37/T37)^(1/5)-1,"--") -> 0.055730996
C38: =IF($C$25="Quarterly","% Growth QoQ","% Growth YoY") -> % Growth QoQ | G38: =IF($C$25="Annual",'Segment Analysis'!G150,'Segment Analysis'!G167) -> 0 | H38: =IF($C$25="Annual",'Segment Analysis'!H150,'Segment Analysis'!H167) -> 0 | I38: =IF($C$25="Annual",'Segment Analysis'!I150,'Segment Analysis'!I167) -> 0 | J38: =IF($C$25="Annual",'Segment Analysis'!J152,'Segment Analysis'!J152) -> 0 | L38: =IF($C$25="Annual",'Segment Analysis'!L149,'Segment Analysis'!Q149) -> 0.081118398 | M38: =IF($C$25="Annual",'Segment Analysis'!M149,'Segment Analysis'!R149) -> 0.076109937 | N38: =IF($C$25="Annual",'Segment Analysis'!N149,'Segment Analysis'!S149) -> 0.083100214 | O38: =IF($C$25="Annual",'Segment Analysis'!O149,'Segment Analysis'!T149) -> 0.075772221 | P38: =IF($C$25="Annual",'Segment Analysis'!P149,'Segment Analysis'!U149) -> 0.086389568 | Q38: =IF($C$25="Annual",'Segment Analysis'!Q149,'Segment Analysis'!V149) -> 0.07 | R38: =IF($C$25="Annual",'Segment Analysis'!R149,'Segment Analysis'!W149) -> 0.042507934 | S38: =IF($C$25="Annual",'Segment Analysis'!S149,'Segment Analysis'!X149) -> 0.053945123 | ... U38: =IF($C$25="Annual",'Segment Analysis'!U149,'Segment Analysis'!Z149) -> 0.039779405 | V38: =IFERROR(V37/U37-1,"--") -> 0.0056234059 | W38: =IFERROR(W37/V37-1,"--") -> 0.029212321 | X38: =IFERROR(X37/W37-1,"--") -> 0.0056234059 | Y38: =IFERROR(Y37/T37-1,"--") -> 0.062693249 | Z38: =IFERROR(Z37/X37-1,"--") -> -0.001 | AA38: =IFERROR(AA37/Z37-1,"--") -> 0.01 | AB38: =IFERROR(AB37/AA37-1,"--") -> 0.025 | AC38: =IFERROR(AC37/AB37-1,"--") -> 0.025 | AD38: =IFERROR(AD37/Y37-1,"--") -> 0.046132457 | AE38: =IFERROR(AE37/AD37-1,"--") -> 0.045 | AF38: =IFERROR(AF37/AE37-1,"--") -> 0.06 | AG38: =IFERROR(AG37/AF37-1,"--") -> 0.065
C39: % of Total Revenue | F39: ='Segment Analysis'!F17 -> 0.28102329 | G39: ='Segment Analysis'!G17 -> 0.28551782 | H39: ='Segment Analysis'!H17 -> 0.30502358 | I39: ='Segment Analysis'!I17 -> 0.31284161 | J39: ='Segment Analysis'!J17 -> 0.29664212 | K39: ='Segment Analysis'!K17 -> 0.32431066 | L39: ='Segment Analysis'!L17 -> 0.31494265 | M39: ='Segment Analysis'!M17 -> 0.32744023 | ... U39: ='Segment Analysis'!U17 -> 0.31920498 | V39: =V37/V$30 -> 0.30845494 | W39: =W37/W$30 -> 0.30901489 | X39: =X37/X$30 -> 0.29998905 | Y39: =Y37/Y$30 -> 0.30892273 | Z39: =Z37/Z$30 -> 0.30049355 | AA39: =AA37/AA$30 -> 0.29014433 | AB39: =AB37/AB$30 -> 0.29041255 | AC39: =AC37/AC$30 -> 0.28659836 | ... AG39: =AG37/AG$30 -> 0.28249367
C41: ='Segment Analysis'!C9 -> Net Card Fees Revenue | F41: ='Segment Analysis'!F9 -> 1713 | G41: ='Segment Analysis'!G9 -> 1789 | H41: ='Segment Analysis'!H9 -> 1846 | I41: ='Segment Analysis'!I9 -> 1907 | J41: ='Segment Analysis'!J9 -> 7255 | K41: ='Segment Analysis'!K9 -> 1974 | L41: ='Segment Analysis'!L9 -> 2060 | M41: ='Segment Analysis'!M9 -> 2170 | ... U41: ='Segment Analysis'!U9 -> 2752 | V41: =IF(Segment2_Rev_Methodology="Segment",V63,IF(Segment2_Rev_Methodology="Activity-Based",V85,IF(Segment2_Rev_Methodology="Backlog",V159,"--"))) -> 2889.6 | W41: =IF(Segment2_Rev_Methodology="Segment",W63,IF(Segment2_Rev_Methodology="Activity-Based",W85,IF(Segment2_Rev_Methodology="Backlog",W159,"--"))) -> 3034.08 | X41: =IF(Segment2_Rev_Methodology="Segment",X63,IF(Segment2_Rev_Methodology="Activity-Based",X85,IF(Segment2_Rev_Methodology="Backlog",X159,"--"))) -> 3216.1248 | Y41: =SUM(U41:X41) -> 11891.805 | Z41: =IF(Segment2_Rev_Methodology="Segment",Z63,IF(Segment2_Rev_Methodology="Activity-Based",Z85,IF(Segment2_Rev_Methodology="Backlog",Z159,"--"))) -> 3312.6085 | AA41: =IF(Segment2_Rev_Methodology="Segment",AA63,IF(Segment2_Rev_Methodology="Activity-Based",AA85,IF(Segment2_Rev_Methodology="Backlog",AA159,"--"))) -> 3445.1129 | AB41: =IF(Segment2_Rev_Methodology="Segment",AB63,IF(Segment2_Rev_Methodology="Activity-Based",AB85,IF(Segment2_Rev_Methodology="Backlog",AB159,"--"))) -> 3514.0151 | AC41: =IF(Segment2_Rev_Methodology="Segment",AC63,IF(Segment2_Rev_Methodology="Activity-Based",AC85,IF(Segment2_Rev_Methodology="Backlog",AC159,"--"))) -> 3619.4356 | AD41: =SUM(Z41:AC41) -> 13891.172 | AE41: =IF(Segment2_Rev_Methodology="Segment",AE63,IF(Segment2_Rev_Methodology="Activity-Based",AE85,IF(Segment2_Rev_Methodology="Backlog",AE159,"--"))) -> 15835.936 | AF41: =IF(Segment2_Rev_Methodology="Segment",AF63,IF(Segment2_Rev_Methodology="Activity-Based",AF85,IF(Segment2_Rev_Methodology="Backlog",AF159,"--"))) -> 17736.249 | AG41: =IF(Segment2_Rev_Methodology="Segment",AG63,IF(Segment2_Rev_Methodology="Activity-Based",AG85,IF(Segment2_Rev_Methodology="Backlog",AG159,"--"))) -> 18800.424 | AI41: =IFERROR((T41/J41)^(1/3)-1,"--") -> 0.11263527 | AJ41: =IFERROR((AG41/T41)^(1/5)-1,"--") -> 0.13473474
C42: % Growth | G42: =IF($C$25="Annual",'Segment Analysis'!G147,'Segment Analysis'!G165) -> 0.044366608 | H42: =IF($C$25="Annual",'Segment Analysis'!H147,'Segment Analysis'!H165) -> 0.031861375 | I42: =IF($C$25="Annual",'Segment Analysis'!I147,'Segment Analysis'!I165) -> 0.03304442 | J42: =IF($C$25="Annual",'Segment Analysis'!J156,'Segment Analysis'!J156) -> 0 | K42: =IF($C$25="Annual",'Segment Analysis'!K147,'Segment Analysis'!K165) -> 0.035133718 | L42: =IF($C$25="Annual",'Segment Analysis'!L147,'Segment Analysis'!L165) -> 0.043566363 | M42: =IF($C$25="Annual",'Segment Analysis'!M147,'Segment Analysis'!M165) -> 0.053398058 | N42: =IF($C$25="Annual",'Segment Analysis'!N147,'Segment Analysis'!N165) -> 0.034562212 | O42: ='Segment Analysis'!O147 -> 0.16457615 | P42: =IF($C$25="Annual",'Segment Analysis'!P147,'Segment Analysis'!P165) -> 0.039198218 | Q42: =IF($C$25="Annual",'Segment Analysis'!Q147,'Segment Analysis'!Q165) -> 0.063009001 | R42: =IF($C$25="Annual",'Segment Analysis'!R147,'Segment Analysis'!R165) -> 0.028629032 | S42: =IF($C$25="Annual",'Segment Analysis'!S147,'Segment Analysis'!S165) -> 0.030576245 | T42: ='Segment Analysis'!T147 -> 0.18274352 | U42: =IF($C$25="Annual",'Segment Analysis'!U147,'Segment Analysis'!U165) -> 0.04678585 | V42: =IFERROR(V41/U41-1,"--") -> 0.05 | W42: =IFERROR(W41/V41-1,"--") -> 0.05 | X42: =IFERROR(X41/W41-1,"--") -> 0.06 | Y42: =IFERROR(Y41/T41-1,"--") -> 0.19001349 | Z42: =IFERROR(Z41/X41-1,"--") -> 0.03 | AA42: =IFERROR(AA41/Z41-1,"--") -> 0.04 | AB42: =IFERROR(AB41/AA41-1,"--") -> 0.02 | AC42: =IFERROR(AC41/AB41-1,"--") -> 0.03 | AD42: =IFERROR(AD41/Y41-1,"--") -> 0.16812985 | AE42: =IFERROR(AE41/AD41-1,"--") -> 0.14 | AF42: =IFERROR(AF41/AE41-1,"--") -> 0.12 | AG42: =IFERROR(AG41/AF41-1,"--") -> 0.06
