Workbook
Name al: '[3]2010 Labor Rates 091130'!$A$161
Name al09salary: [3]Salaries!$G$13
Name al10salary: [3]Salaries!$K$13
Name alid: '[3]2010 Labor Rates 091130'!$E$168
Name alname: [3]Salaries!$A$13
Name aprpto: [3]Vacation!$I$56
Name augpto: [3]Vacation!$M$56
Name avg_Health_and_Welfare: [4]PBCFringe!$Q$22
Name bf: '[3]2010 Labor Rates 091130'!$A$239
Name bf09salary: [3]Salaries!$G$18
Name bf10salary: [3]Salaries!$K$18
Name bfid: '[3]2010 Labor Rates 091130'!$E$246
Name bfname: [3]Salaries!$A$18
Name Bonus_estimate_2011: [4]PBCFringe!$B$100
Name Case_Scenario: [5]Cover!$F$22
Name Case_Scenario: Cover!$F$22
Name cc: '[3]2010 Labor Rates 091130'!$A$135
Name cc09salary: [3]Salaries!$G$11
Name cc10salary: [3]Salaries!$K$11
Name ccid: '[3]2010 Labor Rates 091130'!$E$142
Name ccname: [3]Salaries!$A$11
Name Ccy: [6]data!$A$5
Name cf: '[3]2010 Labor Rates 091130'!$A$148
Name cf09salary: [3]Salaries!$G$12
Name cf10salary: [3]Salaries!$K$12
Name cfid: '[3]2010 Labor Rates 091130'!$E$155
Name cfname: [3]Salaries!$A$12
Name ck: '[3]2010 Labor Rates 091130'!$A$213
Name ck09salary: [3]Salaries!$G$17
Name ck10salary: [3]Salaries!$K$17
Name ckid: '[3]2010 Labor Rates 091130'!$E$220
Name ckname: [3]Salaries!$A$17
Name Company_Cyclical_Multiples_Data: '[5]Multiples Data'!$C$14:$H$26
Name Company_Cyclical_Multiples_Data: 'Multiples Data'!$C$14:$H$26
Name Company_Name: [5]Cover!$F$19
Name Company_Name: Cover!$F$19
Name Company_Rev_Methodology: '[5]Revenue Build'!$C$7
Name Company_Rev_Methodology: 'Revenue Build'!$C$7
Name Cost_of_Debt: [5]WACC!$G$17
Name Cost_of_Debt: WACC!$G$17
Name Cost_of_Equity: [5]WACC!$G$25
Name Cost_of_Equity: WACC!$G$25
Name Cost_of_Preferred: [5]WACC!$G$10
Name Cost_of_Preferred: WACC!$G$10
Name cs: '[3]2010 Labor Rates 091130'!$A$252
Name cs09salary: [3]Salaries!$G$19
Name cs10salary: [3]Salaries!$K$19
Name csid: '[3]2010 Labor Rates 091130'!$E$259
Name csname: [3]Salaries!$A$19
Name Current_Date: [5]Cover!$F$27
Name Current_Date: Cover!$F$27
Name Current_Salary: '[8]Planning Worksheet'!$C:$C
Name CV: '[3]2010 Labor Rates 091130'!$A$5
Name cv09salary: [3]Salaries!$G$2
Name cv10salary: [3]Salaries!$K$2
Name cvid: '[3]2010 Labor Rates 091130'!$E$12
Name cvname: [3]Salaries!$A$2
Name Cycle_Period_Toggle: [5]Valuation!$G$221
Name Cycle_Period_Toggle: Valuation!$G$221
Name Cycle_Toggle: [5]Valuation!$G$220

Sheet Cover
C1: =Company_Name&" - "&MID(CELL("filename",A1),FIND("]",CELL("filename",A1))+1,255)&": "&Case_Scenario&" Case" -> Evercore Inc. - Cover: Base Case | Q1: Font Toggle
C2: $ in Thousands Except Per Share Data | Q2: Report
R3: x
A4: x | C4: Model Assumptions: | I4: Return Summary:
I6: Discounted Cash Flow Analysis | N6: Multiple Analysis
I8: Exit Multiple Method | N8: EV/EBITDA Method
I9: Implied Enterprise Value: | L9: =Valuation!K65 -> 19330394 | P9: Target Price: | Q9: % Return:
I10: Implied Equity Value: | L10: =Valuation!K72 -> 19286441
N11: 1 Year LTM EV/EBITDA | P11: =Valuation!N137 -> 430.49687 | Q11: =Valuation!N138 -> 0.26175113
I12: Implied Share Price: | L12: =Valuation!K76 -> 457.77315
I13: % Return: | L13: =Valuation!K77 -> 0.34169568 | N13: 2009-2018 Late Cycle EV/EBITDA | P13: =Valuation!N215 -> 258.07623 | Q13: =Valuation!N216 -> -0.24359966
I15: Perpetuity Growth Method | N15: P/E Multiple Method
I16: Implied Enterprise Value: | L16: =Valuation!R65 -> 23818873 | P16: Target Price: | Q16: % Return:
I17: Implied Equity Value: | L17: =Valuation!R72 -> 23774919
N18: 1 Year LTM P/E | P18: =Valuation!F126 -> 471.35312 | Q18: =Valuation!F127 -> 0.38149747
C19: Company Name | F19: Evercore Inc. | I19: Implied Share Price: | L19: =Valuation!R76 -> 564.30939
C20: Ticker | F20: EVR | I20: % Return: | L20: =Valuation!R77 -> 0.6539447 | N20: 2009-2018 Late Cycle P/E | P20: =Valuation!F204 -> 569.13382 | Q20: =Valuation!F205 -> 0.6680847
C22: Case Scenario | F22: Base | I22: Table of Contents
C24: Last Fiscal Year | F24: 46053 | I24: Cover
C25: Next Fiscal Year | F25: =Last_FYE+365 -> 46418 | I25: Summary
C26: Last Fiscal Quarter Reported | F26: 4Q | I26: Football Field
C27: Current Valuation Date | F27: 46150 | I27: Integrity
I28: Revenue Build
C29: Current Share Price | F29: 341.19 | I29: Model
C30: 52-Week High | F30: 388.71 | I30: Segment Analysis
C31: 52-Week Low | F31: 215.26 | I31: Drivers
I32: WACC
C33: Effective Tax Rate | F33: =IF(Last_FQR="1Q",Model!P73,IF(Last_FQR="2Q",Model!Q73,IF(Last_FQR="3Q",Model!R73,Model!S73))) -> 0.28977619 | I33: Valuation
C34: Dividend Yield | F34: =IF(Last_FQR="1Q",Model!U267,IF(Last_FQR="2Q",Model!V267,IF(Last_FQR="3Q",Model!W267,Model!X267))) -> 0.014176771 | I34: Comparables
C35: Diluted Shares Outstanding (MRQ) | F35: =IF(Last_FQR="1Q",Model!P286,IF(Last_FQR="2Q",Model!Q286,IF(Last_FQR="3Q",Model!R286,Model!S286))) -> 42131 | I35: Charts
I36: Benchmark
C37: Model Type | F37: Top Down | I37: Multiples Data
I38: Pre-Earnings
I39: Post-Earnings
A42: x
C43: Model Color Legend | I43: Constants
C44: Blue = Hard-Coded Value (historical values & assumptions) | I44: Reference | J44: Type | K44: Name | L44: Value
C45: Black = Formulas | I45: Million | J45: (#) | K45: Mil | L45: 1000000
C46: Green = Linked Value (from separate worksheet) | I46: Thousand | J46: (#) | K46: Thou | L46: 1000
C47: Red = Unique Formula / Anomaly | I47: Hundred | J47: (#) | K47: Hun | L47: 100
...

Sheet Summary
C1: =Company_Name&" - "&MID(CELL("filename",A1),FIND("]",CELL("filename",A1))+1,255)&": "&Case_Scenario&" Case" -> Evercore Inc. - Summary: Base Case
C2: =Cover!C2 -> $ in Thousands Except Per Share Data
C4: Year: | T4: =Model!J24 -> 2023 | U4: =Model!O24 -> 2024 | V4: =Model!T24 -> 2025 | W4: =Model!Y24 -> 2026 | X4: =Model!AD24 -> 2027 | Y4: =Model!AE24 -> 2028 | Z4: =Model!AF24 -> 2029 | AA4: =Model!AG24 -> 2030
G5: Quarterly | T5: Annuals | AC5: CAGR | AE5: CAGR
A6: x | C6: ="Consolidated "&Model!C25 -> Consolidated Income Statement | G6: =Model!P25 -> 1Q25 | H6: =Model!Q25 -> 2Q25 | I6: =Model!R25 -> 3Q25 | J6: =Model!S25 -> 4Q25 | K6: =Model!U25 -> 1Q26 | L6: =Model!V25 -> 2Q26e | M6: =Model!W25 -> 3Q26e | N6: =Model!X25 -> 4Q26e | O6: =Model!Z25 -> 1Q27e | P6: =Model!AA25 -> 2Q27e | Q6: =Model!AB25 -> 3Q27e | R6: =Model!AC25 -> 4Q27e | T6: =Model!J25 -> 2023 | U6: =Model!O25 -> 2024 | V6: =Model!T25 -> 2025 | W6: =Model!Y25 -> 2026e | X6: =Model!AD25 -> 2027e | Y6: =Model!AE25 -> 2028e | Z6: =Model!AF25 -> 2029e | AA6: =Model!AG25 -> 2030e | AC6: Historical | AE6: Projected
C8: =Model!C28 -> Revenue | G8: =Model!P28 -> 699022 | H8: =Model!Q28 -> 838040 | I8: =Model!R28 -> 1045994 | J8: =Model!S28 -> 1297028 | K8: =Model!U28 -> 1400469 | L8: =Model!V28 -> 1541864.2 | M8: =Model!W28 -> 1718730.9 | N8: =Model!X28 -> 2113727.6 | O8: =Model!Z28 -> 1569916.9 | P8: =Model!AA28 -> 1730869.9 | Q8: =Model!AB28 -> 1922407 | R8: =Model!AC28 -> 2440159.7 | T8: =Model!J28 -> 2442666 | U8: =Model!O28 -> 2996361 | V8: =Model!T28 -> 3880084 | W8: =Model!Y28 -> 6774791.7 | X8: =Model!AD28 -> 7663353.4 | Y8: =Model!AE28 -> 7894057.8 | Z8: =Model!AF28 -> 7727144.5 | AA8: =Model!AG28 -> 7330353.4 | AC8: =IFERROR((V8/T8)^(1/(V$4-T$4))-1,"N/A") -> 0.26034232 | AE8: =IFERROR((AA8/V8)^(1/(AA$4-V$4))-1,"N/A") -> 0.13568204
C9: YoY % Growth | K9: =K8/G8-1 -> 1.0034691 | L9: =L8/H8-1 -> 0.83984555 | M9: =M8/I8-1 -> 0.64315564 | N9: =N8/J8-1 -> 0.62966996 | O9: =O8/K8-1 -> 0.12099366 | P9: =P8/L8-1 -> 0.12258258 | Q9: =Q8/M8-1 -> 0.11850374 | R9: =R8/N8-1 -> 0.15443433 | U9: =IF(ISERROR(U8/T8-1),"NA",(U8/T8-1)) -> 0.22667651 | V9: =IF(ISERROR(V8/U8-1),"NA",(V8/U8-1)) -> 0.29493209 | W9: =IF(ISERROR(W8/V8-1),"NA",(W8/V8-1)) -> 0.74604253 | X9: =IF(ISERROR(X8/W8-1),"NA",(X8/W8-1)) -> 0.13115705 | Y9: =IF(ISERROR(Y8/X8-1),"NA",(Y8/X8-1)) -> 0.030104886 | Z9: =IF(ISERROR(Z8/Y8-1),"NA",(Z8/Y8-1)) -> -0.02114417 | AA9: =IF(ISERROR(AA8/Z8-1),"NA",(AA8/Z8-1)) -> -0.05135028
C11: =Model!C30 -> Gross Profit | G11: =Model!P30 -> 699022 | H11: =Model!Q30 -> 838040 | I11: =Model!R30 -> 1045994 | J11: =Model!S30 -> 1297028 | K11: =Model!U30 -> 1400469 | L11: =Model!V30 -> 1541864.2 | M11: =Model!W30 -> 1718730.9 | N11: =Model!X30 -> 2113727.6 | O11: =Model!Z30 -> 1569916.9 | P11: =Model!AA30 -> 1730869.9 | Q11: =Model!AB30 -> 1922407 | R11: =Model!AC30 -> 2440159.7 | T11: =Model!J30 -> 2442666 | U11: =Model!O30 -> 2996361 | V11: =Model!T30 -> 3880084 | W11: =Model!Y30 -> 6774791.7 | X11: =Model!AD30 -> 7663353.4 | Y11: =Model!AE30 -> 7894057.8 | Z11: =Model!AF30 -> 7727144.5 | AA11: =Model!AG30 -> 7330353.4 | AC11: =IFERROR((V11/T11)^(1/(V$4-T$4))-1,"N/A") -> 0.26034232 | AE11: =IFERROR((AA11/V11)^(1/(AA$4-V$4))-1,"N/A") -> 0.13568204
C12: % Margin | G12: =G11/G$8 -> 1 | H12: =H11/H$8 -> 1 | I12: =I11/I$8 -> 1 | J12: =J11/J$8 -> 1 | K12: =K11/K$8 -> 1 | L12: =L11/L$8 -> 1 | M12: =M11/M$8 -> 1 | N12: =N11/N$8 -> 1 | ... R12: =R11/R$8 -> 1 | T12: =T11/T$8 -> 1 | U12: =U11/U$8 -> 1 | V12: =V11/V$8 -> 1 | W12: =W11/W$8 -> 1 | X12: =X11/X$8 -> 1 | Y12: =Y11/Y$8 -> 1 | Z12: =Z11/Z$8 -> 1 | AA12: =AA11/AA$8 -> 1
C13: YoY % Growth | K13: =K11/G11-1 -> 1.0034691 | L13: =L11/H11-1 -> 0.83984555 | M13: =M11/I11-1 -> 0.64315564 | N13: =N11/J11-1 -> 0.62966996 | O13: =O11/K11-1 -> 0.12099366 | P13: =P11/L11-1 -> 0.12258258 | Q13: =Q11/M11-1 -> 0.11850374 | R13: =R11/N11-1 -> 0.15443433 | U13: =U11/T11-1 -> 0.22667651 | V13: =V11/U11-1 -> 0.29493209 | W13: =W11/V11-1 -> 0.74604253 | X13: =X11/W11-1 -> 0.13115705 | Y13: =Y11/X11-1 -> 0.030104886 | Z13: =Z11/Y11-1 -> -0.02114417 | AA13: =AA11/Z11-1 -> -0.05135028
C15: =Model!C37 -> EBIT | G15: =Model!P37 -> 115377 | H15: =Model!Q37 -> 154599 | I15: =Model!R37 -> 223316 | J15: =Model!S37 -> 320914 | K15: =Model!U37 -> 339617 | L15: =Model!V37 -> 315373.1 | M15: =Model!W37 -> 370051.21 | N15: =Model!X37 -> 509628.06 | O15: =Model!Z37 -> 321489.92 | P15: =Model!AA37 -> 372328.77 | Q15: =Model!AB37 -> 438226.91 | R15: =Model!AC37 -> 607462.17 | T15: =Model!J37 -> 375852 | U15: =Model!O37 -> 543682 | V15: =Model!T37 -> 814206 | W15: =Model!Y37 -> 1534669.4 | X15: =Model!AD37 -> 1739507.8 | Y15: =Model!AE37 -> 1798534.7 | Z15: =Model!AF37 -> 1632271.4 | AA15: =Model!AG37 -> 2012773.1 | AC15: =IFERROR((V15/T15)^(1/(V$4-T$4))-1,"N/A") -> 0.47183361 | AE15: =IFERROR((AA15/V15)^(1/(AA$4-V$4))-1,"N/A") -> 0.19842843
C16: Margin | G16: =G15/G$8 -> 0.16505489 | H16: =H15/H$8 -> 0.18447687 | I16: =I15/I$8 -> 0.21349644 | J16: =J15/J$8 -> 0.24742257 | K16: =K15/K$8 -> 0.24250233 | L16: =L15/L$8 -> 0.20454013 | M16: =M15/M$8 -> 0.21530491 | N16: =N15/N$8 -> 0.24110395 | ... R16: =R15/R$8 -> 0.24894361 | T16: =T15/T$8 -> 0.15386958 | U16: =U15/U$8 -> 0.18144743 | V16: =V15/V$8 -> 0.20984236 | W16: =W15/W$8 -> 0.22652643 | X16: =X15/X$8 -> 0.22699042 | Y16: =Y15/Y$8 -> 0.227834 | Z16: =Z15/Z$8 -> 0.21123863 | AA16: =AA15/AA$8 -> 0.27458064
C17: YoY % Growth | K17: =K15/G15-1 -> 1.9435416 | L17: =L15/H15-1 -> 1.0399427 | M17: =M15/I15-1 -> 0.6570743 | N17: =N15/J15-1 -> 0.58805183 | O17: =O15/K15-1 -> -0.053375081 | P17: =P15/L15-1 -> 0.18059775 | Q17: =Q15/M15-1 -> 0.18423317 | R17: =R15/N15-1 -> 0.19197158 | U17: =U15/T15-1 -> 0.44653215 | V17: =V15/U15-1 -> 0.49757763 | W17: =W15/V15-1 -> 0.8848662 | X17: =X15/W15-1 -> 0.13347396 | Y17: =Y15/X15-1 -> 0.033933146 | Z17: =Z15/Y15-1 -> -0.092443784 | AA17: =AA15/Z15-1 -> 0.2331118
C19: =Model!C46 -> Net Income (Loss) | G19: =Model!P46 -> 153790 | H19: =Model!Q46 -> 106939 | I19: =Model!R46 -> 157494 | J19: =Model!S46 -> 222484 | K19: =Model!U46 -> 322721 | L19: =Model!V46 -> 230802.51 | M19: =Model!W46 -> 277383.26 | N19: =Model!X46 -> 376925.18 | O19: =Model!Z46 -> 288459.79 | P19: =Model!AA46 -> 275255.05 | Q19: =Model!AB46 -> 324690.54 | R19: =Model!AC46 -> 451667.06 | T19: =Model!J46 -> 285223 | U19: =Model!O46 -> 417737 | V19: =Model!T46 -> 640707 | W19: =Model!Y46 -> 1207832 | X19: =Model!AD46 -> 1340072.4 | Y19: =Model!AE46 -> 1358063.9 | Z19: =Model!AF46 -> 1231468.3 | AA19: =Model!AG46 -> 1524493 | AC19: =IFERROR((V19/T19)^(1/(V$4-T$4))-1,"N/A") -> 0.49877853 | AE19: =IFERROR((AA19/V19)^(1/(AA$4-V$4))-1,"N/A") -> 0.18930486
C20: Margin | G20: =G19/G$8 -> 0.22000738 | H20: =H19/H$8 -> 0.12760608 | I20: =I19/I$8 -> 0.15056874 | J20: =J19/J$8 -> 0.17153369 | K20: =K19/K$8 -> 0.2304378 | L20: =L19/L$8 -> 0.14969056 | M20: =M19/M$8 -> 0.16138842 | N20: =N19/N$8 -> 0.1783225 | ... R20: =R19/R$8 -> 0.18509734 | T20: =T19/T$8 -> 0.11676709 | U20: =U19/U$8 -> 0.13941478 | V20: =V19/V$8 -> 0.1651271 | W20: =W19/W$8 -> 0.17828326 | X20: =X19/X$8 -> 0.17486763 | Y20: =Y19/Y$8 -> 0.17203623 | Z20: =Z19/Z$8 -> 0.15936913 | AA20: =AA19/AA$8 -> 0.20796992
C21: YoY % Growth | K21: =K19/G19-1 -> 1.0984524 | L21: =L19/H19-1 -> 1.1582632 | M21: =M19/I19-1 -> 0.76123068 | N21: =N19/J19-1 -> 0.69416759 | O21: =O19/K19-1 -> -0.10616356 | P21: =P19/L19-1 -> 0.19259988 | Q21: =Q19/M19-1 -> 0.17054842 | R21: =R19/N19-1 -> 0.19829367 | U21: =U19/T19-1 -> 0.46459788 | V21: =V19/U19-1 -> 0.53375689 | W21: =W19/V19-1 -> 0.88515493 | X21: =X19/W19-1 -> 0.10948583 | Y21: =Y19/X19-1 -> 0.013425749 | Z21: =Z19/Y19-1 -> -0.093217719 | AA21: =AA19/Z19-1 -> 0.23794743
C23: =Model!C58 -> Adj. EPS (Diluted) | G23: =Model!P58 -> 3.4757716 | H23: =Model!Q58 -> 2.3585034 | I23: =Model!R58 -> 3.408449 | J23: =Model!S58 -> 4.8409485 | K23: =Model!U58 -> 7.1979689 | L23: =Model!V58 -> 5.3153286 | M23: =Model!W58 -> 6.0438439 | N23: =Model!X58 -> 8.1844874 | O23: =Model!Z58 -> 5.8774868 | P23: =Model!AA58 -> 5.6505182 | Q23: =Model!AB58 -> 6.6214374 | R23: =Model!AC58 -> 9.179098 | T23: =Model!J58 -> 6.3712063 | U23: =Model!O58 -> 9.0832013 | V23: =Model!T58 -> 14.04956 | W23: =Model!Y58 -> 25.791307 | X23: =Model!AD58 -> 27.030169 | Y23: =Model!AE58 -> 27.91209 | Z23: =Model!AF58 -> 25.962366 | AA23: =Model!AG58 -> 33.296064 | AC23: =IFERROR((V23/T23)^(1/(V$4-T$4))-1,"N/A") -> 0.48497973 | AE23: =IFERROR((AA23/V23)^(1/(AA$4-V$4))-1,"N/A") -> 0.18835456
C24: YoY % Growth | K24: =K23/G23-1 -> 1.0708982 | L24: =L23/H23-1 -> 1.2536871 | M24: =M23/I23-1 -> 0.77319474 | N24: =N23/J23-1 -> 0.69067847 | O24: =O23/K23-1 -> -0.18345205 | P24: =P23/L23-1 -> 0.063060934 | Q24: =Q23/M23-1 -> 0.095567239 | R24: =R23/N23-1 -> 0.12152388 | U24: =IF(ISERROR(U23/T23-1),"NA",(U23/T23-1)) -> 0.42566429 | V24: =IF(ISERROR(V23/U23-1),"NA",(V23/U23-1)) -> 0.54676301 | W24: =IF(ISERROR(W23/V23-1),"NA",(W23/V23-1)) -> 0.83573773 | X24: =IF(ISERROR(X23/W23-1),"NA",(X23/W23-1)) -> 0.048034115 | Y24: =IF(ISERROR(Y23/X23-1),"NA",(Y23/X23-1)) -> 0.032627265 | Z24: =IF(ISERROR(Z23/Y23-1),"NA",(Z23/Y23-1)) -> -0.069852314 | AA24: =IF(ISERROR(AA23/Z23-1),"NA",(AA23/Z23-1)) -> 0.2824742
C27: =Model!C62 -> EBITDA | G27: =Model!P62 -> 121353 | H27: =Model!Q62 -> 161049 | I27: =Model!R62 -> 231172 | J27: =Model!S62 -> 333189 | K27: =Model!U62 -> 352055 | L27: =Model!V62 -> 323791.48 | M27: =Model!W62 -> 378980.17 | N27: =Model!X62 -> 518920.12 | O27: =Model!Z62 -> 321752.46 | P27: =Model!AA62 -> 373022.24 | Q27: =Model!AB62 -> 439382.03 | R27: =Model!AC62 -> 609080.48 | T27: =Model!J62 -> 400200 | U27: =Model!O62 -> 568150 | V27: =Model!T62 -> 846763 | W27: =Model!Y62 -> 1573746.8 | X27: =Model!AD62 -> 1743237.2 | Y27: =Model!AE62 -> 1817103.6 | Z27: =Model!AF62 -> 1661971.8 | AA27: =Model!AG62 -> 2051150.7 | AC27: =IFERROR((V27/T27)^(1/(V$4-T$4))-1,"N/A") -> 0.45459602 | AE27: =IFERROR((AA27/V27)^(1/(AA$4-V$4))-1,"N/A") -> 0.19356793
C28: Margin | G28: =G27/G$8 -> 0.17360398 | H28: =H27/H$8 -> 0.1921734 | I28: =I27/I$8 -> 0.221007 | J28: =J27/J$8 -> 0.25688651 | K28: =K27/K$8 -> 0.25138364 | L28: =L27/L$8 -> 0.21 | M28: =M27/M$8 -> 0.2205 | N28: =N27/N$8 -> 0.2455 | ... R28: =R27/R$8 -> 0.24960681 | T28: =T27/T$8 -> 0.16383738 | U28: =U27/U$8 -> 0.18961333 | V28: =V27/V$8 -> 0.21823316 | W28: =W27/W$8 -> 0.23229449 | X28: =X27/X$8 -> 0.22747707 | Y28: =Y27/Y$8 -> 0.23018625 | Z28: =Z27/Z$8 -> 0.21508227 | AA28: =AA27/AA$8 -> 0.27981608
C29: YoY % Growth | K29: =K27/G27-1 -> 1.901082 | L29: =L27/H27-1 -> 1.0105153 | M29: =M27/I27-1 -> 0.63938614 | N29: =N27/J27-1 -> 0.55743473 | O29: =O27/K27-1 -> -0.086073318 | P29: =P27/L27-1 -> 0.15204466 | Q29: =Q27/M27-1 -> 0.15937999 | R29: =R27/N27-1 -> 0.17374612 | U29: =U27/T27-1 -> 0.41966517 | V29: =V27/U27-1 -> 0.49038634 | W29: =W27/V27-1 -> 0.85854456 | X29: =X27/W27-1 -> 0.10769867 | Y29: =Y27/X27-1 -> 0.042373102 | Z29: =Z27/Y27-1 -> -0.085373115 | AA29: =AA27/Z27-1 -> 0.234167
G31: =G$5 -> Quarterly | T31: =T$5 -> Annuals
A32: x | C32: ="Consolidated "&Model!C120 -> Consolidated Balance Sheet | G32: =G$6 -> 1Q25 | H32: =H$6 -> 2Q25 | I32: =I$6 -> 3Q25 | J32: =J$6 -> 4Q25 | K32: =K$6 -> 1Q26 | L32: =L$6 -> 2Q26e | M32: =M$6 -> 3Q26e | N32: =N$6 -> 4Q26e | ... R32: =R$6 -> 4Q27e | T32: =T$6 -> 2023 | U32: =U$6 -> 2024 | V32: =V$6 -> 2025 | W32: =W$6 -> 2026e | X32: =X$6 -> 2027e | Y32: =Y$6 -> 2028e | Z32: =Z$6 -> 2029e | AA32: =AA$6 -> 2030e
C34: =Model!C122 -> Cash & Cash Equivalents | G34: =Model!P122 -> 552954 | H34: =Model!Q122 -> 617298 | I34: =Model!R122 -> 851908 | J34: =Model!S122 -> 1426020 | K34: =Model!U122 -> 985987 | L34: =Model!V122 -> 795539.03 | M34: =Model!W122 -> 870481.47 | N34: =Model!X122 -> 802310.4 | O34: =Model!Z122 -> 1652640.1 | P34: =Model!AA122 -> 1736972.8 | Q34: =Model!AB122 -> 1858789.1 | R34: =Model!AC122 -> 1772786.4 | T34: =Model!J122 -> 596878 | U34: =Model!O122 -> 873045 | V34: =Model!T122 -> 1426020 | W34: =Model!Y122 -> 802310.4 | X34: =Model!AD122 -> 1772786.4 | Y34: =Model!AE122 -> 473608.99 | Z34: =Model!AF122 -> 766208.18 | AA34: =Model!AG122 -> 1789601
C35: =Model!C123 -> Accounts Receivable | G35: =Model!P123 -> 507003 | H35: =Model!Q123 -> 518048 | I35: =Model!R123 -> 561911 | J35: =Model!S123 -> 619246 | K35: =Model!U123 -> 621229 | L35: =Model!V123 -> 779403.86 | M35: =Model!W123 -> 896729.19 | N35: =Model!X123 -> 1102814.4 | O35: =Model!Z123 -> 793584.35 | P35: =Model!AA123 -> 874945.2 | Q35: =Model!AB123 -> 1002994.9 | R35: =Model!AC123 -> 1273126.8 | T35: =Model!J123 -> 397352 | U35: =Model!O123 -> 455068 | V35: =Model!T123 -> 619246 | W35: =Model!Y123 -> 1102814.4 | X35: =Model!AD123 -> 1273126.8 | Y35: =Model!AE123 -> 1189515.6 | Z35: =Model!AF123 -> 1164364.2 | AA35: =Model!AG123 -> 1104573.8
C36: =Model!C124 -> Inventory | G36: =Model!P124 -> 0 | H36: =Model!Q124 -> 0 | I36: =Model!R124 -> 0 | J36: =Model!S124 -> 0 | K36: =Model!U124 -> 0 | L36: =Model!V124 -> 0 | M36: =Model!W124 -> 0 | N36: =Model!X124 -> 0 | O36: =Model!Z124 -> 0 | P36: =Model!AA124 -> 0 | Q36: =Model!AB124 -> 0 | R36: =Model!AC124 -> 0 | T36: =Model!J124 -> 0 | U36: =Model!O124 -> 0 | V36: =Model!T124 -> 0 | W36: =Model!Y124 -> 0 | X36: =Model!AD124 -> 0 | Y36: =Model!AE124 -> 0 | Z36: =Model!AF124 -> 0 | AA36: =Model!AG124 -> 0
C37: =Model!C125 -> Prepaid & Other Current Assets | G37: =Model!P125 -> 986097 | H37: =Model!Q125 -> 1299760 | I37: =Model!R125 -> 1726752 | J37: =Model!S125 -> 1812975 | K37: =Model!U125 -> 1203341 | L37: =Model!V125 -> 2343633.5 | M37: =Model!W125 -> 2612471 | N37: =Model!X125 -> 3212865.9 | O37: =Model!Z125 -> 2386273.6 | P37: =Model!AA125 -> 2630922.2 | Q37: =Model!AB125 -> 2922058.6 | R37: =Model!AC125 -> 3709042.7 | T37: =Model!J125 -> 1610987 | U37: =Model!O125 -> 1659788 | V37: =Model!T125 -> 1812975 | W37: =Model!Y125 -> 3212865.9 | X37: =Model!AD125 -> 3709042.7 | Y37: =Model!AE125 -> 5920543.3 | Z37: =Model!AF125 -> 6181715.6 | AA37: =Model!AG125 -> 6230800.4
C38: =Model!C126 -> Total Current Assets | G38: =SUM(G34:G37) -> 2046054 | H38: =SUM(H34:H37) -> 2435106 | I38: =SUM(I34:I37) -> 3140571 | J38: =SUM(J34:J37) -> 3858241 | K38: =SUM(K34:K37) -> 2810557 | L38: =SUM(L34:L37) -> 3918576.4 | M38: =SUM(M34:M37) -> 4379681.7 | N38: =SUM(N34:N37) -> 5117990.7 | ... R38: =SUM(R34:R37) -> 6754955.9 | T38: =SUM(T34:T37) -> 2605217 | U38: =SUM(U34:U37) -> 2987901 | V38: =SUM(V34:V37) -> 3858241 | W38: =SUM(W34:W37) -> 5117990.7 | X38: =SUM(X34:X37) -> 6754955.9 | Y38: =SUM(Y34:Y37) -> 7583667.9 | Z38: =SUM(Z34:Z37) -> 8112288 | AA38: =SUM(AA34:AA37) -> 9124975.2
C40: =Model!C128 -> PP&E, Net | G40: =Model!P128 -> 161204 | H40: =Model!Q128 -> 182856 | I40: =Model!R128 -> 188947 | J40: =Model!S128 -> 190064 | K40: =Model!U128 -> 187075 | L40: =Model!V128 -> 201784.59 | M40: =Model!W128 -> 218636.58 | N40: =Model!X128 -> 241050.44 | O40: =Model!Z128 -> 254836.65 | P40: =Model!AA128 -> 270606.23 | Q40: =Model!AB128 -> 288787.22 | R40: =Model!AC128 -> 314271.31 | T40: =Model!J128 -> 137940 | U40: =Model!O128 -> 144756 | V40: =Model!T128 -> 190064 | W40: =Model!Y128 -> 241050.44 | X40: =Model!AD128 -> 314271.31 | Y40: =Model!AE128 -> 376113.34 | Z40: =Model!AF128 -> 424320.1 | AA40: =Model!AG128 -> 457897.79
C41: =Model!#REF! -> #REF! | G41: =Model!P129 -> 0 | H41: =Model!Q129 -> 0 | I41: =Model!R129 -> 0 | J41: =Model!S129 -> 0 | K41: =Model!U129 -> 25871 | L41: =Model!V129 -> 25871 | M41: =Model!W129 -> 25871 | N41: =Model!X129 -> 25871 | O41: =Model!Z129 -> 25871 | P41: =Model!AA129 -> 25871 | Q41: =Model!AB129 -> 25871 | R41: =Model!AC129 -> 25871 | T41: =Model!J129 -> 0 | U41: =Model!O129 -> 0 | V41: =Model!T129 -> 0 | W41: =Model!Y129 -> 25871 | X41: =Model!AD129 -> 25871 | Y41: =Model!AE129 -> 25871 | Z41: =Model!AF129 -> 25871 | AA41: =Model!AG129 -> 25871
C42: =Model!C130 -> Goodwill | G42: =Model!P130 -> 125996 | H42: =Model!Q130 -> 129109 | I42: =Model!R130 -> 128576 | J42: =Model!S130 -> 230783 | K42: =Model!U130 -> 227412 | L42: =Model!V130 -> 227412 | M42: =Model!W130 -> 227412 | N42: =Model!X130 -> 227412 | O42: =Model!Z130 -> 227412 | P42: =Model!AA130 -> 227412 | Q42: =Model!AB130 -> 227412 | R42: =Model!AC130 -> 227412 | T42: =Model!J130 -> 125493 | U42: =Model!O130 -> 124452 | V42: =Model!T130 -> 230783 | W42: =Model!Y130 -> 227412 | X42: =Model!AD130 -> 227412 | Y42: =Model!AE130 -> 227412 | Z42: =Model!AF130 -> 227412 | AA42: =Model!AG130 -> 227412
C43: =Model!C131 -> Other Non-Current Assets | G43: =Model!P131 -> 937861 | H43: =Model!Q131 -> 942588 | I43: =Model!R131 -> 964152 | J43: =Model!S131 -> 1079009 | K43: =Model!U131 -> 1063358 | L43: =Model!V131 -> 1064421.4 | M43: =Model!W131 -> 1067614.6 | N43: =Model!X131 -> 1068682.2 | O43: =Model!Z131 -> 1069750.9 | P43: =Model!AA131 -> 1070820.7 | Q43: =Model!AB131 -> 1074033.1 | R43: =Model!AC131 -> 1075107.2 | T43: =Model!J131 -> 834648 | U43: =Model!O131 -> 916862 | V43: =Model!T131 -> 1079009 | W43: =Model!Y131 -> 1068682.2 | X43: =Model!AD131 -> 1075107.2 | Y43: =Model!AE131 -> 1080482.7 | Z43: =Model!AF131 -> 1085885.1 | AA43: =Model!AG131 -> 1091314.5
C44: =Model!C132 -> Total Non-Current Assets | G44: =SUM(G40:G43) -> 1225061 | H44: =SUM(H40:H43) -> 1254553 | I44: =SUM(I40:I43) -> 1281675 | J44: =SUM(J40:J43) -> 1499856 | K44: =SUM(K40:K43) -> 1503716 | L44: =SUM(L40:L43) -> 1519488.9 | M44: =SUM(M40:M43) -> 1539534.2 | N44: =SUM(N40:N43) -> 1563015.7 | ... R44: =SUM(R40:R43) -> 1642661.5 | T44: =SUM(T40:T43) -> 1098081 | U44: =SUM(U40:U43) -> 1186070 | V44: =SUM(V40:V43) -> 1499856 | W44: =SUM(W40:W43) -> 1563015.7 | X44: =SUM(X40:X43) -> 1642661.5 | Y44: =SUM(Y40:Y43) -> 1709879 | Z44: =SUM(Z40:Z43) -> 1763488.2 | AA44: =SUM(AA40:AA43) -> 1802495.3
C46: =Model!C134 -> Total Assets | G46: =SUM(G38,G44) -> 3271115 | H46: =SUM(H38,H44) -> 3689659 | I46: =SUM(I38,I44) -> 4422246 | J46: =SUM(J38,J44) -> 5358097 | K46: =SUM(K38,K44) -> 4314273 | L46: =SUM(L38,L44) -> 5438065.4 | M46: =SUM(M38,M44) -> 5919215.9 | N46: =SUM(N38,N44) -> 6681006.4 | ... R46: =SUM(R38,R44) -> 8397617.4 | T46: =SUM(T38,T44) -> 3703298 | U46: =SUM(U38,U44) -> 4173971 | V46: =SUM(V38,V44) -> 5358097 | W46: =SUM(W38,W44) -> 6681006.4 | X46: =SUM(X38,X44) -> 8397617.4 | Y46: =SUM(Y38,Y44) -> 9293546.9 | Z46: =SUM(Z38,Z44) -> 9875776.2 | AA46: =SUM(AA38,AA44) -> 10927471
C48: =Model!C136 -> Accounts Payable | G48: =Model!P136 -> 127670 | H48: =Model!Q136 -> 132817 | I48: =Model!R136 -> 103536 | J48: =Model!S136 -> 108485 | K48: =Model!U136 -> 39061 | L48: =Model!V136 -> 185023.7 | M48: =Model!W136 -> 206247.71 | N48: =Model!X136 -> 253647.31 | O48: =Model!Z136 -> 188390.02 | P48: =Model!AA136 -> 207704.38 | Q48: =Model!AB136 -> 230688.84 | R48: =Model!AC136 -> 292819.16 | T48: =Model!J136 -> 71827 | U48: =Model!O136 -> 77535 | V48: =Model!T136 -> 108485 | W48: =Model!Y136 -> 253647.31 | X48: =Model!AD136 -> 292819.16 | Y48: =Model!AE136 -> 221033.62 | Z48: =Model!AF136 -> 216360.05 | AA48: =Model!AG136 -> 205249.9
C49: =Model!C137 -> Accrued Liabilities | G49: =Model!P137 -> 316383 | H49: =Model!Q137 -> 549660 | I49: =Model!R137 -> 881526 | J49: =Model!S137 -> 1381322 | K49: =Model!U137 -> 853818 | L49: =Model!V137 -> 1480189.6 | M49: =Model!W137 -> 1649981.7 | N49: =Model!X137 -> 1902354.8 | O49: =Model!Z137 -> 1507120.2 | P49: =Model!AA137 -> 1661635.1 | Q49: =Model!AB137 -> 1845510.7 | R49: =Model!AC137 -> 2196143.7 | T49: =Model!J137 -> 763160 | U49: =Model!O137 -> 1024076 | V49: =Model!T137 -> 1381322 | W49: =Model!Y137 -> 1902354.8 | X49: =Model!AD137 -> 2196143.7 | Y49: =Model!AE137 -> 1618281.8 | Z49: =Model!AF137 -> 1159071.7 | AA49: =Model!AG137 -> 733035.34
C50: =Model!C138 -> Other Current Liabilities | G50: =Model!P138 -> 99453 | H50: =Model!Q138 -> 95934 | I50: =Model!R138 -> 172987 | J50: =Model!S138 -> 293614 | K50: =Model!U138 -> 123221 | L50: =Model!V138 -> 277535.55 | M50: =Model!W138 -> 309371.57 | N50: =Model!X138 -> 380470.96 | O50: =Model!Z138 -> 313983.37 | P50: =Model!AA138 -> 311556.57 | Q50: =Model!AB138 -> 346033.26 | R50: =Model!AC138 -> 439228.74 | T50: =Model!J138 -> 75072 | U50: =Model!O138 -> 90239 | V50: =Model!T138 -> 293614 | W50: =Model!Y138 -> 380470.96 | X50: =Model!AD138 -> 439228.74 | Y50: =Model!AE138 -> 236821.73 | Z50: =Model!AF138 -> 231814.33 | AA50: =Model!AG138 -> 146607.07
C51: =Model!C139 -> Total Current Liabilities (Excl. Debt) | G51: =SUM(G48:G50) -> 543506 | H51: =SUM(H48:H50) -> 778411 | I51: =SUM(I48:I50) -> 1158049 | J51: =SUM(J48:J50) -> 1783421 | K51: =SUM(K48:K50) -> 1016100 | L51: =SUM(L48:L50) -> 1942748.9 | M51: =SUM(M48:M50) -> 2165601 | N51: =SUM(N48:N50) -> 2536473.1 | ... R51: =SUM(R48:R50) -> 2928191.6 | T51: =SUM(T48:T50) -> 910059 | U51: =SUM(U48:U50) -> 1191850 | V51: =SUM(V48:V50) -> 1783421 | W51: =SUM(W48:W50) -> 2536473.1 | X51: =SUM(X48:X50) -> 2928191.6 | Y51: =SUM(Y48:Y50) -> 2076137.2 | Z51: =SUM(Z48:Z50) -> 1607246 | AA51: =SUM(AA48:AA50) -> 1084892.3
C53: =Model!C141 -> Revolver | G53: =Model!P141 -> 0 | H53: =Model!Q141 -> 0 | I53: =Model!R141 -> 0 | J53: =Model!S141 -> 0 | K53: =Model!U141 -> 0 | L53: =Model!V141 -> 0 | M53: =Model!W141 -> 0 | N53: =Model!X141 -> 0 | O53: =Model!Z141 -> 0 | P53: =Model!AA141 -> 0 | Q53: =Model!AB141 -> 0 | R53: =Model!AC141 -> 0 | T53: =Model!J141 -> 0 | U53: =Model!O141 -> 0 | V53: =Model!T141 -> 0 | W53: =Model!Y141 -> 0 | X53: =Model!AD141 -> 0 | Y53: =Model!AE141 -> 273553.56 | Z53: =Model!AF141 -> 0 | AA53: =Model!AG141 -> 0
C54: =Model!C142 -> LT Debt (Incl. Current Portion) | G54: =Model!P142 -> 375055 | H54: =Model!Q142 -> 377237 | I54: =Model!R142 -> 540353 | J54: =Model!S142 -> 540243 | K54: =Model!U142 -> 539749 | L54: =Model!V142 -> 540049 | M54: =Model!W142 -> 539649 | N54: =Model!X142 -> 539749 | O54: =Model!Z142 -> 539549 | P54: =Model!AA142 -> 539849 | Q54: =Model!AB142 -> 539449 | R54: =Model!AC142 -> 539549 | T54: =Model!J142 -> 373885 | U54: =Model!O142 -> 373895 | V54: =Model!T142 -> 540243 | W54: =Model!Y142 -> 539749 | X54: =Model!AD142 -> 539549 | Y54: =Model!AE142 -> 538949 | Z54: =Model!AF142 -> 538349 | AA54: =Model!AG142 -> 537749
...

Sheet Model Output
B1: =Company_Name&" "&"("&Ticker&")"&" Valuation Overview" -> Evercore Inc. (EVR) Valuation Overview | K1: Price Target Scenario: | N1: =Case_Scenario&" Case" -> Base Case | R1: Base Case Check | S1: =IF(N1="Base Case","","Check!") | Y1: P/E
B2: =Cover!C2 -> $ in Thousands Except Per Share Data | K2: Current Share Price: | O2: =Share_Price -> 341.19 | Y2: EV/EBITDA
K3: Valuation Date: | O3: =Current_Date -> 46150
B4: ="Multiples Analysis "&"("&S21&")" -> Multiples Analysis (P/E) | I4: Return Summary
I6: Exit Multiple Method
I7: =Cover!I9 -> Implied Enterprise Value: | N7: =Cover!L9 -> 19330394
I8: =Cover!I10 -> Implied Equity Value: | N8: =Cover!L10 -> 19286441
I9: =Cover!I12 -> Implied Share Price: | N9: =Cover!L12 -> 457.77315
I10: =Cover!I13 -> % Return: | N10: =Cover!L13 -> 0.34169568
I12: =Cover!I15 -> Perpetuity Growth Method
I13: =Cover!I16 -> Implied Enterprise Value: | N13: =Cover!L16 -> 23818873
I14: =Cover!I17 -> Implied Equity Value: | N14: =Cover!L17 -> 23774919
I15: =Cover!I19 -> Implied Share Price: | N15: =Cover!L19 -> 564.30939
I16: =Cover!I20 -> % Return: | N16: =Cover!L20 -> 0.6539447
E18: Annuals | M18: CAGR | O18: CAGR
B19: Consolidated Financials | E19: =Summary!U6 -> 2024 | F19: =Summary!V6 -> 2025 | G19: =Summary!W6 -> 2026e | H19: =Summary!X6 -> 2027e | I19: =Summary!Y6 -> 2028e | J19: =Summary!Z6 -> 2029e | K19: =Summary!AA6 -> 2030e | M19: Historical | O19: Projected
B21: =Summary!C8 -> Revenue | D21: =Summary!T8 -> 2442666 | E21: =Summary!U8 -> 2996361 | F21: =Summary!V8 -> 3880084 | G21: =Summary!W8 -> 6774791.7 | H21: =Summary!X8 -> 7663353.4 | I21: =Summary!Y8 -> 7894057.8 | J21: =Summary!Z8 -> 7727144.5 | K21: =Summary!AA8 -> 7330353.4 | M21: =Summary!AC8 -> 0.26034232 | O21: =Summary!AE8 -> 0.13568204 | R21: Multiple Toggle | S21: P/E
B22: =Summary!C9 -> YoY % Growth | E22: =Summary!U9 -> 0.22667651 | F22: =Summary!V9 -> 0.29493209 | G22: =Summary!W9 -> 0.74604253 | H22: =Summary!X9 -> 0.13115705 | I22: =Summary!Y9 -> 0.030104886 | J22: =Summary!Z9 -> -0.02114417 | K22: =Summary!AA9 -> -0.05135028
R23: Multiples Analysis | S23: EV/EBITDA | T23: P/E | U23: Chart
B24: =Summary!C11 -> Gross Profit | D24: =Summary!T11 -> 2442666 | E24: =Summary!U11 -> 2996361 | F24: =Summary!V11 -> 3880084 | G24: =Summary!W11 -> 6774791.7 | H24: =Summary!X11 -> 7663353.4 | I24: =Summary!Y11 -> 7894057.8 | J24: =Summary!Z11 -> 7727144.5 | K24: =Summary!AA11 -> 7330353.4 | M24: =Summary!AC11 -> 0.26034232 | O24: =Summary!AE11 -> 0.13568204 | R24: Entry Multiple | S24: =Valuation!D12 -> 12.1 | T24: =Valuation!D11 -> 16.6 | U24: =IF($S$21=$S$23,S24,T24) -> 16.6
B25: =Summary!C12 -> % Margin | E25: =Summary!U12 -> 1 | F25: =Summary!V12 -> 1 | G25: =Summary!W12 -> 1 | H25: =Summary!X12 -> 1 | I25: =Summary!Y12 -> 1 | J25: =Summary!Z12 -> 1 | K25: =Summary!AA12 -> 1 | R25: =Model!Y25 -> 2026e | S25: =(Comparables!H10*S30)/(Model!Y62) -> 0.00014501507 | T25: =(Comparables!$G$10*S30)/Summary!W19 -> 8.4881791 | U25: =IF($S$21=$S$23,S25,T25) -> 8.4881791
B26: =Summary!C13 -> YoY % Growth | E26: =Summary!U13 -> 0.22667651 | F26: =Summary!V13 -> 0.29493209 | G26: =Summary!W13 -> 0.74604253 | H26: =Summary!X13 -> 0.13115705 | I26: =Summary!Y13 -> 0.030104886 | J26: =Summary!Z13 -> -0.02114417 | K26: =Summary!AA13 -> -0.05135028 | R26: =Summary!AA6 -> 2030e | S26: =(Comparables!H10*S30)/(Model!AG62) -> 0.00011126291 | T26: =(Comparables!$G$10*S30)/Summary!AA19 -> 6.7250515 | U26: =IF($S$21=$S$23,S26,T26) -> 6.7250515
R27: Exit Multiple | S27: =Valuation!K60 -> 9 | T27: =Valuation!K72/Summary!AA19 -> 12.651052 | U27: =IF($S$21=$S$23,S27,T27) -> 12.651052
B28: =Summary!C27 -> EBITDA | D28: =Summary!T27 -> 400200 | E28: =Summary!U27 -> 568150 | F28: =Summary!V27 -> 846763 | G28: =Summary!W27 -> 1573746.8 | H28: =Summary!X27 -> 1743237.2 | I28: =Summary!Y27 -> 1817103.6 | J28: =Summary!Z27 -> 1661971.8 | K28: =Summary!AA27 -> 2051150.7 | M28: =Summary!AC27 -> 0.45459602 | O28: =Summary!AE27 -> 0.19356793 | R28: Implied PGM | S28: =Valuation!K79 -> 12.372456 | T28: =Valuation!R72/Summary!AA19 -> 15.595296 | U28: =IF($S$21=$S$23,S28,T28) -> 15.595296
B29: =Summary!C28 -> Margin | E29: =Summary!U28 -> 0.18961333 | F29: =Summary!V28 -> 0.21823316 | G29: =Summary!W28 -> 0.23229449 | H29: =Summary!X28 -> 0.22747707 | I29: =Summary!Y28 -> 0.23018625 | J29: =Summary!Z28 -> 0.21508227 | K29: =Summary!AA28 -> 0.27981608
B30: =Summary!C29 -> YoY % Growth | E30: =Summary!U17 -> 0.44653215 | F30: =Summary!V17 -> 0.49757763 | G30: =Summary!W29 -> 0.85854456 | H30: =Summary!X29 -> 0.10769867 | I30: =Summary!Y29 -> 0.042373102 | J30: =Summary!Z29 -> -0.085373115 | K30: =Summary!AA29 -> 0.234167 | R30: Financials Multiplier | S30: =IF($B$2="$ in Millions Except Per Share Data",1,IF($B$2="$ in Thousands Except Per Share Data",1000,IF($B$2="$ in Billions Except Per Share Data",0.001,0))) -> 1000
B32: =Summary!C19 -> Net Income (Loss) | D32: =Summary!T19 -> 285223 | E32: =Summary!U19 -> 417737 | F32: =Summary!V19 -> 640707 | G32: =Summary!W19 -> 1207832 | H32: =Summary!X19 -> 1340072.4 | I32: =Summary!Y19 -> 1358063.9 | J32: =Summary!Z19 -> 1231468.3 | K32: =Summary!AA19 -> 1524493 | M32: =Summary!AC19 -> 0.49877853 | O32: =Summary!AE19 -> 0.18930486
B33: =Summary!C20 -> Margin | E33: =Summary!U20 -> 0.13941478 | F33: =Summary!V20 -> 0.1651271 | G33: =Summary!W20 -> 0.17828326 | H33: =Summary!X20 -> 0.17486763 | I33: =Summary!Y20 -> 0.17203623 | J33: =Summary!Z20 -> 0.15936913 | K33: =Summary!AA20 -> 0.20796992
B34: =Summary!C21 -> YoY % Growth | E34: =Summary!U21 -> 0.46459788 | F34: =Summary!V21 -> 0.53375689 | G34: =Summary!W21 -> 0.88515493 | H34: =Summary!X21 -> 0.10948583 | I34: =Summary!Y21 -> 0.013425749 | J34: =Summary!Z21 -> -0.093217719 | K34: =Summary!AA21 -> 0.23794743
B36: =Summary!C23 -> Adj. EPS (Diluted) | D36: =Summary!T23 -> 6.3712063 | E36: =Summary!U23 -> 9.0832013 | F36: =Summary!V23 -> 14.04956 | G36: =Summary!W23 -> 25.791307 | H36: =Summary!X23 -> 27.030169 | I36: =Summary!Y23 -> 27.91209 | J36: =Summary!Z23 -> 25.962366 | K36: =Summary!AA23 -> 33.296064 | M36: =Summary!AC23 -> 0.48497973 | O36: =Summary!AE23 -> 0.18835456
B37: =Summary!C24 -> YoY % Growth | E37: =Summary!U24 -> 0.42566429 | F37: =Summary!V24 -> 0.54676301 | G37: =Summary!W24 -> 0.83573773 | H37: =Summary!X24 -> 0.048034115 | I37: =Summary!Y24 -> 0.032627265 | J37: =Summary!Z24 -> -0.069852314 | K37: =Summary!AA24 -> 0.2824742
B39: Free Cash Flow | D39: =Model!J114 -> -71792 | E39: =Model!O114 -> 351405 | F39: =Model!T114 -> 466034 | G39: =Model!Y114 -> 824785.44 | H39: =Model!AD114 -> 1135711 | I39: =Model!AE114 -> 1308047.6 | J39: =Model!AF114 -> 1203739.3 | K39: =Model!AG114 -> 1539595.6 | M39: =IFERROR((F39/D39)^(1/2)-1,"N/A") -> N/A | O39: =IFERROR((K39/G39)^(1/4)-1,"N/A") -> 0.16887056
B40: YoY % Growth | E40: =E39/D39-1 -> -5.8947654 | F40: =F39/E39-1 -> 0.32620196 | G40: =G39/F39-1 -> 0.7697967 | H40: =H39/G39-1 -> 0.37697754 | I40: =I39/H39-1 -> 0.15174331 | J40: =J39/I39-1 -> -0.079743506 | K40: =K39/J39-1 -> 0.27901086
E42: Annuals | M42: Average | O42: Average
B43: Capitalization and Key Ratios | E43: =E19 -> 2024 | F43: =F19 -> 2025 | G43: =G19 -> 2026e | H43: =H19 -> 2027e | I43: =I19 -> 2028e | J43: =J19 -> 2029e | K43: =K19 -> 2030e | M43: Historical | O43: Projected
B44: =Summary!C91 -> Leverage
B45: =Summary!C92 -> Total Debt / EBITDA | D45: =Summary!T92 -> 0.93424538 | E45: =Summary!U92 -> 0.65809205 | F45: =Summary!V92 -> 0.63800969 | G45: =Summary!W92 -> 0.34297068 | H45: =Summary!X92 -> 0.3095098 | I45: =Summary!Y92 -> 0.44714158 | J45: =Summary!Z92 -> 0.32392187 | K45: =Summary!AA92 -> 0.26216942 | M45: =AVERAGE(D45:F45) -> 0.74344904 | O45: =AVERAGE(G45:K45) -> 0.33714267
B46: =Summary!C93 -> Total Debt / Equity | D46: =Summary!T93 -> 0.20975433 | E46: =Summary!U93 -> 0.19254993 | F46: =Summary!V93 -> 0.23287681 | G46: =Summary!W93 -> 0.18390328 | H46: =Summary!X93 -> 0.1266531 | I46: =Summary!Y93 -> 0.1416723 | J46: =Summary!Z93 -> 0.076249531 | K46: =Summary!AA93 -> 0.062275462 | M46: =AVERAGE(D46:F46) -> 0.21172703 | O46: =AVERAGE(G46:K46) -> 0.11815073
B47: =Summary!C94 -> Total Debt / Total Assets | D47: =Summary!T94 -> 0.10096001 | E47: =Summary!U94 -> 0.089577767 | F47: =Summary!V94 -> 0.1008274 | G47: =Summary!W94 -> 0.080788577 | H47: =Summary!X94 -> 0.064250248 | I47: =Summary!Y94 -> 0.087426531 | J47: =Summary!Z94 -> 0.05451207 | K47: =Summary!AA94 -> 0.049210748 | M47: =AVERAGE(D47:F47) -> 0.097121726 | O47: =AVERAGE(G47:K47) -> 0.067237635
B49: =Summary!C103 -> Liquidity
...

Sheet Football Field
C1: =Company_Name&" - "&MID(CELL("filename",A1),FIND("]",CELL("filename",A1))+1,255)&": "&Case_Scenario&" Case" -> Evercore Inc. - Football Field: Base Case
C2: =Cover!C2 -> $ in Thousands Except Per Share Data
A4: x | O4: Valuation Method: | T4: Downside | U4: Delta | V4: Upside | W4: x
O5: =TEXT(Valuation!E108,"0.0%")&" - "&TEXT(Valuation!E110,"0.0%")&" WACC"&" & "&TEXT(Valuation!G106,"0.0%")&" - "&TEXT(Valuation!I106,"0.0%")&" PGR" -> 9.5% - 10.5% WACC & 1.5% - 2.5% PGR | T5: =Valuation!G108 -> 564.098 | U5: =V5-T5 -> 30.880249 | V5: =Valuation!I110 -> 594.97825
O6: =TEXT(Valuation!E100,"0.0%")&" - "&TEXT(Valuation!E102,"0.0%")&" WACC"&" & "&TEXT(Valuation!G98,"0.0x")&" - "&TEXT(Valuation!I98,"0.0x")&" Exit Multiple" -> 9.5% - 10.5% WACC & 8.0x - 10.0x Exit Multiple | T6: =Valuation!G100 -> 443.18419 | U6: =V6-T6 -> 50.182879 | V6: =Valuation!I102 -> 493.36707
O8: =Valuation!F184&": "&TEXT(Valuation!G185,"0.0x")&" - "&TEXT(Valuation!I185,"0.0x") -> NTM EV/EBITDA Spread to Comps: 8.4x - 10.4x | T8: =Valuation!G187 -> 150.76659 | U8: =V8-T8 -> 78.050565 | V8: =Valuation!I189 -> 228.81716
O9: =Valuation!F176&": "&TEXT(Valuation!G177,"0.0x")&" - "&TEXT(Valuation!I177,"0.0x") -> NTM EV/EBITDA: 10.6x - 12.6x | T9: =Valuation!G179 -> 191.12288 | U9: =V9-T9 -> 87.018628 | V9: =Valuation!I181 -> 278.14151
O10: =Valuation!F168&": "&TEXT(Valuation!G169,"0.0x")&" - "&TEXT(Valuation!I169,"0.0x") -> NTM P/E Spread to Comps: 13.3x - 15.3x | T10: =Valuation!G171 -> 361.02434 | U10: =V10-T10 -> 146.50724 | V10: =Valuation!I173 -> 507.53158
O11: =Valuation!F160&": "&TEXT(Valuation!G161,"0.0x")&" - "&TEXT(Valuation!I161,"0.0x") -> NTM P/E: 14.6x - 16.6x | T11: =Valuation!G163 -> 397.10342 | U11: =V11-T11 -> 154.52482 | V11: =Valuation!I165 -> 551.62824
O13: =Valuation!F260&": "&TEXT(Valuation!G261,"0.0x")&" - "&TEXT(Valuation!I261,"0.0x") -> 2009-2018 Early Cycle EV/EBITDA Spread to Comps: 9.9x - 11.9x | T13: =Valuation!G263 -> 178.19658 | U13: =V13-T13 -> 36.257762 | V13: =Valuation!I263 -> 214.45434
O14: =Valuation!F252&": "&TEXT(Valuation!G253,"0.0x")&" - "&TEXT(Valuation!I253,"0.0x") -> 2009-2018 Early Cycle EV/EBITDA: 5.9x - 7.9x | T14: =Valuation!G255 -> 106.58655 | U14: =V14-T14 -> 36.257762 | V14: =Valuation!I255 -> 142.84431
O15: =Valuation!F244&": "&TEXT(Valuation!G245,"0.0x")&" - "&TEXT(Valuation!I245,"0.0x") -> 2009-2018 Early Cycle P/E Spread to Comps: 23.5x - 25.5x | T15: =Valuation!G247 -> 637.05295 | U15: =V15-T15 -> 54.228775 | V15: =Valuation!I247 -> 691.28172
O16: =Valuation!F236&": "&TEXT(Valuation!G237,"0.0x")&" - "&TEXT(Valuation!I237,"0.0x") -> 2009-2018 Early Cycle P/E: 17.9x - 19.9x | T16: =Valuation!G239 -> 485.10605 | U16: =V16-T16 -> 54.228775 | V16: =Valuation!I239 -> 539.33482
O18: 52-Week Price Range: | T18: =Share_Price_Low -> 215.26 | U18: =V18-T18 -> 173.45 | V18: =Share_Price_High -> 388.71
O19: Median Value: | T19: =MEDIAN(T5:T18) -> 361.02434 | U19: =MEDIAN(U5:U18) -> 54.228775 | V19: =MEDIAN(V5:V18) -> 493.36707
A20: x | O20: Implied Return (%): | T20: =T19/Share_Price-1 -> 0.058132817 | V20: =V19/Share_Price-1 -> 0.44601855
T22: Reference Points for Price Axis
U24: Price
A25: x | T25: High | U25: =MAX(V5:V18)*1.1 -> 760.4099 | W25: x
T26: Low | U26: =MIN(T5:T18)*0.9 -> 95.927891
A30: x

Sheet Integrity
C1: =Company_Name&" - "&MID(CELL("filename",A1),FIND("]",CELL("filename",A1))+1,255) -> Evercore Inc. - Integrity
C3: Integrity
C4: Metric
C6: Model:
C7: Balance Sheet Check: | D7: =SUM(Model!F160:AG160) -> 0
C8: Base Case: | D8: =IF(Case_Scenario="Base","OK!","Check!") -> OK!
C9: Interest Expense: | D9: =IF(Model!C8="On","OK!","CHECK - OFF") -> OK!
C10: Valuation Date:
C12: Formatting:
C13: Valuation Sensitivity Tables: | D13: =SUM(Valuation!F92,Valuation!K92,Valuation!P92,Valuation!F151:F155,Valuation!L151:L155,Valuation!F227:F231,Valuation!L227:L231) -> -7.639249
C14: WACC Tables: | D14: =SUM(WACC!Q20,WACC!N33:N37) -> 0
C16: Font Toggles:
C17: Cover: | D17: =Cover!$Q$2 -> Report
C18: Revenue Build: | D18: ='Revenue Build'!$C$22 -> Report
C19: Model: | D19: =Model!$C$5 -> Report
C20: WACC | D20: =WACC!R5 -> Report
C21: Valuation: | D21: =Valuation!$R$2 -> Report
C23: Change Log
C24: Date | D24: Version | E24: Operator | F24: Revisions
C25: 44476 | D25: v01 | E25: Nate Latimer | F25: Top Down / Bottom Up toggle integration and Capital IQ comps sheet w/ ID Locator
C26: 44476 | D26: v02 | E26: Carson Shaner | F26: Formulas for EBIT/EBITDA margins on earnings sheets
C27: 44480 | D27: v03 | E27: Nate Latimer | F27: Historical driver adjustments to reflect Top Down / Bottom Up Toggle
C28: 44488 | D28: v04 | E28: Nate Latimer | F28: Bug fixes to model output, comps sheet and WACC Comps Relevered Beta
C29: 44489 | D29: v05 | E29: Lilianna Ruby | F29: Changed the year end driver in 2021 and 2022 to correctly pull operating margins
C30: 44491 | D30: v06 | E30: Lilianna Ruby | F30: Changed the first page to add 365 to your previous fiscal year
C31: 44496 | D31: v07 | E31: Carson Shaner | F31: Changed Model Output FCF formula, broke apart D&A for historical periods, added checks for EPS & EBITDA in Valuation sensitivity tables, added segment D&A breakdown, linked and fixed SOTP valuation
C32: 44503 | D32: v08 | E32: Lilianna Ruby | F32: Changed average of comps on valuation tab to average all peers not just the first one
C33: 44512 | D33: v09 | E33: Lilianna Ruby | F33: Rolled model forward to reflect 3Q'21. Also changed the multiples tab so the quarters roll forward and end on correct date.
C34: 44522 | D34: v10 | E34: Lilianna Ruby | F34: Fully fixed the multiples tab so it is automatic and fully functional. Also fixed definition of NTM_EPS and NTM_EBITDA
C35: 44582 | D35: v13 | E35: Carson Shaner | F35: Changed EPS, EBITDA, shares, tax rate, etc., to formulas so we do not have to hardcode them.
C36: 44584 | D36: v14 | E36: Lilianna Ruby | F36: Changed discount factor to mid year
... C47: 45581 | D47: v25 | E47: Conor McCabe | F47: Added font toggle to integrity tab for WACC tab. Formatted Comparables Tab.

Sheet Revenue Build
C1: =Company_Name&" - "&MID(CELL("filename",A1),FIND("]",CELL("filename",A1))+1,255)&": "&Case_Scenario&" Case" -> Evercore Inc. - Revenue Build: Base Case
C2: =Cover!C2 -> $ in Thousands Except Per Share Data
A4: x | C4: Segments
C6: =C30&" Methodology" -> Total Company Revenue Methodology
C7: Segment
C8: =C32&" Methodology" -> Investment Banking & Equities Revenue Methodology
C9: =IF(Company_Rev_Methodology="Segment","Segment",IF(Company_Rev_Methodology="Activity-Based","Activity-Based",IF(Company_Rev_Methodology="Backlog","Backlog",IF(Company_Rev_Methodology="Mixed",D9,"--")))) -> Segment | D9: Backlog
C10: =C35&" Methodology" -> Investment Management Revenue Methodology
C11: =IF(Company_Rev_Methodology="Segment","Segment",IF(Company_Rev_Methodology="Activity-Based","Activity-Based",IF(Company_Rev_Methodology="Backlog","Backlog",IF(Company_Rev_Methodology="Mixed",D11,"--")))) -> Segment | D11: Activity-Based
C12: =C38&" Methodology" -> Segment 3 Revenue Methodology
C13: =IF(Company_Rev_Methodology="Segment","Segment",IF(Company_Rev_Methodology="Activity-Based","Activity-Based",IF(Company_Rev_Methodology="Backlog","Backlog",IF(Company_Rev_Methodology="Mixed",D13,"--")))) -> Segment | D13: Segment
C14: =C41&" Methodology" -> Segment 4 Revenue Methodology
C15: =IF(Company_Rev_Methodology="Segment","Segment",IF(Company_Rev_Methodology="Activity-Based","Activity-Based",IF(Company_Rev_Methodology="Backlog","Backlog",IF(Company_Rev_Methodology="Mixed",D15,"--")))) -> Segment | D15: Segment
C16: =C44&" Methodology" -> Segment 5 Revenue Methodology
C17: =IF(Company_Rev_Methodology="Segment","Segment",IF(Company_Rev_Methodology="Activity-Based","Activity-Based",IF(Company_Rev_Methodology="Backlog","Backlog",IF(Company_Rev_Methodology="Mixed",D17,"--")))) -> Segment | D17: Segment
C18: =C47&" Methodology" -> Segment 6 Revenue Methodology
C19: =IF(Company_Rev_Methodology="Segment","Segment",IF(Company_Rev_Methodology="Activity-Based","Activity-Based",IF(Company_Rev_Methodology="Backlog","Backlog",IF(Company_Rev_Methodology="Mixed",D19,"--")))) -> Segment | D19: Segment
C21: Font Toggle
C22: Report
C24: Annual vs. Quarterly
C25: Quarterly
J26: 1 | O26: 2 | T26: 3 | Y26: 4 | AD26: 5 | AE26: 6 | AF26: 7 | AG26: 8
AI27: CAGR
A28: x | C28: Summary | F28: =Model!F$25 -> 1Q23 | G28: =Model!G$25 -> 2Q23 | H28: =Model!H$25 -> 3Q23 | I28: =Model!I$25 -> 4Q23 | J28: =Model!J$25 -> 2023 | K28: =Model!K$25 -> 1Q24 | L28: =Model!L$25 -> 2Q24 | M28: =Model!M$25 -> 3Q24 | ... AG28: =Model!AG$25 -> 2030e | AI28: Historical | AJ28: Projected
C30: Total Company Revenue | F30: ='Segment Analysis'!F7 -> 576314 | G30: ='Segment Analysis'!G7 -> 503600 | H30: ='Segment Analysis'!H7 -> 574404 | I30: ='Segment Analysis'!I7 -> 788348 | J30: ='Segment Analysis'!J7 -> 2442666 | K30: ='Segment Analysis'!K7 -> 585003 | L30: ='Segment Analysis'!L7 -> 693413 | M30: ='Segment Analysis'!M7 -> 738420 | ... U30: ='Segment Analysis'!U7 -> 1400469 | V30: =SUM(V32,V35,V38,V41,V44,V47,) -> 1541864.2 | W30: =SUM(W32,W35,W38,W41,W44,W47,) -> 1718730.9 | X30: =SUM(X32,X35,X38,X41,X44,X47,) -> 2113727.6 | Y30: =SUM(U30:X30) -> 6774791.7 | Z30: =SUM(Z32,Z35,Z38,Z41,Z44,Z47,) -> 1569916.9 | AA30: =SUM(AA32,AA35,AA38,AA41,AA44,AA47,) -> 1730869.9 | AB30: =SUM(AB32,AB35,AB38,AB41,AB44,AB47,) -> 1922407 | AC30: =SUM(AC32,AC35,AC38,AC41,AC44,AC47,) -> 2440159.7 | AD30: =SUM(Z30:AC30) -> 7663353.4 | AE30: =SUM(AE32,AE35,AE38,AE41,AE44,AE47,) -> 7894057.8 | AF30: =SUM(AF32,AF35,AF38,AF41,AF44,AF47,) -> 7727144.5 | AG30: =SUM(AG32,AG35,AG38,AG41,AG44,AG47,) -> 7330353.4 | AI30: =IFERROR((T30/J30)^(1/3)-1,"--") -> 0.16678906 | AJ30: =IFERROR((AG30/T30)^(1/5)-1,"--") -> 0.13568204
C31: =IF($C$25="Quarterly","% Growth QoQ","% Growth YoY") -> % Growth QoQ | G31: =IF($C$25="Annual",'Segment Analysis'!G172,'Segment Analysis'!G192) -> -0.1261708 | H31: =IF($C$25="Annual",'Segment Analysis'!H172,'Segment Analysis'!H192) -> 0.14059571 | I31: =IF($C$25="Annual",'Segment Analysis'!I172,'Segment Analysis'!I192) -> 0.37246259 | K31: =IF($C$25="Annual",'Segment Analysis'!K172,'Segment Analysis'!K192) -> -0.25793812 | L31: =IF($C$25="Annual",'Segment Analysis'!L172,'Segment Analysis'!L192) -> 0.18531529 | M31: =IF($C$25="Annual",'Segment Analysis'!M172,'Segment Analysis'!M192) -> 0.064906484 | N31: =IF($C$25="Annual",'Segment Analysis'!N172,'Segment Analysis'!N192) -> 0.32651472 | O31: =IFERROR(O30/J30-1,"--") -> 0.22667651 | P31: =IFERROR(P30/N30-1,"--") -> -0.28636635 | Q31: =IF($C$25="Annual",'Segment Analysis'!Q172,'Segment Analysis'!Q192) -> 0.198875 | R31: =IF($C$25="Annual",'Segment Analysis'!R172,'Segment Analysis'!R192) -> 0.24814329 | S31: =IF($C$25="Annual",'Segment Analysis'!S172,'Segment Analysis'!S192) -> 0.23999564 | T31: =IFERROR(T30/O30-1,"--") -> 0.29493209 | U31: =IFERROR(U30/S30-1,"--") -> 0.079752326 | V31: =IFERROR(V30/U30-1,"--") -> 0.10096273 | W31: =IFERROR(W30/V30-1,"--") -> 0.1147097 | X31: =IFERROR(X30/W30-1,"--") -> 0.22981877 | Y31: =IFERROR(Y30/T30-1,"--") -> 0.74604253 | Z31: =IFERROR(Z30/X30-1,"--") -> -0.25727569 | AA31: =IFERROR(AA30/Z30-1,"--") -> 0.10252326 | AB31: =IFERROR(AB30/AA30-1,"--") -> 0.11065946 | AC31: =IFERROR(AC30/AB30-1,"--") -> 0.26932523 | AD31: =IFERROR(AD30/Y30-1,"--") -> 0.13115705 | AE31: =IFERROR(AE30/AD30-1,"--") -> 0.030104886 | AF31: =IFERROR(AF30/AE30-1,"--") -> -0.02114417 | AG31: =IFERROR(AG30/AF30-1,"--") -> -0.05135028
C32: ='Segment Analysis'!C8 -> Investment Banking & Equities Revenue | F32: ='Segment Analysis'!F8 -> 554811 | G32: ='Segment Analysis'!G8 -> 482246 | H32: ='Segment Analysis'!H8 -> 552641 | I32: ='Segment Analysis'!I8 -> 766245 | J32: ='Segment Analysis'!J8 -> 2355943 | K32: ='Segment Analysis'!K8 -> 561728 | L32: ='Segment Analysis'!L8 -> 670010 | M32: ='Segment Analysis'!M8 -> 712775 | ... U32: ='Segment Analysis'!U8 -> 1362465 | V32: =IF(Segment1_Rev_Methodology="Segment",V53,IF(Segment1_Rev_Methodology="Activity-Based",V91,IF(Segment1_Rev_Methodology="Backlog",V165,"--"))) -> 1503480.1 | W32: =IF(Segment1_Rev_Methodology="Segment",W53,IF(Segment1_Rev_Methodology="Activity-Based",W91,IF(Segment1_Rev_Methodology="Backlog",W165,"--"))) -> 1679387.3 | X32: =IF(Segment1_Rev_Methodology="Segment",X53,IF(Segment1_Rev_Methodology="Activity-Based",X91,IF(Segment1_Rev_Methodology="Backlog",X165,"--"))) -> 2073203.6 | Y32: =SUM(U32:X32) -> 6618536.1 | Z32: =IF(Segment1_Rev_Methodology="Segment",Z53,IF(Segment1_Rev_Methodology="Activity-Based",Z91,IF(Segment1_Rev_Methodology="Backlog",Z165,"--"))) -> 1528987.7 | AA32: =IF(Segment1_Rev_Methodology="Segment",AA53,IF(Segment1_Rev_Methodology="Activity-Based",AA91,IF(Segment1_Rev_Methodology="Backlog",AA165,"--"))) -> 1689531.4 | AB32: =IF(Segment1_Rev_Methodology="Segment",AB53,IF(Segment1_Rev_Methodology="Activity-Based",AB91,IF(Segment1_Rev_Methodology="Backlog",AB165,"--"))) -> 1880448.4 | AC32: =IF(Segment1_Rev_Methodology="Segment",AC53,IF(Segment1_Rev_Methodology="Activity-Based",AC91,IF(Segment1_Rev_Methodology="Backlog",AC165,"--"))) -> 2397571.7 | AD32: =SUM(Z32:AC32) -> 7496539.2 | AE32: =IF(Segment1_Rev_Methodology="Segment",AE53,IF(Segment1_Rev_Methodology="Activity-Based",AE91,IF(Segment1_Rev_Methodology="Backlog",AE165,"--"))) -> 7743925 | AF32: =IF(Segment1_Rev_Methodology="Segment",AF53,IF(Segment1_Rev_Methodology="Activity-Based",AF91,IF(Segment1_Rev_Methodology="Backlog",AF165,"--"))) -> 7573558.7 | AG32: =IF(Segment1_Rev_Methodology="Segment",AG53,IF(Segment1_Rev_Methodology="Activity-Based",AG91,IF(Segment1_Rev_Methodology="Backlog",AG165,"--"))) -> 7172160.1 | AI32: =IFERROR((T32/J32)^(1/3)-1,"--") -> 0.16126428 | AJ32: =IFERROR((AG32/T32)^(1/5)-1,"--") -> 0.14219012
C33: =IF($C$25="Quarterly","% Growth QoQ","% Growth YoY") -> % Growth QoQ | G33: =IF($C$25="Annual",'Segment Analysis'!G173,'Segment Analysis'!G193) -> -0.13079229 | H33: =IF($C$25="Annual",'Segment Analysis'!H173,'Segment Analysis'!H193) -> 0.14597322 | I33: =IF($C$25="Annual",'Segment Analysis'!I173,'Segment Analysis'!I193) -> 0.38651493 | J33: =IF($C$25="Annual",'Segment Analysis'!J173,'Segment Analysis'!J193) -> 0 | K33: =IF($C$25="Annual",'Segment Analysis'!K173,'Segment Analysis'!K193) -> -0.2669081 | L33: =IF($C$25="Annual",'Segment Analysis'!L173,'Segment Analysis'!L193) -> 0.19276589 | M33: =IF($C$25="Annual",'Segment Analysis'!M173,'Segment Analysis'!M193) -> 0.063827406 | N33: =IF($C$25="Annual",'Segment Analysis'!N173,'Segment Analysis'!N193) -> 0.33839711 | O33: =IFERROR(O32/J32-1,"--") -> 0.23028825 | P33: =IFERROR(P32/N32-1,"--") -> -0.30112078 | Q33: =IF($C$25="Annual",'Segment Analysis'!Q173,'Segment Analysis'!Q193) -> 0.18224906 | R33: =IF($C$25="Annual",'Segment Analysis'!R173,'Segment Analysis'!R193) -> 0.25631865 | S33: =IF($C$25="Annual",'Segment Analysis'!S173,'Segment Analysis'!S193) -> 0.25646549 | T33: =IFERROR(T32/O32-1,"--") -> 0.27287666 | U33: =IFERROR(U32/S32-1,"--") -> 0.095031043 | V33: =IFERROR(V32/U32-1,"--") -> 0.1035 | W33: =IFERROR(W32/V32-1,"--") -> 0.117 | X33: =IFERROR(X32/W32-1,"--") -> 0.2345 | Y33: =IFERROR(Y32/T32-1,"--") -> 0.79392367 | Z33: =IFERROR(Z32/X32-1,"--") -> -0.2625 | AA33: =IFERROR(AA32/Z32-1,"--") -> 0.105 | AB33: =IFERROR(AB32/AA32-1,"--") -> 0.113 | AC33: =IFERROR(AC32/AB32-1,"--") -> 0.275 | AD33: =IFERROR(AD32/Y32-1,"--") -> 0.13265821 | AE33: =IFERROR(AE32/AD32-1,"--") -> 0.033 | AF33: =IFERROR(AF32/AE32-1,"--") -> -0.022 | AG33: =IFERROR(AG32/AF32-1,"--") -> -0.053
C34: % of Total Revenue | F34: ='Segment Analysis'!F16 -> 0.96268874 | G34: ='Segment Analysis'!G16 -> 0.9575973 | H34: ='Segment Analysis'!H16 -> 0.96211203 | I34: ='Segment Analysis'!I16 -> 0.97196289 | J34: ='Segment Analysis'!J16 -> 0.96449658 | K34: ='Segment Analysis'!K16 -> 0.96021388 | L34: ='Segment Analysis'!L16 -> 0.96624955 | M34: ='Segment Analysis'!M16 -> 0.96527044 | ... U34: ='Segment Analysis'!U16 -> 0.97286338 | V34: =V32/V$30 -> 0.97510543 | W34: =W32/W$30 -> 0.9771089 | X34: =X32/X$30 -> 0.98082821 | Y34: =Y32/Y$30 -> 0.97693573 | Z34: =Z32/Z$30 -> 0.97392907 | AA34: =AA32/AA$30 -> 0.97611693 | AB34: =AB32/AB$30 -> 0.97817395 | AC34: =AC32/AC$30 -> 0.98254707 | ... AG34: =AG32/AG$30 -> 0.97841941
C35: ='Segment Analysis'!C9 -> Investment Management Revenue | F35: ='Segment Analysis'!F9 -> 17332 | G35: ='Segment Analysis'!G9 -> 17173 | H35: ='Segment Analysis'!H9 -> 17579 | I35: ='Segment Analysis'!I9 -> 17922 | J35: ='Segment Analysis'!J9 -> 70006 | K35: ='Segment Analysis'!K9 -> 19087 | L35: ='Segment Analysis'!L9 -> 19214 | M35: ='Segment Analysis'!M9 -> 21447 | ... U35: ='Segment Analysis'!U9 -> 38004 | V35: =IF(Segment2_Rev_Methodology="Segment",V59,IF(Segment2_Rev_Methodology="Activity-Based",V103,IF(Segment2_Rev_Methodology="Backlog",V177,"--"))) -> 38384.04 | W35: =IF(Segment2_Rev_Methodology="Segment",W59,IF(Segment2_Rev_Methodology="Activity-Based",W103,IF(Segment2_Rev_Methodology="Backlog",W177,"--"))) -> 39343.641 | X35: =IF(Segment2_Rev_Methodology="Segment",X59,IF(Segment2_Rev_Methodology="Activity-Based",X103,IF(Segment2_Rev_Methodology="Backlog",X177,"--"))) -> 40523.95 | Y35: =SUM(U35:X35) -> 156255.63 | Z35: =IF(Segment2_Rev_Methodology="Segment",Z59,IF(Segment2_Rev_Methodology="Activity-Based",Z103,IF(Segment2_Rev_Methodology="Backlog",Z177,"--"))) -> 40929.19 | AA35: =IF(Segment2_Rev_Methodology="Segment",AA59,IF(Segment2_Rev_Methodology="Activity-Based",AA103,IF(Segment2_Rev_Methodology="Backlog",AA177,"--"))) -> 41338.482 | AB35: =IF(Segment2_Rev_Methodology="Segment",AB59,IF(Segment2_Rev_Methodology="Activity-Based",AB103,IF(Segment2_Rev_Methodology="Backlog",AB177,"--"))) -> 41958.559 | AC35: =IF(Segment2_Rev_Methodology="Segment",AC59,IF(Segment2_Rev_Methodology="Activity-Based",AC103,IF(Segment2_Rev_Methodology="Backlog",AC177,"--"))) -> 42587.937 | AD35: =SUM(Z35:AC35) -> 166814.17 | AE35: =IF(Segment2_Rev_Methodology="Segment",AE59,IF(Segment2_Rev_Methodology="Activity-Based",AE103,IF(Segment2_Rev_Methodology="Backlog",AE177,"--"))) -> 150132.75 | AF35: =IF(Segment2_Rev_Methodology="Segment",AF59,IF(Segment2_Rev_Methodology="Activity-Based",AF103,IF(Segment2_Rev_Methodology="Backlog",AF177,"--"))) -> 153585.8 | AG35: =IF(Segment2_Rev_Methodology="Segment",AG59,IF(Segment2_Rev_Methodology="Activity-Based",AG103,IF(Segment2_Rev_Methodology="Backlog",AG177,"--"))) -> 158193.38 | AI35: =IFERROR((T35/J35)^(1/3)-1,"--") -> 0.39651382 | AJ35: =IFERROR((AG35/T35)^(1/5)-1,"--") -> -0.036651414
C36: % Growth | G36: =IF($C$25="Annual",'Segment Analysis'!G174,'Segment Analysis'!G194) -> -0.0091737826 | H36: =IF($C$25="Annual",'Segment Analysis'!H174,'Segment Analysis'!H194) -> 0.023641763 | I36: =IF($C$25="Annual",'Segment Analysis'!I174,'Segment Analysis'!I194) -> 0.019511918 | K36: =IF($C$25="Annual",'Segment Analysis'!K174,'Segment Analysis'!K194) -> 0.065003906 | L36: =IF($C$25="Annual",'Segment Analysis'!L174,'Segment Analysis'!L194) -> 0.0066537434 | M36: =IF($C$25="Annual",'Segment Analysis'!M174,'Segment Analysis'!M194) -> 0.11621734 | N36: =IF($C$25="Annual",'Segment Analysis'!N174,'Segment Analysis'!N194) -> -0.0042430177 | O36: ='Segment Analysis'!O174 -> 0.15852927 | P36: =IFERROR(P35/N35-1,"--") -> 0.51283012 | Q36: =IF($C$25="Annual",'Segment Analysis'!Q174,'Segment Analysis'!Q194) -> 0.54197103 | R36: =IF($C$25="Annual",'Segment Analysis'!R174,'Segment Analysis'!R194) -> 0.1187924 | S36: =IF($C$25="Annual",'Segment Analysis'!S174,'Segment Analysis'!S194) -> -0.05262308 | T36: ='Segment Analysis'!T174 -> 1.3508705 | U36: =IFERROR(U35/S35-1,"--") -> -0.28026817 | V36: =IFERROR(V35/U35-1,"--") -> 0.01 | W36: =IFERROR(W35/V35-1,"--") -> 0.025 | X36: =IFERROR(X35/W35-1,"--") -> 0.03 | Y36: =IFERROR(Y35/T35-1,"--") -> -0.18047029 | Z36: =IFERROR(Z35/X35-1,"--") -> 0.01 | AA36: =IFERROR(AA35/Z35-1,"--") -> 0.01 | AB36: =IFERROR(AB35/AA35-1,"--") -> 0.015 | AC36: =IFERROR(AC35/AB35-1,"--") -> 0.015 | AD36: =IFERROR(AD35/Y35-1,"--") -> 0.067572197 | AE36: =IFERROR(AE35/AD35-1,"--") -> -0.1 | AF36: =IFERROR(AF35/AE35-1,"--") -> 0.023 | AG36: =IFERROR(AG35/AF35-1,"--") -> 0.03
C37: % of Total Revenue | F37: ='Segment Analysis'!F17 -> 0.030073883 | G37: ='Segment Analysis'!G17 -> 0.034100477 | H37: ='Segment Analysis'!H17 -> 0.030603896 | I37: ='Segment Analysis'!I17 -> 0.022733615 | J37: ='Segment Analysis'!J17 -> 0.028659669 | K37: ='Segment Analysis'!K17 -> 0.032627183 | L37: ='Segment Analysis'!L17 -> 0.027709316 | M37: ='Segment Analysis'!M17 -> 0.029044446 | ... U37: ='Segment Analysis'!U17 -> 0.027136624 | V37: =V35/V$30 -> 0.024894566 | W37: =W35/W$30 -> 0.022891099 | X37: =X35/X$30 -> 0.019171794 | Y37: =Y35/Y$30 -> 0.023064271 | Z37: =Z35/Z$30 -> 0.026070928 | AA37: =AA35/AA$30 -> 0.023883067 | AB37: =AB35/AB$30 -> 0.021826054 | AC37: =AC35/AC$30 -> 0.01745293 | ... AG37: =AG35/AG$30 -> 0.021580594
C38: ='Segment Analysis'!C10 -> Segment 3 Revenue | F38: ='Segment Analysis'!F10 -> 0 | G38: ='Segment Analysis'!G10 -> 0 | H38: ='Segment Analysis'!H10 -> 0 | I38: ='Segment Analysis'!I10 -> 0 | J38: ='Segment Analysis'!J10 -> 0 | K38: ='Segment Analysis'!K10 -> 0 | L38: ='Segment Analysis'!L10 -> 0 | M38: ='Segment Analysis'!M10 -> 0 | ... U38: ='Segment Analysis'!U10 -> 0 | V38: =IF(Segment3_Rev_Methodology="Segment",V65,IF(Segment3_Rev_Methodology="Activity-Based",V115,IF(Segment3_Rev_Methodology="Backlog",V189,"--"))) -> 0 | W38: =IF(Segment3_Rev_Methodology="Segment",W65,IF(Segment3_Rev_Methodology="Activity-Based",W115,IF(Segment3_Rev_Methodology="Backlog",W189,"--"))) -> 0 | X38: =IF(Segment3_Rev_Methodology="Segment",X65,IF(Segment3_Rev_Methodology="Activity-Based",X115,IF(Segment3_Rev_Methodology="Backlog",X189,"--"))) -> 0 | Y38: =SUM(U38:X38) -> 0 | Z38: =IF(Segment3_Rev_Methodology="Segment",Z65,IF(Segment3_Rev_Methodology="Activity-Based",Z115,IF(Segment3_Rev_Methodology="Backlog",Z189,"--"))) -> 0 | AA38: =IF(Segment3_Rev_Methodology="Segment",AA65,IF(Segment3_Rev_Methodology="Activity-Based",AA115,IF(Segment3_Rev_Methodology="Backlog",AA189,"--"))) -> 0 | AB38: =IF(Segment3_Rev_Methodology="Segment",AB65,IF(Segment3_Rev_Methodology="Activity-Based",AB115,IF(Segment3_Rev_Methodology="Backlog",AB189,"--"))) -> 0 | AC38: =IF(Segment3_Rev_Methodology="Segment",AC65,IF(Segment3_Rev_Methodology="Activity-Based",AC115,IF(Segment3_Rev_Methodology="Backlog",AC189,"--"))) -> 0 | AD38: =SUM(Z38:AC38) -> 0 | AE38: =IF(Segment3_Rev_Methodology="Segment",AE65,IF(Segment3_Rev_Methodology="Activity-Based",AE115,IF(Segment3_Rev_Methodology="Backlog",AE189,"--"))) -> 0 | AF38: =IF(Segment3_Rev_Methodology="Segment",AF65,IF(Segment3_Rev_Methodology="Activity-Based",AF115,IF(Segment3_Rev_Methodology="Backlog",AF189,"--"))) -> 0 | AG38: =IF(Segment3_Rev_Methodology="Segment",AG65,IF(Segment3_Rev_Methodology="Activity-Based",AG115,IF(Segment3_Rev_Methodology="Backlog",AG189,"--"))) -> 0 | AI38: =IFERROR((T38/J38)^(1/3)-1,"--") -> -- | AJ38: =IFERROR((AG38/T38)^(1/5)-1,"--") -> --
