Workbook
Name __1_0_Table2_: [1]MERGER!#REF!
Name __FDS_HYPERLINK_TOGGLE_STATE__: "ON"
Name _1_0_Table2_: [1]MERGER!#REF!
Name _2_0_Table2_: [1]MERGER!#REF!
Name _3_0_Table2_: [1]MERGER!#REF!
Name _4_0_Table2_: [1]MERGER!#REF!
Name _5_0_Table2_: [1]MERGER!#REF!
Name _9_0_Table2_: [1]MERGER!#REF!
Name _AtRisk_SimSetting_AutomaticallyGenerateReports: FALSE
Name _AtRisk_SimSetting_AutomaticResultsDisplayMode: 0
Name _AtRisk_SimSetting_ConvergenceConfidenceLevel: 0.95
Name _AtRisk_SimSetting_ConvergencePercentileToTest: 0.9
Name _AtRisk_SimSetting_ConvergencePerformMeanTest: TRUE
Name _AtRisk_SimSetting_ConvergencePerformPercentileTest: FALSE
Name _AtRisk_SimSetting_ConvergencePerformStdDeviationTest: FALSE
Name _AtRisk_SimSetting_ConvergenceTestAllOutputs: TRUE
Name _AtRisk_SimSetting_ConvergenceTestingPeriod: 100
Name _AtRisk_SimSetting_ConvergenceTolerance: 0.03
Name _AtRisk_SimSetting_LiveUpdate: TRUE
Name _AtRisk_SimSetting_LiveUpdatePeriod: -1
Name _AtRisk_SimSetting_RandomNumberGenerator: 0
Name _AtRisk_SimSetting_ReportsList: 0
Name _AtRisk_SimSetting_SimNameCount: 0
Name _AtRisk_SimSetting_SmartSensitivityAnalysisEnabled: TRUE
Name _AtRisk_SimSetting_StatisticFunctionUpdating: 1
Name _AtRisk_SimSetting_StdRecalcBehavior: 0
Name _AtRisk_SimSetting_StdRecalcWithoutRiskStatic: 0
Name _AtRisk_SimSetting_StdRecalcWithoutRiskStaticPercentile: 0.5
Name _bdm.001de5d049b6489bbc2025ad50c87030.edm: Model!$1:$1048576
Name _bdm.146e958bbea04416b86a4d5943392c04.edm: Model!$M$102
Name _bdm.1ff456f35144482ea0525e6d75d0206f.edm: Integrity!$1:$1048576
Name _bdm.a65ed6e2cd6142fea39714a1a8762f97.edm: Integrity!$1:$1048576
Name _bdm.bf5a9ed53fe44c598e3cfb84ac34b21f.edm: Integrity!$F$37
Name _bdm.dca432f6461240c98baf2847c1b05465.edm: Integrity!$1:$1048576
Name _Fill: #REF!
Name _Key1: #REF!
Name _Order1: 255
Name _Order2: 255
Name _Sort: #REF!
Name _Table1_In1: [2]merger!#REF!
Name _Table1_Out: [2]merger!#REF!
Name _Table2_In1: [2]merger!#REF!
Name _Table2_Out: [2]merger!#REF!
Name a: {"summary1",#N/A,TRUE,"Comps";"summary2",#N/A,TRUE,"Comps";"summary3",#N/A,TRUE,"Comps"}
Name aaaaaaaa: {"summary1",#N/A,TRUE,"Comps";"summary2",#N/A,TRUE,"Comps";"summary3",#N/A,TRUE,"Comps"}
Name adsfsadfas: {"multiple",#N/A,FALSE,"client (2)";"margins",#N/A,FALSE,"client (2)";"data",#N/A,FALSE,"client (2)";"multiple",#N/A,FALSE,"client";"margins",#N/A,FALSE,"client";"data",#N/A,FALSE,"client"}
Name adsfsdfe: {"Page1",#N/A,FALSE,"CompCo";"Page2",#N/A,FALSE,"CompCo"}
Name aefae: {"inputs raw data",#N/A,TRUE,"INPUT"}
Name aefe: {"cap_structure",#N/A,FALSE,"Graph-Mkt Cap";"price",#N/A,FALSE,"Graph-Price";"ebit",#N/A,FALSE,"Graph-EBITDA";"ebitda",#N/A,FALSE,"Graph-EBITDA"}
Name al: '[3]2010 Labor Rates 091130'!$A$161
Name al09salary: [3]Salaries!$G$13
Name al10salary: [3]Salaries!$K$13
Name alid: '[3]2010 Labor Rates 091130'!$E$168
Name alname: [3]Salaries!$A$13
Name aprpto: [3]Vacation!$I$56
Name asdfasdfas: {"cap_structure",#N/A,FALSE,"Graph-Mkt Cap";"price",#N/A,FALSE,"Graph-Price";"ebit",#N/A,FALSE,"Graph-EBITDA";"ebitda",#N/A,FALSE,"Graph-EBITDA"}
Name asdfsdfasdf: {"Page1",#N/A,FALSE,"CompCo";"Page2",#N/A,FALSE,"CompCo"}
Name augpto: [3]Vacation!$M$56
Name avg_Health_and_Welfare: [4]PBCFringe!$Q$22
Name awefweawe: {"Page1",#N/A,FALSE,"CompCo";"Page2",#N/A,FALSE,"CompCo"}

Sheet Cover
C1: =Company_Name&" - "&MID(CELL("filename",A1),FIND("]",CELL("filename",A1))+1,255)&": "&Case_Scenario&" Case" -> Hamilton Lane Inc. - Cover: Base Case | Q1: Font Toggle
C2: $ in Millions Except Per Share Data | Q2: Report
R3: x
A4: x | C4: Model Assumptions: | I4: Return Summary:
I6: Discounted Cash Flow Analysis | N6: Multiple Analysis
I8: Exit Multiple Method | N8: EV/EBITDA Method
I9: Implied Enterprise Value: | L9: =Valuation!K65 -> 8117.2262 | P9: Target Price: | Q9: % Return:
I10: Implied Equity Value: | L10: =Valuation!K72 -> 7855.7462
N11: 1 Year LTM EV/EBITDA | P11: =Valuation!N137 -> 104.36318 | Q11: =Valuation!N138 -> -0.11751072
I12: Implied Share Price: | L12: =Valuation!K76 -> 144.22152
I13: % Return: | L13: =Valuation!K77 -> 0.21952917 | N13: 2009-2018 Late Cycle EV/EBITDA | P13: =Valuation!N215 -> 52.268602 | Q13: =Valuation!N216 -> -0.5580196
I15: Perpetuity Growth Method | N15: P/E Multiple Method
I16: Implied Enterprise Value: | L16: =Valuation!R65 -> 5013.5852 | P16: Target Price: | Q16: % Return:
I17: Implied Equity Value: | L17: =Valuation!R72 -> 4752.1052
N18: 1 Year LTM P/E | P18: =Valuation!F126 -> 144.38346 | Q18: =Valuation!F127 -> 0.22089852
C19: Company Name | F19: Hamilton Lane Inc. | I19: Implied Share Price: | L19: =Valuation!R76 -> 87.242614
C20: Ticker | F20: HLNE | I20: % Return: | L20: =Valuation!R77 -> -0.2622813 | N20: 2009-2018 Late Cycle P/E | P20: =Valuation!F204 -> 107.29422 | Q20: =Valuation!F205 -> -0.092726057
C22: Case Scenario | F22: Base | I22: Table of Contents
C24: Last Fiscal Year | F24: 45747 | I24: Cover
C25: Next Fiscal Year | F25: =Last_FYE+365 -> 46112 | I25: Summary
C26: Last Fiscal Quarter Reported | F26: 1Q | I26: Football Field
C27: Current Valuation Date | F27: 45940 | I27: Integrity
I28: Revenue Build
C29: Current Share Price | F29: 118.26 | I29: Model
C30: 52-Week High | F30: 203.72 | I30: Segment Analysis
C31: 52-Week Low | F31: 124.1 | I31: Drivers
I32: WACC
C33: Effective Tax Rate | F33: =IF(Last_FQR="1Q",Model!U71,IF(Last_FQR="2Q",Model!V71,IF(Last_FQR="3Q",Model!W71,Model!X71))) -> 0.19255309 | I33: Valuation
C34: Dividend Yield | F34: =IF(Last_FQR="1Q",Model!U266,IF(Last_FQR="2Q",Model!V266,IF(Last_FQR="3Q",Model!W266,Model!X266))) -> 0.013084722 | I34: Comparables
C35: Diluted Shares Outstanding (MRQ) | F35: =IF(Last_FQR="1Q",Model!U285,IF(Last_FQR="2Q",Model!V285,IF(Last_FQR="3Q",Model!W285,Model!X285))) -> 54.47 | I35: Charts
I36: Benchmark
C37: Model Type | F37: Top Down | I37: Multiples Data
I38: Pre-Earnings
I39: Post-Earnings
A42: x
C43: Model Color Legend | I43: Constants
C44: Blue = Hard-Coded Value (historical values & assumptions) | I44: Reference | J44: Type | K44: Name | L44: Value
C45: Black = Formulas | I45: Million | J45: (#) | K45: Mil | L45: 1000000
C46: Green = Linked Value (from separate worksheet) | I46: Thousand | J46: (#) | K46: Thou | L46: 1000
C47: Red = Unique Formula / Anomaly | I47: Hundred | J47: (#) | K47: Hun | L47: 100
...

Sheet Summary
C1: =Company_Name&" - "&MID(CELL("filename",A1),FIND("]",CELL("filename",A1))+1,255)&": "&Case_Scenario&" Case" -> Hamilton Lane Inc. - Summary: Base Case
C2: =Cover!C2 -> $ in Millions Except Per Share Data
C4: Year: | T4: =Model!J24 -> 2023 | U4: =Model!O24 -> 2024 | V4: =Model!T24 -> 2025 | W4: =Model!Y24 -> 2026 | X4: =Model!AD24 -> 2027 | Y4: =Model!AE24 -> 2028 | Z4: =Model!AF24 -> 2029 | AA4: =Model!AG24 -> 2030
G5: Quarterly | T5: Annuals | AC5: CAGR | AE5: CAGR
A6: x | C6: ="Consolidated "&Model!C25 -> Consolidated Income Statement | G6: =Model!P25 -> 1Q25 | H6: =Model!Q25 -> 2Q25 | I6: =Model!R25 -> 3Q25 | J6: =Model!S25 -> 4Q25 | K6: =Model!U25 -> 1Q26 | L6: =Model!V25 -> 2Q26e | M6: =Model!W25 -> 3Q26e | N6: =Model!X25 -> 4Q26e | O6: =Model!Z25 -> 1Q27e | P6: =Model!AA25 -> 2Q27e | Q6: =Model!AB25 -> 3Q27e | R6: =Model!AC25 -> 4Q27e | T6: =Model!J25 -> 2023 | U6: =Model!O25 -> 2024 | V6: =Model!T25 -> 2025 | W6: =Model!Y25 -> 2026e | X6: =Model!AD25 -> 2027e | Y6: =Model!AE25 -> 2028e | Z6: =Model!AF25 -> 2029e | AA6: =Model!AG25 -> 2030e | AC6: Historical | AE6: Projected
C8: =Model!C28 -> Revenue | G8: =Model!P28 -> 196.731 | H8: =Model!Q28 -> 149.999 | I8: =Model!R28 -> 168.261 | J8: =Model!S28 -> 197.973 | K8: =Model!U28 -> 175.958 | L8: =Model!V28 -> 183.91066 | M8: =Model!W28 -> 195.21191 | N8: =Model!X28 -> 211.57639 | O8: =Model!Z28 -> 224.51778 | P8: =Model!AA28 -> 237.98885 | Q8: =Model!AB28 -> 249.25561 | R8: =Model!AC28 -> 260.76606 | T8: =Model!J28 -> 528.753 | U8: =Model!O28 -> 553.842 | V8: =Model!T28 -> 712.964 | W8: =Model!Y28 -> 766.65695 | X8: =Model!AD28 -> 972.5283 | Y8: =Model!AE28 -> 1040.6053 | Z8: =Model!AF28 -> 1097.8386 | AA8: =Model!AG28 -> 1169.5212 | AC8: =IFERROR((V8/T8)^(1/(V$4-T$4))-1,"N/A") -> 0.16120094 | AE8: =IFERROR((AA8/V8)^(1/(AA$4-V$4))-1,"N/A") -> 0.10404837
C9: YoY % Growth | K9: =K8/G8-1 -> -0.10559088 | L9: =L8/H8-1 -> 0.22607924 | M9: =M8/I8-1 -> 0.16017321 | N9: =N8/J8-1 -> 0.068713335 | O9: =O8/K8-1 -> 0.27597371 | P9: =P8/L8-1 -> 0.29404598 | Q9: =Q8/M8-1 -> 0.27684633 | R9: =R8/N8-1 -> 0.23249133 | U9: =IF(ISERROR(U8/T8-1),"NA",(U8/T8-1)) -> 0.047449376 | V9: =IF(ISERROR(V8/U8-1),"NA",(V8/U8-1)) -> 0.28730577 | W9: =IF(ISERROR(W8/V8-1),"NA",(W8/V8-1)) -> 0.075309483 | X9: =IF(ISERROR(X8/W8-1),"NA",(X8/W8-1)) -> 0.26853125 | Y9: =IF(ISERROR(Y8/X8-1),"NA",(Y8/X8-1)) -> 0.07 | Z9: =IF(ISERROR(Z8/Y8-1),"NA",(Z8/Y8-1)) -> 0.055 | AA9: =IF(ISERROR(AA8/Z8-1),"NA",(AA8/Z8-1)) -> 0.065294368
C11: =Model!C30 -> Gross Profit | G11: =Model!P30 -> 196.731 | H11: =Model!Q30 -> 149.999 | I11: =Model!R30 -> 168.261 | J11: =Model!S30 -> 197.973 | K11: =Model!U30 -> 175.958 | L11: =Model!V30 -> 183.91066 | M11: =Model!W30 -> 195.21191 | N11: =Model!X30 -> 211.57639 | O11: =Model!Z30 -> 224.51778 | P11: =Model!AA30 -> 237.98885 | Q11: =Model!AB30 -> 249.25561 | R11: =Model!AC30 -> 260.76606 | T11: =Model!J30 -> 528.753 | U11: =Model!O30 -> 553.842 | V11: =Model!T30 -> 712.964 | W11: =Model!Y30 -> 766.65695 | X11: =Model!AD30 -> 972.5283 | Y11: =Model!AE30 -> 1040.6053 | Z11: =Model!AF30 -> 1097.8386 | AA11: =Model!AG30 -> 1169.5212 | AC11: =IFERROR((V11/T11)^(1/(V$4-T$4))-1,"N/A") -> 0.16120094 | AE11: =IFERROR((AA11/V11)^(1/(AA$4-V$4))-1,"N/A") -> 0.10404837
C12: % Margin | G12: =G11/G$8 -> 1 | H12: =H11/H$8 -> 1 | I12: =I11/I$8 -> 1 | J12: =J11/J$8 -> 1 | K12: =K11/K$8 -> 1 | L12: =L11/L$8 -> 1 | M12: =M11/M$8 -> 1 | N12: =N11/N$8 -> 1 | ... R12: =R11/R$8 -> 1 | T12: =T11/T$8 -> 1 | U12: =U11/U$8 -> 1 | V12: =V11/V$8 -> 1 | W12: =W11/W$8 -> 1 | X12: =X11/X$8 -> 1 | Y12: =Y11/Y$8 -> 1 | Z12: =Z11/Z$8 -> 1 | AA12: =AA11/AA$8 -> 1
C13: YoY % Growth | K13: =K11/G11-1 -> -0.10559088 | L13: =L11/H11-1 -> 0.22607924 | M13: =M11/I11-1 -> 0.16017321 | N13: =N11/J11-1 -> 0.068713335 | O13: =O11/K11-1 -> 0.27597371 | P13: =P11/L11-1 -> 0.29404598 | Q13: =Q11/M11-1 -> 0.27684633 | R13: =R11/N11-1 -> 0.23249133 | U13: =U11/T11-1 -> 0.047449376 | V13: =V11/U11-1 -> 0.28730577 | W13: =W11/V11-1 -> 0.075309483 | X13: =X11/W11-1 -> 0.26853125 | Y13: =Y11/X11-1 -> 0.07 | Z13: =Z11/Y11-1 -> 0.055 | AA13: =AA11/Z11-1 -> 0.065294368
C15: =Model!C36 -> EBIT | G15: =Model!P36 -> 89.611 | H15: =Model!Q36 -> 67.192 | I15: =Model!R36 -> 75.722 | J15: =Model!S36 -> 84.028 | K15: =Model!U36 -> 76.975 | L15: =Model!V36 -> 79.633316 | M15: =Model!W36 -> 84.526755 | N15: =Model!X36 -> 91.612575 | O15: =Model!Z36 -> 96.542647 | P15: =Model!AA36 -> 102.33521 | Q15: =Model!AB36 -> 107.17991 | R15: =Model!AC36 -> 112.12941 | T15: =Model!J36 -> 239.912 | U15: =Model!O36 -> 245.817 | V15: =Model!T36 -> 316.553 | W15: =Model!Y36 -> 332.74765 | X15: =Model!AD36 -> 418.18717 | Y15: =Model!AE36 -> 437.05422 | Z15: =Model!AF36 -> 461.0922 | AA15: =Model!AG36 -> 491.19892 | AC15: =IFERROR((V15/T15)^(1/(V$4-T$4))-1,"N/A") -> 0.14867516 | AE15: =IFERROR((AA15/V15)^(1/(AA$4-V$4))-1,"N/A") -> 0.091848029
C16: Margin | G16: =G15/G$8 -> 0.45550015 | H16: =H15/H$8 -> 0.44794965 | I16: =I15/I$8 -> 0.45002704 | J16: =J15/J$8 -> 0.42444172 | K16: =K15/K$8 -> 0.43746235 | L16: =L15/L$8 -> 0.433 | M16: =M15/M$8 -> 0.433 | N16: =N15/N$8 -> 0.433 | ... R16: =R15/R$8 -> 0.43 | T16: =T15/T$8 -> 0.4537317 | U16: =U15/U$8 -> 0.44383958 | V16: =V15/V$8 -> 0.44399577 | W16: =W15/W$8 -> 0.43402417 | X16: =X15/X$8 -> 0.43 | Y16: =Y15/Y$8 -> 0.42 | Z16: =Z15/Z$8 -> 0.42 | AA16: =AA15/AA$8 -> 0.42
C17: YoY % Growth | K17: =K15/G15-1 -> -0.14100947 | L17: =L15/H15-1 -> 0.18516067 | M17: =M15/I15-1 -> 0.11627737 | N17: =N15/J15-1 -> 0.090262469 | O17: =O15/K15-1 -> 0.25420781 | P17: =P15/L15-1 -> 0.2850803 | Q17: =Q15/M15-1 -> 0.26799982 | R17: =R15/N15-1 -> 0.22395213 | U17: =U15/T15-1 -> 0.024613192 | V17: =V15/U15-1 -> 0.28775878 | W17: =W15/V15-1 -> 0.051159349 | X17: =X15/W15-1 -> 0.25676973 | Y17: =Y15/X15-1 -> 0.045116279 | Z17: =Z15/Y15-1 -> 0.055 | AA17: =AA15/Z15-1 -> 0.065294368
C19: =Model!C45 -> Net Income (Loss) | G19: =Model!P45 -> 87.087 | H19: =Model!Q45 -> 75.922 | I19: =Model!R45 -> 77.455 | J19: =Model!S45 -> 73.304 | K19: =Model!U45 -> 77.07 | L19: =Model!V45 -> 67.837287 | M19: =Model!W45 -> 72.074365 | N19: =Model!X45 -> 78.129684 | O19: =Model!Z45 -> 84.212015 | P19: =Model!AA45 -> 89.098414 | Q19: =Model!AB45 -> 90.400262 | R19: =Model!AC45 -> 94.386421 | T19: =Model!J45 -> 187.056 | U19: =Model!O45 -> 227.204 | V19: =Model!T45 -> 313.768 | W19: =Model!Y45 -> 295.11134 | X19: =Model!AD45 -> 358.09711 | Y19: =Model!AE45 -> 374.51536 | Z19: =Model!AF45 -> 395.85242 | AA19: =Model!AG45 -> 422.14236 | AC19: =IFERROR((V19/T19)^(1/(V$4-T$4))-1,"N/A") -> 0.29514533 | AE19: =IFERROR((AA19/V19)^(1/(AA$4-V$4))-1,"N/A") -> 0.061133577
C20: Margin | G20: =G19/G$8 -> 0.44267045 | H20: =H19/H$8 -> 0.50615004 | I20: =I19/I$8 -> 0.46032652 | J20: =J19/J$8 -> 0.37027271 | K20: =K19/K$8 -> 0.43800225 | L20: =L19/L$8 -> 0.36886 | M20: =M19/M$8 -> 0.36921091 | N20: =N19/N$8 -> 0.36927412 | ... R20: =R19/R$8 -> 0.36195823 | T20: =T19/T$8 -> 0.35376821 | U20: =U19/U$8 -> 0.41023252 | V20: =V19/V$8 -> 0.44008954 | W20: =W19/W$8 -> 0.38493271 | X20: =X19/X$8 -> 0.36821254 | Y20: =Y19/Y$8 -> 0.35990146 | Z20: =Z19/Z$8 -> 0.36057434 | AA20: =AA19/AA$8 -> 0.36095314
C21: YoY % Growth | K21: =K19/G19-1 -> -0.11502291 | L21: =L19/H19-1 -> -0.1064871 | M21: =M19/I19-1 -> -0.069467879 | N21: =N19/J19-1 -> 0.065831113 | O21: =O19/K19-1 -> 0.092669199 | P21: =P19/L19-1 -> 0.31341359 | Q21: =Q19/M19-1 -> 0.25426372 | R21: =R19/N19-1 -> 0.20807376 | U21: =U19/T19-1 -> 0.21463091 | V21: =V19/U19-1 -> 0.38099681 | W21: =W19/V19-1 -> -0.05946006 | X21: =X19/W19-1 -> 0.21343056 | Y21: =Y19/X19-1 -> 0.045848579 | Z21: =Z19/Y19-1 -> 0.05697246 | AA21: =AA19/Z19-1 -> 0.066413498
C23: =Model!C57 -> Adj. EPS (Diluted) | G23: =Model!P57 -> 1.0909158 | H23: =Model!Q57 -> 1.0148025 | I23: =Model!R57 -> 0.97375 | J23: =Model!S57 -> 1.2530769 | K23: =Model!U57 -> 0.98668992 | L23: =Model!V57 -> 0.87400613 | M23: =Model!W57 -> 0.9289711 | N23: =Model!X57 -> 1.0098351 | O23: =Model!Z57 -> 1.1213841 | P23: =Model!AA57 -> 1.185597 | Q23: =Model!AB57 -> 1.2097494 | R23: =Model!AC57 -> 1.265593 | T23: =Model!J57 -> 2.0297218 | U23: =Model!O57 -> 2.613321 | V23: =Model!T57 -> 5.3949628 | W23: =Model!Y57 -> 3.7993392 | X23: =Model!AD57 -> 4.782132 | Y23: =Model!AE57 -> 5.2892288 | Z23: =Model!AF57 -> 5.5611767 | AA23: =Model!AG57 -> 5.965623 | AC23: =IFERROR((V23/T23)^(1/(V$4-T$4))-1,"N/A") -> 0.63033169 | AE23: =IFERROR((AA23/V23)^(1/(AA$4-V$4))-1,"N/A") -> 0.020313118
C24: YoY % Growth | K24: =K23/G23-1 -> -0.095539817 | L24: =L23/H23-1 -> -0.13874264 | M24: =M23/I23-1 -> -0.045986033 | N24: =N23/J23-1 -> -0.19411566 | O24: =O23/K23-1 -> 0.13651111 | P24: =P23/L23-1 -> 0.35650874 | Q24: =Q23/M23-1 -> 0.30224655 | R24: =R23/N23-1 -> 0.25326703 | U24: =IF(ISERROR(U23/T23-1),"NA",(U23/T23-1)) -> 0.28752669 | V24: =IF(ISERROR(V23/U23-1),"NA",(V23/U23-1)) -> 1.0644088 | W24: =IF(ISERROR(W23/V23-1),"NA",(W23/V23-1)) -> -0.29576174 | X24: =IF(ISERROR(X23/W23-1),"NA",(X23/W23-1)) -> 0.25867467 | Y24: =IF(ISERROR(Y23/X23-1),"NA",(Y23/X23-1)) -> 0.10603989 | Z24: =IF(ISERROR(Z23/Y23-1),"NA",(Z23/Y23-1)) -> 0.051415408 | AA24: =IF(ISERROR(AA23/Z23-1),"NA",(AA23/Z23-1)) -> 0.072726758
C27: =Model!C61 -> EBITDA | G27: =Model!P61 -> 61.488 | H27: =Model!Q61 -> 46.252 | I27: =Model!R61 -> 51.239 | J27: =Model!S61 -> 61.223 | K27: =Model!U61 -> 53.65 | L27: =Model!V61 -> 59.403143 | M27: =Model!W61 -> 63.053445 | N27: =Model!X61 -> 68.339172 | O27: =Model!Z61 -> 73.080538 | P27: =Model!AA61 -> 77.465371 | Q27: =Model!AB61 -> 82.316664 | R27: =Model!AC61 -> 86.117992 | T27: =Model!J61 -> 161.848 | U27: =Model!O61 -> 159.471 | V27: =Model!T61 -> 220.202 | W27: =Model!Y61 -> 244.44576 | X27: =Model!AD61 -> 318.98056 | Y27: =Model!AE61 -> 346.72968 | Z27: =Model!AF61 -> 362.39651 | AA27: =Model!AG61 -> 386.05896 | AC27: =IFERROR((V27/T27)^(1/(V$4-T$4))-1,"N/A") -> 0.16642538 | AE27: =IFERROR((AA27/V27)^(1/(AA$4-V$4))-1,"N/A") -> 0.11883611
C28: Margin | G28: =G27/G$8 -> 0.31254861 | H28: =H27/H$8 -> 0.30834872 | I28: =I27/I$8 -> 0.30452095 | J28: =J27/J$8 -> 0.30924924 | K28: =K27/K$8 -> 0.30490231 | L28: =L27/L$8 -> 0.323 | M28: =M27/M$8 -> 0.323 | N28: =N27/N$8 -> 0.323 | ... R28: =R27/R$8 -> 0.33025 | T28: =T27/T$8 -> 0.30609377 | U28: =U27/U$8 -> 0.28793591 | V28: =V27/V$8 -> 0.3088543 | W28: =W27/W$8 -> 0.31884634 | X28: =X27/X$8 -> 0.32799104 | Y28: =Y27/Y$8 -> 0.3332 | Z28: =Z27/Z$8 -> 0.3301 | AA28: =AA27/AA$8 -> 0.3301
C29: YoY % Growth | K29: =K27/G27-1 -> -0.12747203 | L29: =L27/H27-1 -> 0.28433675 | M29: =M27/I27-1 -> 0.23057525 | N29: =N27/J27-1 -> 0.11623364 | O29: =O27/K27-1 -> 0.36217219 | P29: =P27/L27-1 -> 0.30406181 | Q29: =Q27/M27-1 -> 0.3055062 | R29: =R27/N27-1 -> 0.26015561 | U29: =U27/T27-1 -> -0.01468662 | V29: =V27/U27-1 -> 0.38082786 | W29: =W27/V27-1 -> 0.11009782 | X29: =X27/W27-1 -> 0.30491346 | Y29: =Y27/X27-1 -> 0.086993122 | Z29: =Z27/Y27-1 -> 0.045184574 | AA29: =AA27/Z27-1 -> 0.065294368
G31: =G$5 -> Quarterly | T31: =T$5 -> Annuals
A32: x | C32: ="Consolidated "&Model!C120 -> Consolidated Balance Sheet | G32: =G$6 -> 1Q25 | H32: =H$6 -> 2Q25 | I32: =I$6 -> 3Q25 | J32: =J$6 -> 4Q25 | K32: =K$6 -> 1Q26 | L32: =L$6 -> 2Q26e | M32: =M$6 -> 3Q26e | N32: =N$6 -> 4Q26e | ... R32: =R$6 -> 4Q27e | T32: =T$6 -> 2023 | U32: =U$6 -> 2024 | V32: =V$6 -> 2025 | W32: =W$6 -> 2026e | X32: =X$6 -> 2027e | Y32: =Y$6 -> 2028e | Z32: =Z$6 -> 2029e | AA32: =AA$6 -> 2030e
C34: =Model!C122 -> Cash & Cash Equivalents | G34: =Model!P122 -> 151.663 | H34: =Model!Q122 -> 193.771 | I34: =Model!R122 -> 285.553 | J34: =Model!S122 -> 229.161 | K34: =Model!U122 -> 263.347 | L34: =Model!V122 -> 261.16987 | M34: =Model!W122 -> 283.12019 | N34: =Model!X122 -> 273.99227 | O34: =Model!Z122 -> 248.19035 | P34: =Model!AA122 -> 244.48216 | Q34: =Model!AB122 -> 235.06938 | R34: =Model!AC122 -> 206.78503 | T34: =Model!J122 -> 99.686 | U34: =Model!O122 -> 114.634 | V34: =Model!T122 -> 229.161 | W34: =Model!Y122 -> 273.99227 | X34: =Model!AD122 -> 206.78503 | Y34: =Model!AE122 -> 256.12555 | Z34: =Model!AF122 -> 269.77717 | AA34: =Model!AG122 -> 252.11707
C35: =Model!C123 -> Fees Receivable | G35: =Model!P123 -> 141.099 | H35: =Model!Q123 -> 95.509 | I35: =Model!R123 -> 135.622 | J35: =Model!S123 -> 181.411 | K35: =Model!U123 -> 158.061 | L35: =Model!V123 -> 159.6587 | M35: =Model!W123 -> 167.62761 | N35: =Model!X123 -> 181.67972 | O35: =Model!Z123 -> 212.18164 | P35: =Model!AA123 -> 224.91254 | Q35: =Model!AB123 -> 232.9998 | R35: =Model!AC123 -> 243.75958 | T35: =Model!J123 -> 47.14 | U35: =Model!O123 -> 108.291 | V35: =Model!T123 -> 181.411 | W35: =Model!Y123 -> 181.67972 | X35: =Model!AD123 -> 243.75958 | Y35: =Model!AE123 -> 222.37592 | Z35: =Model!AF123 -> 240.62215 | AA35: =Model!AG123 -> 256.33342
C36: =Model!C124 -> Inventory | G36: =Model!P124 -> 0 | H36: =Model!Q124 -> 0 | I36: =Model!R124 -> 0 | J36: =Model!S124 -> 0 | K36: =Model!U124 -> 0 | L36: =Model!V124 -> 0 | M36: =Model!W124 -> 0 | N36: =Model!X124 -> 0 | O36: =Model!Z124 -> 0 | P36: =Model!AA124 -> 0 | Q36: =Model!AB124 -> 0 | R36: =Model!AC124 -> 0 | T36: =Model!J124 -> 0 | U36: =Model!O124 -> 0 | V36: =Model!T124 -> 0 | W36: =Model!Y124 -> 0 | X36: =Model!AD124 -> 0 | Y36: =Model!AE124 -> 0 | Z36: =Model!AF124 -> 0 | AA36: =Model!AG124 -> 0
C37: =Model!C125 -> Prepaid & Other Current Assets | G37: =Model!P125 -> 26.492 | H37: =Model!Q125 -> 39.075 | I37: =Model!R125 -> 36.643 | J37: =Model!S125 -> 33.806 | K37: =Model!U125 -> 36.945 | L37: =Model!V125 -> 36.782132 | M37: =Model!W125 -> 39.042381 | N37: =Model!X125 -> 42.315277 | O37: =Model!Z125 -> 44.903557 | P37: =Model!AA125 -> 47.59777 | Q37: =Model!AB125 -> 49.851121 | R37: =Model!AC125 -> 52.153212 | T37: =Model!J125 -> 21.807 | U37: =Model!O125 -> 24.208 | V37: =Model!T125 -> 33.806 | W37: =Model!Y125 -> 42.315277 | X37: =Model!AD125 -> 52.153212 | Y37: =Model!AE125 -> 57.23329 | Z37: =Model!AF125 -> 60.381121 | AA37: =Model!AG125 -> 64.323668
C38: =Model!C126 -> Total Current Assets | G38: =SUM(G34:G37) -> 319.254 | H38: =SUM(H34:H37) -> 328.355 | I38: =SUM(I34:I37) -> 457.818 | J38: =SUM(J34:J37) -> 444.378 | K38: =SUM(K34:K37) -> 458.353 | L38: =SUM(L34:L37) -> 457.61071 | M38: =SUM(M34:M37) -> 489.79018 | N38: =SUM(N34:N37) -> 497.98726 | ... R38: =SUM(R34:R37) -> 502.69782 | T38: =SUM(T34:T37) -> 168.633 | U38: =SUM(U34:U37) -> 247.133 | V38: =SUM(V34:V37) -> 444.378 | W38: =SUM(W34:W37) -> 497.98726 | X38: =SUM(X34:X37) -> 502.69782 | Y38: =SUM(Y34:Y37) -> 535.73476 | Z38: =SUM(Z34:Z37) -> 570.78044 | AA38: =SUM(AA34:AA37) -> 572.77416
C40: =Model!C128 -> PP&E, Net | G40: =Model!P128 -> 95.085 | H40: =Model!Q128 -> 95.255 | I40: =Model!R128 -> 97.373 | J40: =Model!S128 -> 98.999 | K40: =Model!U128 -> 96.677 | L40: =Model!V128 -> 98.883928 | M40: =Model!W128 -> 101.22647 | N40: =Model!X128 -> 103.34223 | O40: =Model!Z128 -> 105.13838 | P40: =Model!AA128 -> 107.04229 | Q40: =Model!AB128 -> 109.03633 | R40: =Model!AC128 -> 111.12246 | T40: =Model!J128 -> 90.752 | U40: =Model!O128 -> 95.438 | V40: =Model!T128 -> 98.999 | W40: =Model!Y128 -> 103.34223 | X40: =Model!AD128 -> 111.12246 | Y40: =Model!AE128 -> 119.4473 | Z40: =Model!AF128 -> 128.23001 | AA40: =Model!AG128 -> 137.58618
C41: =Model!C129 -> Investments and Assets of Consolidated Variable Interest Entities | G41: =Model!P129 -> 698.273 | H41: =Model!Q129 -> 743.533 | I41: =Model!R129 -> 780.836 | J41: =Model!S129 -> 838.453 | K41: =Model!U129 -> 945.038 | L41: =Model!V129 -> 973.38914 | M41: =Model!W129 -> 1002.5908 | N41: =Model!X129 -> 1032.6685 | O41: =Model!Z129 -> 1104.9553 | P41: =Model!AA129 -> 1171.2527 | Q41: =Model!AB129 -> 1235.6716 | R41: =Model!AC129 -> 1297.4551 | T41: =Model!J129 -> 647.246 | U41: =Model!O129 -> 666.742 | V41: =Model!T129 -> 838.453 | W41: =Model!Y129 -> 1032.6685 | X41: =Model!AD129 -> 1297.4551 | Y41: =Model!AE129 -> 1492.0734 | Z41: =Model!AF129 -> 1715.8844 | AA41: =Model!AG129 -> 1973.2671
C42: =Model!C130 -> Deferred Income Taxes | G42: =Model!P130 -> 259.301 | H42: =Model!Q130 -> 257.187 | I42: =Model!R130 -> 255.001 | J42: =Model!S130 -> 308.525 | K42: =Model!U130 -> 301.97 | L42: =Model!V130 -> 285.06152 | M42: =Model!W130 -> 302.57845 | N42: =Model!X130 -> 327.9434 | O42: =Model!Z130 -> 348.00256 | P42: =Model!AA130 -> 368.88272 | Q42: =Model!AB130 -> 386.34619 | R42: =Model!AC130 -> 404.18739 | T42: =Model!J130 -> 233.912 | U42: =Model!O130 -> 261.887 | V42: =Model!T130 -> 308.525 | W42: =Model!Y130 -> 327.9434 | X42: =Model!AD130 -> 404.18739 | Y42: =Model!AE130 -> 437.05422 | Z42: =Model!AF130 -> 461.0922 | AA42: =Model!AG130 -> 491.19892
C43: =Model!#REF! -> #REF! | G43: =Model!#REF! -> #REF! | H43: =Model!#REF! -> #REF! | I43: =Model!#REF! -> #REF! | J43: =Model!#REF! -> #REF! | K43: =Model!#REF! -> #REF! | L43: =Model!#REF! -> #REF! | M43: =Model!#REF! -> #REF! | N43: =Model!#REF! -> #REF! | ... R43: =Model!#REF! -> #REF! | T43: =Model!#REF! -> #REF! | U43: =Model!#REF! -> #REF! | V43: =Model!#REF! -> #REF! | W43: =Model!#REF! -> #REF! | X43: =Model!#REF! -> #REF! | Y43: =Model!#REF! -> #REF! | Z43: =Model!#REF! -> #REF! | AA43: =Model!#REF! -> #REF!
C44: =Model!C131 -> Total Non-Current Assets | G44: =SUM(G40:G42) -> 1052.659 | H44: =SUM(H40:H42) -> 1095.975 | I44: =SUM(I40:I42) -> 1133.21 | J44: =SUM(J40:J42) -> 1245.977 | K44: =SUM(K40:K42) -> 1343.685 | L44: =SUM(L40:L42) -> 1357.3346 | M44: =SUM(M40:M42) -> 1406.3957 | N44: =SUM(N40:N42) -> 1463.9542 | ... AA44: =SUM(AA40:AA42) -> 2602.0522
C46: =Model!C133 -> Total Assets | G46: =SUM(G38,G44) -> 1371.913 | H46: =SUM(H38,H44) -> 1424.33 | I46: =SUM(I38,I44) -> 1591.028 | J46: =SUM(J38,J44) -> 1690.355 | K46: =SUM(K38,K44) -> 1802.038 | L46: =SUM(L38,L44) -> 1814.9453 | M46: =SUM(M38,M44) -> 1896.1859 | N46: =SUM(N38,N44) -> 1961.9414 | ... R46: =SUM(R38,R44) -> 2315.4628 | T46: =SUM(T38,T44) -> 1140.543 | U46: =SUM(U38,U44) -> 1271.2 | V46: =SUM(V38,V44) -> 1690.355 | W46: =SUM(W38,W44) -> 1961.9414 | X46: =SUM(X38,X44) -> 2315.4628 | Y46: =SUM(Y38,Y44) -> 2584.3097 | Z46: =SUM(Z38,Z44) -> 2875.9871 | AA46: =SUM(AA38,AA44) -> 3174.8263
C48: =Model!C135 -> Accounts Payable | G48: =Model!P135 -> 4.683 | H48: =Model!Q135 -> 6.43 | I48: =Model!R135 -> 5.25 | J48: =Model!S135 -> 5.469 | K48: =Model!U135 -> 6.508 | L48: =Model!V135 -> 6.3024768 | M48: =Model!W135 -> 6.617047 | N48: =Model!X135 -> 7.1717495 | O48: =Model!Z135 -> 8.4379211 | P48: =Model!AA135 -> 8.1988466 | Q48: =Model!AB135 -> 8.4936557 | R48: =Model!AC135 -> 8.885887 | T48: =Model!J135 -> 4.559 | U48: =Model!O135 -> 4.505 | V48: =Model!T135 -> 5.469 | W48: =Model!Y135 -> 7.1717495 | X48: =Model!AD135 -> 8.885887 | Y48: =Model!AE135 -> 9.094605 | Z48: =Model!AF135 -> 9.5948083 | AA48: =Model!AG135 -> 10.221295
C49: =Model!C136 -> Accrued Liabilities | G49: =Model!P136 -> 109.325 | H49: =Model!Q136 -> 100.164 | I49: =Model!R136 -> 111.612 | J49: =Model!S136 -> 95.599 | K49: =Model!U136 -> 110.395 | L49: =Model!V136 -> 114.70508 | M49: =Model!W136 -> 121.75367 | N49: =Model!X136 -> 131.96019 | O49: =Model!Z136 -> 143.33215 | P49: =Model!AA136 -> 151.93208 | Q49: =Model!AB136 -> 159.12478 | R49: =Model!AC136 -> 166.47305 | T49: =Model!J136 -> 54.962 | U49: =Model!O136 -> 77.422 | V49: =Model!T136 -> 95.599 | W49: =Model!Y136 -> 131.96019 | X49: =Model!AD136 -> 166.47305 | Y49: =Model!AE136 -> 181.06532 | Z49: =Model!AF136 -> 191.02391 | AA49: =Model!AG136 -> 203.4967
C50: =Model!C137 -> Other Current Liabilities | G50: =Model!P137 -> 0 | H50: =Model!Q137 -> 0 | I50: =Model!R137 -> 0 | J50: =Model!S137 -> 0 | K50: =Model!U137 -> 0 | L50: =Model!V137 -> 0 | M50: =Model!W137 -> 0 | N50: =Model!X137 -> 0 | O50: =Model!Z137 -> 0 | P50: =Model!AA137 -> 0 | Q50: =Model!AB137 -> 0 | R50: =Model!AC137 -> 0 | T50: =Model!J137 -> 0 | U50: =Model!O137 -> 0 | V50: =Model!T137 -> 0 | W50: =Model!Y137 -> 0 | X50: =Model!AD137 -> 0 | Y50: =Model!AE137 -> 0 | Z50: =Model!AF137 -> 0 | AA50: =Model!AG137 -> 0
C51: =Model!C138 -> Total Current Liabilities (Excl. Debt) | G51: =SUM(G48:G50) -> 114.008 | H51: =SUM(H48:H50) -> 106.594 | I51: =SUM(I48:I50) -> 116.862 | J51: =SUM(J48:J50) -> 101.068 | K51: =SUM(K48:K50) -> 116.903 | L51: =SUM(L48:L50) -> 121.00756 | M51: =SUM(M48:M50) -> 128.37071 | N51: =SUM(N48:N50) -> 139.13194 | ... R51: =SUM(R48:R50) -> 175.35894 | T51: =SUM(T48:T50) -> 59.521 | U51: =SUM(U48:U50) -> 81.927 | V51: =SUM(V48:V50) -> 101.068 | W51: =SUM(W48:W50) -> 139.13194 | X51: =SUM(X48:X50) -> 175.35894 | Y51: =SUM(Y48:Y50) -> 190.15992 | Z51: =SUM(Z48:Z50) -> 200.61872 | AA51: =SUM(AA48:AA50) -> 213.71799
C53: =Model!C141 -> Revolver | G53: =Model!P141 -> 0 | H53: =Model!Q141 -> 0 | I53: =Model!R141 -> 0 | J53: =Model!S141 -> 0 | K53: =Model!U141 -> 0 | L53: =Model!V141 -> 0 | M53: =Model!W141 -> 0 | N53: =Model!X141 -> 0 | O53: =Model!Z141 -> 0 | P53: =Model!AA141 -> 0 | Q53: =Model!AB141 -> 0 | R53: =Model!AC141 -> 0 | T53: =Model!J141 -> 0 | U53: =Model!O141 -> 0 | V53: =Model!T141 -> 0 | W53: =Model!Y141 -> 0 | X53: =Model!AD141 -> 0 | Y53: =Model!AE141 -> 0 | Z53: =Model!AF141 -> 0 | AA53: =Model!AG141 -> 0
C54: =Model!C142 -> LT Debt (Incl. Current Portion) | G54: =Model!P142 -> 195.565 | H54: =Model!Q142 -> 194.971 | I54: =Model!R142 -> 292.024 | J54: =Model!S142 -> 290.303 | K54: =Model!U142 -> 288.582 | L54: =Model!V142 -> 287.082 | M54: =Model!W142 -> 285.582 | N54: =Model!X142 -> 284.082 | O54: =Model!Z142 -> 282.582 | P54: =Model!AA142 -> 281.082 | Q54: =Model!AB142 -> 279.582 | R54: =Model!AC142 -> 278.082 | T54: =Model!J142 -> 213.533 | U54: =Model!O142 -> 196.159 | V54: =Model!T142 -> 290.303 | W54: =Model!Y142 -> 284.082 | X54: =Model!AD142 -> 278.082 | Y54: =Model!AE142 -> 272.082 | Z54: =Model!AF142 -> 266.082 | AA54: =Model!AG142 -> 260.082
...

Sheet Model Output
B1: =Company_Name&" "&"("&Ticker&")"&" Valuation Overview" -> Hamilton Lane Inc. (HLNE) Valuation Overview | K1: Price Target Scenario: | N1: =Case_Scenario&" Case" -> Base Case | R1: Base Case Check | S1: =IF(N1="Base Case","","Check!") | Y1: P/E
B2: =Cover!C2 -> $ in Millions Except Per Share Data | K2: Current Share Price: | O2: =Share_Price -> 118.26 | Y2: EV/EBITDA
K3: Valuation Date: | O3: =Current_Date -> 45940
B4: ="Multiples Analysis "&"("&S21&")" -> Multiples Analysis (P/E) | I4: Return Summary
I6: Exit Multiple Method
I7: =Cover!I9 -> Implied Enterprise Value: | N7: =Cover!L9 -> 8117.2262
I8: =Cover!I10 -> Implied Equity Value: | N8: =Cover!L10 -> 7855.7462
I9: =Cover!I12 -> Implied Share Price: | N9: =Cover!L12 -> 144.22152
I10: =Cover!I13 -> % Return: | N10: =Cover!L13 -> 0.21952917
I12: =Cover!I15 -> Perpetuity Growth Method
I13: =Cover!I16 -> Implied Enterprise Value: | N13: =Cover!L16 -> 5013.5852
I14: =Cover!I17 -> Implied Equity Value: | N14: =Cover!L17 -> 4752.1052
I15: =Cover!I19 -> Implied Share Price: | N15: =Cover!L19 -> 87.242614
I16: =Cover!I20 -> % Return: | N16: =Cover!L20 -> -0.2622813
E18: Annuals | M18: CAGR | O18: CAGR
B19: Consolidated Financials | E19: =Summary!U6 -> 2024 | F19: =Summary!V6 -> 2025 | G19: =Summary!W6 -> 2026e | H19: =Summary!X6 -> 2027e | I19: =Summary!Y6 -> 2028e | J19: =Summary!Z6 -> 2029e | K19: =Summary!AA6 -> 2030e | M19: Historical | O19: Projected
B21: =Summary!C8 -> Revenue | D21: =Summary!T8 -> 528.753 | E21: =Summary!U8 -> 553.842 | F21: =Summary!V8 -> 712.964 | G21: =Summary!W8 -> 766.65695 | H21: =Summary!X8 -> 972.5283 | I21: =Summary!Y8 -> 1040.6053 | J21: =Summary!Z8 -> 1097.8386 | K21: =Summary!AA8 -> 1169.5212 | M21: =Summary!AC8 -> 0.16120094 | O21: =Summary!AE8 -> 0.10404837 | R21: Multiple Toggle | S21: P/E
B22: =Summary!C9 -> YoY % Growth | E22: =Summary!U9 -> 0.047449376 | F22: =Summary!V9 -> 0.28730577 | G22: =Summary!W9 -> 0.075309483 | H22: =Summary!X9 -> 0.26853125 | I22: =Summary!Y9 -> 0.07 | J22: =Summary!Z9 -> 0.055 | K22: =Summary!AA9 -> 0.065294368
R23: Multiples Analysis | S23: EV/EBITDA | T23: P/E | U23: Chart
B24: =Summary!C11 -> Gross Profit | D24: =Summary!T11 -> 528.753 | E24: =Summary!U11 -> 553.842 | F24: =Summary!V11 -> 712.964 | G24: =Summary!W11 -> 766.65695 | H24: =Summary!X11 -> 972.5283 | I24: =Summary!Y11 -> 1040.6053 | J24: =Summary!Z11 -> 1097.8386 | K24: =Summary!AA11 -> 1169.5212 | M24: =Summary!AC11 -> 0.16120094 | O24: =Summary!AE11 -> 0.10404837 | R24: Entry Multiple | S24: =Valuation!D12 -> 22.107789 | T24: =Valuation!D11 -> 25.058916 | U24: =IF($S$21=$S$23,S24,T24) -> 25.058916
B25: =Summary!C12 -> % Margin | E25: =Summary!U12 -> 1 | F25: =Summary!V12 -> 1 | G25: =Summary!W12 -> 1 | H25: =Summary!X12 -> 1 | I25: =Summary!Y12 -> 1 | J25: =Summary!Z12 -> 1 | K25: =Summary!AA12 -> 1 | R25: =Model!Y25 -> 2026e | S25: =(Comparables!H10*S30)/(Model!Y61) -> 24.14901 | T25: =(Comparables!$G$10*S30)/Summary!W19 -> 18.816316 | U25: =IF($S$21=$S$23,S25,T25) -> 18.816316
B26: =Summary!C13 -> YoY % Growth | E26: =Summary!U13 -> 0.047449376 | F26: =Summary!V13 -> 0.28730577 | G26: =Summary!W13 -> 0.075309483 | H26: =Summary!X13 -> 0.26853125 | I26: =Summary!Y13 -> 0.07 | J26: =Summary!Z13 -> 0.055 | K26: =Summary!AA13 -> 0.065294368 | R26: =Summary!AA6 -> 2030e | S26: =(Comparables!H10*S30)/(Model!AG61) -> 15.29073 | T26: =(Comparables!$G$10*S30)/Summary!AA19 -> 13.154113 | U26: =IF($S$21=$S$23,S26,T26) -> 13.154113
R27: Exit Multiple | S27: =Valuation!K60 -> 25 | T27: =Valuation!K72/Summary!AA19 -> 18.609235 | U27: =IF($S$21=$S$23,S27,T27) -> 18.609235
B28: =Summary!C27 -> EBITDA | D28: =Summary!T27 -> 161.848 | E28: =Summary!U27 -> 159.471 | F28: =Summary!V27 -> 220.202 | G28: =Summary!W27 -> 244.44576 | H28: =Summary!X27 -> 318.98056 | I28: =Summary!Y27 -> 346.72968 | J28: =Summary!Z27 -> 362.39651 | K28: =Summary!AA27 -> 386.05896 | M28: =Summary!AC27 -> 0.16642538 | O28: =Summary!AE27 -> 0.11883611 | R28: Implied PGM | S28: =Valuation!K79 -> 13.895187 | T28: =Valuation!R72/Summary!AA19 -> 11.257115 | U28: =IF($S$21=$S$23,S28,T28) -> 11.257115
B29: =Summary!C28 -> Margin | E29: =Summary!U28 -> 0.28793591 | F29: =Summary!V28 -> 0.3088543 | G29: =Summary!W28 -> 0.31884634 | H29: =Summary!X28 -> 0.32799104 | I29: =Summary!Y28 -> 0.3332 | J29: =Summary!Z28 -> 0.3301 | K29: =Summary!AA28 -> 0.3301
B30: =Summary!C29 -> YoY % Growth | E30: =Summary!U17 -> 0.024613192 | F30: =Summary!V17 -> 0.28775878 | G30: =Summary!W29 -> 0.11009782 | H30: =Summary!X29 -> 0.30491346 | I30: =Summary!Y29 -> 0.086993122 | J30: =Summary!Z29 -> 0.045184574 | K30: =Summary!AA29 -> 0.065294368 | R30: Financials Multiplier | S30: =IF($B$2="$ in Millions Except Per Share Data",1,IF($B$2="$ in Thousands Except Per Share Data",1000,IF($B$2="$ in Billions Except Per Share Data",0.001,0))) -> 1
B32: =Summary!C19 -> Net Income (Loss) | D32: =Summary!T19 -> 187.056 | E32: =Summary!U19 -> 227.204 | F32: =Summary!V19 -> 313.768 | G32: =Summary!W19 -> 295.11134 | H32: =Summary!X19 -> 358.09711 | I32: =Summary!Y19 -> 374.51536 | J32: =Summary!Z19 -> 395.85242 | K32: =Summary!AA19 -> 422.14236 | M32: =Summary!AC19 -> 0.29514533 | O32: =Summary!AE19 -> 0.061133577
B33: =Summary!C20 -> Margin | E33: =Summary!U20 -> 0.41023252 | F33: =Summary!V20 -> 0.44008954 | G33: =Summary!W20 -> 0.38493271 | H33: =Summary!X20 -> 0.36821254 | I33: =Summary!Y20 -> 0.35990146 | J33: =Summary!Z20 -> 0.36057434 | K33: =Summary!AA20 -> 0.36095314
B34: =Summary!C21 -> YoY % Growth | E34: =Summary!U21 -> 0.21463091 | F34: =Summary!V21 -> 0.38099681 | G34: =Summary!W21 -> -0.05946006 | H34: =Summary!X21 -> 0.21343056 | I34: =Summary!Y21 -> 0.045848579 | J34: =Summary!Z21 -> 0.05697246 | K34: =Summary!AA21 -> 0.066413498
B36: =Summary!C23 -> Adj. EPS (Diluted) | D36: =Summary!T23 -> 2.0297218 | E36: =Summary!U23 -> 2.613321 | F36: =Summary!V23 -> 5.3949628 | G36: =Summary!W23 -> 3.7993392 | H36: =Summary!X23 -> 4.782132 | I36: =Summary!Y23 -> 5.2892288 | J36: =Summary!Z23 -> 5.5611767 | K36: =Summary!AA23 -> 5.965623 | M36: =Summary!AC23 -> 0.63033169 | O36: =Summary!AE23 -> 0.020313118
B37: =Summary!C24 -> YoY % Growth | E37: =Summary!U24 -> 0.28752669 | F37: =Summary!V24 -> 1.0644088 | G37: =Summary!W24 -> -0.29576174 | H37: =Summary!X24 -> 0.25867467 | I37: =Summary!Y24 -> 0.10603989 | J37: =Summary!Z24 -> 0.051415408 | K37: =Summary!AA24 -> 0.072726758
B39: Free Cash Flow | D39: =Model!J114 -> 191.153 | E39: =Model!O114 -> 161.313 | F39: =Model!T114 -> 238.051 | G39: =Model!Y114 -> 292.20213 | H39: =Model!AD114 -> 289.95117 | I39: =Model!AE114 -> 387.78289 | J39: =Model!AF114 -> 369.32368 | K39: =Model!AG114 -> 397.70141 | M39: =IFERROR((F39/D39)^(1/2)-1,"N/A") -> 0.11594925 | O39: =IFERROR((K39/G39)^(1/4)-1,"N/A") -> 0.080111121
B40: YoY % Growth | E40: =E39/D39-1 -> -0.15610532 | F40: =F39/E39-1 -> 0.47570872 | G40: =G39/F39-1 -> 0.22747701 | H40: =H39/G39-1 -> -0.0077034412 | I40: =I39/H39-1 -> 0.33740758 | J40: =J39/I39-1 -> -0.047601908 | K40: =K39/J39-1 -> 0.076837001
E42: Annuals | M42: Average | O42: Average
B43: Capitalization and Key Ratios | E43: =E19 -> 2024 | F43: =F19 -> 2025 | G43: =G19 -> 2026e | H43: =H19 -> 2027e | I43: =I19 -> 2028e | J43: =J19 -> 2029e | K43: =K19 -> 2030e | M43: Historical | O43: Projected
B44: =Summary!C91 -> Leverage
B45: =Summary!C92 -> Total Debt / EBITDA | D45: =Summary!T92 -> 1.3193428 | E45: =Summary!U92 -> 1.2300606 | F45: =Summary!V92 -> 1.3183486 | G45: =Summary!W92 -> 1.1621474 | H45: =Summary!X92 -> 0.87178352 | I45: =Summary!Y92 -> 0.78470929 | J45: =Summary!Z92 -> 0.73422892 | K45: =Summary!AA92 -> 0.67368466 | M45: =AVERAGE(D45:F45) -> 1.2892507 | O45: =AVERAGE(G45:K45) -> 0.84531075
B46: =Summary!C93 -> Total Debt / Equity | D46: =Summary!T93 -> 0.37188432 | E46: =Summary!U93 -> 0.29019407 | F46: =Summary!V93 -> 0.31421644 | G46: =Summary!W93 -> 0.25404395 | H46: =Summary!X93 -> 0.19866935 | I46: =Summary!Y93 -> 0.16387608 | J46: =Summary!Z93 -> 0.13748538 | K46: =Summary!AA93 -> 0.11758546 | M46: =AVERAGE(D46:F46) -> 0.32543161 | O46: =AVERAGE(G46:K46) -> 0.17433204
B47: =Summary!C94 -> Total Debt / Total Assets | D47: =Summary!T94 -> 0.18722047 | E47: =Summary!U94 -> 0.1543101 | F47: =Summary!V94 -> 0.17174085 | G47: =Summary!W94 -> 0.14479637 | H47: =Summary!X94 -> 0.1200978 | I47: =Summary!Y94 -> 0.10528227 | J47: =Summary!Z94 -> 0.092518497 | K47: =Summary!AA94 -> 0.081920071 | M47: =AVERAGE(D47:F47) -> 0.17109047 | O47: =AVERAGE(G47:K47) -> 0.108923
B49: =Summary!C103 -> Liquidity
...

Sheet Football Field
C1: =Company_Name&" - "&MID(CELL("filename",A1),FIND("]",CELL("filename",A1))+1,255)&": "&Case_Scenario&" Case" -> Hamilton Lane Inc. - Football Field: Base Case
C2: =Cover!C2 -> $ in Millions Except Per Share Data
A4: x | O4: Valuation Method: | T4: Downside | U4: Delta | V4: Upside | W4: x
O5: =TEXT(Valuation!E108,"0.0%")&" - "&TEXT(Valuation!E110,"0.0%")&" WACC"&" & "&TEXT(Valuation!G106,"0.0%")&" - "&TEXT(Valuation!I106,"0.0%")&" PGR" -> 8.0% - 9.0% WACC & 1.5% - 2.5% PGR | T5: =Valuation!G108 -> 195.04955 | U5: =V5-T5 -> 20.385916 | V5: =Valuation!I110 -> 215.43546
O6: =TEXT(Valuation!E100,"0.0%")&" - "&TEXT(Valuation!E102,"0.0%")&" WACC"&" & "&TEXT(Valuation!G98,"0.0x")&" - "&TEXT(Valuation!I98,"0.0x")&" Exit Multiple" -> 8.0% - 9.0% WACC & 24.0x - 26.0x Exit Multiple | T6: =Valuation!G100 -> 250.78262 | U6: =V6-T6 -> 27.264041 | V6: =Valuation!I102 -> 278.04666
O8: =Valuation!F184&": "&TEXT(Valuation!G185,"0.0x")&" - "&TEXT(Valuation!I185,"0.0x") -> NTM EV/EBITDA Spread to Comps: 29.3x - 31.3x | T8: =Valuation!G187 -> 209.23348 | U8: =V8-T8 -> 100.49025 | V8: =Valuation!I189 -> 309.72373
O9: =Valuation!F176&": "&TEXT(Valuation!G177,"0.0x")&" - "&TEXT(Valuation!I177,"0.0x") -> NTM EV/EBITDA: 21.5x - 23.5x | T9: =Valuation!G179 -> 197.97414 | U9: =V9-T9 -> 97.988172 | V9: =Valuation!I181 -> 295.96231
O10: =Valuation!F168&": "&TEXT(Valuation!G169,"0.0x")&" - "&TEXT(Valuation!I169,"0.0x") -> NTM P/E Spread to Comps: 33.2x - 35.2x | T10: =Valuation!G171 -> 241.4239 | U10: =V10-T10 -> 85.926567 | V10: =Valuation!I173 -> 327.35047
O11: =Valuation!F160&": "&TEXT(Valuation!G161,"0.0x")&" - "&TEXT(Valuation!I161,"0.0x") -> NTM P/E: 26.9x - 28.9x | T11: =Valuation!G163 -> 234.48845 | U11: =V11-T11 -> 84.385357 | V11: =Valuation!I165 -> 318.87381
O13: =Valuation!F260&": "&TEXT(Valuation!G261,"0.0x")&" - "&TEXT(Valuation!I261,"0.0x") -> 2009-2018 Early Cycle EV/EBITDA Spread to Comps: 17.7x - 19.7x | T13: =Valuation!G263 -> 202.21364 | U13: =V13-T13 -> 39.300331 | V13: =Valuation!I263 -> 241.51397
O14: =Valuation!F252&": "&TEXT(Valuation!G253,"0.0x")&" - "&TEXT(Valuation!I253,"0.0x") -> 2009-2018 Early Cycle EV/EBITDA: 10.8x - 12.8x | T14: =Valuation!G255 -> 99.103102 | U14: =V14-T14 -> 39.300331 | V14: =Valuation!I255 -> 138.40343
O15: =Valuation!F244&": "&TEXT(Valuation!G245,"0.0x")&" - "&TEXT(Valuation!I245,"0.0x") -> 2009-2018 Early Cycle P/E Spread to Comps: 42.9x - 44.9x | T15: =Valuation!G247 -> 267.04261 | U15: =V15-T15 -> 26.408301 | V15: =Valuation!I247 -> 293.45091
O16: =Valuation!F236&": "&TEXT(Valuation!G237,"0.0x")&" - "&TEXT(Valuation!I237,"0.0x") -> 2009-2018 Early Cycle P/E: 19.7x - 21.7x | T16: =Valuation!G239 -> 205.30919 | U16: =V16-T16 -> 26.408301 | V16: =Valuation!I239 -> 231.71749
O18: 52-Week Price Range: | T18: =Share_Price_Low -> 124.1 | U18: =V18-T18 -> 79.62 | V18: =Share_Price_High -> 203.72
O19: Median Value: | T19: =MEDIAN(T5:T18) -> 205.30919 | U19: =MEDIAN(U5:U18) -> 39.300331 | V19: =MEDIAN(V5:V18) -> 278.04666
A20: x | O20: Implied Return (%): | T20: =T19/Share_Price-1 -> 0.73608312 | V20: =V19/Share_Price-1 -> 1.3511471
T22: Reference Points for Price Axis
U24: Price
A25: x | T25: High | U25: =MAX(V5:V18)*1.1 -> 360.08551 | W25: x
T26: Low | U26: =MIN(T5:T18)*0.9 -> 89.192792
A30: x

Sheet Integrity
C1: =Company_Name&" - "&MID(CELL("filename",A1),FIND("]",CELL("filename",A1))+1,255) -> Hamilton Lane Inc. - Integrity
C3: Integrity
C4: Metric
C6: Model:
C7: Balance Sheet Check: | D7: =SUM(Model!F159:AG159) -> 0
C8: Base Case: | D8: =IF(Case_Scenario="Base","OK!","Check!") -> OK!
C9: Interest Expense: | D9: =IF(Model!C8="On","OK!","CHECK - OFF") -> OK!
C10: Valuation Date:
C12: Formatting:
C13: Valuation Sensitivity Tables: | D13: =SUM(Valuation!F92,Valuation!K92,Valuation!P92,Valuation!F151:F155,Valuation!L151:L155,Valuation!F227:F231,Valuation!L227:L231) -> 0
C14: WACC Tables: | D14: =SUM(WACC!Q20,WACC!N33:N37) -> 0
C16: Font Toggles:
C17: Cover: | D17: =Cover!$Q$2 -> Report
C18: Revenue Build: | D18: ='Revenue Build'!$C$22 -> Report
C19: Model: | D19: =Model!$C$5 -> Report
C20: WACC | D20: =WACC!R5 -> Report
C21: Valuation: | D21: =Valuation!$R$2 -> Report
C23: Change Log
C24: Date | D24: Version | E24: Operator | F24: Revisions
C25: 44476 | D25: v01 | E25: Nate Latimer | F25: Top Down / Bottom Up toggle integration and Capital IQ comps sheet w/ ID Locator
C26: 44476 | D26: v02 | E26: Carson Shaner | F26: Formulas for EBIT/EBITDA margins on earnings sheets
C27: 44480 | D27: v03 | E27: Nate Latimer | F27: Historical driver adjustments to reflect Top Down / Bottom Up Toggle
C28: 44488 | D28: v04 | E28: Nate Latimer | F28: Bug fixes to model output, comps sheet and WACC Comps Relevered Beta
C29: 44489 | D29: v05 | E29: Lilianna Ruby | F29: Changed the year end driver in 2021 and 2022 to correctly pull operating margins
C30: 44491 | D30: v06 | E30: Lilianna Ruby | F30: Changed the first page to add 365 to your previous fiscal year
C31: 44496 | D31: v07 | E31: Carson Shaner | F31: Changed Model Output FCF formula, broke apart D&A for historical periods, added checks for EPS & EBITDA in Valuation sensitivity tables, added segment D&A breakdown, linked and fixed SOTP valuation
C32: 44503 | D32: v08 | E32: Lilianna Ruby | F32: Changed average of comps on valuation tab to average all peers not just the first one
C33: 44512 | D33: v09 | E33: Lilianna Ruby | F33: Rolled model forward to reflect 3Q'21. Also changed the multiples tab so the quarters roll forward and end on correct date.
C34: 44522 | D34: v10 | E34: Lilianna Ruby | F34: Fully fixed the multiples tab so it is automatic and fully functional. Also fixed definition of NTM_EPS and NTM_EBITDA
C35: 44582 | D35: v13 | E35: Carson Shaner | F35: Changed EPS, EBITDA, shares, tax rate, etc., to formulas so we do not have to hardcode them.
C36: 44584 | D36: v14 | E36: Lilianna Ruby | F36: Changed discount factor to mid year
... C47: 45581 | D47: v25 | E47: Conor McCabe | F47: Added font toggle to integrity tab for WACC tab. Formatted Comparables Tab.

Sheet Revenue Build
C1: =Company_Name&" - "&MID(CELL("filename",A1),FIND("]",CELL("filename",A1))+1,255)&": "&Case_Scenario&" Case" -> Hamilton Lane Inc. - Revenue Build: Base Case
C2: =Cover!C2 -> $ in Millions Except Per Share Data
A4: x | C4: Segments
C6: =C30&" Methodology" -> Total Company Revenue Methodology
C7: Segment
C8: =C32&" Methodology" -> Management & Advisory Fees Methodology
C9: =IF(Company_Rev_Methodology="Segment","Segment",IF(Company_Rev_Methodology="Activity-Based","Activity-Based",IF(Company_Rev_Methodology="Backlog","Backlog",IF(Company_Rev_Methodology="Mixed",D9,"--")))) -> Segment | D9: Backlog
C10: =C35&" Methodology" -> Incentive Fees Methodology
C11: =IF(Company_Rev_Methodology="Segment","Segment",IF(Company_Rev_Methodology="Activity-Based","Activity-Based",IF(Company_Rev_Methodology="Backlog","Backlog",IF(Company_Rev_Methodology="Mixed",D11,"--")))) -> Segment | D11: Activity-Based
C12: =C38&" Methodology" -> Segment 3 Revenue Methodology
C13: =IF(Company_Rev_Methodology="Segment","Segment",IF(Company_Rev_Methodology="Activity-Based","Activity-Based",IF(Company_Rev_Methodology="Backlog","Backlog",IF(Company_Rev_Methodology="Mixed",D13,"--")))) -> Segment | D13: Segment
C14: =C41&" Methodology" -> Segment 4 Revenue Methodology
C15: =IF(Company_Rev_Methodology="Segment","Segment",IF(Company_Rev_Methodology="Activity-Based","Activity-Based",IF(Company_Rev_Methodology="Backlog","Backlog",IF(Company_Rev_Methodology="Mixed",D15,"--")))) -> Segment | D15: Segment
C16: =C44&" Methodology" -> Segment 5 Revenue Methodology
C17: =IF(Company_Rev_Methodology="Segment","Segment",IF(Company_Rev_Methodology="Activity-Based","Activity-Based",IF(Company_Rev_Methodology="Backlog","Backlog",IF(Company_Rev_Methodology="Mixed",D17,"--")))) -> Segment | D17: Segment
C18: =C47&" Methodology" -> Segment 6 Revenue Methodology
C19: =IF(Company_Rev_Methodology="Segment","Segment",IF(Company_Rev_Methodology="Activity-Based","Activity-Based",IF(Company_Rev_Methodology="Backlog","Backlog",IF(Company_Rev_Methodology="Mixed",D19,"--")))) -> Segment | D19: Segment
C21: Font Toggle
C22: Report
C24: Annual vs. Quarterly
C25: Quarterly
J26: 1 | O26: 2 | T26: 3 | Y26: 4 | AD26: 5 | AE26: 6 | AF26: 7 | AG26: 8
AI27: CAGR
A28: x | C28: Summary | F28: =Model!F$25 -> 1Q23 | G28: =Model!G$25 -> 2Q23 | H28: =Model!H$25 -> 3Q23 | I28: =Model!I$25 -> 4Q23 | J28: =Model!J$25 -> 2023 | K28: =Model!K$25 -> 1Q24 | L28: =Model!L$25 -> 2Q24 | M28: =Model!M$25 -> 3Q24 | ... AG28: =Model!AG$25 -> 2030e | AI28: Historical | AJ28: Projected
C30: Total Company Revenue | F30: ='Segment Analysis'!F7 -> 135.509 | G30: ='Segment Analysis'!G7 -> 153.382 | H30: ='Segment Analysis'!H7 -> 127.074 | I30: ='Segment Analysis'!I7 -> 112.788 | J30: ='Segment Analysis'!J7 -> 528.753 | K30: ='Segment Analysis'!K7 -> 125.037 | L30: ='Segment Analysis'!L7 -> 126.876 | M30: ='Segment Analysis'!M7 -> 125.264 | ... U30: ='Segment Analysis'!U7 -> 175.958 | V30: =SUM(V32,V35,V38,V41,V44,V47,) -> 183.91066 | W30: =SUM(W32,W35,W38,W41,W44,W47,) -> 195.21191 | X30: =SUM(X32,X35,X38,X41,X44,X47,) -> 211.57639 | Y30: =SUM(U30:X30) -> 766.65695 | Z30: =SUM(Z32,Z35,Z38,Z41,Z44,Z47,) -> 224.51778 | AA30: =SUM(AA32,AA35,AA38,AA41,AA44,AA47,) -> 237.98885 | AB30: =SUM(AB32,AB35,AB38,AB41,AB44,AB47,) -> 249.25561 | AC30: =SUM(AC32,AC35,AC38,AC41,AC44,AC47,) -> 260.76606 | AD30: =SUM(Z30:AC30) -> 972.5283 | AE30: =SUM(AE32,AE35,AE38,AE41,AE44,AE47,) -> 1040.6053 | AF30: =SUM(AF32,AF35,AF38,AF41,AF44,AF47,) -> 1097.8386 | AG30: =SUM(AG32,AG35,AG38,AG41,AG44,AG47,) -> 1169.5212 | AI30: =IFERROR((T30/J30)^(1/3)-1,"--") -> 0.10476927 | AJ30: =IFERROR((AG30/T30)^(1/5)-1,"--") -> 0.10404837
C31: =IF($C$25="Quarterly","% Growth QoQ","% Growth YoY") -> % Growth QoQ | G31: =IF($C$25="Annual",'Segment Analysis'!G162,'Segment Analysis'!G182) -> 0.1318953 | H31: =IF($C$25="Annual",'Segment Analysis'!H162,'Segment Analysis'!H182) -> -0.17151947 | I31: =IF($C$25="Annual",'Segment Analysis'!I162,'Segment Analysis'!I182) -> -0.11242268 | K31: =IF($C$25="Annual",'Segment Analysis'!K162,'Segment Analysis'!K182) -> 0.10860198 | L31: =IF($C$25="Annual",'Segment Analysis'!L162,'Segment Analysis'!L182) -> 0.014707647 | M31: =IF($C$25="Annual",'Segment Analysis'!M162,'Segment Analysis'!M182) -> -0.012705319 | N31: =IF($C$25="Annual",'Segment Analysis'!N162,'Segment Analysis'!N182) -> 0.41034136 | O31: ='Segment Analysis'!O162 -> 0.047449376 | P31: =IF($C$25="Annual",'Segment Analysis'!P162,'Segment Analysis'!P182) -> 0.1135822 | Q31: =IF($C$25="Annual",'Segment Analysis'!Q162,'Segment Analysis'!Q182) -> -0.23754263 | R31: =IF($C$25="Annual",'Segment Analysis'!R162,'Segment Analysis'!R182) -> 0.12174748 | S31: =IF($C$25="Annual",'Segment Analysis'!S162,'Segment Analysis'!S182) -> 0.17658281 | T31: ='Segment Analysis'!T162 -> 0.28730577 | U31: =IF($C$25="Annual",'Segment Analysis'!U162,'Segment Analysis'!U182) -> -0.11120203 | V31: =IFERROR(V30/U30-1,"--") -> 0.045196354 | W31: =IFERROR(W30/V30-1,"--") -> 0.061449646 | X31: =IFERROR(X30/W30-1,"--") -> 0.083829314 | Y31: =IFERROR(Y30/T30-1,"--") -> 0.075309483 | Z31: =IFERROR(Z30/X30-1,"--") -> 0.061166549 | AA31: =IFERROR(AA30/Z30-1,"--") -> 0.06 | AB31: =IFERROR(AB30/AA30-1,"--") -> 0.047341527 | AC31: =IFERROR(AC30/AB30-1,"--") -> 0.046179325 | AD31: =IFERROR(AD30/Y30-1,"--") -> 0.26853125 | AE31: =IFERROR(AE30/AD30-1,"--") -> 0.07 | AF31: =IFERROR(AF30/AE30-1,"--") -> 0.055 | AG31: =IFERROR(AG30/AF30-1,"--") -> 0.065294368
C32: ='Segment Analysis'!C8 -> Management & Advisory Fees | F32: ='Segment Analysis'!F8 -> 85.946 | G32: ='Segment Analysis'!G8 -> 92.88 | H32: ='Segment Analysis'!H8 -> 97.355 | I32: ='Segment Analysis'!I8 -> 95.692 | J32: ='Segment Analysis'!J8 -> 371.873 | K32: ='Segment Analysis'!K8 -> 105.407 | L32: ='Segment Analysis'!L8 -> 109.184 | M32: ='Segment Analysis'!M8 -> 113.641 | ... U32: ='Segment Analysis'!U8 -> 133.696 | V32: =IF(Segment1_Rev_Methodology="Segment",V53,IF(Segment1_Rev_Methodology="Activity-Based",V91,IF(Segment1_Rev_Methodology="Backlog",V165,"--"))) -> 140.3808 | W32: =IF(Segment1_Rev_Methodology="Segment",W53,IF(Segment1_Rev_Methodology="Activity-Based",W91,IF(Segment1_Rev_Methodology="Backlog",W165,"--"))) -> 149.50555 | X32: =IF(Segment1_Rev_Methodology="Segment",X53,IF(Segment1_Rev_Methodology="Activity-Based",X91,IF(Segment1_Rev_Methodology="Backlog",X165,"--"))) -> 162.21352 | Y32: =SUM(U32:X32) -> 585.79588 | Z32: =IF(Segment1_Rev_Methodology="Segment",Z53,IF(Segment1_Rev_Methodology="Activity-Based",Z91,IF(Segment1_Rev_Methodology="Backlog",Z165,"--"))) -> 171.94634 | AA32: =IF(Segment1_Rev_Methodology="Segment",AA53,IF(Segment1_Rev_Methodology="Activity-Based",AA91,IF(Segment1_Rev_Methodology="Backlog",AA165,"--"))) -> 182.26312 | AB32: =IF(Segment1_Rev_Methodology="Segment",AB53,IF(Segment1_Rev_Methodology="Activity-Based",AB91,IF(Segment1_Rev_Methodology="Backlog",AB165,"--"))) -> 190.46496 | AC32: =IF(Segment1_Rev_Methodology="Segment",AC53,IF(Segment1_Rev_Methodology="Activity-Based",AC91,IF(Segment1_Rev_Methodology="Backlog",AC165,"--"))) -> 199.03588 | AD32: =SUM(Z32:AC32) -> 743.71029 | AE32: =IF(Segment1_Rev_Methodology="Segment",AE53,IF(Segment1_Rev_Methodology="Activity-Based",AE91,IF(Segment1_Rev_Methodology="Backlog",AE165,"--"))) -> 795.77001 | AF32: =IF(Segment1_Rev_Methodology="Segment",AF53,IF(Segment1_Rev_Methodology="Activity-Based",AF91,IF(Segment1_Rev_Methodology="Backlog",AF165,"--"))) -> 839.53736 | AG32: =IF(Segment1_Rev_Methodology="Segment",AG53,IF(Segment1_Rev_Methodology="Activity-Based",AG91,IF(Segment1_Rev_Methodology="Backlog",AG165,"--"))) -> 898.30497 | AI32: =IFERROR((T32/J32)^(1/3)-1,"--") -> 0.113828 | AJ32: =IFERROR((AG32/T32)^(1/5)-1,"--") -> 0.11818832
C33: =IF($C$25="Quarterly","% Growth QoQ","% Growth YoY") -> % Growth QoQ | G33: =IF($C$25="Annual",'Segment Analysis'!G163,'Segment Analysis'!G183) -> 0.080678566 | H33: =IF($C$25="Annual",'Segment Analysis'!H163,'Segment Analysis'!H183) -> 0.048180448 | I33: =IF($C$25="Annual",'Segment Analysis'!I163,'Segment Analysis'!I183) -> -0.017081814 | K33: =IF($C$25="Annual",'Segment Analysis'!K163,'Segment Analysis'!K183) -> 0.10152364 | L33: =IF($C$25="Annual",'Segment Analysis'!L163,'Segment Analysis'!L183) -> 0.035832535 | M33: =IF($C$25="Annual",'Segment Analysis'!M163,'Segment Analysis'!M183) -> 0.040820999 | N33: =IF($C$25="Annual",'Segment Analysis'!N163,'Segment Analysis'!N183) -> 0.088550787 | O33: ='Segment Analysis'!O163 -> 0.21529662 | P33: =IF($C$25="Annual",'Segment Analysis'!P163,'Segment Analysis'!P183) -> 0.13142663 | Q33: =IF($C$25="Annual",'Segment Analysis'!Q163,'Segment Analysis'!Q183) -> -0.14417485 | R33: =IF($C$25="Annual",'Segment Analysis'!R163,'Segment Analysis'!R183) -> 0.054256447 | S33: =IF($C$25="Annual",'Segment Analysis'!S163,'Segment Analysis'!S183) -> 0.012321629 | T33: ='Segment Analysis'!T163 -> 0.13703046 | U33: =IF($C$25="Annual",'Segment Analysis'!U163,'Segment Analysis'!U183) -> 0.045823621 | V33: =IFERROR(V32/U32-1,"--") -> 0.05 | W33: =IFERROR(W32/V32-1,"--") -> 0.065 | X33: =IFERROR(X32/W32-1,"--") -> 0.085 | Y33: =IFERROR(Y32/T32-1,"--") -> 0.1399801 | Z33: =IFERROR(Z32/X32-1,"--") -> 0.06 | AA33: =IFERROR(AA32/Z32-1,"--") -> 0.06 | AB33: =IFERROR(AB32/AA32-1,"--") -> 0.045 | AC33: =IFERROR(AC32/AB32-1,"--") -> 0.045 | AD33: =IFERROR(AD32/Y32-1,"--") -> 0.26957242 | AE33: =IFERROR(AE32/AD32-1,"--") -> 0.07 | AF33: =IFERROR(AF32/AE32-1,"--") -> 0.055 | AG33: =IFERROR(AG32/AF32-1,"--") -> 0.07
C34: % of Total Revenue | F34: ='Segment Analysis'!F16 -> 0.6342457 | G34: ='Segment Analysis'!G16 -> 0.60554694 | H34: ='Segment Analysis'!H16 -> 0.7661284 | I34: ='Segment Analysis'!I16 -> 0.84842359 | J34: ='Segment Analysis'!J16 -> 0.70330192 | K34: ='Segment Analysis'!K16 -> 0.84300647 | L34: ='Segment Analysis'!L16 -> 0.86055676 | M34: ='Segment Analysis'!M16 -> 0.90721197 | ... U34: ='Segment Analysis'!U16 -> 0.75981768 | V34: =V32/V$30 -> 0.76330975 | W34: =W32/W$30 -> 0.76586288 | X34: =X32/X$30 -> 0.76669012 | Y34: =Y32/Y$30 -> 0.76409126 | Z34: =Z32/Z$30 -> 0.76584729 | AA34: =AA32/AA$30 -> 0.76584729 | AB34: =AB32/AB$30 -> 0.7641351 | AC34: =AC32/AC$30 -> 0.76327371 | ... AG34: =AG32/AG$30 -> 0.76809633
C35: ='Segment Analysis'!C9 -> Incentive Fees | F35: ='Segment Analysis'!F9 -> 49.563 | G35: ='Segment Analysis'!G9 -> 60.502 | H35: ='Segment Analysis'!H9 -> 29.719 | I35: ='Segment Analysis'!I9 -> 17.096 | J35: ='Segment Analysis'!J9 -> 156.88 | K35: ='Segment Analysis'!K9 -> 19.63 | L35: ='Segment Analysis'!L9 -> 17.692 | M35: ='Segment Analysis'!M9 -> 11.623 | ... U35: ='Segment Analysis'!U9 -> 42.262 | V35: =IF(Segment2_Rev_Methodology="Segment",V59,IF(Segment2_Rev_Methodology="Activity-Based",V103,IF(Segment2_Rev_Methodology="Backlog",V177,"--"))) -> 43.52986 | W35: =IF(Segment2_Rev_Methodology="Segment",W59,IF(Segment2_Rev_Methodology="Activity-Based",W103,IF(Segment2_Rev_Methodology="Backlog",W177,"--"))) -> 45.706353 | X35: =IF(Segment2_Rev_Methodology="Segment",X59,IF(Segment2_Rev_Methodology="Activity-Based",X103,IF(Segment2_Rev_Methodology="Backlog",X177,"--"))) -> 49.362861 | Y35: =SUM(U35:X35) -> 180.86107 | Z35: =IF(Segment2_Rev_Methodology="Segment",Z59,IF(Segment2_Rev_Methodology="Activity-Based",Z103,IF(Segment2_Rev_Methodology="Backlog",Z177,"--"))) -> 52.571447 | AA35: =IF(Segment2_Rev_Methodology="Segment",AA59,IF(Segment2_Rev_Methodology="Activity-Based",AA103,IF(Segment2_Rev_Methodology="Backlog",AA177,"--"))) -> 55.725734 | AB35: =IF(Segment2_Rev_Methodology="Segment",AB59,IF(Segment2_Rev_Methodology="Activity-Based",AB103,IF(Segment2_Rev_Methodology="Backlog",AB177,"--"))) -> 58.790649 | AC35: =IF(Segment2_Rev_Methodology="Segment",AC59,IF(Segment2_Rev_Methodology="Activity-Based",AC103,IF(Segment2_Rev_Methodology="Backlog",AC177,"--"))) -> 61.730182 | AD35: =SUM(Z35:AC35) -> 228.81801 | AE35: =IF(Segment2_Rev_Methodology="Segment",AE59,IF(Segment2_Rev_Methodology="Activity-Based",AE103,IF(Segment2_Rev_Methodology="Backlog",AE177,"--"))) -> 244.83527 | AF35: =IF(Segment2_Rev_Methodology="Segment",AF59,IF(Segment2_Rev_Methodology="Activity-Based",AF103,IF(Segment2_Rev_Methodology="Backlog",AF177,"--"))) -> 258.30121 | AG35: =IF(Segment2_Rev_Methodology="Segment",AG59,IF(Segment2_Rev_Methodology="Activity-Based",AG103,IF(Segment2_Rev_Methodology="Backlog",AG177,"--"))) -> 271.21627 | AI35: =IFERROR((T35/J35)^(1/3)-1,"--") -> 0.08268096 | AJ35: =IFERROR((AG35/T35)^(1/5)-1,"--") -> 0.063773907
C36: % Growth | G36: =IF($C$25="Annual",'Segment Analysis'!G164,'Segment Analysis'!G184) -> 0.220709 | H36: =IF($C$25="Annual",'Segment Analysis'!H164,'Segment Analysis'!H184) -> -0.5087931 | I36: =IF($C$25="Annual",'Segment Analysis'!I164,'Segment Analysis'!I184) -> -0.42474511 | K36: =IF($C$25="Annual",'Segment Analysis'!K164,'Segment Analysis'!K184) -> 0.14822181 | L36: =IF($C$25="Annual",'Segment Analysis'!L164,'Segment Analysis'!L184) -> -0.098726439 | M36: =IF($C$25="Annual",'Segment Analysis'!M164,'Segment Analysis'!M184) -> -0.3430364 | N36: =IF($C$25="Annual",'Segment Analysis'!N164,'Segment Analysis'!N184) -> 3.5565689 | O36: ='Segment Analysis'!O164 -> -0.3504207 | P36: =IF($C$25="Annual",'Segment Analysis'!P164,'Segment Analysis'!P184) -> 0.071901966 | Q36: =IF($C$25="Annual",'Segment Analysis'!Q164,'Segment Analysis'!Q184) -> -0.46773767 | R36: =IF($C$25="Annual",'Segment Analysis'!R164,'Segment Analysis'!R184) -> 0.38929706 | S36: =IF($C$25="Annual",'Segment Analysis'!S164,'Segment Analysis'!S184) -> 0.67071631 | T36: ='Segment Analysis'!T164 -> 0.9537515 | U36: =IF($C$25="Annual",'Segment Analysis'!U164,'Segment Analysis'!U184) -> -0.39741926 | V36: =IFERROR(V35/U35-1,"--") -> 0.03 | W36: =IFERROR(W35/V35-1,"--") -> 0.05 | X36: =IFERROR(X35/W35-1,"--") -> 0.08 | Y36: =IFERROR(Y35/T35-1,"--") -> -0.091602297 | Z36: =IFERROR(Z35/X35-1,"--") -> 0.065 | AA36: =IFERROR(AA35/Z35-1,"--") -> 0.06 | AB36: =IFERROR(AB35/AA35-1,"--") -> 0.055 | AC36: =IFERROR(AC35/AB35-1,"--") -> 0.05 | AD36: =IFERROR(AD35/Y35-1,"--") -> 0.26515898 | AE36: =IFERROR(AE35/AD35-1,"--") -> 0.07 | AF36: =IFERROR(AF35/AE35-1,"--") -> 0.055 | AG36: =IFERROR(AG35/AF35-1,"--") -> 0.05
C37: % of Total Revenue | F37: ='Segment Analysis'!F17 -> 0.3657543 | G37: ='Segment Analysis'!G17 -> 0.39445306 | H37: ='Segment Analysis'!H17 -> 0.2338716 | I37: ='Segment Analysis'!I17 -> 0.15157641 | J37: ='Segment Analysis'!J17 -> 0.29669808 | K37: ='Segment Analysis'!K17 -> 0.15699353 | L37: ='Segment Analysis'!L17 -> 0.13944324 | M37: ='Segment Analysis'!M17 -> 0.092788032 | ... U37: ='Segment Analysis'!U17 -> 0.24018232 | V37: =V35/V$30 -> 0.23669025 | W37: =W35/W$30 -> 0.23413712 | X37: =X35/X$30 -> 0.23330988 | Y37: =Y35/Y$30 -> 0.23590874 | Z37: =Z35/Z$30 -> 0.23415271 | AA37: =AA35/AA$30 -> 0.23415271 | AB37: =AB35/AB$30 -> 0.2358649 | AC37: =AC35/AC$30 -> 0.23672629 | ... AG37: =AG35/AG$30 -> 0.23190367
C38: ='Segment Analysis'!C10 -> Segment 3 Revenue | F38: ='Segment Analysis'!F10 -> 0 | G38: ='Segment Analysis'!G10 -> 0 | H38: ='Segment Analysis'!H10 -> 0 | I38: ='Segment Analysis'!I10 -> 0 | J38: ='Segment Analysis'!J10 -> 0 | K38: ='Segment Analysis'!K10 -> 0 | L38: ='Segment Analysis'!L10 -> 0 | M38: ='Segment Analysis'!M10 -> 0 | ... U38: ='Segment Analysis'!U10 -> 0 | V38: =IF(Segment3_Rev_Methodology="Segment",V65,IF(Segment3_Rev_Methodology="Activity-Based",V115,IF(Segment3_Rev_Methodology="Backlog",V189,"--"))) -> 0 | W38: =IF(Segment3_Rev_Methodology="Segment",W65,IF(Segment3_Rev_Methodology="Activity-Based",W115,IF(Segment3_Rev_Methodology="Backlog",W189,"--"))) -> 0 | X38: =IF(Segment3_Rev_Methodology="Segment",X65,IF(Segment3_Rev_Methodology="Activity-Based",X115,IF(Segment3_Rev_Methodology="Backlog",X189,"--"))) -> 0 | Y38: =SUM(U38:X38) -> 0 | Z38: =IF(Segment3_Rev_Methodology="Segment",Z65,IF(Segment3_Rev_Methodology="Activity-Based",Z115,IF(Segment3_Rev_Methodology="Backlog",Z189,"--"))) -> 0 | AA38: =IF(Segment3_Rev_Methodology="Segment",AA65,IF(Segment3_Rev_Methodology="Activity-Based",AA115,IF(Segment3_Rev_Methodology="Backlog",AA189,"--"))) -> 0 | AB38: =IF(Segment3_Rev_Methodology="Segment",AB65,IF(Segment3_Rev_Methodology="Activity-Based",AB115,IF(Segment3_Rev_Methodology="Backlog",AB189,"--"))) -> 0 | AC38: =IF(Segment3_Rev_Methodology="Segment",AC65,IF(Segment3_Rev_Methodology="Activity-Based",AC115,IF(Segment3_Rev_Methodology="Backlog",AC189,"--"))) -> 0 | AD38: =SUM(Z38:AC38) -> 0 | AE38: =IF(Segment3_Rev_Methodology="Segment",AE65,IF(Segment3_Rev_Methodology="Activity-Based",AE115,IF(Segment3_Rev_Methodology="Backlog",AE189,"--"))) -> 0 | AF38: =IF(Segment3_Rev_Methodology="Segment",AF65,IF(Segment3_Rev_Methodology="Activity-Based",AF115,IF(Segment3_Rev_Methodology="Backlog",AF189,"--"))) -> 0 | AG38: =IF(Segment3_Rev_Methodology="Segment",AG65,IF(Segment3_Rev_Methodology="Activity-Based",AG115,IF(Segment3_Rev_Methodology="Backlog",AG189,"--"))) -> 0 | AI38: =IFERROR((T38/J38)^(1/3)-1,"--") -> -- | AJ38: =IFERROR((AG38/T38)^(1/5)-1,"--") -> --
