Workbook
Name al: '[3]2010 Labor Rates 091130'!$A$161
Name al09salary: [3]Salaries!$G$13
Name al10salary: [3]Salaries!$K$13
Name alid: '[3]2010 Labor Rates 091130'!$E$168
Name alname: [3]Salaries!$A$13
Name aprpto: [3]Vacation!$I$56
Name augpto: [3]Vacation!$M$56
Name avg_Health_and_Welfare: [4]PBCFringe!$Q$22
Name bf: '[3]2010 Labor Rates 091130'!$A$239
Name bf09salary: [3]Salaries!$G$18
Name bf10salary: [3]Salaries!$K$18
Name bfid: '[3]2010 Labor Rates 091130'!$E$246
Name bfname: [3]Salaries!$A$18
Name Bonus_estimate_2011: [4]PBCFringe!$B$100
Name Case_Scenario: [5]Cover!$F$22
Name Case_Scenario: #REF!
Name Case_Scenario: Cover!$F$17
Name cc: '[3]2010 Labor Rates 091130'!$A$135
Name cc09salary: [3]Salaries!$G$11
Name cc10salary: [3]Salaries!$K$11
Name ccid: '[3]2010 Labor Rates 091130'!$E$142
Name ccname: [3]Salaries!$A$11
Name Ccy: [6]data!$A$5
Name cf: '[3]2010 Labor Rates 091130'!$A$148
Name cf09salary: [3]Salaries!$G$12
Name cf10salary: [3]Salaries!$K$12
Name cfid: '[3]2010 Labor Rates 091130'!$E$155
Name cfname: [3]Salaries!$A$12
Name ck: '[3]2010 Labor Rates 091130'!$A$213
Name ck09salary: [3]Salaries!$G$17
Name ck10salary: [3]Salaries!$K$17
Name ckid: '[3]2010 Labor Rates 091130'!$E$220
Name ckname: [3]Salaries!$A$17
Name Company_Cyclical_Multiples_Data: '[5]Multiples Data'!$C$14:$H$26
Name Company_Cyclical_Multiples_Data: #REF!
Name Company_Name: [5]Cover!$F$19
Name Company_Name: #REF!
Name Company_Name: [8]Cover!$F$19
Name Company_Rev_Methodology: '[5]Revenue Build'!$C$7
Name Company_Rev_Methodology: #REF!
Name Cost_of_Debt: [5]WACC!$G$17
Name Cost_of_Debt: #REF!
Name Cost_of_Equity: [5]WACC!$G$25
Name Cost_of_Equity: #REF!
Name Cost_of_Preferred: [5]WACC!$G$10
Name Cost_of_Preferred: #REF!
Name cs: '[3]2010 Labor Rates 091130'!$A$252
Name cs09salary: [3]Salaries!$G$19
Name cs10salary: [3]Salaries!$K$19
Name csid: '[3]2010 Labor Rates 091130'!$E$259
Name csname: [3]Salaries!$A$19
Name Current_Date: [5]Cover!$F$27
Name Current_Date: #REF!
Name Current_Salary: '[9]Planning Worksheet'!$C:$C
Name CV: '[3]2010 Labor Rates 091130'!$A$5
Name cv09salary: [3]Salaries!$G$2
Name cv10salary: [3]Salaries!$K$2
Name cvid: '[3]2010 Labor Rates 091130'!$E$12
Name cvname: [3]Salaries!$A$2
Name Cycle_Period_Toggle: [5]Valuation!$G$221

Sheet Cover
B3: Model Assumptions: | J3: Return Summary:
J5: Sum of the Parts Analysis
J7: Implied Share Price | N7: =Valuation!L16 -> 113.45876
J8: % Return | N8: =Valuation!L17 -> 0.26121347
B13: Company Name | F13: KKR & Co., Inc.
B14: Ticker | F14: KKR
B17: Case Scenario | F17: Base
B19: Last Fiscal Year | F19: 46022
B20: Next Fiscal Year | F20: =F19+365 -> 46387
B21: Last Fiscal Quarter Reported | F21: 4Q
B22: Current Valuation Date | F22: 46091
B24: Current Share Price | F24: 89.96
B25: 52-Week High | F25: 153.87
B26: 52-Week Low | F26: 84.52
B32: Model Note:
B33: To remain consistent with Street reporting, all numbers are pulled from investor presentations that are released each quarter.

Sheet Revenue Build
B2: Report
AF4: CAGR
A5: x | B5: Summary | C5: =Model!E2 -> 1Q23 | D5: =Model!F2 -> 2Q23 | E5: =Model!G2 -> 3Q23 | F5: =Model!H2 -> 4Q23 | G5: =Model!I2 -> 2023 | H5: =Model!J2 -> 1Q24 | I5: =Model!K2 -> 2Q24 | J5: =Model!L2 -> 3Q24 | ... AD5: =Model!AF2 -> 2030e | AF5: Historical | AG5: Projected
B7: =+Model!B11 -> Fee-Related Earnings | C7: =+SUM(C9,C11,C13,C15,C17) -> 548578 | D7: =+SUM(D9,D11,D13,D15,D17) -> 602309 | E7: =+SUM(E9,E11,E13,E15,E17) -> 557525 | F7: =+SUM(F9,F11,F13,F15,F17) -> 675374 | G7: =+SUM(C7:F7) -> 2383786 | H7: =+SUM(H9,H11,H13,H15,H17) -> 668741 | I7: =+SUM(I9,I11,I13,I15,I17) -> 755397 | J7: =+SUM(J9,J11,J13,J15,J17) -> 1000673 | K7: =+SUM(K9,K11,K13,K15,K17) -> 842985 | L7: =+SUM(H7:K7) -> 3267796 | M7: =+SUM(M9,M11,M13,M15,M17) -> 822603 | N7: =+SUM(N9,N11,N13,N15,N17) -> 886754 | O7: =+SUM(O9,O11,O13,O15,O17) -> 1032936 | P7: =+SUM(P9,P11,P13,P15,P17) -> 972020 | Q7: =+SUM(M7:P7) -> 3714313 | R7: =SUM(R9,R11,R13,R15,R17) -> 1034171.5 | S7: =SUM(S9,S11,S13,S15,S17) -> 1114538.8 | T7: =SUM(T9,T11,T13,T15,T17) -> 1174421.9 | U7: =SUM(U9,U11,U13,U15,U17) -> 1180505.5 | V7: =SUM(R7:U7) -> 4503637.7 | W7: =SUM(W9,W11,W13,W15,W17) -> 1232755.9 | X7: =SUM(X9,X11,X13,X15,X17) -> 1336605.3 | Y7: =SUM(Y9,Y11,Y13,Y15,Y17) -> 1398143.1 | Z7: =SUM(Z9,Z11,Z13,Z15,Z17) -> 1390318.5 | AA7: =SUM(W7:Z7) -> 5357822.8 | AB7: =SUM(AB9,AB11,AB13,AB15,AB17) -> 5922058 | AC7: =SUM(AC9,AC11,AC13,AC15,AC17) -> 6585176.2 | AD7: =SUM(AD9,AD11,AD13,AD15,AD17) -> 7117956.6 | AF7: =IFERROR((Q7/G7)^(1/3)-1,"--") -> 0.15932111 | AG7: =IFERROR((AD7/Q7)^(1/5)-1,"--") -> 0.13892563
B8: % Growth | D8: =D7/C7-1 -> 0.097945962 | E8: =E7/D7-1 -> -0.074353862 | F8: =F7/E7-1 -> 0.21137886 | G8: 0 | H8: =+H7/F7-1 -> -0.009821225 | I8: =I7/H7-1 -> 0.12958081 | J8: =J7/I7-1 -> 0.32469814 | K8: =K7/J7-1 -> -0.15758195 | L8: 0 | M8: =+M7/K7-1 -> -0.024178366 | N8: =N7/M7-1 -> 0.077985371 | O8: =O7/N7-1 -> 0.16485068 | P8: =P7/O7-1 -> -0.058973644 | Q8: 0 | R8: =R7/P7-1 -> 0.06394051 | S8: =S7/Q7-1 -> -0.69993406 | T8: =T7/R7-1 -> 0.13561621 | U8: =U7/S7-1 -> 0.059187446 | V8: =V7/Q7-1 -> 0.21250892 | W8: =W7/U7-1 -> 0.044261054 | X8: =X7/V7-1 -> -0.70321651 | Y8: =Y7/W7-1 -> 0.13416051 | Z8: =Z7/X7-1 -> 0.040186258 | AA8: =AA7/V7-1 -> 0.18966561 | AB8: =AB7/Z7-1 -> 3.2594974 | AC8: =AC7/AA7-1 -> 0.22907688 | AD8: =AD7/AB7-1 -> 0.20193971
B9: =Model!B6 -> Management Fees | C9: ='Segment Analysis'!E7 -> 738156 | D9: ='Segment Analysis'!F7 -> 748888 | E9: ='Segment Analysis'!G7 -> 758700 | F9: ='Segment Analysis'!H7 -> 784581 | G9: =+SUM(C9:F9) -> 3030325 | H9: ='Segment Analysis'!J7 -> 815327 | I9: ='Segment Analysis'!K7 -> 847307 | J9: ='Segment Analysis'!L7 -> 892629 | K9: ='Segment Analysis'!M7 -> 906118 | L9: =+SUM(H9:K9) -> 3461381 | M9: ='Segment Analysis'!O7 -> 917334 | N9: ='Segment Analysis'!P7 -> 995763 | O9: ='Segment Analysis'!Q7 -> 1063553 | P9: ='Segment Analysis'!R7 -> 1124191 | Q9: =+SUM(M9:P9) -> 4100841 | R9: =R22 -> 1143864.3 | S9: =S22 -> 1185043.5 | T9: =T22 -> 1241925.5 | U9: =U22 -> 1291602.6 | V9: =SUM(R9:U9) -> 4862435.9 | W9: =W22 -> 1346495.7 | X9: =X22 -> 1397662.5 | Y9: =Y22 -> 1453569 | Z9: =Z22 -> 1504443.9 | AA9: =SUM(W9:Z9) -> 5702171.1 | AB9: =AB22 -> 6295196.9 | AC9: =AC22 -> 7230033.7 | AD9: =AD22 -> 8014492.3 | AF9: =IFERROR((Q9/G9)^(1/3)-1,"--") -> 0.10610046 | AG9: =IFERROR((AD9/Q9)^(1/5)-1,"--") -> 0.1434064
B10: % Growth | D10: =D23 -> 0.014538932 | E10: =E23 -> 0.013102093 | F10: =F23 -> 0.034112297 | G10: =+G23 -> 0 | H10: =+H9/F9-1 -> 0.039187796 | I10: =I23 -> 0.039223526 | J10: =J23 -> 0.053489467 | K10: =K23 -> 0.015111541 | L10: =+L23 -> 0.14224745 | M10: =+M9/K9-1 -> 0.012378079 | N10: =N23 -> 0.085496668 | O10: =O23 -> 0.068078448 | P10: =P23 -> 0.057014554 | Q10: =+Q23 -> 0.18474129 | R10: =R23 -> 0.0175 | S10: =S23 -> 0.036 | T10: =T23 -> 0.048 | U10: =U23 -> 0.04 | V10: =V23 -> 0.18571676 | W10: =W23 -> 0.0425 | X10: =X23 -> 0.038 | Y10: =Y23 -> 0.04 | ... AD10: =AD23 -> 0.1085
B11: =Model!B7 -> Transaction and Monitoring Fees | C11: ='Segment Analysis'!E8 -> 142179 | D11: ='Segment Analysis'!F8 -> 190228 | E11: ='Segment Analysis'!G8 -> 124014 | F11: ='Segment Analysis'!H8 -> 264233 | G11: =+SUM(C11:F11) -> 720654 | H11: ='Segment Analysis'!J8 -> 152084 | I11: ='Segment Analysis'!K8 -> 222858 | J11: ='Segment Analysis'!L8 -> 467145 | K11: ='Segment Analysis'!M8 -> 323797 | L11: =+SUM(H11:K11) -> 1165884 | M11: ='Segment Analysis'!O8 -> 261509 | N11: ='Segment Analysis'!P8 -> 234249 | O11: ='Segment Analysis'!Q8 -> 328124 | P11: ='Segment Analysis'!R8 -> 268695 | Q11: =+SUM(M11:P11) -> 1092577 | R11: =R28 -> 297579.71 | S11: =S28 -> 331057.43 | T11: =T28 -> 335195.65 | U11: =U28 -> 355307.39 | V11: =SUM(R11:U11) -> 1319140.2 | W11: =W28 -> 353530.85 | X11: =X28 -> 396838.38 | Y11: =Y28 -> 400806.76 | Z11: =Z28 -> 418843.07 | AA11: =SUM(W11:Z11) -> 1570019.1 | AB11: =AB28 -> 1703470.7 | AC11: =AC28 -> 1682177.3 | AD11: =AD28 -> 1593863 | AF11: =IFERROR((Q11/G11)^(1/3)-1,"--") -> 0.14879292 | AG11: =IFERROR((AD11/Q11)^(1/5)-1,"--") -> 0.078449433
B12: % Growth | D12: =D29 -> 0.33794724 | E12: =E29 -> -0.34807704 | F12: =F29 -> 1.1306707 | G12: =+G29 -> 0 | H12: =+H11/F11-1 -> -0.42443222 | I12: =I29 -> 0.46536125 | J12: =J29 -> 1.0961554 | K12: =K29 -> -0.30685975 | L12: =+L29 -> 0.61781382 | M12: =+M11/K11-1 -> -0.19236744 | N12: =N29 -> -0.10424115 | O12: =O29 -> 0.40074878 | P12: =P29 -> -0.1811175 | Q12: =+Q29 -> -0.062876753 | R12: =R29 -> 0.1075 | S12: =S29 -> 0.1125 | T12: =T29 -> 0.0125 | U12: =U29 -> 0.06 | V12: =V29 -> 0.20736587 | W12: =W29 -> -0.005 | X12: =X29 -> 0.1225 | Y12: =Y29 -> 0.01 | ... AD12: =AD29 -> -0.0525
B13: =Model!B8 -> Fee-Related Performance Revenues | C13: ='Segment Analysis'!E9 -> 21741 | D13: ='Segment Analysis'!F9 -> 28352 | E13: ='Segment Analysis'!G9 -> 20436 | F13: ='Segment Analysis'!H9 -> 23898 | G13: =+SUM(C13:F13) -> 94427 | H13: ='Segment Analysis'!J9 -> 19101 | I13: ='Segment Analysis'!K9 -> 37145 | J13: ='Segment Analysis'!L9 -> 56655 | K13: ='Segment Analysis'!M9 -> 25091 | L13: =+SUM(H13:K13) -> 137992 | M13: ='Segment Analysis'!O9 -> 21277 | N13: ='Segment Analysis'!P9 -> 53737 | O13: ='Segment Analysis'!Q9 -> 73177 | P13: ='Segment Analysis'!R9 -> 33593 | Q13: =+SUM(M13:P13) -> 181784 | R13: =R34 -> 38296.02 | S13: =S34 -> 67018.035 | T13: =T34 -> 83772.544 | U13: =U34 -> 47750.35 | V13: =SUM(R13:U13) -> 236836.95 | W13: =W34 -> 41542.804 | X13: =X34 -> 82877.895 | Y13: =Y34 -> 104011.76 | Z13: =Z34 -> 55126.232 | AA13: =SUM(W13:Z13) -> 283558.69 | AB13: =AB34 -> 351612.77 | AC13: =AC34 -> 502806.27 | AD13: =AD34 -> 698900.71 | AF13: =IFERROR((Q13/G13)^(1/3)-1,"--") -> 0.2439984 | AG13: =IFERROR((AD13/Q13)^(1/5)-1,"--") -> 0.30909742
B14: % Growth | D14: =D41 -> 0.071838656 | E14: =E41 -> -0.06649547 | F14: =F41 -> 0.18768854 | G14: =G41 -> 0 | H14: =+H13/F13-1 -> -0.20072809 | I14: =I41 -> 0.12244555 | J14: =J41 -> 0.27916338 | K14: =K41 -> -0.11397277 | L14: =L41 -> -0.036307284 | M14: =+M13/K13-1 -> -0.1520067 | N14: =N41 -> 0.069683508 | O14: =O41 -> 0.14107791 | P14: =P41 -> -0.025964502 | Q14: =Q41 -> 0.12807374 | R14: =R41 -> 0.03 | S14: =S41 -> 0.0675 | T14: =T41 -> 0.0475 | U14: =U41 -> 0.015 | ... AD14: =AD41 -> 0.09
B15: =Model!B9 -> Fee-Related Compensation | C15: ='Segment Analysis'!E10 -> -203094 | D15: ='Segment Analysis'!F10 -> -217684 | E15: ='Segment Analysis'!G10 -> -203209 | F15: ='Segment Analysis'!H10 -> -241349 | G15: =+SUM(C15:F15) -> -865336 | H15: ='Segment Analysis'!J10 -> -172640 | I15: ='Segment Analysis'!K10 -> -193779 | J15: ='Segment Analysis'!L10 -> -247875 | K15: ='Segment Analysis'!M10 -> -219624 | L15: =+SUM(H15:K15) -> -833918 | M15: ='Segment Analysis'!O10 -> -210021 | N15: ='Segment Analysis'!P10 -> -224656 | O15: ='Segment Analysis'!Q10 -> -256350 | P15: ='Segment Analysis'!R10 -> -249694 | Q15: =+SUM(M15:P15) -> -940721 | R15: =R40 -> -257184.82 | S15: =S40 -> -274544.8 | T15: =T40 -> -287585.67 | U15: =U40 -> -291899.46 | V15: =SUM(R15:U15) -> -1111214.7 | W15: =W40 -> -302115.94 | X15: =X40 -> -324774.63 | Y15: =Y40 -> -337765.62 | Z15: =Z40 -> -341143.28 | AA15: =SUM(W15:Z15) -> -1305799.5 | AB15: =AB40 -> -1462495.4 | AC15: =AC40 -> -1652619.8 | AD15: =AD40 -> -1801355.6 | AF15: =IFERROR((Q15/G15)^(1/3)-1,"--") -> 0.028234147 | AG15: =IFERROR((AD15/Q15)^(1/5)-1,"--") -> 0.13874825
B16: % Growth | D16: =D41 -> 0.071838656 | E16: =E41 -> -0.06649547 | F16: =F41 -> 0.18768854 | G16: =G41 -> 0 | H16: =+H15/F15-1 -> -0.28468732 | I16: =I41 -> 0.12244555 | J16: =J41 -> 0.27916338 | K16: =K41 -> -0.11397277 | L16: =L41 -> -0.036307284 | M16: =+M15/K15-1 -> -0.04372473 | N16: =N41 -> 0.069683508 | O16: =O41 -> 0.14107791 | P16: =P41 -> -0.025964502 | Q16: =Q41 -> 0.12807374 | R16: =R41 -> 0.03 | S16: =S41 -> 0.0675 | T16: =T41 -> 0.0475 | U16: =U41 -> 0.015 | ... AD16: =AD41 -> 0.09
B17: =Model!B10 -> Other Operating Expenses | C17: ='Segment Analysis'!E11 -> -150404 | D17: ='Segment Analysis'!F11 -> -147475 | E17: ='Segment Analysis'!G11 -> -142416 | F17: ='Segment Analysis'!H11 -> -155989 | G17: =+SUM(C17:F17) -> -596284 | H17: ='Segment Analysis'!J11 -> -145131 | I17: ='Segment Analysis'!K11 -> -158134 | J17: ='Segment Analysis'!L11 -> -167881 | K17: ='Segment Analysis'!M11 -> -192397 | L17: =+SUM(H17:K17) -> -663543 | M17: ='Segment Analysis'!O11 -> -167496 | N17: ='Segment Analysis'!P11 -> -172339 | O17: ='Segment Analysis'!Q11 -> -175568 | P17: ='Segment Analysis'!R11 -> -204765 | Q17: =+SUM(M17:P17) -> -720168 | R17: =R46 -> -188383.8 | S17: =S46 -> -194035.31 | T17: =T46 -> -198886.2 | U17: =U46 -> -222255.32 | V17: =SUM(R17:U17) -> -803560.64 | W17: =W46 -> -206697.45 | X17: =X46 -> -215998.84 | Y17: =Y46 -> -222478.8 | Z17: =Z46 -> -246951.47 | AA17: =SUM(W17:Z17) -> -892126.56 | AB17: =AB46 -> -965727.01 | AC17: =AC46 -> -1177221.2 | AD17: =AD46 -> -1387943.8 | AF17: =IFERROR((Q17/G17)^(1/3)-1,"--") -> 0.064944287 | AG17: =IFERROR((AD17/Q17)^(1/5)-1,"--") -> 0.14021727
B18: % Growth | D18: =D47 -> -0.019474216 | E18: =E47 -> -0.034304119 | F18: =F47 -> 0.095305303 | G18: =G47 -> 0 | H18: =+H17/F17-1 -> -0.069607472 | I18: =I47 -> 0.089594918 | J18: =J47 -> 0.061637598 | K18: =K47 -> 0.14603201 | L18: =L47 -> 0.11279692 | M18: =+M17/K17-1 -> -0.12942509 | N18: =N47 -> 0.028914123 | O18: =O47 -> 0.018736328 | P18: =P47 -> 0.16630024 | Q18: =Q47 -> 0.085337348 | R18: =R47 -> -0.08 | S18: =S47 -> 0.03 | T18: =T47 -> 0.025 | U18: =U47 -> 0.1175 | ... AD18: =AD47 -> 0.179
A20: x | B20: Growth Rate | C20: =C5 -> 1Q23 | D20: =D5 -> 2Q23 | E20: =E5 -> 3Q23 | F20: =F5 -> 4Q23 | G20: =G5 -> 2023 | H20: =H5 -> 1Q24 | I20: =I5 -> 2Q24 | J20: =J5 -> 3Q24 | ... AD20: =AD5 -> 2030e
B22: =B9 -> Management Fees | C22: =C9 -> 738156 | D22: =D9 -> 748888 | E22: =E9 -> 758700 | F22: =F9 -> 784581 | G22: =G9 -> 3030325 | H22: =H9 -> 815327 | I22: =I9 -> 847307 | ... Q22: =Q9 -> 4100841 | R22: =P22*(1+R23) -> 1143864.3 | S22: =R22*(1+S23) -> 1185043.5 | T22: =S22*(1+T23) -> 1241925.5 | U22: =T22*(1+U23) -> 1291602.6 | V22: =SUM(R22:U22) -> 4862435.9 | W22: =U22*(1+W23) -> 1346495.7 | X22: =W22*(1+X23) -> 1397662.5 | Y22: =X22*(1+Y23) -> 1453569 | Z22: =Y22*(1+Z23) -> 1504443.9 | AA22: =SUM(W22:Z22) -> 5702171.1 | AB22: =AA22*(1+AB23) -> 6295196.9 | AC22: =AB22*(1+AC23) -> 7230033.7 | AD22: =AC22*(1+AD23) -> 8014492.3
B23: =B10 -> % Growth | D23: =D22/C22-1 -> 0.014538932 | E23: =E22/D22-1 -> 0.013102093 | F23: =F22/E22-1 -> 0.034112297 | G23: 0 | H23: =H22/F22-1 -> 0.039187796 | I23: =I22/H22-1 -> 0.039223526 | J23: =J22/I22-1 -> 0.053489467 | K23: =K22/J22-1 -> 0.015111541 | L23: =L22/G22-1 -> 0.14224745 | M23: =M22/K22-1 -> 0.012378079 | N23: =N22/M22-1 -> 0.085496668 | O23: =O22/N22-1 -> 0.068078448 | P23: =P22/O22-1 -> 0.057014554 | Q23: =Q22/L22-1 -> 0.18474129 | R23: =IF(Case_Scenario="Bull",R24,IF(Case_Scenario="Base",R25,IF(Case_Scenario="Bear",R26,"N/A"))) -> 0.0175 | S23: =IF(Case_Scenario="Bull",S24,IF(Case_Scenario="Base",S25,IF(Case_Scenario="Bear",S26,"N/A"))) -> 0.036 | T23: =IF(Case_Scenario="Bull",T24,IF(Case_Scenario="Base",T25,IF(Case_Scenario="Bear",T26,"N/A"))) -> 0.048 | U23: =IF(Case_Scenario="Bull",U24,IF(Case_Scenario="Base",U25,IF(Case_Scenario="Bear",U26,"N/A"))) -> 0.04 | V23: =V22/Q22-1 -> 0.18571676 | W23: =IF(Case_Scenario="Bull",W24,IF(Case_Scenario="Base",W25,IF(Case_Scenario="Bear",W26,"N/A"))) -> 0.0425 | X23: =IF(Case_Scenario="Bull",X24,IF(Case_Scenario="Base",X25,IF(Case_Scenario="Bear",X26,"N/A"))) -> 0.038 | Y23: =IF(Case_Scenario="Bull",Y24,IF(Case_Scenario="Base",Y25,IF(Case_Scenario="Bear",Y26,"N/A"))) -> 0.04 | Z23: =IF(Case_Scenario="Bull",Z24,IF(Case_Scenario="Base",Z25,IF(Case_Scenario="Bear",Z26,"N/A"))) -> 0.035 | AA23: =AA22/V22-1 -> 0.17269846 | AB23: =IF(Case_Scenario="Bull",AB24,IF(Case_Scenario="Base",AB25,IF(Case_Scenario="Bear",AB26,"N/A"))) -> 0.104 | AC23: =IF(Case_Scenario="Bull",AC24,IF(Case_Scenario="Base",AC25,IF(Case_Scenario="Bear",AC26,"N/A"))) -> 0.1485 | AD23: =IF(Case_Scenario="Bull",AD24,IF(Case_Scenario="Base",AD25,IF(Case_Scenario="Bear",AD26,"N/A"))) -> 0.1085
B24: Bull Case | R24: =R25+1% -> 0.0275 | S24: =S25+1% -> 0.046 | T24: =T25+1% -> 0.058 | U24: =U25+1% -> 0.05 | W24: =W25+1% -> 0.0525 | X24: =X25+1% -> 0.048 | Y24: =Y25+1% -> 0.05 | Z24: =Z25+1% -> 0.045 | AB24: =AB25+1% -> 0.114 | AC24: =AC25+1% -> 0.1585 | AD24: =AD25+1% -> 0.1185
B25: Base Case | R25: 0.0175 | S25: 0.036 | T25: 0.048 | U25: 0.04 | W25: 0.0425 | X25: 0.038 | Y25: 0.04 | Z25: 0.035 | AB25: 0.104 | AC25: 0.1485 | AD25: =+AC25-4% -> 0.1085
B26: Bear Case | R26: =R25-1% -> 0.0075 | S26: =S25-1% -> 0.026 | T26: =T25-1% -> 0.038 | U26: =U25-1% -> 0.03 | W26: =W25-1% -> 0.0325 | X26: =X25-1% -> 0.028 | Y26: =Y25-1% -> 0.03 | Z26: =Z25-1% -> 0.025 | AB26: =AB25-1% -> 0.094 | AC26: =AC25-1% -> 0.1385 | AD26: =AD25-1% -> 0.0985
B28: =B11 -> Transaction and Monitoring Fees | C28: =C11 -> 142179 | D28: =D11 -> 190228 | E28: =E11 -> 124014 | F28: =F11 -> 264233 | G28: =G11 -> 720654 | H28: =H11 -> 152084 | I28: =I11 -> 222858 | ... Q28: =Q11 -> 1092577 | R28: =P28*(1+R29) -> 297579.71 | S28: =R28*(1+S29) -> 331057.43 | T28: =S28*(1+T29) -> 335195.65 | U28: =T28*(1+U29) -> 355307.39 | V28: =SUM(R28:U28) -> 1319140.2 | W28: =U28*(1+W29) -> 353530.85 | X28: =W28*(1+X29) -> 396838.38 | Y28: =X28*(1+Y29) -> 400806.76 | Z28: =Y28*(1+Z29) -> 418843.07 | AA28: =SUM(W28:Z28) -> 1570019.1 | AB28: =AA28*(1+AB29) -> 1703470.7 | AC28: =AB28*(1+AC29) -> 1682177.3 | AD28: =AC28*(1+AD29) -> 1593863
B29: =B16 -> % Growth | D29: =D28/C28-1 -> 0.33794724 | E29: =E28/D28-1 -> -0.34807704 | F29: =F28/E28-1 -> 1.1306707 | G29: 0 | H29: =H28/F28-1 -> -0.42443222 | I29: =I28/H28-1 -> 0.46536125 | J29: =J28/I28-1 -> 1.0961554 | K29: =K28/J28-1 -> -0.30685975 | L29: =L28/G28-1 -> 0.61781382 | M29: =M28/K28-1 -> -0.19236744 | N29: =N28/M28-1 -> -0.10424115 | O29: =O28/N28-1 -> 0.40074878 | P29: =P28/O28-1 -> -0.1811175 | Q29: =Q28/L28-1 -> -0.062876753 | R29: =IF(Case_Scenario="Bull",R30,IF(Case_Scenario="Base",R31,IF(Case_Scenario="Bear",R32,"N/A"))) -> 0.1075 | S29: =IF(Case_Scenario="Bull",S30,IF(Case_Scenario="Base",S31,IF(Case_Scenario="Bear",S32,"N/A"))) -> 0.1125 | T29: =IF(Case_Scenario="Bull",T30,IF(Case_Scenario="Base",T31,IF(Case_Scenario="Bear",T32,"N/A"))) -> 0.0125 | U29: =IF(Case_Scenario="Bull",U30,IF(Case_Scenario="Base",U31,IF(Case_Scenario="Bear",U32,"N/A"))) -> 0.06 | V29: =V28/Q28-1 -> 0.20736587 | W29: =IF(Case_Scenario="Bull",W30,IF(Case_Scenario="Base",W31,IF(Case_Scenario="Bear",W32,"N/A"))) -> -0.005 | X29: =IF(Case_Scenario="Bull",X30,IF(Case_Scenario="Base",X31,IF(Case_Scenario="Bear",X32,"N/A"))) -> 0.1225 | Y29: =IF(Case_Scenario="Bull",Y30,IF(Case_Scenario="Base",Y31,IF(Case_Scenario="Bear",Y32,"N/A"))) -> 0.01 | Z29: =IF(Case_Scenario="Bull",Z30,IF(Case_Scenario="Base",Z31,IF(Case_Scenario="Bear",Z32,"N/A"))) -> 0.045 | AA29: =AA28/V28-1 -> 0.19018364 | AB29: =IF(Case_Scenario="Bull",AB30,IF(Case_Scenario="Base",AB31,IF(Case_Scenario="Bear",AB32,"N/A"))) -> 0.085 | AC29: =IF(Case_Scenario="Bull",AC30,IF(Case_Scenario="Base",AC31,IF(Case_Scenario="Bear",AC32,"N/A"))) -> -0.0125 | AD29: =IF(Case_Scenario="Bull",AD30,IF(Case_Scenario="Base",AD31,IF(Case_Scenario="Bear",AD32,"N/A"))) -> -0.0525
B30: Bull Case | R30: =R31+1% -> 0.1175 | S30: =S31+1% -> 0.1225 | T30: =T31+1% -> 0.0225 | U30: =U31+1% -> 0.07 | W30: =W31+1% -> 0.005 | X30: =X31+1% -> 0.1325 | Y30: =Y31+1% -> 0.02 | Z30: =Z31+1% -> 0.055 | AB30: =AB31+1% -> 0.095 | AC30: =AC31+1% -> -0.0025 | AD30: =AD31+1% -> -0.0425
B31: Base Case | R31: 0.1075 | S31: 0.1125 | T31: 0.0125 | U31: 0.06 | W31: -0.005 | X31: 0.1225 | Y31: 0.01 | Z31: 0.045 | AB31: 0.085 | AC31: -0.0125 | AD31: =+AC31-4% -> -0.0525
B32: Bear Case | R32: =R31-1% -> 0.0975 | S32: =S31-1% -> 0.1025 | T32: =T31-1% -> 0.0025 | U32: =U31-1% -> 0.05 | W32: =W31-1% -> -0.015 | X32: =X31-1% -> 0.1125 | Y32: =Y31-1% -> 0 | Z32: =Z31-1% -> 0.035 | AB32: =AB31-1% -> 0.075 | AC32: =AC31-1% -> -0.0225 | AD32: =AD31-1% -> -0.0625
B34: =B13 -> Fee-Related Performance Revenues | C34: =C13 -> 21741 | D34: =D13 -> 28352 | E34: =E13 -> 20436 | F34: =F13 -> 23898 | G34: =G13 -> 94427 | H34: =H13 -> 19101 | I34: =I13 -> 37145 | ... Q34: =Q13 -> 181784 | R34: =P34*(1+R35) -> 38296.02 | S34: =R34*(1+S35) -> 67018.035 | T34: =S34*(1+T35) -> 83772.544 | U34: =T34*(1+U35) -> 47750.35 | V34: =SUM(R34:U34) -> 236836.95 | W34: =U34*(1+W35) -> 41542.804 | X34: =W34*(1+X35) -> 82877.895 | Y34: =X34*(1+Y35) -> 104011.76 | Z34: =Y34*(1+Z35) -> 55126.232 | AA34: =SUM(W34:Z34) -> 283558.69 | AB34: =AA34*(1+AB35) -> 351612.77 | AC34: =AB34*(1+AC35) -> 502806.27 | AD34: =AC34*(1+AD35) -> 698900.71
B35: % Growth | D35: =D34/C34-1 -> 0.30407985 | E35: =E34/D34-1 -> -0.27920429 | F35: =F34/E34-1 -> 0.16940693 | G35: 0 | H35: =H34/F34-1 -> -0.20072809 | I35: =I34/H34-1 -> 0.94466258 | J35: =J34/I34-1 -> 0.52523893 | K35: =K34/J34-1 -> -0.55712647 | L35: =L34/G34-1 -> 0.46136169 | M35: =M34/K34-1 -> -0.1520067 | N35: =N34/M34-1 -> 1.525591 | O35: =O34/N34-1 -> 0.36176191 | P35: =P34/O34-1 -> -0.54093499 | Q35: =Q34/L34-1 -> 0.31735173 | R35: =IF(Case_Scenario="Bull",R36,IF(Case_Scenario="Base",R37,IF(Case_Scenario="Bear",R38,"N/A"))) -> 0.14 | S35: =IF(Case_Scenario="Bull",S36,IF(Case_Scenario="Base",S37,IF(Case_Scenario="Bear",S38,"N/A"))) -> 0.75 | T35: =IF(Case_Scenario="Bull",T36,IF(Case_Scenario="Base",T37,IF(Case_Scenario="Bear",T38,"N/A"))) -> 0.25 | U35: =IF(Case_Scenario="Bull",U36,IF(Case_Scenario="Base",U37,IF(Case_Scenario="Bear",U38,"N/A"))) -> -0.43 | V35: =V34/Q34-1 -> 0.30284815 | W35: =IF(Case_Scenario="Bull",W36,IF(Case_Scenario="Base",W37,IF(Case_Scenario="Bear",W38,"N/A"))) -> -0.13 | X35: =IF(Case_Scenario="Bull",X36,IF(Case_Scenario="Base",X37,IF(Case_Scenario="Bear",X38,"N/A"))) -> 0.995 | Y35: =IF(Case_Scenario="Bull",Y36,IF(Case_Scenario="Base",Y37,IF(Case_Scenario="Bear",Y38,"N/A"))) -> 0.255 | Z35: =IF(Case_Scenario="Bull",Z36,IF(Case_Scenario="Base",Z37,IF(Case_Scenario="Bear",Z38,"N/A"))) -> -0.47 | AA35: =AA34/V34-1 -> 0.19727387 | AB35: =IF(Case_Scenario="Bull",AB36,IF(Case_Scenario="Base",AB37,IF(Case_Scenario="Bear",AB38,"N/A"))) -> 0.24 | AC35: =IF(Case_Scenario="Bull",AC36,IF(Case_Scenario="Base",AC37,IF(Case_Scenario="Bear",AC38,"N/A"))) -> 0.43 | AD35: =IF(Case_Scenario="Bull",AD36,IF(Case_Scenario="Base",AD37,IF(Case_Scenario="Bear",AD38,"N/A"))) -> 0.39
B36: Bull Case | R36: =R37+1% -> 0.15 | S36: =S37+1% -> 0.76 | T36: =T37+1% -> 0.26 | U36: =U37+1% -> -0.42 | W36: =W37+1% -> -0.12 | X36: =X37+1% -> 1.005 | Y36: =Y37+1% -> 0.265 | Z36: =Z37+1% -> -0.46 | AB36: =AB37+1% -> 0.25 | AC36: =AC37+1% -> 0.44 | AD36: =AD37+1% -> 0.4
B37: Base Case | R37: 0.14 | S37: 0.75 | T37: 0.25 | U37: -0.43 | W37: -0.13 | X37: 0.995 | Y37: 0.255 | Z37: -0.47 | AB37: 0.24 | AC37: 0.43 | AD37: =+AC37-4% -> 0.39
B38: Bear Case | R38: =R37-1% -> 0.13 | S38: =S37-1% -> 0.74 | T38: =T37-1% -> 0.24 | U38: =U37-1% -> -0.44 | W38: =W37-1% -> -0.14 | X38: =X37-1% -> 0.985 | Y38: =Y37-1% -> 0.245 | Z38: =Z37-1% -> -0.48 | AB38: =AB37-1% -> 0.23 | AC38: =AC37-1% -> 0.42 | AD38: =AD37-1% -> 0.38
B40: =B15 -> Fee-Related Compensation | C40: =C15 -> -203094 | D40: =D15 -> -217684 | E40: =E15 -> -203209 | F40: =F15 -> -241349 | G40: =G15 -> -865336 | H40: =H15 -> -172640 | I40: =I15 -> -193779 | ... Q40: =Q15 -> -940721 | R40: =P40*(1+R41) -> -257184.82 | S40: =R40*(1+S41) -> -274544.8 | T40: =S40*(1+T41) -> -287585.67 | U40: =T40*(1+U41) -> -291899.46 | V40: =SUM(R40:U40) -> -1111214.7 | W40: =U40*(1+W41) -> -302115.94 | X40: =W40*(1+X41) -> -324774.63 | Y40: =X40*(1+Y41) -> -337765.62 | Z40: =Y40*(1+Z41) -> -341143.28 | AA40: =SUM(W40:Z40) -> -1305799.5 | AB40: =AA40*(1+AB41) -> -1462495.4 | AC40: =AB40*(1+AC41) -> -1652619.8 | AD40: =AC40*(1+AD41) -> -1801355.6
B41: =B23 -> % Growth | D41: =D40/C40-1 -> 0.071838656 | E41: =E40/D40-1 -> -0.06649547 | F41: =F40/E40-1 -> 0.18768854 | G41: 0 | H41: =H40/F40-1 -> -0.28468732 | I41: =I40/H40-1 -> 0.12244555 | J41: =J40/I40-1 -> 0.27916338 | K41: =K40/J40-1 -> -0.11397277 | L41: =L40/G40-1 -> -0.036307284 | M41: =M40/K40-1 -> -0.04372473 | N41: =N40/M40-1 -> 0.069683508 | O41: =O40/N40-1 -> 0.14107791 | P41: =P40/O40-1 -> -0.025964502 | Q41: =Q40/L40-1 -> 0.12807374 | R41: =IF(Case_Scenario="Bull",R42,IF(Case_Scenario="Base",R43,IF(Case_Scenario="Bear",R44,"N/A"))) -> 0.03 | S41: =IF(Case_Scenario="Bull",S42,IF(Case_Scenario="Base",S43,IF(Case_Scenario="Bear",S44,"N/A"))) -> 0.0675 | T41: =IF(Case_Scenario="Bull",T42,IF(Case_Scenario="Base",T43,IF(Case_Scenario="Bear",T44,"N/A"))) -> 0.0475 | U41: =IF(Case_Scenario="Bull",U42,IF(Case_Scenario="Base",U43,IF(Case_Scenario="Bear",U44,"N/A"))) -> 0.015 | V41: =V40/Q40-1 -> 0.18123731 | W41: =IF(Case_Scenario="Bull",W42,IF(Case_Scenario="Base",W43,IF(Case_Scenario="Bear",W44,"N/A"))) -> 0.035 | X41: =IF(Case_Scenario="Bull",X42,IF(Case_Scenario="Base",X43,IF(Case_Scenario="Bear",X44,"N/A"))) -> 0.075 | Y41: =IF(Case_Scenario="Bull",Y42,IF(Case_Scenario="Base",Y43,IF(Case_Scenario="Bear",Y44,"N/A"))) -> 0.04 | Z41: =IF(Case_Scenario="Bull",Z42,IF(Case_Scenario="Base",Z43,IF(Case_Scenario="Bear",Z44,"N/A"))) -> 0.01 | AA41: =AA40/V40-1 -> 0.17510992 | AB41: =IF(Case_Scenario="Bull",AB42,IF(Case_Scenario="Base",AB43,IF(Case_Scenario="Bear",AB44,"N/A"))) -> 0.12 | AC41: =IF(Case_Scenario="Bull",AC42,IF(Case_Scenario="Base",AC43,IF(Case_Scenario="Bear",AC44,"N/A"))) -> 0.13 | AD41: =IF(Case_Scenario="Bull",AD42,IF(Case_Scenario="Base",AD43,IF(Case_Scenario="Bear",AD44,"N/A"))) -> 0.09
B42: Bull Case | R42: =R43+1% -> 0.04 | S42: =S43+1% -> 0.0775 | T42: =T43+1% -> 0.0575 | U42: =U43+1% -> 0.025 | W42: =W43+1% -> 0.045 | X42: =X43+1% -> 0.085 | Y42: =Y43+1% -> 0.05 | Z42: =Z43+1% -> 0.02 | AB42: =AB43+1% -> 0.13 | AC42: =AC43+1% -> 0.14 | AD42: =AD43+1% -> 0.1
B43: Base Case | R43: 0.03 | S43: 0.0675 | T43: 0.0475 | U43: 0.015 | W43: 0.035 | X43: 0.075 | Y43: 0.04 | Z43: 0.01 | AB43: 0.12 | AC43: 0.13 | AD43: =+AC43-4% -> 0.09
B44: Bear Case | R44: =R43-1% -> 0.02 | S44: =S43-1% -> 0.0575 | T44: =T43-1% -> 0.0375 | U44: =U43-1% -> 0.005 | W44: =W43-1% -> 0.025 | X44: =X43-1% -> 0.065 | Y44: =Y43-1% -> 0.03 | Z44: =Z43-1% -> 0 | AB44: =AB43-1% -> 0.11 | AC44: =AC43-1% -> 0.12 | AD44: =AD43-1% -> 0.08
B46: =B17 -> Other Operating Expenses | C46: =C17 -> -150404 | D46: =D17 -> -147475 | E46: =E17 -> -142416 | F46: =F17 -> -155989 | G46: =G17 -> -596284 | H46: =H17 -> -145131 | I46: =I17 -> -158134 | ... Q46: =Q17 -> -720168 | R46: =P46*(1+R47) -> -188383.8 | S46: =R46*(1+S47) -> -194035.31 | T46: =S46*(1+T47) -> -198886.2 | U46: =T46*(1+U47) -> -222255.32 | V46: =SUM(R46:U46) -> -803560.64 | W46: =U46*(1+W47) -> -206697.45 | X46: =W46*(1+X47) -> -215998.84 | Y46: =X46*(1+Y47) -> -222478.8 | Z46: =Y46*(1+Z47) -> -246951.47 | AA46: =SUM(W46:Z46) -> -892126.56 | AB46: =AA46*(1+AB47) -> -965727.01 | AC46: =AB46*(1+AC47) -> -1177221.2 | AD46: =AC46*(1+AD47) -> -1387943.8
B47: =B29 -> % Growth | D47: =D46/C46-1 -> -0.019474216 | E47: =E46/D46-1 -> -0.034304119 | F47: =F46/E46-1 -> 0.095305303 | G47: 0 | H47: =H46/F46-1 -> -0.069607472 | I47: =I46/H46-1 -> 0.089594918 | J47: =J46/I46-1 -> 0.061637598 | K47: =K46/J46-1 -> 0.14603201 | L47: =L46/G46-1 -> 0.11279692 | M47: =M46/K46-1 -> -0.12942509 | N47: =N46/M46-1 -> 0.028914123 | O47: =O46/N46-1 -> 0.018736328 | P47: =P46/O46-1 -> 0.16630024 | Q47: =Q46/L46-1 -> 0.085337348 | R47: =IF(Case_Scenario="Bull",R48,IF(Case_Scenario="Base",R49,IF(Case_Scenario="Bear",R50,"N/A"))) -> -0.08 | S47: =IF(Case_Scenario="Bull",S48,IF(Case_Scenario="Base",S49,IF(Case_Scenario="Bear",S50,"N/A"))) -> 0.03 | T47: =IF(Case_Scenario="Bull",T48,IF(Case_Scenario="Base",T49,IF(Case_Scenario="Bear",T50,"N/A"))) -> 0.025 | U47: =IF(Case_Scenario="Bull",U48,IF(Case_Scenario="Base",U49,IF(Case_Scenario="Bear",U50,"N/A"))) -> 0.1175 | V47: =V46/Q46-1 -> 0.11579609 | W47: =IF(Case_Scenario="Bull",W48,IF(Case_Scenario="Base",W49,IF(Case_Scenario="Bear",W50,"N/A"))) -> -0.07 | X47: =IF(Case_Scenario="Bull",X48,IF(Case_Scenario="Base",X49,IF(Case_Scenario="Bear",X50,"N/A"))) -> 0.045 | Y47: =IF(Case_Scenario="Bull",Y48,IF(Case_Scenario="Base",Y49,IF(Case_Scenario="Bear",Y50,"N/A"))) -> 0.03 | Z47: =IF(Case_Scenario="Bull",Z48,IF(Case_Scenario="Base",Z49,IF(Case_Scenario="Bear",Z50,"N/A"))) -> 0.11 | AA47: =AA46/V46-1 -> 0.11021686 | AB47: =IF(Case_Scenario="Bull",AB48,IF(Case_Scenario="Base",AB49,IF(Case_Scenario="Bear",AB50,"N/A"))) -> 0.0825 | AC47: =IF(Case_Scenario="Bull",AC48,IF(Case_Scenario="Base",AC49,IF(Case_Scenario="Bear",AC50,"N/A"))) -> 0.219 | AD47: =IF(Case_Scenario="Bull",AD48,IF(Case_Scenario="Base",AD49,IF(Case_Scenario="Bear",AD50,"N/A"))) -> 0.179
B48: Bull Case | R48: =R49+1% -> -0.07 | S48: =S49+1% -> 0.04 | T48: =T49+1% -> 0.035 | U48: =U49+1% -> 0.1275 | W48: =W49+1% -> -0.06 | X48: =X49+1% -> 0.055 | Y48: =Y49+1% -> 0.04 | Z48: =Z49+1% -> 0.12 | AB48: =AB49+1% -> 0.0925 | AC48: =AC49+1% -> 0.229 | AD48: =AD49+1% -> 0.189
B49: Base Case | R49: -0.08 | S49: 0.03 | T49: 0.025 | U49: 0.1175 | W49: -0.07 | X49: 0.045 | Y49: 0.03 | Z49: 0.11 | AB49: 0.0825 | AC49: 0.219 | AD49: =+AC49-4% -> 0.179
...

Sheet Model
A2: x | B2: Income Statement | E2: ='Segment Analysis'!E2 -> 1Q23 | F2: ='Segment Analysis'!F2 -> 2Q23 | G2: ='Segment Analysis'!G2 -> 3Q23 | H2: ='Segment Analysis'!H2 -> 4Q23 | I2: ='Segment Analysis'!I2 -> 2023 | J2: ='Segment Analysis'!J2 -> 1Q24 | K2: ='Segment Analysis'!K2 -> 2Q24 | L2: ='Segment Analysis'!L2 -> 3Q24 | ... AF2: ='Segment Analysis'!AF2 -> 2030e
B5: Asset Management
B6: {=+'Segment Analysis'!B7:B11} -> Management Fees | E6: =+'Segment Analysis'!E7 -> 738156 | F6: =+'Segment Analysis'!F7 -> 748888 | G6: =+'Segment Analysis'!G7 -> 758700 | H6: =+'Segment Analysis'!H7 -> 784581 | I6: =+SUM(E6:H6) -> 3030325 | J6: =+'Segment Analysis'!J7 -> 815327 | K6: =+'Segment Analysis'!K7 -> 847307 | L6: =+'Segment Analysis'!L7 -> 892629 | M6: =+'Segment Analysis'!M7 -> 906118 | N6: =+SUM(J6:M6) -> 3461381 | O6: =+'Segment Analysis'!O7 -> 917334 | P6: =+'Segment Analysis'!P7 -> 995763 | Q6: =+'Segment Analysis'!Q7 -> 1063553 | R6: =+'Segment Analysis'!R7 -> 1124191 | S6: =+SUM(O6:R6) -> 4100841 | T6: =+'Revenue Build'!R9 -> 1143864.3 | U6: =+'Revenue Build'!S9 -> 1185043.5 | V6: =+'Revenue Build'!T9 -> 1241925.5 | W6: =+'Revenue Build'!U9 -> 1291602.6 | X6: =+SUM(T6:W6) -> 4862435.9 | Y6: =+'Revenue Build'!W9 -> 1346495.7 | Z6: =+'Revenue Build'!X9 -> 1397662.5 | AA6: =+'Revenue Build'!Y9 -> 1453569 | AB6: =+'Revenue Build'!Z9 -> 1504443.9 | AC6: =+SUM(Y6:AB6) -> 5702171.1 | AD6: =+'Revenue Build'!AB9 -> 6295196.9 | AE6: =+'Revenue Build'!AC9 -> 7230033.7 | AF6: =+'Revenue Build'!AD9 -> 8014492.3
B7: Transaction and Monitoring Fees | E7: =+'Segment Analysis'!E8 -> 142179 | F7: =+'Segment Analysis'!F8 -> 190228 | G7: =+'Segment Analysis'!G8 -> 124014 | H7: =+'Segment Analysis'!H8 -> 264233 | I7: =+SUM(E7:H7) -> 720654 | J7: =+'Segment Analysis'!J8 -> 152084 | K7: =+'Segment Analysis'!K8 -> 222858 | L7: =+'Segment Analysis'!L8 -> 467145 | M7: =+'Segment Analysis'!M8 -> 323797 | N7: =+SUM(J7:M7) -> 1165884 | O7: =+'Segment Analysis'!O8 -> 261509 | P7: =+'Segment Analysis'!P8 -> 234249 | Q7: =+'Segment Analysis'!Q8 -> 328124 | R7: =+'Segment Analysis'!R8 -> 268695 | S7: =+SUM(O7:R7) -> 1092577 | T7: =+'Segment Analysis'!T8 -> 297579.71 | U7: =+'Segment Analysis'!U8 -> 331057.43 | V7: =+'Segment Analysis'!V8 -> 335195.65 | W7: =+'Segment Analysis'!W8 -> 355307.39 | X7: =+SUM(T7:W7) -> 1319140.2 | Y7: =+'Segment Analysis'!Y8 -> 353530.85 | Z7: =+'Segment Analysis'!Z8 -> 396838.38 | AA7: =+'Segment Analysis'!AA8 -> 400806.76 | AB7: =+'Segment Analysis'!AB8 -> 418843.07 | AC7: =+SUM(Y7:AB7) -> 1570019.1 | AD7: =+'Segment Analysis'!AD8 -> 1703470.7 | AE7: =+'Segment Analysis'!AE8 -> 1682177.3 | AF7: =+'Segment Analysis'!AF8 -> 1593863
B8: Fee-Related Performance Revenues | E8: =+'Segment Analysis'!E9 -> 21741 | F8: =+'Segment Analysis'!F9 -> 28352 | G8: =+'Segment Analysis'!G9 -> 20436 | H8: =+'Segment Analysis'!H9 -> 23898 | I8: =+SUM(E8:H8) -> 94427 | J8: =+'Segment Analysis'!J9 -> 19101 | K8: =+'Segment Analysis'!K9 -> 37145 | L8: =+'Segment Analysis'!L9 -> 56655 | M8: =+'Segment Analysis'!M9 -> 25091 | N8: =+SUM(J8:M8) -> 137992 | O8: =+'Segment Analysis'!O9 -> 21277 | P8: =+'Segment Analysis'!P9 -> 53737 | Q8: =+'Segment Analysis'!Q9 -> 73177 | R8: =+'Segment Analysis'!R9 -> 33593 | S8: =+SUM(O8:R8) -> 181784 | T8: =+'Segment Analysis'!T9 -> 38296.02 | U8: =+'Segment Analysis'!U9 -> 67018.035 | V8: =+'Segment Analysis'!V9 -> 83772.544 | W8: =+'Segment Analysis'!W9 -> 47750.35 | X8: =+SUM(T8:W8) -> 236836.95 | Y8: =+'Segment Analysis'!Y9 -> 41542.804 | Z8: =+'Segment Analysis'!Z9 -> 82877.895 | AA8: =+'Segment Analysis'!AA9 -> 104011.76 | AB8: =+'Segment Analysis'!AB9 -> 55126.232 | AC8: =+SUM(Y8:AB8) -> 283558.69 | AD8: =+'Segment Analysis'!AD9 -> 351612.77 | AE8: =+'Segment Analysis'!AE9 -> 502806.27 | AF8: =+'Segment Analysis'!AF9 -> 698900.71
B9: Fee-Related Compensation | E9: =+'Segment Analysis'!E10 -> -203094 | F9: =+'Segment Analysis'!F10 -> -217684 | G9: =+'Segment Analysis'!G10 -> -203209 | H9: =+'Segment Analysis'!H10 -> -241349 | I9: =+SUM(E9:H9) -> -865336 | J9: =+'Segment Analysis'!J10 -> -172640 | K9: =+'Segment Analysis'!K10 -> -193779 | L9: =+'Segment Analysis'!L10 -> -247875 | M9: =+'Segment Analysis'!M10 -> -219624 | N9: =+SUM(J9:M9) -> -833918 | O9: =+'Segment Analysis'!O10 -> -210021 | P9: =+'Segment Analysis'!P10 -> -224656 | Q9: =+'Segment Analysis'!Q10 -> -256350 | R9: =+'Segment Analysis'!R10 -> -249694 | S9: =+SUM(O9:R9) -> -940721 | T9: =+'Segment Analysis'!T10 -> -257184.82 | U9: =+'Segment Analysis'!U10 -> -274544.8 | V9: =+'Segment Analysis'!V10 -> -287585.67 | W9: =+'Segment Analysis'!W10 -> -291899.46 | X9: =+SUM(T9:W9) -> -1111214.7 | Y9: =+'Segment Analysis'!Y10 -> -302115.94 | Z9: =+'Segment Analysis'!Z10 -> -324774.63 | AA9: =+'Segment Analysis'!AA10 -> -337765.62 | AB9: =+'Segment Analysis'!AB10 -> -341143.28 | AC9: =+SUM(Y9:AB9) -> -1305799.5 | AD9: =+'Segment Analysis'!AD10 -> -1462495.4 | AE9: =+'Segment Analysis'!AE10 -> -1652619.8 | AF9: =+'Segment Analysis'!AF10 -> -1801355.6
B10: Other Operating Expenses | E10: =+'Segment Analysis'!E11 -> -150404 | F10: =+'Segment Analysis'!F11 -> -147475 | G10: =+'Segment Analysis'!G11 -> -142416 | H10: =+'Segment Analysis'!H11 -> -155989 | I10: =+SUM(E10:H10) -> -596284 | J10: =+'Segment Analysis'!J11 -> -145131 | K10: =+'Segment Analysis'!K11 -> -158134 | L10: =+'Segment Analysis'!L11 -> -167881 | M10: =+'Segment Analysis'!M11 -> -192397 | N10: =+SUM(J10:M10) -> -663543 | O10: =+'Segment Analysis'!O11 -> -167496 | P10: =+'Segment Analysis'!P11 -> -172339 | Q10: =+'Segment Analysis'!Q11 -> -175568 | R10: =+'Segment Analysis'!R11 -> -204765 | S10: =+SUM(O10:R10) -> -720168 | T10: =+'Segment Analysis'!T11 -> -188383.8 | U10: =+'Segment Analysis'!U11 -> -194035.31 | V10: =+'Segment Analysis'!V11 -> -198886.2 | W10: =+'Segment Analysis'!W11 -> -222255.32 | X10: =+SUM(T10:W10) -> -803560.64 | Y10: =+'Segment Analysis'!Y11 -> -206697.45 | Z10: =+'Segment Analysis'!Z11 -> -215998.84 | AA10: =+'Segment Analysis'!AA11 -> -222478.8 | AB10: =+'Segment Analysis'!AB11 -> -246951.47 | AC10: =+SUM(Y10:AB10) -> -892126.56 | AD10: =+'Segment Analysis'!AD11 -> -965727.01 | AE10: =+'Segment Analysis'!AE11 -> -1177221.2 | AF10: =+'Segment Analysis'!AF11 -> -1387943.8
B11: Fee-Related Earnings | E11: =+SUM(E6:E10) -> 548578 | F11: =+SUM(F6:F10) -> 602309 | G11: =+SUM(G6:G10) -> 557525 | H11: =+SUM(H6:H10) -> 675374 | I11: =+SUM(E11:H11) -> 2383786 | J11: =+SUM(J6:J10) -> 668741 | K11: =+SUM(K6:K10) -> 755397 | L11: =+SUM(L6:L10) -> 1000673 | M11: =+SUM(M6:M10) -> 842985 | N11: =+SUM(J11:M11) -> 3267796 | O11: =+SUM(O6:O10) -> 822603 | P11: =+SUM(P6:P10) -> 886754 | Q11: =+SUM(Q6:Q10) -> 1032936 | R11: =+SUM(R6:R10) -> 972020 | S11: =+SUM(O11:R11) -> 3714313 | T11: =SUM(T6:T10) -> 1034171.5 | U11: =SUM(U6:U10) -> 1114538.8 | V11: =SUM(V6:V10) -> 1174421.9 | W11: =SUM(W6:W10) -> 1180505.5 | X11: =+SUM(T11:W11) -> 4503637.7 | Y11: =SUM(Y6:Y10) -> 1232755.9 | Z11: =SUM(Z6:Z10) -> 1336605.3 | AA11: =SUM(AA6:AA10) -> 1398143.1 | AB11: =SUM(AB6:AB10) -> 1390318.5 | AC11: =+SUM(Y11:AB11) -> 5357822.8 | AD11: =SUM(AD6:AD10) -> 5922058 | AE11: =SUM(AE6:AE10) -> 6585176.2 | AF11: =SUM(AF6:AF10) -> 7117956.6
B12: % Growth | F12: =+F11/E11-1 -> 0.097945962 | G12: =+G11/F11-1 -> -0.074353862 | H12: =+H11/G11-1 -> 0.21137886 | J12: =+J11/I11-1 -> -0.71946265 | K12: =+K11/J11-1 -> 0.12958081 | L12: =+L11/K11-1 -> 0.32469814 | M12: =+M11/L11-1 -> -0.15758195 | N12: =+N11/I11-1 -> 0.37084285 | O12: =+O11/N11-1 -> -0.74826978 | P12: =+P11/O11-1 -> 0.077985371 | Q12: =+Q11/P11-1 -> 0.16485068 | R12: =+R11/Q11-1 -> -0.058973644 | S12: =+S11/N11-1 -> 0.13664164 | T12: =+T11/S11-1 -> -0.72157127 | U12: =+U11/T11-1 -> 0.077711833 | V12: =+V11/U11-1 -> 0.053728996 | W12: =+W11/V11-1 -> 0.0051801263 | X12: =+X11/S11-1 -> 0.21250892 | Y12: =+Y11/X11-1 -> -0.72627551 | Z12: =+Z11/Y11-1 -> 0.084241634 | AA12: =+AA11/Z11-1 -> 0.046040365 | AB12: =+AB11/AA11-1 -> -0.005596445 | AC12: =+AC11/X11-1 -> 0.18966561 | AD12: =+AD11/AC11-1 -> 0.10531052 | AE12: =+AE11/AD11-1 -> 0.11197429 | AF12: =+AF11/AE11-1 -> 0.080906022
B14: Realized Performance Income (Loss)
B15: Realized Performance Income | E15: 175398 | F15: 149334 | G15: 329266 | H15: =1065389-SUM(E15:G15) -> 411391 | I15: =+SUM(E15:H15) -> 1065389 | J15: 271545 | K15: 482309 | L15: 391920 | M15: =1822115-SUM(J15:L15) -> 676341 | N15: =+SUM(J15:M15) -> 1822115 | O15: 347920 | P15: 418850 | Q15: 930659 | R15: =1879512-SUM(O15:Q15) -> 182083 | S15: =+SUM(O15:R15) -> 1879512 | T15: =+R15*(1+T53) -> 682811.25 | U15: =+T15*(1+U53) -> 792061.05 | V15: =+U15*(1+V53) -> 891068.68 | W15: =+V15*(1+W53) -> 1118291.2 | X15: =+SUM(T15:W15) -> 3484232.2 | Y15: =+W15*(1+Y53) -> 944956.06 | Z15: =+Y15*(1+Z53) -> 1055988.4 | AA15: =+Z15*(1+AA53) -> 1108787.8 | AB15: =+AA15*(1+AB53) -> 1333317.3 | AC15: =+SUM(Y15:AB15) -> 4443049.6 | AD15: =+AC15*(1+AD53) -> 5049525.9 | AE15: =+AD15*(1+AE53) -> 4584464.6 | AF15: =+AE15*(1+AF53) -> 4721998.5
B16: Realized Performance Income Compensation | E16: -114009 | F16: -97085 | G16: -213816 | H16: =+-666440-SUM(E16:G16) -> -241530 | I16: =+SUM(E16:H16) -> -666440 | J16: -193547 | K16: -359470 | L16: -289994 | M16: =+-1213327-SUM(J16:L16) -> -370316 | N16: =+SUM(J16:M16) -> -1213327 | O16: -259931 | P16: -309536 | Q16: -697994 | R16: =+-1387776-SUM(O16:Q16) -> -120315 | S16: =+SUM(O16:R16) -> -1387776 | T16: =+T15*T54 -> -491624.1 | U16: =+U15*U54 -> -572264.11 | V16: =+V15*V54 -> -648252.47 | W16: =+W15*W54 -> -735276.46 | X16: =+SUM(T16:W16) -> -2447417.1 | Y16: =+Y15*Y54 -> -685093.14 | Z16: =+Z15*Z54 -> -768231.56 | AA16: =+AA15*AA54 -> -807197.53 | AB16: =+AB15*AB54 -> -879989.45 | AC16: =+SUM(Y16:AB16) -> -3140511.7 | AD16: =+AD15*AD54 -> -3634143.8 | AE16: =+AE15*AE54 -> -3295771.6 | AF16: =+AF15*AF54 -> -3398422.3
B17: Net Realized Performance Income (Loss) | E17: =+SUM(E15:E16) -> 61389 | F17: =+SUM(F15:F16) -> 52249 | G17: =+SUM(G15:G16) -> 115450 | H17: =+SUM(H15:H16) -> 169861 | I17: =+SUM(E17:H17) -> 398949 | J17: =+SUM(J15:J16) -> 77998 | K17: =+SUM(K15:K16) -> 122839 | L17: =+SUM(L15:L16) -> 101926 | M17: =+SUM(M15:M16) -> 306025 | N17: =+SUM(J17:M17) -> 608788 | O17: =+SUM(O15:O16) -> 87989 | P17: =+SUM(P15:P16) -> 109314 | Q17: =+SUM(Q15:Q16) -> 232665 | R17: =+SUM(R15:R16) -> 61768 | S17: =+SUM(O17:R17) -> 491736 | T17: =+SUM(T15:T16) -> 191187.15 | U17: =+SUM(U15:U16) -> 219796.94 | V17: =+SUM(V15:V16) -> 242816.22 | W17: =+SUM(W15:W16) -> 383014.73 | X17: =+SUM(T17:W17) -> 1036815 | Y17: =+SUM(Y15:Y16) -> 259862.92 | Z17: =+SUM(Z15:Z16) -> 287756.84 | AA17: =+SUM(AA15:AA16) -> 301590.29 | AB17: =+SUM(AB15:AB16) -> 453327.9 | AC17: =+SUM(Y17:AB17) -> 1302537.9 | AD17: =+SUM(AD15:AD16) -> 1415382.1 | AE17: =+SUM(AE15:AE16) -> 1288693 | AF17: =+SUM(AF15:AF16) -> 1323576.2
B19: Realized Performance Income (Loss)
B20: Realized Performance Income | E20: 198094 | F20: 114675 | G20: 231196 | H20: =690727-SUM(E20:G20) -> 146762 | I20: =+SUM(E20:H20) -> 690727 | J20: 134753 | K20: 138546 | L20: 151546 | M20: =534668-SUM(J20:L20) -> 109823 | N20: =+SUM(J20:M20) -> 534668 | O20: 217957 | P20: 153998 | Q20: 4436 | R20: =403455-SUM(O20:Q20) -> 27064 | S20: =+SUM(O20:R20) -> 403455 | T20: =+R20*(1+T57) -> 198920.4 | U20: =+T20*(1+U57) -> 208866.42 | V20: =+U20*(1+V57) -> 221398.41 | W20: =+V20*(1+W57) -> 270106.05 | X20: =+SUM(T20:W20) -> 899291.28 | Y20: =+W20*(1+Y57) -> 251198.63 | Z20: =+Y20*(1+Z57) -> 268782.53 | AA20: =+Z20*(1+AA57) -> 275233.32 | AB20: =+AA20*(1+AB57) -> 297251.98 | AC20: =+SUM(Y20:AB20) -> 1092466.5 | AD20: =+AC20*(1+AD57) -> 1398357.1 | AE20: =+AD20*(1+AE57) -> 1514420.7 | AF20: =+AE20*(1+AF57) -> 1590141.7
B21: Realized Performance Income Compensation | E21: -29714 | F21: -17183 | G21: -34679 | H21: =+-103590-SUM(E21:G21) -> -22014 | I21: =+SUM(E21:H21) -> -103590 | J21: -20211 | K21: -20782 | L21: -22732 | M21: =+-80198-SUM(J21:L21) -> -16473 | N21: =+SUM(J21:M21) -> -80198 | O21: -32694 | P21: -23100 | Q21: -665 | R21: =+-60520-SUM(O21:Q21) -> -4061 | S21: =+SUM(O21:R21) -> -60520 | T21: =+T20*T58 -> -29838.06 | U21: =+U20*U58 -> -31329.963 | V21: =+V20*V58 -> -33209.761 | W21: =+W20*W58 -> -40515.908 | X21: =+SUM(T21:W21) -> -134893.69 | Y21: =+Y20*Y58 -> -37679.795 | Z21: =+Z20*Z58 -> -40317.38 | AA21: =+AA20*AA58 -> -41284.997 | AB21: =+AB20*AB58 -> -44587.797 | AC21: =+SUM(Y21:AB21) -> -163869.97 | AD21: =+AD20*AD58 -> -209753.56 | AE21: =+AE20*AE58 -> -221105.42 | AF21: =+AF20*AF58 -> -232160.69
B22: Net Realized Performance Income (Loss) | E22: =+SUM(E20:E21) -> 168380 | F22: =+SUM(F20:F21) -> 97492 | G22: =+SUM(G20:G21) -> 196517 | H22: =+SUM(H20:H21) -> 124748 | I22: =+SUM(E22:H22) -> 587137 | J22: =+SUM(J20:J21) -> 114542 | K22: =+SUM(K20:K21) -> 117764 | L22: =+SUM(L20:L21) -> 128814 | M22: =+SUM(M20:M21) -> 93350 | N22: =+SUM(J22:M22) -> 454470 | O22: =+SUM(O20:O21) -> 185263 | P22: =+SUM(P20:P21) -> 130898 | Q22: =+SUM(Q20:Q21) -> 3771 | R22: =+SUM(R20:R21) -> 23003 | S22: =+SUM(O22:R22) -> 342935 | T22: =+SUM(T20:T21) -> 169082.34 | U22: =+SUM(U20:U21) -> 177536.46 | V22: =+SUM(V20:V21) -> 188188.64 | W22: =+SUM(W20:W21) -> 229590.15 | X22: =+SUM(T22:W22) -> 764397.59 | Y22: =+SUM(Y20:Y21) -> 213518.84 | Z22: =+SUM(Z20:Z21) -> 228465.15 | AA22: =+SUM(AA20:AA21) -> 233948.32 | AB22: =+SUM(AB20:AB21) -> 252664.18 | AC22: =+SUM(Y22:AB22) -> 928596.49 | AD22: =+SUM(AD20:AD21) -> 1188603.5 | AE22: =+SUM(AE20:AE21) -> 1293315.3 | AF22: =+SUM(AF20:AF21) -> 1357981
B24: Total Asset Management Operating Earnings | E24: =+SUM(E22,E17,E11) -> 778347 | F24: =+SUM(F22,F17,F11) -> 752050 | G24: =+SUM(G22,G17,G11) -> 869492 | H24: =+SUM(H22,H17,H11) -> 969983 | I24: =+SUM(E24:H24) -> 3369872 | J24: =+SUM(J22,J17,J11) -> 861281 | K24: =+SUM(K22,K17,K11) -> 996000 | L24: =+SUM(L22,L17,L11) -> 1231413 | M24: =+SUM(M22,M17,M11) -> 1242360 | N24: =+SUM(J24:M24) -> 4331054 | O24: =+SUM(O22,O17,O11) -> 1095855 | P24: =+SUM(P22,P17,P11) -> 1126966 | Q24: =+SUM(Q22,Q17,Q11) -> 1269372 | R24: =+SUM(R22,R17,R11) -> 1056791 | S24: =+SUM(O24:R24) -> 4548984 | T24: =+SUM(T22,T17,T11) -> 1394440.9 | U24: =+SUM(U22,U17,U11) -> 1511872.2 | V24: =+SUM(V22,V17,V11) -> 1605426.7 | W24: =+SUM(W22,W17,W11) -> 1793110.4 | X24: =+SUM(T24:W24) -> 6304850.3 | Y24: =+SUM(Y22,Y17,Y11) -> 1706137.7 | Z24: =+SUM(Z22,Z17,Z11) -> 1852827.3 | AA24: =+SUM(AA22,AA17,AA11) -> 1933681.7 | AB24: =+SUM(AB22,AB17,AB11) -> 2096310.6 | AC24: =+SUM(Y24:AB24) -> 7588957.3 | AD24: =+SUM(AD22,AD17,AD11) -> 8526043.6 | AE24: =+SUM(AE22,AE17,AE11) -> 9167184.5 | AF24: =+SUM(AF22,AF17,AF11) -> 9799513.8
B26: Insurance
B27: Net Investment Income | E27: 1271255 | F27: 1283794 | G27: 1356407 | H27: 1466361 | I27: =+SUM(E27:H27) -> 5377817 | J27: 1486419 | K27: 1538046 | L27: 1636300 | M27: 1668057 | N27: =+SUM(J27:M27) -> 6328822 | O27: 1729343 | P27: 1788525 | Q27: 1835025 | R27: 1871225 | S27: =+SUM(O27:R27) -> 7224118 | T27: =+R27*(1+T61) -> 1981627.3 | U27: =+T27*(1+U61) -> 1985590.5 | V27: =+U27*(1+V61) -> 2033244.7 | W27: =+V27*(1+W61) -> 2092208.8 | X27: =+SUM(T27:W27) -> 8092671.3 | Y27: =+W27*(1+Y61) -> 2160205.6 | Z27: =+Y27*(1+Z61) -> 2225011.8 | AA27: =+Z27*(1+AA61) -> 2291762.1 | AB27: =+AA27*(1+AB61) -> 2360515 | AC27: =+SUM(Y27:AB27) -> 9037494.4 | AD27: =+AC27*(1+AD61) -> 9728862.7 | AE27: =+AD27*(1+AE61) -> 10830656 | AF27: =+AE27*(1+AF61) -> 11697109
B28: Net Cost of Insurance | E28: =+-750612 -> -750612 | F28: -811677 | G28: -820014 | H28: =+-3283009-SUM(E28:G28) -> -900706 | I28: =+SUM(E28:H28) -> -3283009 | J28: -1003327 | K28: -1070616 | L28: -1166891 | M28: =+-4448886-SUM(J28:L28) -> -1208052 | N28: =+SUM(J28:M28) -> -4448886 | O28: -1241222 | P28: -1277381 | Q28: -1305073 | R28: =+-5229343-SUM(O28:Q28) -> -1405667 | S28: =+SUM(O28:R28) -> -5229343 | T28: =+T62*T$27 -> -1419835.9 | U28: =+U62*U$27 -> -1465365.8 | V28: =+V62*V$27 -> -1505617.7 | W28: =+W62*W$27 -> -1544050.1 | X28: =+SUM(T28:W28) -> -5934869.5 | Y28: =+Y62*Y$27 -> -1588831.2 | Z28: =+Z62*Z$27 -> -1630933.6 | AA28: =+AA62*AA$27 -> -1675278.1 | AB28: =+AB62*AB$27 -> -1721995.7 | AC28: =+SUM(Y28:AB28) -> -6617038.6 | AD28: =+AD62*AD$27 -> -7199358.4 | AE28: =+AE62*AE$27 -> -8003855.1 | AF28: =+AF62*AF$27 -> -8655860.6
B29: General, Administrative, and Other | E29: =+-196714 -> -196714 | F29: -203285 | G29: -204701 | H29: =+-805109-SUM(E29:G29) -> -200409 | I29: =+SUM(E29:H29) -> -805109 | J29: -210252 | K29: -214217 | L29: -230889 | M29: =+-865390-SUM(J29:L29) -> -210032 | N29: =+SUM(J29:M29) -> -865390 | O29: -229349 | P29: -233212 | Q29: -225299 | R29: =+-885380-SUM(O29:Q29) -> -197520 | S29: =+SUM(O29:R29) -> -885380 | T29: =+T63*T$27 -> -326968.5 | U29: =+U63*U$27 -> -327622.44 | V29: =+V63*V$27 -> -330402.26 | W29: =+W63*W$27 -> -326384.57 | X29: =+SUM(T29:W29) -> -1311377.8 | Y29: =+Y63*Y$27 -> -351033.41 | Z29: =+Z63*Z$27 -> -360451.9 | AA29: =+AA63*AA$27 -> -364390.17 | AB29: =+AB63*AB$27 -> -358798.28 | AC29: =+SUM(Y29:AB29) -> -1434673.8 | AD29: =+AD63*AD$27 -> -1483651.6 | AE29: =+AE63*AE$27 -> -1643010.6 | AF29: =+AF63*AF$27 -> -1754566.3
B30: Pre-Tax Operating Earnings Attributable to Non-Controlling Interest | E30: -118817 | F30: -98608 | G30: -121665 | H30: =+-473062-SUM(E30:G30) -> -133972 | I30: =+SUM(E30:H30) -> -473062 | J30: 0 | K30: 0 | L30: 0 | M30: 0 | N30: =+SUM(J30:M30) -> 0 | O30: 0 | P30: 0 | Q30: 0 | R30: 0 | S30: =+SUM(O30:R30) -> 0 | T30: =+T64*T$27 -> 0 | U30: =+U64*U$27 -> 0 | V30: =+V64*V$27 -> 0 | W30: =+W64*W$27 -> 0 | X30: =+SUM(T30:W30) -> 0 | Y30: =+Y64*Y$27 -> 0 | Z30: =+Z64*Z$27 -> 0 | AA30: =+AA64*AA$27 -> 0 | AB30: =+AB64*AB$27 -> 0 | AC30: =+SUM(Y30:AB30) -> 0 | AD30: =+AD64*AD$27 -> 0 | AE30: =+AE64*AE$27 -> 0 | AF30: =+AF64*AF$27 -> 0
B31: Insurance Segment Operating Earnings | E31: =+SUM(E27:E30) -> 205112 | F31: =+SUM(F27:F30) -> 170224 | G31: =+SUM(G27:G30) -> 210027 | H31: =+SUM(H27:H30) -> 231274 | I31: =+SUM(E31:H31) -> 816637 | J31: =+SUM(J27:J30) -> 272840 | K31: =+SUM(K27:K30) -> 253213 | L31: =+SUM(L27:L30) -> 238520 | M31: =+SUM(M27:M30) -> 249973 | N31: =+SUM(J31:M31) -> 1014546 | O31: =+SUM(O27:O30) -> 258772 | P31: =+SUM(P27:P30) -> 277932 | Q31: =+SUM(Q27:Q30) -> 304653 | R31: =+SUM(R27:R30) -> 268038 | S31: =+SUM(O31:R31) -> 1109395 | T31: =SUM(T27:T30) -> 234822.83 | U31: =SUM(U27:U30) -> 192602.28 | V31: =SUM(V27:V30) -> 197224.74 | W31: =SUM(W27:W30) -> 221774.13 | X31: =+SUM(T31:W31) -> 846423.98 | Y31: =SUM(Y27:Y30) -> 220340.97 | Z31: =SUM(Z27:Z30) -> 233626.23 | AA31: =SUM(AA27:AA30) -> 252093.83 | AB31: =SUM(AB27:AB30) -> 279721.02 | AC31: =+SUM(Y31:AB31) -> 985782.06 | AD31: =SUM(AD27:AD30) -> 1045852.7 | AE31: =SUM(AE27:AE30) -> 1183790.7 | AF31: =SUM(AF27:AF30) -> 1286682
B33: Strategic Holdings
B34: Total Strategic Holdings Earnings | E34: 0 | F34: 0 | G34: 0 | H34: 0 | I34: =+SUM(E34:H34) -> 0 | J34: 20720 | K34: 40852 | L34: 6828 | M34: =76211-SUM(J34:L34) -> 7811 | N34: =+SUM(J34:M34) -> 76211 | O34: 31486 | P34: 29121 | Q34: 57663 | R34: =162096-SUM(O34:Q34) -> 43826 | S34: =+SUM(O34:R34) -> 162096 | T34: =+R34*(1+T$66) -> 76695.5 | U34: =+T34*(1+U$66) -> 85132.005 | V34: =+U34*(1+V$66) -> 96199.166 | W34: =+V34*(1+W$66) -> 106781.07 | X34: =+SUM(T34:W34) -> 364807.74 | Y34: =+W34*(1+Y$66) -> 115323.56 | Z34: =+Y34*(1+Z$66) -> 123972.83 | AA34: =+Z34*(1+AA$66) -> 130171.47 | AB34: =+AA34*(1+AB$66) -> 136680.04 | AC34: =+SUM(Y34:AB34) -> 506147.9 | AD34: =+AC34*(1+AD$66) -> 766814.06 | AE34: =+AD34*(1+AE$66) -> 1000692.4 | AF34: =+AE34*(1+AF$66) -> 1150796.2
B36: Total Segment Earnings | E36: =+SUM(E34,E31,E24) -> 983459 | F36: =+SUM(F34,F31,F24) -> 922274 | G36: =+SUM(G34,G31,G24) -> 1079519 | H36: =+SUM(H34,H31,H24) -> 1201257 | I36: =+SUM(E36:H36) -> 4186509 | J36: =+SUM(J34,J31,J24) -> 1154841 | K36: =+SUM(K34,K31,K24) -> 1290065 | L36: =+SUM(L34,L31,L24) -> 1476761 | M36: =+SUM(M34,M31,M24) -> 1500144 | N36: =+SUM(J36:M36) -> 5421811 | O36: =+SUM(O34,O31,O24) -> 1386113 | P36: =+SUM(P34,P31,P24) -> 1434019 | Q36: =+SUM(Q34,Q31,Q24) -> 1631688 | R36: =+SUM(R34,R31,R24) -> 1368655 | S36: =+SUM(O36:R36) -> 5820475 | T36: =+SUM(T34,T31,T24) -> 1705959.3 | U36: =+SUM(U34,U31,U24) -> 1789606.5 | V36: =+SUM(V34,V31,V24) -> 1898850.6 | W36: =+SUM(W34,W31,W24) -> 2121665.6 | X36: =+SUM(T36:W36) -> 7516082 | Y36: =+SUM(Y34,Y31,Y24) -> 2041802.2 | Z36: =+SUM(Z34,Z31,Z24) -> 2210426.4 | AA36: =+SUM(AA34,AA31,AA24) -> 2315947 | AB36: =+SUM(AB34,AB31,AB24) -> 2512711.6 | AC36: =+SUM(Y36:AB36) -> 9080887.2 | AD36: =+SUM(AD34,AD31,AD24) -> 10338710 | AE36: =+SUM(AE34,AE31,AE24) -> 11351668 | AF36: =+SUM(AF34,AF31,AF24) -> 12236992
B38: Interest Expense | E38: -85500 | F38: -92010 | G38: -89429 | H38: =+-357084-SUM(E38:G38) -> -90145 | I38: =+SUM(E38:H38) -> -357084 | J38: =+-74730 -> -74730 | K38: -79952 | L38: =+-88101 -> -88101 | M38: =+-318441-SUM(J38:L38) -> -75658 | N38: =+SUM(J38:M38) -> -318441 | O38: =+-91470 -> -91470 | P38: =+-93607 -> -93607 | Q38: =+-102789 -> -102789 | R38: =+-404800-SUM(O38:Q38) -> -116934 | S38: =+SUM(O38:R38) -> -404800 | T38: =+T69*T$36 -> -110887.35 | U38: =+U69*U$36 -> -111850.41 | V38: =+V69*V$36 -> -111082.76 | W38: =+W69*W$36 -> -111387.44 | X38: =+SUM(T38:W38) -> -445207.97 | Y38: =+Y69*Y$36 -> -104131.91 | Z38: =+Z69*Z$36 -> -104995.25 | AA38: =+AA69*AA$36 -> -105375.59 | AB38: =+AB69*AB$36 -> -105533.89 | AC38: =+SUM(Y38:AB38) -> -420036.64 | AD38: =+AD69*AD$36 -> -436810.51 | AE38: =+AE69*AE$36 -> -465418.37 | AF38: =+AF69*AF$36 -> -489479.68
B39: Income Tax | E39: -173057 | F39: -171542 | G39: -204640 | H39: =+-763382-SUM(E39:G39) -> -214143 | I39: =+SUM(E39:H39) -> -763382 | J39: -216366 | K39: -238244 | L39: =+-294850 -> -294850 | M39: =+-988757-SUM(J39:L39) -> -239297 | N39: =+SUM(J39:M39) -> -988757 | O39: =+-260655 -> -260655 | P39: =+-277062 -> -277062 | Q39: =+-325158 -> -325158 | R39: =+-1108064-SUM(O39:Q39) -> -245189 | S39: =+SUM(O39:R39) -> -1108064 | T39: =+T73*T$36 -> -326691.2 | U39: =+U73*U$36 -> -352552.48 | V39: =+V73*V$36 -> -377871.28 | W39: =+W73*W$36 -> -424333.12 | X39: =+SUM(T39:W39) -> -1481448.1 | Y39: =+Y73*Y$36 -> -416527.65 | Z39: =+Z73*Z$36 -> -445400.91 | AA39: =+AA73*AA$36 -> -470137.24 | AB39: =+AB73*AB$36 -> -505055.04 | AC39: =+SUM(Y39:AB39) -> -1837120.8 | AD39: =+AD73*AD$36 -> -2016048.5 | AE39: =+AE73*AE$36 -> -2156816.8 | AF39: =+AF73*AF$36 -> -2325028.5
B40: Non-Controlling Interest | E40: =+-5626 -> -5626 | F40: -6118 | G40: -5719 | H40: =+-25590-SUM(E40:G40) -> -8127 | I40: =+SUM(E40:H40) -> -25590 | J40: 0 | K40: 0 | L40: 0 | M40: 0 | N40: =+SUM(J40:M40) -> 0 | O40: 0 | P40: 0 | Q40: 0 | R40: 0 | S40: =+SUM(O40:R40) -> 0 | T40: =+T71*T$36 -> 0 | U40: =+U71*U$36 -> 0 | V40: =+V71*V$36 -> 0 | W40: =+W71*W$36 -> 0 | X40: =+SUM(T40:W40) -> 0 | Y40: =+Y71*Y$36 -> 0 | Z40: =+Z71*Z$36 -> 0 | AA40: =+AA71*AA$36 -> 0 | AB40: =+AB71*AB$36 -> 0 | AC40: =+SUM(Y40:AB40) -> 0 | AD40: =+AD71*AD$36 -> 0 | AE40: =+AE71*AE$36 -> 0 | AF40: =+AF71*AF$36 -> 0
B41: Preferred Stock Dividends | E41: 0 | F41: 0 | G41: 0 | H41: 0 | I41: =+SUM(E41:H41) -> 0 | J41: 0 | K41: 0 | L41: 0 | M41: 0 | N41: =+SUM(J41:M41) -> 0 | O41: 0 | P41: 0 | Q41: 0 | R41: 0 | S41: =+SUM(O41:R41) -> 0 | T41: =+T72*T$36 -> 0 | U41: =+U72*U$36 -> 0 | V41: =+V72*V$36 -> 0 | W41: =+W72*W$36 -> 0 | X41: =+SUM(T41:W41) -> 0 | Y41: =+Y72*Y$36 -> 0 | Z41: =+Z72*Z$36 -> 0 | AA41: =+AA72*AA$36 -> 0 | AB41: =+AB72*AB$36 -> 0 | AC41: =+SUM(Y41:AB41) -> 0 | AD41: =+AD72*AD$36 -> 0 | AE41: =+AE72*AE$36 -> 0 | AF41: =+AF72*AF$36 -> 0
B43: Adjusted Net Income (ANI) [Formerly Distributable Earnings] | E43: =+SUM(E36:E41) -> 719276 | F43: =+SUM(F36:F41) -> 652604 | G43: =+SUM(G36:G41) -> 779731 | H43: =+SUM(H36:H41) -> 888842 | I43: =+SUM(E43:H43) -> 3040453 | J43: =+SUM(J36:J41) -> 863745 | K43: =+SUM(K36:K41) -> 971869 | L43: =+SUM(L36:L41) -> 1093810 | M43: =+SUM(M36:M41) -> 1185189 | N43: =+SUM(J43:M43) -> 4114613 | O43: =+SUM(O36:O41) -> 1033988 | P43: =+SUM(P36:P41) -> 1063350 | Q43: =+SUM(Q36:Q41) -> 1203741 | R43: =+SUM(R36:R41) -> 1006532 | S43: =+SUM(O43:R43) -> 4307611 | T43: =+SUM(T36:T41) -> 1268380.7 | U43: =+SUM(U36:U41) -> 1325203.6 | V43: =+SUM(V36:V41) -> 1409896.6 | W43: =+SUM(W36:W41) -> 1585945 | X43: =+SUM(T43:W43) -> 5589426 | Y43: =+SUM(Y36:Y41) -> 1521142.7 | Z43: =+SUM(Z36:Z41) -> 1660030.2 | AA43: =+SUM(AA36:AA41) -> 1740434.2 | AB43: =+SUM(AB36:AB41) -> 1902122.7 | AC43: =+SUM(Y43:AB43) -> 6823729.7 | AD43: =+SUM(AD36:AD41) -> 7885851.4 | AE43: =+SUM(AE36:AE41) -> 8729432.4 | AF43: =+SUM(AF36:AF41) -> 9422483.9
B45: Fee-Related Earnings Per Share | E45: =+E11/E77 -> 0.61594638 | F45: =+F11/F77 -> 0.67499403 | G45: =+G11/G77 -> 0.62745212 | H45: =+H11/H77 -> 0.75952392 | I45: =SUM(E45:H45) -> 2.6779165 | J45: =+J11/J77 -> 0.75076556 | K45: =+K11/K77 -> 0.84458152 | L45: =+L11/L77 -> 1.1187633 | M45: =+M11/M77 -> 0.94106742 | N45: =SUM(J45:M45) -> 3.6551778 | O45: =+O11/O77 -> 0.91785419 | P45: =+P11/P77 -> 0.98496934 | Q45: =+Q11/Q77 -> 1.1470377 | R45: =+R11/R77 -> 1.0787404 | S45: =SUM(O45:R45) -> 4.1286017 | T45: =+T11/T77 -> 1.1484159 | U45: =+U11/U77 -> 1.2369059 | V45: =+V11/V77 -> 1.3026552 | W45: =+W11/W77 -> 1.3075468 | X45: =SUM(T45:W45) -> 4.9955238 | Y45: =+Y11/Y77 -> 1.3622817 | Z45: =+Z11/Z77 -> 1.473769 | AA45: =+AA11/AA77 -> 1.535493 | AB45: =+AB11/AB77 -> 1.5244219 | AC45: =SUM(Y45:AB45) -> 5.8959655 | AD45: =+AD11/AD77 -> 6.4997563 | AE45: =+AE11/AE77 -> 7.3731441 | AF45: =+AF11/AF77 -> 7.9696759
B46: Performance Related Earnings Per Share | E46: =+SUM(E22,E17)/E77 -> 0.25798589 | F46: =+SUM(F22,F17)/F77 -> 0.16781134 | G46: =+SUM(G22,G17)/G77 -> 0.35109521 | H46: =+SUM(H22,H17)/H77 -> 0.33131655 | I46: =SUM(E46:H46) -> 1.108209 | J46: =+SUM(J22,J17)/J77 -> 0.21615603 | K46: =+SUM(K22,K17)/K77 -> 0.26900934 | L46: =+SUM(L22,L17)/L77 -> 0.25796982 | M46: =+SUM(M22,M17)/M77 -> 0.44584281 | N46: =SUM(J46:M46) -> 1.188978 | O46: =+SUM(O22,O17)/O77 -> 0.30489251 | P46: =+SUM(P22,P17)/P77 -> 0.26681746 | Q46: =+SUM(Q22,Q17)/Q77 -> 0.26255355 | R46: =+SUM(R22,R17)/R77 -> 0.094078215 | S46: =SUM(O46:R46) -> 0.92834174 | T46: =+SUM(T22,T17)/T77 -> 0.40006828 | U46: =+SUM(U22,U17)/U77 -> 0.4409573 | V46: =+SUM(V22,V17)/V77 -> 0.47806564 | W46: =+SUM(W22,W17)/W77 -> 0.67853095 | X46: =SUM(T46:W46) -> 1.9976222 | Y46: =+SUM(Y22,Y17)/Y77 -> 0.52312 | Z46: =+SUM(Z22,Z17)/Z77 -> 0.56919717 | AA46: =+SUM(AA22,AA17)/AA77 -> 0.58814849 | AB46: =+SUM(AB22,AB17)/AB77 -> 0.77408866 | AC46: =SUM(Y46:AB46) -> 2.4545543 | AD46: =+SUM(AD22,AD17)/AD77 -> 2.8580051 | AE46: =+SUM(AE22,AE17)/AE77 -> 2.8909658 | AF46: =+SUM(AF22,AF17)/AF77 -> 3.0024266
B47: ANI per Share | E47: =+E43/E77 -> 0.80760703 | F47: =+F43/F77 -> 0.7313585 | G47: =+G43/G77 -> 0.87752813 | H47: =+H43/H77 -> 0.9995895 | I47: =SUM(E47:H47) -> 3.4160832 | J47: =+J43/J77 -> 0.96968782 | K47: =+K43/K77 -> 1.0866109 | L47: =+L43/L77 -> 1.2228914 | M47: =+M43/M77 -> 1.3230873 | N47: =SUM(J47:M47) -> 4.6022774 | O47: =+O43/O77 -> 1.153716 | P47: =+P43/P77 -> 1.1811248 | Q47: =+Q43/Q77 -> 1.3367104 | R47: =+R43/R77 -> 1.1170416 | S47: =SUM(O47:R47) -> 4.7885928 | T47: =+T43/T77 -> 1.4084981 | U47: =+U43/U77 -> 1.4707 | V47: =+V43/V77 -> 1.5638411 | W47: =+W43/W77 -> 1.7566181 | X47: =SUM(T47:W47) -> 6.1996572 | Y47: =+Y43/Y77 -> 1.6809692 | Z47: =+Z43/Z77 -> 1.830384 | AA47: =+AA43/AA77 -> 1.9114098 | AB47: =+AB43/AB77 -> 2.0855923 | AC47: =SUM(Y47:AB47) -> 7.5083553 | AD47: =+AD43/AD77 -> 8.6551183 | AE47: =+AE43/AE77 -> 9.7739773 | AF47: =+AF43/AF77 -> 10.549958
A49: x | B49: Income Statement Analysis | E49: =+E2 -> 1Q23 | F49: =+F2 -> 2Q23 | G49: =+G2 -> 3Q23 | H49: =+H2 -> 4Q23 | I49: =+I2 -> 2023 | J49: =+J2 -> 1Q24 | K49: =+K2 -> 2Q24 | L49: =+L2 -> 3Q24 | ... S49: =+S2 -> 2025 | T49: =T2 -> 1Q26e | U49: =+U2 -> 2Q26e | V49: =+V2 -> 3Q26e | W49: =+W2 -> 4Q26e | X49: =+X2 -> 2026e | Y49: =+Y2 -> 1Q27e | Z49: =+Z2 -> 2Q27e | AA49: =+AA2 -> 3Q27e | AB49: =+AB2 -> 4Q27e | ... AF49: =+AF2 -> 2030e
B50: Drivers
B52: {=+B14:B16} -> Realized Performance Income (Loss)
B53: Realized Performance Income | E53: =+Drivers!E11 -> 0 | F53: =+Drivers!F11 -> -0.14859919 | G53: =+Drivers!G11 -> 1.2048964 | H53: =+Drivers!H11 -> 0.2494184 | I53: 0 | J53: =+Drivers!J11 -> -0.74512127 | K53: =+Drivers!K11 -> 0.77616601 | L53: =+Drivers!L11 -> -0.1874089 | M53: =+Drivers!M11 -> 0.72571188 | N53: =N15/I15-1 -> 0.71028141 | O53: =+Drivers!O11 -> -0.80905706 | P53: =+Drivers!P11 -> 0.20386871 | Q53: =+Drivers!Q11 -> 1.2219386 | R53: =+Drivers!R11 -> -0.80435047 | S53: =S15/N15-1 -> 0.031500207 | T53: =+Drivers!T11 -> 2.75 | U53: =+Drivers!U11 -> 0.16 | V53: =+Drivers!V11 -> 0.125 | W53: =+Drivers!W11 -> 0.255 | X53: =X15/S15-1 -> 0.85379619 | Y53: =+Drivers!Y11 -> -0.155 | Z53: =+Drivers!Z11 -> 0.1175 | AA53: =+Drivers!AA11 -> 0.05 | AB53: =+Drivers!AB11 -> 0.2025 | AC53: =AC15/X15-1 -> 0.27518759 | AD53: =+Drivers!AD11 -> 0.1365 | AE53: =+Drivers!AE11 -> -0.0921 | AF53: =+Drivers!AF11 -> 0.03
B54: Realized Performance Income Compensation | E54: =+Drivers!E17 -> 0 | F54: =+Drivers!F17 -> -0.65011987 | G54: =+Drivers!G17 -> -0.64937163 | H54: =+Drivers!H17 -> -0.5871057 | I54: 0 | J54: =+Drivers!J17 -> -0.71276216 | K54: =+Drivers!K17 -> -0.74531058 | L54: =+Drivers!L17 -> -0.73993162 | M54: =+Drivers!M17 -> -0.54752854 | N54: =N16/N15 -> -0.66588936 | O54: =+Drivers!O17 -> -0.74709991 | P54: =+Drivers!P17 -> -0.73901397 | Q54: =+Drivers!Q17 -> -0.74999973 | R54: =+Drivers!R17 -> -0.66077009 | S54: =S16/S15 -> -0.73837039 | T54: =+Drivers!T17 -> -0.72 | U54: =+Drivers!U17 -> -0.7225 | V54: =+Drivers!V17 -> -0.7275 | W54: =+Drivers!W17 -> -0.6575 | X54: =X16/X15 -> -0.70242654 | Y54: =+Drivers!Y17 -> -0.725 | Z54: =+Drivers!Z17 -> -0.7275 | AA54: =+Drivers!AA17 -> -0.728 | AB54: =+Drivers!AB17 -> -0.66 | AC54: =AC16/AC15 -> -0.70683696 | AD54: =+Drivers!AD17 -> -0.7197 | AE54: =+Drivers!AE17 -> -0.7189 | AF54: =+Drivers!AF17 -> -0.7197
...

Sheet Segment Analysis
E1: 2023 | F1: =E1 -> 2023 | G1: =F1 -> 2023 | H1: =G1 -> 2023 | I1: =H1 -> 2023 | J1: =I1+1 -> 2024 | K1: =J1 -> 2024 | L1: =K1 -> 2024 | M1: =L1 -> 2024 | N1: =M1 -> 2024 | O1: =N1+1 -> 2025 | P1: =O1 -> 2025 | Q1: =P1 -> 2025 | R1: =Q1 -> 2025 | S1: =R1 -> 2025 | T1: =S1+1 -> 2026 | U1: =T1 -> 2026 | V1: =U1 -> 2026 | W1: =V1 -> 2026 | X1: =W1 -> 2026 | Y1: =X1+1 -> 2027 | Z1: =Y1 -> 2027 | AA1: =Z1 -> 2027 | AB1: =AA1 -> 2027 | AC1: =AB1 -> 2027 | AD1: =AC1+1 -> 2028 | AE1: =AD1+1 -> 2029 | AF1: =AE1+1 -> 2030
